 django.request 2020-04-30 12:30:33,077 ERROR    Internal Server Error: /product/csv-categorys
Traceback (most recent call last):
  File "D:\MISC\GITHUB\knit_server//app\products\kviews\csv_ref_categories_view.py", line 80, in category_csv
    decoded_file = file.read().decode('utf-8').splitlines()
AttributeError: 'NoneType' object has no attribute 'read'

During handling of the above exception, another exception occurred:

Traceback (most recent call last):
  File "C:\ProgramData\Miniconda3\lib\site-packages\django\core\handlers\exception.py", line 34, in inner
    response = get_response(request)
  File "C:\ProgramData\Miniconda3\lib\site-packages\django\core\handlers\base.py", line 115, in _get_response
    response = self.process_exception_by_middleware(e, request)
  File "C:\ProgramData\Miniconda3\lib\site-packages\django\core\handlers\base.py", line 113, in _get_response
    response = wrapped_callback(request, *callback_args, **callback_kwargs)
  File "C:\ProgramData\Miniconda3\lib\site-packages\django\views\decorators\csrf.py", line 54, in wrapped_view
    return view_func(*args, **kwargs)
  File "C:\ProgramData\Miniconda3\lib\site-packages\rest_framework\viewsets.py", line 114, in view
    return self.dispatch(request, *args, **kwargs)
  File "C:\ProgramData\Miniconda3\lib\site-packages\rest_framework\views.py", line 505, in dispatch
    response = self.handle_exception(exc)
  File "C:\ProgramData\Miniconda3\lib\site-packages\rest_framework\views.py", line 465, in handle_exception
    self.raise_uncaught_exception(exc)
  File "C:\ProgramData\Miniconda3\lib\site-packages\rest_framework\views.py", line 476, in raise_uncaught_exception
    raise exc
  File "C:\ProgramData\Miniconda3\lib\site-packages\rest_framework\views.py", line 502, in dispatch
    response = handler(request, *args, **kwargs)
  File "D:\MISC\GITHUB\knit_server//app\products\kviews\csv_ref_categories_view.py", line 56, in create
    results = category_csv(request.FILES.get("category"))
  File "D:\MISC\GITHUB\knit_server//app\products\kviews\csv_ref_categories_view.py", line 110, in category_csv
    print("Something went wrong", e)
NameError: name 'e' is not defined
 django.request 2020-04-30 12:31:04,389 ERROR    Internal Server Error: /product/csv-categorys
Traceback (most recent call last):
  File "C:\ProgramData\Miniconda3\lib\site-packages\django\core\handlers\exception.py", line 34, in inner
    response = get_response(request)
  File "C:\ProgramData\Miniconda3\lib\site-packages\django\core\handlers\base.py", line 115, in _get_response
    response = self.process_exception_by_middleware(e, request)
  File "C:\ProgramData\Miniconda3\lib\site-packages\django\core\handlers\base.py", line 113, in _get_response
    response = wrapped_callback(request, *callback_args, **callback_kwargs)
  File "C:\ProgramData\Miniconda3\lib\site-packages\django\views\decorators\csrf.py", line 54, in wrapped_view
    return view_func(*args, **kwargs)
  File "C:\ProgramData\Miniconda3\lib\site-packages\rest_framework\viewsets.py", line 114, in view
    return self.dispatch(request, *args, **kwargs)
  File "C:\ProgramData\Miniconda3\lib\site-packages\rest_framework\views.py", line 505, in dispatch
    response = self.handle_exception(exc)
  File "C:\ProgramData\Miniconda3\lib\site-packages\rest_framework\views.py", line 465, in handle_exception
    self.raise_uncaught_exception(exc)
  File "C:\ProgramData\Miniconda3\lib\site-packages\rest_framework\views.py", line 476, in raise_uncaught_exception
    raise exc
  File "C:\ProgramData\Miniconda3\lib\site-packages\rest_framework\views.py", line 502, in dispatch
    response = handler(request, *args, **kwargs)
  File "D:\MISC\GITHUB\knit_server//app\products\kviews\csv_ref_categories_view.py", line 56, in create
    results = category_csv(request.FILES.get("category"))
  File "D:\MISC\GITHUB\knit_server//app\products\kviews\csv_ref_categories_view.py", line 80, in category_csv
    decoded_file = file.read().decode('utf-8').splitlines()
AttributeError: 'NoneType' object has no attribute 'read'
 django.request 2020-04-30 12:36:17,045 ERROR    Internal Server Error: /product/csv-categorys
Traceback (most recent call last):
  File "C:\ProgramData\Miniconda3\lib\site-packages\django\core\handlers\exception.py", line 34, in inner
    response = get_response(request)
  File "C:\ProgramData\Miniconda3\lib\site-packages\django\core\handlers\base.py", line 115, in _get_response
    response = self.process_exception_by_middleware(e, request)
  File "C:\ProgramData\Miniconda3\lib\site-packages\django\core\handlers\base.py", line 113, in _get_response
    response = wrapped_callback(request, *callback_args, **callback_kwargs)
  File "C:\ProgramData\Miniconda3\lib\site-packages\django\views\decorators\csrf.py", line 54, in wrapped_view
    return view_func(*args, **kwargs)
  File "C:\ProgramData\Miniconda3\lib\site-packages\rest_framework\viewsets.py", line 114, in view
    return self.dispatch(request, *args, **kwargs)
  File "C:\ProgramData\Miniconda3\lib\site-packages\rest_framework\views.py", line 505, in dispatch
    response = self.handle_exception(exc)
  File "C:\ProgramData\Miniconda3\lib\site-packages\rest_framework\views.py", line 465, in handle_exception
    self.raise_uncaught_exception(exc)
  File "C:\ProgramData\Miniconda3\lib\site-packages\rest_framework\views.py", line 476, in raise_uncaught_exception
    raise exc
  File "C:\ProgramData\Miniconda3\lib\site-packages\rest_framework\views.py", line 502, in dispatch
    response = handler(request, *args, **kwargs)
  File "D:\MISC\GITHUB\knit_server//app\products\kviews\csv_ref_categories_view.py", line 56, in create
    results = category_csv(request.FILES.get("category"))
  File "D:\MISC\GITHUB\knit_server//app\products\kviews\csv_ref_categories_view.py", line 88, in category_csv
    desc = row.get('description').encode('ascii','ignore')
AttributeError: 'NoneType' object has no attribute 'encode'
 django.request 2020-04-30 12:41:13,460 ERROR    Internal Server Error: /product/csv-categorys
Traceback (most recent call last):
  File "C:\ProgramData\Miniconda3\lib\site-packages\django\core\handlers\exception.py", line 34, in inner
    response = get_response(request)
  File "C:\ProgramData\Miniconda3\lib\site-packages\django\core\handlers\base.py", line 115, in _get_response
    response = self.process_exception_by_middleware(e, request)
  File "C:\ProgramData\Miniconda3\lib\site-packages\django\core\handlers\base.py", line 113, in _get_response
    response = wrapped_callback(request, *callback_args, **callback_kwargs)
  File "C:\ProgramData\Miniconda3\lib\site-packages\django\views\decorators\csrf.py", line 54, in wrapped_view
    return view_func(*args, **kwargs)
  File "C:\ProgramData\Miniconda3\lib\site-packages\rest_framework\viewsets.py", line 114, in view
    return self.dispatch(request, *args, **kwargs)
  File "C:\ProgramData\Miniconda3\lib\site-packages\rest_framework\views.py", line 505, in dispatch
    response = self.handle_exception(exc)
  File "C:\ProgramData\Miniconda3\lib\site-packages\rest_framework\views.py", line 465, in handle_exception
    self.raise_uncaught_exception(exc)
  File "C:\ProgramData\Miniconda3\lib\site-packages\rest_framework\views.py", line 476, in raise_uncaught_exception
    raise exc
  File "C:\ProgramData\Miniconda3\lib\site-packages\rest_framework\views.py", line 502, in dispatch
    response = handler(request, *args, **kwargs)
  File "D:\MISC\GITHUB\knit_server//app\products\kviews\csv_ref_categories_view.py", line 56, in create
    results = category_csv(request.FILES.get("category"))
  File "D:\MISC\GITHUB\knit_server//app\products\kviews\csv_ref_categories_view.py", line 80, in category_csv
    decoded_file = file.read().decode('utf-8').splitlines()
UnicodeDecodeError: 'utf-8' codec can't decode byte 0x92 in position 895: invalid start byte
 django.request 2020-04-30 12:45:27,254 ERROR    Internal Server Error: /product/csv-categorys
Traceback (most recent call last):
  File "D:\MISC\GITHUB\knit_server//app\products\kviews\csv_ref_categories_view.py", line 80, in category_csv
    decoded_file = file.read().decode('utf-8').splitlines()
UnicodeDecodeError: 'utf-8' codec can't decode byte 0x92 in position 895: invalid start byte

During handling of the above exception, another exception occurred:

Traceback (most recent call last):
  File "C:\ProgramData\Miniconda3\lib\site-packages\django\core\handlers\exception.py", line 34, in inner
    response = get_response(request)
  File "C:\ProgramData\Miniconda3\lib\site-packages\django\core\handlers\base.py", line 115, in _get_response
    response = self.process_exception_by_middleware(e, request)
  File "C:\ProgramData\Miniconda3\lib\site-packages\django\core\handlers\base.py", line 113, in _get_response
    response = wrapped_callback(request, *callback_args, **callback_kwargs)
  File "C:\ProgramData\Miniconda3\lib\site-packages\django\views\decorators\csrf.py", line 54, in wrapped_view
    return view_func(*args, **kwargs)
  File "C:\ProgramData\Miniconda3\lib\site-packages\rest_framework\viewsets.py", line 114, in view
    return self.dispatch(request, *args, **kwargs)
  File "C:\ProgramData\Miniconda3\lib\site-packages\rest_framework\views.py", line 505, in dispatch
    response = self.handle_exception(exc)
  File "C:\ProgramData\Miniconda3\lib\site-packages\rest_framework\views.py", line 465, in handle_exception
    self.raise_uncaught_exception(exc)
  File "C:\ProgramData\Miniconda3\lib\site-packages\rest_framework\views.py", line 476, in raise_uncaught_exception
    raise exc
  File "C:\ProgramData\Miniconda3\lib\site-packages\rest_framework\views.py", line 502, in dispatch
    response = handler(request, *args, **kwargs)
  File "D:\MISC\GITHUB\knit_server//app\products\kviews\csv_ref_categories_view.py", line 56, in create
    results = category_csv(request.FILES.get("category"))
  File "D:\MISC\GITHUB\knit_server//app\products\kviews\csv_ref_categories_view.py", line 113, in category_csv
    results.append({'unicode_error':category_serializer.instance.id, "status":status.HTTP_400_BAD_REQUEST})
UnboundLocalError: local variable 'category_serializer' referenced before assignment
 django.request 2020-04-30 12:47:42,627 WARNING  Bad Request: /product/csv-categorys
 django.request 2020-04-30 12:48:12,073 WARNING  Bad Request: /product/csv-categorys
 django.request 2020-04-30 13:23:32,967 ERROR    Internal Server Error: /product/csv-categorys
Traceback (most recent call last):
  File "C:\ProgramData\Miniconda3\lib\site-packages\django\core\handlers\exception.py", line 34, in inner
    response = get_response(request)
  File "C:\ProgramData\Miniconda3\lib\site-packages\django\core\handlers\base.py", line 115, in _get_response
    response = self.process_exception_by_middleware(e, request)
  File "C:\ProgramData\Miniconda3\lib\site-packages\django\core\handlers\base.py", line 113, in _get_response
    response = wrapped_callback(request, *callback_args, **callback_kwargs)
  File "C:\ProgramData\Miniconda3\lib\site-packages\django\views\decorators\csrf.py", line 54, in wrapped_view
    return view_func(*args, **kwargs)
  File "C:\ProgramData\Miniconda3\lib\site-packages\rest_framework\viewsets.py", line 114, in view
    return self.dispatch(request, *args, **kwargs)
  File "C:\ProgramData\Miniconda3\lib\site-packages\rest_framework\views.py", line 505, in dispatch
    response = self.handle_exception(exc)
  File "C:\ProgramData\Miniconda3\lib\site-packages\rest_framework\views.py", line 465, in handle_exception
    self.raise_uncaught_exception(exc)
  File "C:\ProgramData\Miniconda3\lib\site-packages\rest_framework\views.py", line 476, in raise_uncaught_exception
    raise exc
  File "C:\ProgramData\Miniconda3\lib\site-packages\rest_framework\views.py", line 502, in dispatch
    response = handler(request, *args, **kwargs)
  File "D:\MISC\GITHUB\knit_server//app\products\kviews\csv_ref_categories_view.py", line 56, in create
    results = category_csv(request.FILES.get("category"))
  File "D:\MISC\GITHUB\knit_server//app\products\kviews\csv_ref_categories_view.py", line 109, in category_csv
    if len(errors):
NameError: name 'errors' is not defined
 django.request 2020-04-30 13:28:40,740 ERROR    Internal Server Error: /product/csv-categorys
Traceback (most recent call last):
  File "C:\ProgramData\Miniconda3\lib\site-packages\django\core\handlers\exception.py", line 34, in inner
    response = get_response(request)
  File "C:\ProgramData\Miniconda3\lib\site-packages\django\core\handlers\base.py", line 145, in _get_response
    response = self.process_exception_by_middleware(e, request)
  File "C:\ProgramData\Miniconda3\lib\site-packages\django\core\handlers\base.py", line 143, in _get_response
    response = response.render()
  File "C:\ProgramData\Miniconda3\lib\site-packages\django\template\response.py", line 105, in render
    self.content = self.rendered_content
  File "C:\ProgramData\Miniconda3\lib\site-packages\rest_framework\response.py", line 70, in rendered_content
    ret = renderer.render(self.data, accepted_media_type, context)
  File "C:\ProgramData\Miniconda3\lib\site-packages\rest_framework\renderers.py", line 103, in render
    allow_nan=not self.strict, separators=separators
  File "C:\ProgramData\Miniconda3\lib\site-packages\rest_framework\utils\json.py", line 25, in dumps
    return json.dumps(*args, **kwargs)
  File "C:\ProgramData\Miniconda3\lib\json\__init__.py", line 238, in dumps
    **kw).encode(obj)
  File "C:\ProgramData\Miniconda3\lib\json\encoder.py", line 199, in encode
    chunks = self.iterencode(o, _one_shot=True)
  File "C:\ProgramData\Miniconda3\lib\json\encoder.py", line 257, in iterencode
    return _iterencode(o, 0)
  File "C:\ProgramData\Miniconda3\lib\site-packages\rest_framework\utils\encoders.py", line 67, in default
    return super().default(obj)
  File "C:\ProgramData\Miniconda3\lib\json\encoder.py", line 179, in default
    raise TypeError(f'Object of type {o.__class__.__name__} '
TypeError: Object of type Response is not JSON serializable
 django.request 2020-04-30 13:29:55,560 ERROR    Internal Server Error: /product/csv-categorys
Traceback (most recent call last):
  File "C:\ProgramData\Miniconda3\lib\site-packages\django\core\handlers\exception.py", line 34, in inner
    response = get_response(request)
  File "C:\ProgramData\Miniconda3\lib\site-packages\django\core\handlers\base.py", line 145, in _get_response
    response = self.process_exception_by_middleware(e, request)
  File "C:\ProgramData\Miniconda3\lib\site-packages\django\core\handlers\base.py", line 143, in _get_response
    response = response.render()
  File "C:\ProgramData\Miniconda3\lib\site-packages\django\template\response.py", line 105, in render
    self.content = self.rendered_content
  File "C:\ProgramData\Miniconda3\lib\site-packages\rest_framework\response.py", line 70, in rendered_content
    ret = renderer.render(self.data, accepted_media_type, context)
  File "C:\ProgramData\Miniconda3\lib\site-packages\rest_framework\renderers.py", line 103, in render
    allow_nan=not self.strict, separators=separators
  File "C:\ProgramData\Miniconda3\lib\site-packages\rest_framework\utils\json.py", line 25, in dumps
    return json.dumps(*args, **kwargs)
  File "C:\ProgramData\Miniconda3\lib\json\__init__.py", line 238, in dumps
    **kw).encode(obj)
  File "C:\ProgramData\Miniconda3\lib\json\encoder.py", line 199, in encode
    chunks = self.iterencode(o, _one_shot=True)
  File "C:\ProgramData\Miniconda3\lib\json\encoder.py", line 257, in iterencode
    return _iterencode(o, 0)
  File "C:\ProgramData\Miniconda3\lib\site-packages\rest_framework\utils\encoders.py", line 67, in default
    return super().default(obj)
  File "C:\ProgramData\Miniconda3\lib\json\encoder.py", line 179, in default
    raise TypeError(f'Object of type {o.__class__.__name__} '
TypeError: Object of type Response is not JSON serializable
 django.request 2020-04-30 13:30:42,067 ERROR    Internal Server Error: /product/csv-categorys
Traceback (most recent call last):
  File "C:\ProgramData\Miniconda3\lib\site-packages\django\core\handlers\exception.py", line 34, in inner
    response = get_response(request)
  File "C:\ProgramData\Miniconda3\lib\site-packages\django\core\handlers\base.py", line 145, in _get_response
    response = self.process_exception_by_middleware(e, request)
  File "C:\ProgramData\Miniconda3\lib\site-packages\django\core\handlers\base.py", line 143, in _get_response
    response = response.render()
  File "C:\ProgramData\Miniconda3\lib\site-packages\django\template\response.py", line 105, in render
    self.content = self.rendered_content
  File "C:\ProgramData\Miniconda3\lib\site-packages\rest_framework\response.py", line 70, in rendered_content
    ret = renderer.render(self.data, accepted_media_type, context)
  File "C:\ProgramData\Miniconda3\lib\site-packages\rest_framework\renderers.py", line 103, in render
    allow_nan=not self.strict, separators=separators
  File "C:\ProgramData\Miniconda3\lib\site-packages\rest_framework\utils\json.py", line 25, in dumps
    return json.dumps(*args, **kwargs)
  File "C:\ProgramData\Miniconda3\lib\json\__init__.py", line 238, in dumps
    **kw).encode(obj)
  File "C:\ProgramData\Miniconda3\lib\json\encoder.py", line 199, in encode
    chunks = self.iterencode(o, _one_shot=True)
  File "C:\ProgramData\Miniconda3\lib\json\encoder.py", line 257, in iterencode
    return _iterencode(o, 0)
  File "C:\ProgramData\Miniconda3\lib\site-packages\rest_framework\utils\encoders.py", line 67, in default
    return super().default(obj)
  File "C:\ProgramData\Miniconda3\lib\json\encoder.py", line 179, in default
    raise TypeError(f'Object of type {o.__class__.__name__} '
TypeError: Object of type Response is not JSON serializable
 django.request 2020-04-30 15:50:44,135 ERROR    Internal Server Error: /product/csv-ref-tables
Traceback (most recent call last):
  File "C:\ProgramData\Miniconda3\lib\site-packages\django\core\handlers\exception.py", line 34, in inner
    response = get_response(request)
  File "C:\ProgramData\Miniconda3\lib\site-packages\django\core\handlers\base.py", line 145, in _get_response
    response = self.process_exception_by_middleware(e, request)
  File "C:\ProgramData\Miniconda3\lib\site-packages\django\core\handlers\base.py", line 143, in _get_response
    response = response.render()
  File "C:\ProgramData\Miniconda3\lib\site-packages\django\template\response.py", line 105, in render
    self.content = self.rendered_content
  File "C:\ProgramData\Miniconda3\lib\site-packages\rest_framework\response.py", line 70, in rendered_content
    ret = renderer.render(self.data, accepted_media_type, context)
  File "C:\ProgramData\Miniconda3\lib\site-packages\rest_framework\renderers.py", line 103, in render
    allow_nan=not self.strict, separators=separators
  File "C:\ProgramData\Miniconda3\lib\site-packages\rest_framework\utils\json.py", line 25, in dumps
    return json.dumps(*args, **kwargs)
  File "C:\ProgramData\Miniconda3\lib\json\__init__.py", line 238, in dumps
    **kw).encode(obj)
  File "C:\ProgramData\Miniconda3\lib\json\encoder.py", line 199, in encode
    chunks = self.iterencode(o, _one_shot=True)
  File "C:\ProgramData\Miniconda3\lib\json\encoder.py", line 257, in iterencode
    return _iterencode(o, 0)
  File "C:\ProgramData\Miniconda3\lib\site-packages\rest_framework\utils\encoders.py", line 67, in default
    return super().default(obj)
  File "C:\ProgramData\Miniconda3\lib\json\encoder.py", line 179, in default
    raise TypeError(f'Object of type {o.__class__.__name__} '
TypeError: Object of type SizeModel is not JSON serializable
 django.request 2020-04-30 15:59:48,031 ERROR    Internal Server Error: /product/csv-ref-tables
Traceback (most recent call last):
  File "C:\ProgramData\Miniconda3\lib\site-packages\django\core\handlers\exception.py", line 34, in inner
    response = get_response(request)
  File "C:\ProgramData\Miniconda3\lib\site-packages\django\core\handlers\base.py", line 145, in _get_response
    response = self.process_exception_by_middleware(e, request)
  File "C:\ProgramData\Miniconda3\lib\site-packages\django\core\handlers\base.py", line 143, in _get_response
    response = response.render()
  File "C:\ProgramData\Miniconda3\lib\site-packages\django\template\response.py", line 105, in render
    self.content = self.rendered_content
  File "C:\ProgramData\Miniconda3\lib\site-packages\rest_framework\response.py", line 70, in rendered_content
    ret = renderer.render(self.data, accepted_media_type, context)
  File "C:\ProgramData\Miniconda3\lib\site-packages\rest_framework\renderers.py", line 103, in render
    allow_nan=not self.strict, separators=separators
  File "C:\ProgramData\Miniconda3\lib\site-packages\rest_framework\utils\json.py", line 25, in dumps
    return json.dumps(*args, **kwargs)
  File "C:\ProgramData\Miniconda3\lib\json\__init__.py", line 238, in dumps
    **kw).encode(obj)
  File "C:\ProgramData\Miniconda3\lib\json\encoder.py", line 199, in encode
    chunks = self.iterencode(o, _one_shot=True)
  File "C:\ProgramData\Miniconda3\lib\json\encoder.py", line 257, in iterencode
    return _iterencode(o, 0)
  File "C:\ProgramData\Miniconda3\lib\site-packages\rest_framework\utils\encoders.py", line 67, in default
    return super().default(obj)
  File "C:\ProgramData\Miniconda3\lib\json\encoder.py", line 179, in default
    raise TypeError(f'Object of type {o.__class__.__name__} '
TypeError: Object of type ColorModel is not JSON serializable
