 django.request 2020-04-25 12:41:10,232 ERROR    Internal Server Error: /user/csv-vendors
Traceback (most recent call last):
  File "C:\ProgramData\Miniconda3\lib\site-packages\django\core\handlers\exception.py", line 34, in inner
    response = get_response(request)
  File "C:\ProgramData\Miniconda3\lib\site-packages\django\core\handlers\base.py", line 115, in _get_response
    response = self.process_exception_by_middleware(e, request)
  File "C:\ProgramData\Miniconda3\lib\site-packages\django\core\handlers\base.py", line 113, in _get_response
    response = wrapped_callback(request, *callback_args, **callback_kwargs)
  File "C:\ProgramData\Miniconda3\lib\site-packages\django\views\decorators\csrf.py", line 54, in wrapped_view
    return view_func(*args, **kwargs)
  File "C:\ProgramData\Miniconda3\lib\site-packages\rest_framework\viewsets.py", line 114, in view
    return self.dispatch(request, *args, **kwargs)
  File "C:\ProgramData\Miniconda3\lib\site-packages\rest_framework\views.py", line 505, in dispatch
    response = self.handle_exception(exc)
  File "C:\ProgramData\Miniconda3\lib\site-packages\rest_framework\views.py", line 465, in handle_exception
    self.raise_uncaught_exception(exc)
  File "C:\ProgramData\Miniconda3\lib\site-packages\rest_framework\views.py", line 476, in raise_uncaught_exception
    raise exc
  File "C:\ProgramData\Miniconda3\lib\site-packages\rest_framework\views.py", line 502, in dispatch
    response = handler(request, *args, **kwargs)
  File "D:\MISC\GITHUB\knit_server//app\users\kviews\vendor_view.py", line 143, in create
    with open(csv_file) as f:
FileNotFoundError: [Errno 2] No such file or directory: 'images'
 django.request 2020-04-25 12:41:39,504 ERROR    Internal Server Error: /user/csv-vendors
Traceback (most recent call last):
  File "C:\ProgramData\Miniconda3\lib\site-packages\django\core\handlers\exception.py", line 34, in inner
    response = get_response(request)
  File "C:\ProgramData\Miniconda3\lib\site-packages\django\core\handlers\base.py", line 115, in _get_response
    response = self.process_exception_by_middleware(e, request)
  File "C:\ProgramData\Miniconda3\lib\site-packages\django\core\handlers\base.py", line 113, in _get_response
    response = wrapped_callback(request, *callback_args, **callback_kwargs)
  File "C:\ProgramData\Miniconda3\lib\site-packages\django\views\decorators\csrf.py", line 54, in wrapped_view
    return view_func(*args, **kwargs)
  File "C:\ProgramData\Miniconda3\lib\site-packages\rest_framework\viewsets.py", line 114, in view
    return self.dispatch(request, *args, **kwargs)
  File "C:\ProgramData\Miniconda3\lib\site-packages\rest_framework\views.py", line 505, in dispatch
    response = self.handle_exception(exc)
  File "C:\ProgramData\Miniconda3\lib\site-packages\rest_framework\views.py", line 465, in handle_exception
    self.raise_uncaught_exception(exc)
  File "C:\ProgramData\Miniconda3\lib\site-packages\rest_framework\views.py", line 476, in raise_uncaught_exception
    raise exc
  File "C:\ProgramData\Miniconda3\lib\site-packages\rest_framework\views.py", line 502, in dispatch
    response = handler(request, *args, **kwargs)
  File "D:\MISC\GITHUB\knit_server//app\users\kviews\vendor_view.py", line 141, in create
    for csv_file, values in request.FILES:
ValueError: too many values to unpack (expected 2)
 django.request 2020-04-25 12:42:46,567 ERROR    Internal Server Error: /user/csv-vendors
Traceback (most recent call last):
  File "C:\ProgramData\Miniconda3\lib\site-packages\django\core\handlers\exception.py", line 34, in inner
    response = get_response(request)
  File "C:\ProgramData\Miniconda3\lib\site-packages\django\core\handlers\base.py", line 115, in _get_response
    response = self.process_exception_by_middleware(e, request)
  File "C:\ProgramData\Miniconda3\lib\site-packages\django\core\handlers\base.py", line 113, in _get_response
    response = wrapped_callback(request, *callback_args, **callback_kwargs)
  File "C:\ProgramData\Miniconda3\lib\site-packages\django\views\decorators\csrf.py", line 54, in wrapped_view
    return view_func(*args, **kwargs)
  File "C:\ProgramData\Miniconda3\lib\site-packages\rest_framework\viewsets.py", line 114, in view
    return self.dispatch(request, *args, **kwargs)
  File "C:\ProgramData\Miniconda3\lib\site-packages\rest_framework\views.py", line 505, in dispatch
    response = self.handle_exception(exc)
  File "C:\ProgramData\Miniconda3\lib\site-packages\rest_framework\views.py", line 465, in handle_exception
    self.raise_uncaught_exception(exc)
  File "C:\ProgramData\Miniconda3\lib\site-packages\rest_framework\views.py", line 476, in raise_uncaught_exception
    raise exc
  File "C:\ProgramData\Miniconda3\lib\site-packages\rest_framework\views.py", line 502, in dispatch
    response = handler(request, *args, **kwargs)
  File "D:\MISC\GITHUB\knit_server//app\users\kviews\vendor_view.py", line 143, in create
    with open(request.FILES[csv_file]) as f:
TypeError: expected str, bytes or os.PathLike object, not InMemoryUploadedFile
 django.request 2020-04-25 12:44:18,636 ERROR    Internal Server Error: /user/csv-vendors
Traceback (most recent call last):
  File "C:\ProgramData\Miniconda3\lib\site-packages\django\core\handlers\exception.py", line 34, in inner
    response = get_response(request)
  File "C:\ProgramData\Miniconda3\lib\site-packages\django\core\handlers\base.py", line 115, in _get_response
    response = self.process_exception_by_middleware(e, request)
  File "C:\ProgramData\Miniconda3\lib\site-packages\django\core\handlers\base.py", line 113, in _get_response
    response = wrapped_callback(request, *callback_args, **callback_kwargs)
  File "C:\ProgramData\Miniconda3\lib\site-packages\django\views\decorators\csrf.py", line 54, in wrapped_view
    return view_func(*args, **kwargs)
  File "C:\ProgramData\Miniconda3\lib\site-packages\rest_framework\viewsets.py", line 114, in view
    return self.dispatch(request, *args, **kwargs)
  File "C:\ProgramData\Miniconda3\lib\site-packages\rest_framework\views.py", line 505, in dispatch
    response = self.handle_exception(exc)
  File "C:\ProgramData\Miniconda3\lib\site-packages\rest_framework\views.py", line 465, in handle_exception
    self.raise_uncaught_exception(exc)
  File "C:\ProgramData\Miniconda3\lib\site-packages\rest_framework\views.py", line 476, in raise_uncaught_exception
    raise exc
  File "C:\ProgramData\Miniconda3\lib\site-packages\rest_framework\views.py", line 502, in dispatch
    response = handler(request, *args, **kwargs)
  File "D:\MISC\GITHUB\knit_server//app\users\kviews\vendor_view.py", line 143, in create
    with open(request.FILES[csv_file].name) as f:
FileNotFoundError: [Errno 2] No such file or directory: 'ref_vendor_users.csv'
 django.request 2020-04-25 13:11:44,994 ERROR    Internal Server Error: /user/csv-vendors
Traceback (most recent call last):
  File "C:\ProgramData\Miniconda3\lib\site-packages\django\core\handlers\exception.py", line 34, in inner
    response = get_response(request)
  File "C:\ProgramData\Miniconda3\lib\site-packages\django\core\handlers\base.py", line 115, in _get_response
    response = self.process_exception_by_middleware(e, request)
  File "C:\ProgramData\Miniconda3\lib\site-packages\django\core\handlers\base.py", line 113, in _get_response
    response = wrapped_callback(request, *callback_args, **callback_kwargs)
  File "C:\ProgramData\Miniconda3\lib\site-packages\django\views\decorators\csrf.py", line 54, in wrapped_view
    return view_func(*args, **kwargs)
  File "C:\ProgramData\Miniconda3\lib\site-packages\rest_framework\viewsets.py", line 114, in view
    return self.dispatch(request, *args, **kwargs)
  File "C:\ProgramData\Miniconda3\lib\site-packages\rest_framework\views.py", line 505, in dispatch
    response = self.handle_exception(exc)
  File "C:\ProgramData\Miniconda3\lib\site-packages\rest_framework\views.py", line 465, in handle_exception
    self.raise_uncaught_exception(exc)
  File "C:\ProgramData\Miniconda3\lib\site-packages\rest_framework\views.py", line 476, in raise_uncaught_exception
    raise exc
  File "C:\ProgramData\Miniconda3\lib\site-packages\rest_framework\views.py", line 502, in dispatch
    response = handler(request, *args, **kwargs)
  File "D:\MISC\GITHUB\knit_server//app\users\kviews\vendor_view.py", line 147, in create
    reader = csv_reader.reader(f)
NameError: name 'f' is not defined
 django.request 2020-04-25 13:47:52,427 ERROR    Internal Server Error: /user/csv-vendors
Traceback (most recent call last):
  File "C:\ProgramData\Miniconda3\lib\site-packages\django\core\handlers\exception.py", line 34, in inner
    response = get_response(request)
  File "C:\ProgramData\Miniconda3\lib\site-packages\django\core\handlers\base.py", line 115, in _get_response
    response = self.process_exception_by_middleware(e, request)
  File "C:\ProgramData\Miniconda3\lib\site-packages\django\core\handlers\base.py", line 113, in _get_response
    response = wrapped_callback(request, *callback_args, **callback_kwargs)
  File "C:\ProgramData\Miniconda3\lib\site-packages\django\views\decorators\csrf.py", line 54, in wrapped_view
    return view_func(*args, **kwargs)
  File "C:\ProgramData\Miniconda3\lib\site-packages\rest_framework\viewsets.py", line 114, in view
    return self.dispatch(request, *args, **kwargs)
  File "C:\ProgramData\Miniconda3\lib\site-packages\rest_framework\views.py", line 505, in dispatch
    response = self.handle_exception(exc)
  File "C:\ProgramData\Miniconda3\lib\site-packages\rest_framework\views.py", line 465, in handle_exception
    self.raise_uncaught_exception(exc)
  File "C:\ProgramData\Miniconda3\lib\site-packages\rest_framework\views.py", line 476, in raise_uncaught_exception
    raise exc
  File "C:\ProgramData\Miniconda3\lib\site-packages\rest_framework\views.py", line 502, in dispatch
    response = handler(request, *args, **kwargs)
  File "D:\MISC\GITHUB\knit_server//app\users\kviews\vendor_view.py", line 147, in create
    reader = csv_reader.reader()
TypeError: '_csv.reader' object is not callable
 django.request 2020-04-25 13:54:50,928 ERROR    Internal Server Error: /user/csv-vendors
Traceback (most recent call last):
  File "C:\ProgramData\Miniconda3\lib\site-packages\django\core\handlers\exception.py", line 34, in inner
    response = get_response(request)
  File "C:\ProgramData\Miniconda3\lib\site-packages\django\core\handlers\base.py", line 115, in _get_response
    response = self.process_exception_by_middleware(e, request)
  File "C:\ProgramData\Miniconda3\lib\site-packages\django\core\handlers\base.py", line 113, in _get_response
    response = wrapped_callback(request, *callback_args, **callback_kwargs)
  File "C:\ProgramData\Miniconda3\lib\site-packages\django\views\decorators\csrf.py", line 54, in wrapped_view
    return view_func(*args, **kwargs)
  File "C:\ProgramData\Miniconda3\lib\site-packages\rest_framework\viewsets.py", line 114, in view
    return self.dispatch(request, *args, **kwargs)
  File "C:\ProgramData\Miniconda3\lib\site-packages\rest_framework\views.py", line 505, in dispatch
    response = self.handle_exception(exc)
  File "C:\ProgramData\Miniconda3\lib\site-packages\rest_framework\views.py", line 465, in handle_exception
    self.raise_uncaught_exception(exc)
  File "C:\ProgramData\Miniconda3\lib\site-packages\rest_framework\views.py", line 476, in raise_uncaught_exception
    raise exc
  File "C:\ProgramData\Miniconda3\lib\site-packages\rest_framework\views.py", line 502, in dispatch
    response = handler(request, *args, **kwargs)
  File "D:\MISC\GITHUB\knit_server//app\users\kviews\vendor_view.py", line 149, in create
    for i, row in enumerate(reader):
_csv.Error: iterator should return strings, not bytes (did you open the file in text mode?)
 django.request 2020-04-25 14:02:06,552 ERROR    Internal Server Error: /user/csv-vendors
Traceback (most recent call last):
  File "C:\ProgramData\Miniconda3\lib\site-packages\django\core\handlers\exception.py", line 34, in inner
    response = get_response(request)
  File "C:\ProgramData\Miniconda3\lib\site-packages\django\core\handlers\base.py", line 115, in _get_response
    response = self.process_exception_by_middleware(e, request)
  File "C:\ProgramData\Miniconda3\lib\site-packages\django\core\handlers\base.py", line 113, in _get_response
    response = wrapped_callback(request, *callback_args, **callback_kwargs)
  File "C:\ProgramData\Miniconda3\lib\site-packages\django\views\decorators\csrf.py", line 54, in wrapped_view
    return view_func(*args, **kwargs)
  File "C:\ProgramData\Miniconda3\lib\site-packages\rest_framework\viewsets.py", line 114, in view
    return self.dispatch(request, *args, **kwargs)
  File "C:\ProgramData\Miniconda3\lib\site-packages\rest_framework\views.py", line 505, in dispatch
    response = self.handle_exception(exc)
  File "C:\ProgramData\Miniconda3\lib\site-packages\rest_framework\views.py", line 465, in handle_exception
    self.raise_uncaught_exception(exc)
  File "C:\ProgramData\Miniconda3\lib\site-packages\rest_framework\views.py", line 476, in raise_uncaught_exception
    raise exc
  File "C:\ProgramData\Miniconda3\lib\site-packages\rest_framework\views.py", line 502, in dispatch
    response = handler(request, *args, **kwargs)
  File "D:\MISC\GITHUB\knit_server//app\users\kviews\vendor_view.py", line 149, in create
    for i, row in enumerate(csv_reader):
  File "C:\ProgramData\Miniconda3\lib\csv.py", line 111, in __next__
    self.fieldnames
  File "C:\ProgramData\Miniconda3\lib\csv.py", line 98, in fieldnames
    self._fieldnames = next(self.reader)
_csv.Error: iterator should return strings, not bytes (did you open the file in text mode?)
 django.request 2020-04-25 14:02:56,948 ERROR    Internal Server Error: /user/csv-vendors
Traceback (most recent call last):
  File "C:\ProgramData\Miniconda3\lib\site-packages\django\core\handlers\exception.py", line 34, in inner
    response = get_response(request)
  File "C:\ProgramData\Miniconda3\lib\site-packages\django\core\handlers\base.py", line 115, in _get_response
    response = self.process_exception_by_middleware(e, request)
  File "C:\ProgramData\Miniconda3\lib\site-packages\django\core\handlers\base.py", line 113, in _get_response
    response = wrapped_callback(request, *callback_args, **callback_kwargs)
  File "C:\ProgramData\Miniconda3\lib\site-packages\django\views\decorators\csrf.py", line 54, in wrapped_view
    return view_func(*args, **kwargs)
  File "C:\ProgramData\Miniconda3\lib\site-packages\rest_framework\viewsets.py", line 114, in view
    return self.dispatch(request, *args, **kwargs)
  File "C:\ProgramData\Miniconda3\lib\site-packages\rest_framework\views.py", line 505, in dispatch
    response = self.handle_exception(exc)
  File "C:\ProgramData\Miniconda3\lib\site-packages\rest_framework\views.py", line 465, in handle_exception
    self.raise_uncaught_exception(exc)
  File "C:\ProgramData\Miniconda3\lib\site-packages\rest_framework\views.py", line 476, in raise_uncaught_exception
    raise exc
  File "C:\ProgramData\Miniconda3\lib\site-packages\rest_framework\views.py", line 502, in dispatch
    response = handler(request, *args, **kwargs)
  File "D:\MISC\GITHUB\knit_server//app\users\kviews\vendor_view.py", line 149, in create
    for row in csv_reader:
  File "C:\ProgramData\Miniconda3\lib\csv.py", line 111, in __next__
    self.fieldnames
  File "C:\ProgramData\Miniconda3\lib\csv.py", line 98, in fieldnames
    self._fieldnames = next(self.reader)
_csv.Error: iterator should return strings, not bytes (did you open the file in text mode?)
 django.request 2020-04-25 14:05:24,363 ERROR    Internal Server Error: /user/csv-vendors
Traceback (most recent call last):
  File "C:\ProgramData\Miniconda3\lib\site-packages\django\core\handlers\exception.py", line 34, in inner
    response = get_response(request)
  File "C:\ProgramData\Miniconda3\lib\site-packages\django\core\handlers\base.py", line 115, in _get_response
    response = self.process_exception_by_middleware(e, request)
  File "C:\ProgramData\Miniconda3\lib\site-packages\django\core\handlers\base.py", line 113, in _get_response
    response = wrapped_callback(request, *callback_args, **callback_kwargs)
  File "C:\ProgramData\Miniconda3\lib\site-packages\django\views\decorators\csrf.py", line 54, in wrapped_view
    return view_func(*args, **kwargs)
  File "C:\ProgramData\Miniconda3\lib\site-packages\rest_framework\viewsets.py", line 114, in view
    return self.dispatch(request, *args, **kwargs)
  File "C:\ProgramData\Miniconda3\lib\site-packages\rest_framework\views.py", line 505, in dispatch
    response = self.handle_exception(exc)
  File "C:\ProgramData\Miniconda3\lib\site-packages\rest_framework\views.py", line 465, in handle_exception
    self.raise_uncaught_exception(exc)
  File "C:\ProgramData\Miniconda3\lib\site-packages\rest_framework\views.py", line 476, in raise_uncaught_exception
    raise exc
  File "C:\ProgramData\Miniconda3\lib\site-packages\rest_framework\views.py", line 502, in dispatch
    response = handler(request, *args, **kwargs)
  File "D:\MISC\GITHUB\knit_server//app\users\kviews\vendor_view.py", line 154, in create
    user_data['username'] = row[0]
KeyError: 0
 django.request 2020-04-25 14:26:02,556 ERROR    Internal Server Error: /user/csv-vendors
Traceback (most recent call last):
  File "C:\ProgramData\Miniconda3\lib\site-packages\django\db\models\fields\__init__.py", line 1768, in get_prep_value
    return int(value)
ValueError: invalid literal for int() with base 10: ''

The above exception was the direct cause of the following exception:

Traceback (most recent call last):
  File "C:\ProgramData\Miniconda3\lib\site-packages\django\core\handlers\exception.py", line 34, in inner
    response = get_response(request)
  File "C:\ProgramData\Miniconda3\lib\site-packages\django\core\handlers\base.py", line 115, in _get_response
    response = self.process_exception_by_middleware(e, request)
  File "C:\ProgramData\Miniconda3\lib\site-packages\django\core\handlers\base.py", line 113, in _get_response
    response = wrapped_callback(request, *callback_args, **callback_kwargs)
  File "C:\ProgramData\Miniconda3\lib\site-packages\django\views\decorators\csrf.py", line 54, in wrapped_view
    return view_func(*args, **kwargs)
  File "C:\ProgramData\Miniconda3\lib\site-packages\rest_framework\viewsets.py", line 114, in view
    return self.dispatch(request, *args, **kwargs)
  File "C:\ProgramData\Miniconda3\lib\site-packages\rest_framework\views.py", line 505, in dispatch
    response = self.handle_exception(exc)
  File "C:\ProgramData\Miniconda3\lib\site-packages\rest_framework\views.py", line 465, in handle_exception
    self.raise_uncaught_exception(exc)
  File "C:\ProgramData\Miniconda3\lib\site-packages\rest_framework\views.py", line 476, in raise_uncaught_exception
    raise exc
  File "C:\ProgramData\Miniconda3\lib\site-packages\rest_framework\views.py", line 502, in dispatch
    response = handler(request, *args, **kwargs)
  File "D:\MISC\GITHUB\knit_server//app\users\kviews\vendor_view.py", line 167, in create
    results.append({'vendorId':vendor_serializer.instance.id, "status":status.HTTP_201_CREATED})
  File "C:\ProgramData\Miniconda3\lib\site-packages\rest_framework\serializers.py", line 212, in save
    self.instance = self.create(validated_data)
  File "D:\MISC\GITHUB\knit_server//app\users\kserializers\vendor_serializer.py", line 52, in create
    vendor = Vendor.objects.create(user=user_serializer.instance, **validated_data)
  File "C:\ProgramData\Miniconda3\lib\site-packages\django\db\models\manager.py", line 82, in manager_method
    return getattr(self.get_queryset(), name)(*args, **kwargs)
  File "C:\ProgramData\Miniconda3\lib\site-packages\django\db\models\query.py", line 433, in create
    obj.save(force_insert=True, using=self.db)
  File "C:\ProgramData\Miniconda3\lib\site-packages\django\db\models\base.py", line 746, in save
    force_update=force_update, update_fields=update_fields)
  File "C:\ProgramData\Miniconda3\lib\site-packages\django\db\models\base.py", line 784, in save_base
    force_update, using, update_fields,
  File "C:\ProgramData\Miniconda3\lib\site-packages\django\db\models\base.py", line 886, in _save_table
    results = self._do_insert(cls._base_manager, using, fields, returning_fields, raw)
  File "C:\ProgramData\Miniconda3\lib\site-packages\django\db\models\base.py", line 925, in _do_insert
    using=using, raw=raw,
  File "C:\ProgramData\Miniconda3\lib\site-packages\django\db\models\manager.py", line 82, in manager_method
    return getattr(self.get_queryset(), name)(*args, **kwargs)
  File "C:\ProgramData\Miniconda3\lib\site-packages\django\db\models\query.py", line 1204, in _insert
    return query.get_compiler(using=using).execute_sql(returning_fields)
  File "C:\ProgramData\Miniconda3\lib\site-packages\django\db\models\sql\compiler.py", line 1376, in execute_sql
    for sql, params in self.as_sql():
  File "C:\ProgramData\Miniconda3\lib\site-packages\django\db\models\sql\compiler.py", line 1321, in as_sql
    for obj in self.query.objs
  File "C:\ProgramData\Miniconda3\lib\site-packages\django\db\models\sql\compiler.py", line 1321, in <listcomp>
    for obj in self.query.objs
  File "C:\ProgramData\Miniconda3\lib\site-packages\django\db\models\sql\compiler.py", line 1320, in <listcomp>
    [self.prepare_value(field, self.pre_save_val(field, obj)) for field in fields]
  File "C:\ProgramData\Miniconda3\lib\site-packages\django\db\models\sql\compiler.py", line 1261, in prepare_value
    value = field.get_db_prep_save(value, connection=self.connection)
  File "C:\ProgramData\Miniconda3\lib\site-packages\django\db\models\fields\__init__.py", line 817, in get_db_prep_save
    return self.get_db_prep_value(value, connection=connection, prepared=False)
  File "C:\ProgramData\Miniconda3\lib\site-packages\django\db\models\fields\__init__.py", line 812, in get_db_prep_value
    value = self.get_prep_value(value)
  File "C:\ProgramData\Miniconda3\lib\site-packages\django\db\models\fields\__init__.py", line 1772, in get_prep_value
    ) from e
ValueError: Field 'masters' expected a number but got ''.
 django.request 2020-04-25 14:26:25,563 WARNING  Bad Request: /user/csv-vendors
 django.request 2020-04-25 15:01:51,741 WARNING  Bad Request: /user/csv-vendors
 django.request 2020-04-25 15:02:47,169 WARNING  Bad Request: /user/csv-vendors
 django.request 2020-04-25 15:02:52,472 WARNING  Bad Request: /user/csv-vendors
 django.request 2020-04-25 15:03:54,273 WARNING  Bad Request: /user/csv-vendors
 django.request 2020-04-25 15:07:34,673 ERROR    Internal Server Error: /user/csv-vendors
Traceback (most recent call last):
  File "C:\ProgramData\Miniconda3\lib\site-packages\django\core\handlers\exception.py", line 34, in inner
    response = get_response(request)
  File "C:\ProgramData\Miniconda3\lib\site-packages\django\core\handlers\base.py", line 115, in _get_response
    response = self.process_exception_by_middleware(e, request)
  File "C:\ProgramData\Miniconda3\lib\site-packages\django\core\handlers\base.py", line 113, in _get_response
    response = wrapped_callback(request, *callback_args, **callback_kwargs)
  File "C:\ProgramData\Miniconda3\lib\site-packages\django\views\decorators\csrf.py", line 54, in wrapped_view
    return view_func(*args, **kwargs)
  File "C:\ProgramData\Miniconda3\lib\site-packages\rest_framework\viewsets.py", line 114, in view
    return self.dispatch(request, *args, **kwargs)
  File "C:\ProgramData\Miniconda3\lib\site-packages\rest_framework\views.py", line 505, in dispatch
    response = self.handle_exception(exc)
  File "C:\ProgramData\Miniconda3\lib\site-packages\rest_framework\views.py", line 465, in handle_exception
    self.raise_uncaught_exception(exc)
  File "C:\ProgramData\Miniconda3\lib\site-packages\rest_framework\views.py", line 476, in raise_uncaught_exception
    raise exc
  File "C:\ProgramData\Miniconda3\lib\site-packages\rest_framework\views.py", line 502, in dispatch
    response = handler(request, *args, **kwargs)
  File "D:\MISC\GITHUB\knit_server//app\users\kviews\vendor_view.py", line 172, in create
    results.append({'vendorId':vendor_serializer.instance.id, "status":status.HTTP_201_CREATED})
AttributeError: 'NoneType' object has no attribute 'id'
 django.request 2020-04-25 15:19:05,829 ERROR    Internal Server Error: /user/csv-vendors
Traceback (most recent call last):
  File "C:\ProgramData\Miniconda3\lib\site-packages\django\core\handlers\exception.py", line 34, in inner
    response = get_response(request)
  File "C:\ProgramData\Miniconda3\lib\site-packages\django\core\handlers\base.py", line 115, in _get_response
    response = self.process_exception_by_middleware(e, request)
  File "C:\ProgramData\Miniconda3\lib\site-packages\django\core\handlers\base.py", line 113, in _get_response
    response = wrapped_callback(request, *callback_args, **callback_kwargs)
  File "C:\ProgramData\Miniconda3\lib\site-packages\django\views\decorators\csrf.py", line 54, in wrapped_view
    return view_func(*args, **kwargs)
  File "C:\ProgramData\Miniconda3\lib\site-packages\rest_framework\viewsets.py", line 114, in view
    return self.dispatch(request, *args, **kwargs)
  File "C:\ProgramData\Miniconda3\lib\site-packages\rest_framework\views.py", line 505, in dispatch
    response = self.handle_exception(exc)
  File "C:\ProgramData\Miniconda3\lib\site-packages\rest_framework\views.py", line 465, in handle_exception
    self.raise_uncaught_exception(exc)
  File "C:\ProgramData\Miniconda3\lib\site-packages\rest_framework\views.py", line 476, in raise_uncaught_exception
    raise exc
  File "C:\ProgramData\Miniconda3\lib\site-packages\rest_framework\views.py", line 502, in dispatch
    response = handler(request, *args, **kwargs)
  File "D:\MISC\GITHUB\knit_server//app\users\kviews\vendor_view.py", line 161, in create
    vendor_details['doorService'] = int(row.get('doorService'))
ValueError: invalid literal for int() with base 10: ''
 django.request 2020-04-25 15:19:09,108 ERROR    Internal Server Error: /user/csv-vendors
Traceback (most recent call last):
  File "C:\ProgramData\Miniconda3\lib\site-packages\django\core\handlers\exception.py", line 34, in inner
    response = get_response(request)
  File "C:\ProgramData\Miniconda3\lib\site-packages\django\core\handlers\base.py", line 115, in _get_response
    response = self.process_exception_by_middleware(e, request)
  File "C:\ProgramData\Miniconda3\lib\site-packages\django\core\handlers\base.py", line 113, in _get_response
    response = wrapped_callback(request, *callback_args, **callback_kwargs)
  File "C:\ProgramData\Miniconda3\lib\site-packages\django\views\decorators\csrf.py", line 54, in wrapped_view
    return view_func(*args, **kwargs)
  File "C:\ProgramData\Miniconda3\lib\site-packages\rest_framework\viewsets.py", line 114, in view
    return self.dispatch(request, *args, **kwargs)
  File "C:\ProgramData\Miniconda3\lib\site-packages\rest_framework\views.py", line 505, in dispatch
    response = self.handle_exception(exc)
  File "C:\ProgramData\Miniconda3\lib\site-packages\rest_framework\views.py", line 465, in handle_exception
    self.raise_uncaught_exception(exc)
  File "C:\ProgramData\Miniconda3\lib\site-packages\rest_framework\views.py", line 476, in raise_uncaught_exception
    raise exc
  File "C:\ProgramData\Miniconda3\lib\site-packages\rest_framework\views.py", line 502, in dispatch
    response = handler(request, *args, **kwargs)
  File "D:\MISC\GITHUB\knit_server//app\users\kviews\vendor_view.py", line 161, in create
    vendor_details['doorService'] = int(row.get('doorService'))
ValueError: invalid literal for int() with base 10: ''
 django.request 2020-04-25 15:19:56,102 ERROR    Internal Server Error: /user/csv-vendors
Traceback (most recent call last):
  File "C:\ProgramData\Miniconda3\lib\site-packages\django\core\handlers\exception.py", line 34, in inner
    response = get_response(request)
  File "C:\ProgramData\Miniconda3\lib\site-packages\django\core\handlers\base.py", line 115, in _get_response
    response = self.process_exception_by_middleware(e, request)
  File "C:\ProgramData\Miniconda3\lib\site-packages\django\core\handlers\base.py", line 113, in _get_response
    response = wrapped_callback(request, *callback_args, **callback_kwargs)
  File "C:\ProgramData\Miniconda3\lib\site-packages\django\views\decorators\csrf.py", line 54, in wrapped_view
    return view_func(*args, **kwargs)
  File "C:\ProgramData\Miniconda3\lib\site-packages\rest_framework\viewsets.py", line 114, in view
    return self.dispatch(request, *args, **kwargs)
  File "C:\ProgramData\Miniconda3\lib\site-packages\rest_framework\views.py", line 505, in dispatch
    response = self.handle_exception(exc)
  File "C:\ProgramData\Miniconda3\lib\site-packages\rest_framework\views.py", line 465, in handle_exception
    self.raise_uncaught_exception(exc)
  File "C:\ProgramData\Miniconda3\lib\site-packages\rest_framework\views.py", line 476, in raise_uncaught_exception
    raise exc
  File "C:\ProgramData\Miniconda3\lib\site-packages\rest_framework\views.py", line 502, in dispatch
    response = handler(request, *args, **kwargs)
  File "D:\MISC\GITHUB\knit_server//app\users\kviews\vendor_view.py", line 161, in create
    vendor_details['doorService'] = int(row.get('doorService'), 10)
ValueError: invalid literal for int() with base 10: ''
 django.request 2020-04-25 15:20:43,432 ERROR    Internal Server Error: /user/csv-vendors
Traceback (most recent call last):
  File "C:\ProgramData\Miniconda3\lib\site-packages\django\core\handlers\exception.py", line 34, in inner
    response = get_response(request)
  File "C:\ProgramData\Miniconda3\lib\site-packages\django\core\handlers\base.py", line 115, in _get_response
    response = self.process_exception_by_middleware(e, request)
  File "C:\ProgramData\Miniconda3\lib\site-packages\django\core\handlers\base.py", line 113, in _get_response
    response = wrapped_callback(request, *callback_args, **callback_kwargs)
  File "C:\ProgramData\Miniconda3\lib\site-packages\django\views\decorators\csrf.py", line 54, in wrapped_view
    return view_func(*args, **kwargs)
  File "C:\ProgramData\Miniconda3\lib\site-packages\rest_framework\viewsets.py", line 114, in view
    return self.dispatch(request, *args, **kwargs)
  File "C:\ProgramData\Miniconda3\lib\site-packages\rest_framework\views.py", line 505, in dispatch
    response = self.handle_exception(exc)
  File "C:\ProgramData\Miniconda3\lib\site-packages\rest_framework\views.py", line 465, in handle_exception
    self.raise_uncaught_exception(exc)
  File "C:\ProgramData\Miniconda3\lib\site-packages\rest_framework\views.py", line 476, in raise_uncaught_exception
    raise exc
  File "C:\ProgramData\Miniconda3\lib\site-packages\rest_framework\views.py", line 502, in dispatch
    response = handler(request, *args, **kwargs)
  File "D:\MISC\GITHUB\knit_server//app\users\kviews\vendor_view.py", line 160, in create
    vendor_details['masters'] = int(row.get('masters', 0), 10)
ValueError: invalid literal for int() with base 10: ''
 django.request 2020-04-25 15:24:06,972 ERROR    Internal Server Error: /user/csv-vendors
Traceback (most recent call last):
  File "C:\ProgramData\Miniconda3\lib\site-packages\django\core\handlers\exception.py", line 34, in inner
    response = get_response(request)
  File "C:\ProgramData\Miniconda3\lib\site-packages\django\core\handlers\base.py", line 115, in _get_response
    response = self.process_exception_by_middleware(e, request)
  File "C:\ProgramData\Miniconda3\lib\site-packages\django\core\handlers\base.py", line 113, in _get_response
    response = wrapped_callback(request, *callback_args, **callback_kwargs)
  File "C:\ProgramData\Miniconda3\lib\site-packages\django\views\decorators\csrf.py", line 54, in wrapped_view
    return view_func(*args, **kwargs)
  File "C:\ProgramData\Miniconda3\lib\site-packages\rest_framework\viewsets.py", line 114, in view
    return self.dispatch(request, *args, **kwargs)
  File "C:\ProgramData\Miniconda3\lib\site-packages\rest_framework\views.py", line 505, in dispatch
    response = self.handle_exception(exc)
  File "C:\ProgramData\Miniconda3\lib\site-packages\rest_framework\views.py", line 465, in handle_exception
    self.raise_uncaught_exception(exc)
  File "C:\ProgramData\Miniconda3\lib\site-packages\rest_framework\views.py", line 476, in raise_uncaught_exception
    raise exc
  File "C:\ProgramData\Miniconda3\lib\site-packages\rest_framework\views.py", line 502, in dispatch
    response = handler(request, *args, **kwargs)
  File "D:\MISC\GITHUB\knit_server//app\users\kviews\vendor_view.py", line 160, in create
    vendor_details['masters'] = int(float(row.get('masters', 0)))
ValueError: could not convert string to float: 
 django.request 2020-04-25 15:44:40,250 ERROR    Internal Server Error: /user/csv-vendors
Traceback (most recent call last):
  File "C:\ProgramData\Miniconda3\lib\site-packages\django\core\handlers\exception.py", line 34, in inner
    response = get_response(request)
  File "C:\ProgramData\Miniconda3\lib\site-packages\django\core\handlers\base.py", line 115, in _get_response
    response = self.process_exception_by_middleware(e, request)
  File "C:\ProgramData\Miniconda3\lib\site-packages\django\core\handlers\base.py", line 113, in _get_response
    response = wrapped_callback(request, *callback_args, **callback_kwargs)
  File "C:\ProgramData\Miniconda3\lib\site-packages\django\views\decorators\csrf.py", line 54, in wrapped_view
    return view_func(*args, **kwargs)
  File "C:\ProgramData\Miniconda3\lib\site-packages\rest_framework\viewsets.py", line 114, in view
    return self.dispatch(request, *args, **kwargs)
  File "C:\ProgramData\Miniconda3\lib\site-packages\rest_framework\views.py", line 505, in dispatch
    response = self.handle_exception(exc)
  File "C:\ProgramData\Miniconda3\lib\site-packages\rest_framework\views.py", line 465, in handle_exception
    self.raise_uncaught_exception(exc)
  File "C:\ProgramData\Miniconda3\lib\site-packages\rest_framework\views.py", line 476, in raise_uncaught_exception
    raise exc
  File "C:\ProgramData\Miniconda3\lib\site-packages\rest_framework\views.py", line 502, in dispatch
    response = handler(request, *args, **kwargs)
  File "D:\MISC\GITHUB\knit_server//app\users\kviews\vendor_view.py", line 163, in create
    vendor_details['openTime'] =  arrow.get(row.get('openTime')).format('YYYY-MM-DD HH:mm:ss') if row.get('openTime') else None
  File "C:\ProgramData\Miniconda3\lib\site-packages\arrow\api.py", line 21, in get
    return _factory.get(*args, **kwargs)
  File "C:\ProgramData\Miniconda3\lib\site-packages\arrow\factory.py", line 196, in get
    dt = parser.DateTimeParser(locale).parse_iso(arg)
  File "C:\ProgramData\Miniconda3\lib\site-packages\arrow\parser.py", line 211, in parse_iso
    return self._parse_multiformat(datetime_string, formats)
  File "C:\ProgramData\Miniconda3\lib\site-packages\arrow\parser.py", line 494, in _parse_multiformat
    string, ", ".join(formats)
arrow.parser.ParserError: Could not match input '9:30:00' to any of the following formats: YYYY-MM-DD, YYYY-M-DD, YYYY-M-D, YYYY/MM/DD, YYYY/M/DD, YYYY/M/D, YYYY.MM.DD, YYYY.M.DD, YYYY.M.D, YYYYMMDD, YYYY-DDDD, YYYYDDDD, YYYY-MM, YYYY/MM, YYYY.MM, YYYY
 django.request 2020-04-25 16:08:48,481 ERROR    Internal Server Error: /user/csv-vendors
Traceback (most recent call last):
  File "C:\ProgramData\Miniconda3\lib\site-packages\django\core\handlers\exception.py", line 34, in inner
    response = get_response(request)
  File "C:\ProgramData\Miniconda3\lib\site-packages\django\core\handlers\base.py", line 115, in _get_response
    response = self.process_exception_by_middleware(e, request)
  File "C:\ProgramData\Miniconda3\lib\site-packages\django\core\handlers\base.py", line 113, in _get_response
    response = wrapped_callback(request, *callback_args, **callback_kwargs)
  File "C:\ProgramData\Miniconda3\lib\site-packages\django\views\decorators\csrf.py", line 54, in wrapped_view
    return view_func(*args, **kwargs)
  File "C:\ProgramData\Miniconda3\lib\site-packages\rest_framework\viewsets.py", line 114, in view
    return self.dispatch(request, *args, **kwargs)
  File "C:\ProgramData\Miniconda3\lib\site-packages\rest_framework\views.py", line 505, in dispatch
    response = self.handle_exception(exc)
  File "C:\ProgramData\Miniconda3\lib\site-packages\rest_framework\views.py", line 465, in handle_exception
    self.raise_uncaught_exception(exc)
  File "C:\ProgramData\Miniconda3\lib\site-packages\rest_framework\views.py", line 476, in raise_uncaught_exception
    raise exc
  File "C:\ProgramData\Miniconda3\lib\site-packages\rest_framework\views.py", line 502, in dispatch
    response = handler(request, *args, **kwargs)
  File "D:\MISC\GITHUB\knit_server//app\users\kviews\vendor_view.py", line 165, in create
    vendor_details['openTime'] = arrow.now().replace(hour=timeSplit[0], minute=timeSplit[1])
  File "C:\ProgramData\Miniconda3\lib\site-packages\arrow\arrow.py", line 624, in replace
    current = self._datetime.replace(**absolute_kwargs)
TypeError: an integer is required (got type str)
 django.request 2020-04-25 16:11:45,239 ERROR    Internal Server Error: /user/csv-vendors
Traceback (most recent call last):
  File "C:\ProgramData\Miniconda3\lib\site-packages\django\core\handlers\exception.py", line 34, in inner
    response = get_response(request)
  File "C:\ProgramData\Miniconda3\lib\site-packages\django\core\handlers\base.py", line 115, in _get_response
    response = self.process_exception_by_middleware(e, request)
  File "C:\ProgramData\Miniconda3\lib\site-packages\django\core\handlers\base.py", line 113, in _get_response
    response = wrapped_callback(request, *callback_args, **callback_kwargs)
  File "C:\ProgramData\Miniconda3\lib\site-packages\django\views\decorators\csrf.py", line 54, in wrapped_view
    return view_func(*args, **kwargs)
  File "C:\ProgramData\Miniconda3\lib\site-packages\rest_framework\viewsets.py", line 114, in view
    return self.dispatch(request, *args, **kwargs)
  File "C:\ProgramData\Miniconda3\lib\site-packages\rest_framework\views.py", line 505, in dispatch
    response = self.handle_exception(exc)
  File "C:\ProgramData\Miniconda3\lib\site-packages\rest_framework\views.py", line 465, in handle_exception
    self.raise_uncaught_exception(exc)
  File "C:\ProgramData\Miniconda3\lib\site-packages\rest_framework\views.py", line 476, in raise_uncaught_exception
    raise exc
  File "C:\ProgramData\Miniconda3\lib\site-packages\rest_framework\views.py", line 502, in dispatch
    response = handler(request, *args, **kwargs)
  File "D:\MISC\GITHUB\knit_server//app\users\kviews\vendor_view.py", line 165, in create
    vendor_details['openTime'] = arrow.now().replace(hour=timeSplit[0], minute=timeSplit[1])
  File "C:\ProgramData\Miniconda3\lib\site-packages\arrow\arrow.py", line 624, in replace
    current = self._datetime.replace(**absolute_kwargs)
TypeError: an integer is required (got type str)
 django.request 2020-04-25 16:15:40,975 ERROR    Internal Server Error: /user/csv-vendors
Traceback (most recent call last):
  File "C:\ProgramData\Miniconda3\lib\site-packages\django\core\handlers\exception.py", line 34, in inner
    response = get_response(request)
  File "C:\ProgramData\Miniconda3\lib\site-packages\django\core\handlers\base.py", line 115, in _get_response
    response = self.process_exception_by_middleware(e, request)
  File "C:\ProgramData\Miniconda3\lib\site-packages\django\core\handlers\base.py", line 113, in _get_response
    response = wrapped_callback(request, *callback_args, **callback_kwargs)
  File "C:\ProgramData\Miniconda3\lib\site-packages\django\views\decorators\csrf.py", line 54, in wrapped_view
    return view_func(*args, **kwargs)
  File "C:\ProgramData\Miniconda3\lib\site-packages\rest_framework\viewsets.py", line 114, in view
    return self.dispatch(request, *args, **kwargs)
  File "C:\ProgramData\Miniconda3\lib\site-packages\rest_framework\views.py", line 505, in dispatch
    response = self.handle_exception(exc)
  File "C:\ProgramData\Miniconda3\lib\site-packages\rest_framework\views.py", line 465, in handle_exception
    self.raise_uncaught_exception(exc)
  File "C:\ProgramData\Miniconda3\lib\site-packages\rest_framework\views.py", line 476, in raise_uncaught_exception
    raise exc
  File "C:\ProgramData\Miniconda3\lib\site-packages\rest_framework\views.py", line 502, in dispatch
    response = handler(request, *args, **kwargs)
  File "D:\MISC\GITHUB\knit_server//app\users\kviews\vendor_view.py", line 165, in create
    vendor_details['openTime'] = arrow.now().replace(hour=timeSplit[0], minute=timeSplit[1])
  File "C:\ProgramData\Miniconda3\lib\site-packages\arrow\arrow.py", line 624, in replace
    current = self._datetime.replace(**absolute_kwargs)
TypeError: an integer is required (got type str)
 django.request 2020-04-25 16:27:44,308 ERROR    Internal Server Error: /user/csv-vendors
Traceback (most recent call last):
  File "D:\MISC\GITHUB\knit_server//app\users\kviews\vendor_view.py", line 169, in create
    vendor_serializer.save()
  File "C:\ProgramData\Miniconda3\lib\site-packages\rest_framework\serializers.py", line 212, in save
    self.instance = self.create(validated_data)
  File "D:\MISC\GITHUB\knit_server//app\users\kserializers\vendor_serializer.py", line 47, in create
    user_serializer.is_valid(raise_exception=True)
  File "C:\ProgramData\Miniconda3\lib\site-packages\rest_framework\serializers.py", line 242, in is_valid
    raise ValidationError(self.errors)
rest_framework.exceptions.ValidationError: {'username_exists': ErrorDetail(string='Username is already in use. Try with different name', code='invalid'), 'email_exists': ErrorDetail(string='Email is already in use. Try with different email', code='invalid'), 'phone_exists': ErrorDetail(string='Phone number is already in use. Try with different number', code='invalid')}

During handling of the above exception, another exception occurred:

Traceback (most recent call last):
  File "C:\ProgramData\Miniconda3\lib\site-packages\django\core\handlers\exception.py", line 34, in inner
    response = get_response(request)
  File "C:\ProgramData\Miniconda3\lib\site-packages\django\core\handlers\base.py", line 115, in _get_response
    response = self.process_exception_by_middleware(e, request)
  File "C:\ProgramData\Miniconda3\lib\site-packages\django\core\handlers\base.py", line 113, in _get_response
    response = wrapped_callback(request, *callback_args, **callback_kwargs)
  File "C:\ProgramData\Miniconda3\lib\site-packages\django\views\decorators\csrf.py", line 54, in wrapped_view
    return view_func(*args, **kwargs)
  File "C:\ProgramData\Miniconda3\lib\site-packages\rest_framework\viewsets.py", line 114, in view
    return self.dispatch(request, *args, **kwargs)
  File "C:\ProgramData\Miniconda3\lib\site-packages\rest_framework\views.py", line 505, in dispatch
    response = self.handle_exception(exc)
  File "C:\ProgramData\Miniconda3\lib\site-packages\rest_framework\views.py", line 465, in handle_exception
    self.raise_uncaught_exception(exc)
  File "C:\ProgramData\Miniconda3\lib\site-packages\rest_framework\views.py", line 476, in raise_uncaught_exception
    raise exc
  File "C:\ProgramData\Miniconda3\lib\site-packages\rest_framework\views.py", line 502, in dispatch
    response = handler(request, *args, **kwargs)
  File "D:\MISC\GITHUB\knit_server//app\users\kviews\vendor_view.py", line 172, in create
    print("Already has the vendor", vendor_serializer.errors(), vendor_serializer.error_messages)
TypeError: 'ReturnDict' object is not callable
 django.request 2020-04-25 16:28:27,370 ERROR    Internal Server Error: /user/csv-vendors
Traceback (most recent call last):
  File "D:\MISC\GITHUB\knit_server//app\users\kviews\vendor_view.py", line 169, in create
    vendor_serializer.save()
  File "C:\ProgramData\Miniconda3\lib\site-packages\rest_framework\serializers.py", line 212, in save
    self.instance = self.create(validated_data)
  File "D:\MISC\GITHUB\knit_server//app\users\kserializers\vendor_serializer.py", line 47, in create
    user_serializer.is_valid(raise_exception=True)
  File "C:\ProgramData\Miniconda3\lib\site-packages\rest_framework\serializers.py", line 242, in is_valid
    raise ValidationError(self.errors)
rest_framework.exceptions.ValidationError: {'username_exists': ErrorDetail(string='Username is already in use. Try with different name', code='invalid'), 'email_exists': ErrorDetail(string='Email is already in use. Try with different email', code='invalid'), 'phone_exists': ErrorDetail(string='Phone number is already in use. Try with different number', code='invalid')}

During handling of the above exception, another exception occurred:

Traceback (most recent call last):
  File "C:\ProgramData\Miniconda3\lib\site-packages\django\core\handlers\exception.py", line 34, in inner
    response = get_response(request)
  File "C:\ProgramData\Miniconda3\lib\site-packages\django\core\handlers\base.py", line 115, in _get_response
    response = self.process_exception_by_middleware(e, request)
  File "C:\ProgramData\Miniconda3\lib\site-packages\django\core\handlers\base.py", line 113, in _get_response
    response = wrapped_callback(request, *callback_args, **callback_kwargs)
  File "C:\ProgramData\Miniconda3\lib\site-packages\django\views\decorators\csrf.py", line 54, in wrapped_view
    return view_func(*args, **kwargs)
  File "C:\ProgramData\Miniconda3\lib\site-packages\rest_framework\viewsets.py", line 114, in view
    return self.dispatch(request, *args, **kwargs)
  File "C:\ProgramData\Miniconda3\lib\site-packages\rest_framework\views.py", line 505, in dispatch
    response = self.handle_exception(exc)
  File "C:\ProgramData\Miniconda3\lib\site-packages\rest_framework\views.py", line 465, in handle_exception
    self.raise_uncaught_exception(exc)
  File "C:\ProgramData\Miniconda3\lib\site-packages\rest_framework\views.py", line 476, in raise_uncaught_exception
    raise exc
  File "C:\ProgramData\Miniconda3\lib\site-packages\rest_framework\views.py", line 502, in dispatch
    response = handler(request, *args, **kwargs)
  File "D:\MISC\GITHUB\knit_server//app\users\kviews\vendor_view.py", line 172, in create
    print("Already has the vendor", vendor_serializer.errors())
TypeError: 'ReturnDict' object is not callable
 django.request 2020-04-25 23:32:01,900 WARNING  Not Found: /
 django.request 2020-04-25 23:32:02,053 WARNING  Not Found: /favicon.ico
 django.request 2020-04-25 23:32:55,632 ERROR    Internal Server Error: /product/upload
Traceback (most recent call last):
  File "C:\ProgramData\Miniconda3\lib\site-packages\django\utils\datastructures.py", line 76, in __getitem__
    list_ = super().__getitem__(key)
KeyError: 'description'

During handling of the above exception, another exception occurred:

Traceback (most recent call last):
  File "C:\ProgramData\Miniconda3\lib\site-packages\django\core\handlers\exception.py", line 34, in inner
    response = get_response(request)
  File "C:\ProgramData\Miniconda3\lib\site-packages\django\core\handlers\base.py", line 115, in _get_response
    response = self.process_exception_by_middleware(e, request)
  File "C:\ProgramData\Miniconda3\lib\site-packages\django\core\handlers\base.py", line 113, in _get_response
    response = wrapped_callback(request, *callback_args, **callback_kwargs)
  File "C:\ProgramData\Miniconda3\lib\site-packages\django\views\decorators\csrf.py", line 54, in wrapped_view
    return view_func(*args, **kwargs)
  File "C:\ProgramData\Miniconda3\lib\site-packages\rest_framework\viewsets.py", line 114, in view
    return self.dispatch(request, *args, **kwargs)
  File "C:\ProgramData\Miniconda3\lib\site-packages\rest_framework\views.py", line 505, in dispatch
    response = self.handle_exception(exc)
  File "C:\ProgramData\Miniconda3\lib\site-packages\rest_framework\views.py", line 465, in handle_exception
    self.raise_uncaught_exception(exc)
  File "C:\ProgramData\Miniconda3\lib\site-packages\rest_framework\views.py", line 476, in raise_uncaught_exception
    raise exc
  File "C:\ProgramData\Miniconda3\lib\site-packages\rest_framework\views.py", line 502, in dispatch
    response = handler(request, *args, **kwargs)
  File "D:\MISC\GITHUB\knit_server//app\products\kviews\imageview.py", line 19, in create
    image_serializer = KImageSerializer(data= {'description': request.data['description'], 'image': request.FILES[image]})
  File "C:\ProgramData\Miniconda3\lib\site-packages\django\utils\datastructures.py", line 78, in __getitem__
    raise MultiValueDictKeyError(key)
django.utils.datastructures.MultiValueDictKeyError: 'description'
 django.request 2020-04-26 00:01:38,081 ERROR    Internal Server Error: /product/csv-stitch
Traceback (most recent call last):
  File "C:\ProgramData\Miniconda3\lib\site-packages\django\core\handlers\exception.py", line 34, in inner
    response = get_response(request)
  File "C:\ProgramData\Miniconda3\lib\site-packages\django\core\handlers\base.py", line 115, in _get_response
    response = self.process_exception_by_middleware(e, request)
  File "C:\ProgramData\Miniconda3\lib\site-packages\django\core\handlers\base.py", line 113, in _get_response
    response = wrapped_callback(request, *callback_args, **callback_kwargs)
  File "C:\ProgramData\Miniconda3\lib\site-packages\django\views\decorators\csrf.py", line 54, in wrapped_view
    return view_func(*args, **kwargs)
  File "C:\ProgramData\Miniconda3\lib\site-packages\rest_framework\viewsets.py", line 114, in view
    return self.dispatch(request, *args, **kwargs)
  File "C:\ProgramData\Miniconda3\lib\site-packages\rest_framework\views.py", line 505, in dispatch
    response = self.handle_exception(exc)
  File "C:\ProgramData\Miniconda3\lib\site-packages\rest_framework\views.py", line 465, in handle_exception
    self.raise_uncaught_exception(exc)
  File "C:\ProgramData\Miniconda3\lib\site-packages\rest_framework\views.py", line 476, in raise_uncaught_exception
    raise exc
  File "C:\ProgramData\Miniconda3\lib\site-packages\rest_framework\views.py", line 502, in dispatch
    response = handler(request, *args, **kwargs)
  File "D:\MISC\GITHUB\knit_server//app\products\kviews\stitchview.py", line 103, in create
    result = urllib.urlretrieve(row.get('image'))
AttributeError: module 'urllib' has no attribute 'urlretrieve'
 django.request 2020-04-26 00:04:33,997 ERROR    Internal Server Error: /product/csv-stitch
Traceback (most recent call last):
  File "C:\ProgramData\Miniconda3\lib\site-packages\django\core\handlers\exception.py", line 34, in inner
    response = get_response(request)
  File "C:\ProgramData\Miniconda3\lib\site-packages\django\core\handlers\base.py", line 115, in _get_response
    response = self.process_exception_by_middleware(e, request)
  File "C:\ProgramData\Miniconda3\lib\site-packages\django\core\handlers\base.py", line 113, in _get_response
    response = wrapped_callback(request, *callback_args, **callback_kwargs)
  File "C:\ProgramData\Miniconda3\lib\site-packages\django\views\decorators\csrf.py", line 54, in wrapped_view
    return view_func(*args, **kwargs)
  File "C:\ProgramData\Miniconda3\lib\site-packages\rest_framework\viewsets.py", line 114, in view
    return self.dispatch(request, *args, **kwargs)
  File "C:\ProgramData\Miniconda3\lib\site-packages\rest_framework\views.py", line 505, in dispatch
    response = self.handle_exception(exc)
  File "C:\ProgramData\Miniconda3\lib\site-packages\rest_framework\views.py", line 465, in handle_exception
    self.raise_uncaught_exception(exc)
  File "C:\ProgramData\Miniconda3\lib\site-packages\rest_framework\views.py", line 476, in raise_uncaught_exception
    raise exc
  File "C:\ProgramData\Miniconda3\lib\site-packages\rest_framework\views.py", line 502, in dispatch
    response = handler(request, *args, **kwargs)
  File "D:\MISC\GITHUB\knit_server//app\products\kviews\stitchview.py", line 103, in create
    result = urllib.request.urlretrieve(row.get('image'))
  File "C:\ProgramData\Miniconda3\lib\urllib\request.py", line 247, in urlretrieve
    with contextlib.closing(urlopen(url, data)) as fp:
  File "C:\ProgramData\Miniconda3\lib\urllib\request.py", line 222, in urlopen
    return opener.open(url, data, timeout)
  File "C:\ProgramData\Miniconda3\lib\urllib\request.py", line 510, in open
    req = Request(fullurl, data)
  File "C:\ProgramData\Miniconda3\lib\urllib\request.py", line 328, in __init__
    self.full_url = url
  File "C:\ProgramData\Miniconda3\lib\urllib\request.py", line 354, in full_url
    self._parse()
  File "C:\ProgramData\Miniconda3\lib\urllib\request.py", line 383, in _parse
    raise ValueError("unknown url type: %r" % self.full_url)
ValueError: unknown url type: 'media/ref_images/stitch/sarees.jpg'
 django.request 2020-04-26 00:06:36,722 ERROR    Internal Server Error: /product/csv-stitch
Traceback (most recent call last):
  File "C:\ProgramData\Miniconda3\lib\site-packages\django\core\handlers\exception.py", line 34, in inner
    response = get_response(request)
  File "C:\ProgramData\Miniconda3\lib\site-packages\django\core\handlers\base.py", line 115, in _get_response
    response = self.process_exception_by_middleware(e, request)
  File "C:\ProgramData\Miniconda3\lib\site-packages\django\core\handlers\base.py", line 113, in _get_response
    response = wrapped_callback(request, *callback_args, **callback_kwargs)
  File "C:\ProgramData\Miniconda3\lib\site-packages\django\views\decorators\csrf.py", line 54, in wrapped_view
    return view_func(*args, **kwargs)
  File "C:\ProgramData\Miniconda3\lib\site-packages\rest_framework\viewsets.py", line 114, in view
    return self.dispatch(request, *args, **kwargs)
  File "C:\ProgramData\Miniconda3\lib\site-packages\rest_framework\views.py", line 505, in dispatch
    response = self.handle_exception(exc)
  File "C:\ProgramData\Miniconda3\lib\site-packages\rest_framework\views.py", line 465, in handle_exception
    self.raise_uncaught_exception(exc)
  File "C:\ProgramData\Miniconda3\lib\site-packages\rest_framework\views.py", line 476, in raise_uncaught_exception
    raise exc
  File "C:\ProgramData\Miniconda3\lib\site-packages\rest_framework\views.py", line 502, in dispatch
    response = handler(request, *args, **kwargs)
  File "D:\MISC\GITHUB\knit_server//app\products\kviews\stitchview.py", line 102, in create
    img = os.path.join(settings.BASE_DIR, row.get('image'))
NameError: name 'settings' is not defined
 django.request 2020-04-26 00:08:17,451 ERROR    Internal Server Error: /product/csv-stitch
Traceback (most recent call last):
  File "C:\ProgramData\Miniconda3\lib\site-packages\django\core\handlers\exception.py", line 34, in inner
    response = get_response(request)
  File "C:\ProgramData\Miniconda3\lib\site-packages\django\core\handlers\base.py", line 115, in _get_response
    response = self.process_exception_by_middleware(e, request)
  File "C:\ProgramData\Miniconda3\lib\site-packages\django\core\handlers\base.py", line 113, in _get_response
    response = wrapped_callback(request, *callback_args, **callback_kwargs)
  File "C:\ProgramData\Miniconda3\lib\site-packages\django\views\decorators\csrf.py", line 54, in wrapped_view
    return view_func(*args, **kwargs)
  File "C:\ProgramData\Miniconda3\lib\site-packages\rest_framework\viewsets.py", line 114, in view
    return self.dispatch(request, *args, **kwargs)
  File "C:\ProgramData\Miniconda3\lib\site-packages\rest_framework\views.py", line 505, in dispatch
    response = self.handle_exception(exc)
  File "C:\ProgramData\Miniconda3\lib\site-packages\rest_framework\views.py", line 465, in handle_exception
    self.raise_uncaught_exception(exc)
  File "C:\ProgramData\Miniconda3\lib\site-packages\rest_framework\views.py", line 476, in raise_uncaught_exception
    raise exc
  File "C:\ProgramData\Miniconda3\lib\site-packages\rest_framework\views.py", line 502, in dispatch
    response = handler(request, *args, **kwargs)
  File "D:\MISC\GITHUB\knit_server//app\products\kviews\stitchview.py", line 105, in create
    result = urllib.request.urlretrieve(row.get('image'))
  File "C:\ProgramData\Miniconda3\lib\urllib\request.py", line 247, in urlretrieve
    with contextlib.closing(urlopen(url, data)) as fp:
  File "C:\ProgramData\Miniconda3\lib\urllib\request.py", line 222, in urlopen
    return opener.open(url, data, timeout)
  File "C:\ProgramData\Miniconda3\lib\urllib\request.py", line 510, in open
    req = Request(fullurl, data)
  File "C:\ProgramData\Miniconda3\lib\urllib\request.py", line 328, in __init__
    self.full_url = url
  File "C:\ProgramData\Miniconda3\lib\urllib\request.py", line 354, in full_url
    self._parse()
  File "C:\ProgramData\Miniconda3\lib\urllib\request.py", line 383, in _parse
    raise ValueError("unknown url type: %r" % self.full_url)
ValueError: unknown url type: 'media/ref_images/stitch/sarees.jpg'
 django.request 2020-04-26 00:11:45,490 ERROR    Internal Server Error: /product/csv-stitch
Traceback (most recent call last):
  File "C:\ProgramData\Miniconda3\lib\site-packages\django\core\handlers\exception.py", line 34, in inner
    response = get_response(request)
  File "C:\ProgramData\Miniconda3\lib\site-packages\django\core\handlers\base.py", line 115, in _get_response
    response = self.process_exception_by_middleware(e, request)
  File "C:\ProgramData\Miniconda3\lib\site-packages\django\core\handlers\base.py", line 113, in _get_response
    response = wrapped_callback(request, *callback_args, **callback_kwargs)
  File "C:\ProgramData\Miniconda3\lib\site-packages\django\views\decorators\csrf.py", line 54, in wrapped_view
    return view_func(*args, **kwargs)
  File "C:\ProgramData\Miniconda3\lib\site-packages\rest_framework\viewsets.py", line 114, in view
    return self.dispatch(request, *args, **kwargs)
  File "C:\ProgramData\Miniconda3\lib\site-packages\rest_framework\views.py", line 505, in dispatch
    response = self.handle_exception(exc)
  File "C:\ProgramData\Miniconda3\lib\site-packages\rest_framework\views.py", line 465, in handle_exception
    self.raise_uncaught_exception(exc)
  File "C:\ProgramData\Miniconda3\lib\site-packages\rest_framework\views.py", line 476, in raise_uncaught_exception
    raise exc
  File "C:\ProgramData\Miniconda3\lib\site-packages\rest_framework\views.py", line 502, in dispatch
    response = handler(request, *args, **kwargs)
  File "D:\MISC\GITHUB\knit_server//app\products\kviews\stitchview.py", line 106, in create
    filename = urlparse(row['image']).path.split('/')[-1]
TypeError: 'module' object is not callable
 django.request 2020-04-26 00:13:03,878 ERROR    Internal Server Error: /product/csv-stitch
Traceback (most recent call last):
  File "C:\ProgramData\Miniconda3\lib\site-packages\django\core\handlers\exception.py", line 34, in inner
    response = get_response(request)
  File "C:\ProgramData\Miniconda3\lib\site-packages\django\core\handlers\base.py", line 115, in _get_response
    response = self.process_exception_by_middleware(e, request)
  File "C:\ProgramData\Miniconda3\lib\site-packages\django\core\handlers\base.py", line 113, in _get_response
    response = wrapped_callback(request, *callback_args, **callback_kwargs)
  File "C:\ProgramData\Miniconda3\lib\site-packages\django\views\decorators\csrf.py", line 54, in wrapped_view
    return view_func(*args, **kwargs)
  File "C:\ProgramData\Miniconda3\lib\site-packages\rest_framework\viewsets.py", line 114, in view
    return self.dispatch(request, *args, **kwargs)
  File "C:\ProgramData\Miniconda3\lib\site-packages\rest_framework\views.py", line 505, in dispatch
    response = self.handle_exception(exc)
  File "C:\ProgramData\Miniconda3\lib\site-packages\rest_framework\views.py", line 465, in handle_exception
    self.raise_uncaught_exception(exc)
  File "C:\ProgramData\Miniconda3\lib\site-packages\rest_framework\views.py", line 476, in raise_uncaught_exception
    raise exc
  File "C:\ProgramData\Miniconda3\lib\site-packages\rest_framework\views.py", line 502, in dispatch
    response = handler(request, *args, **kwargs)
  File "D:\MISC\GITHUB\knit_server//app\products\kviews\stitchview.py", line 107, in create
    stitch_data['images'] = File(open(result[0]))
FileNotFoundError: [Errno 2] No such file or directory: 'D'
 django.request 2020-04-26 00:15:13,908 ERROR    Internal Server Error: /product/csv-stitch
Traceback (most recent call last):
  File "C:\ProgramData\Miniconda3\lib\site-packages\django\core\handlers\exception.py", line 34, in inner
    response = get_response(request)
  File "C:\ProgramData\Miniconda3\lib\site-packages\django\core\handlers\base.py", line 115, in _get_response
    response = self.process_exception_by_middleware(e, request)
  File "C:\ProgramData\Miniconda3\lib\site-packages\django\core\handlers\base.py", line 113, in _get_response
    response = wrapped_callback(request, *callback_args, **callback_kwargs)
  File "C:\ProgramData\Miniconda3\lib\site-packages\django\views\decorators\csrf.py", line 54, in wrapped_view
    return view_func(*args, **kwargs)
  File "C:\ProgramData\Miniconda3\lib\site-packages\rest_framework\viewsets.py", line 114, in view
    return self.dispatch(request, *args, **kwargs)
  File "C:\ProgramData\Miniconda3\lib\site-packages\rest_framework\views.py", line 505, in dispatch
    response = self.handle_exception(exc)
  File "C:\ProgramData\Miniconda3\lib\site-packages\rest_framework\views.py", line 465, in handle_exception
    self.raise_uncaught_exception(exc)
  File "C:\ProgramData\Miniconda3\lib\site-packages\rest_framework\views.py", line 476, in raise_uncaught_exception
    raise exc
  File "C:\ProgramData\Miniconda3\lib\site-packages\rest_framework\views.py", line 502, in dispatch
    response = handler(request, *args, **kwargs)
  File "D:\MISC\GITHUB\knit_server//app\products\kviews\stitchview.py", line 104, in create
    img = os.path.join(settings.BASE_DIR, result)
  File "C:\ProgramData\Miniconda3\lib\urllib\request.py", line 247, in urlretrieve
    with contextlib.closing(urlopen(url, data)) as fp:
  File "C:\ProgramData\Miniconda3\lib\urllib\request.py", line 222, in urlopen
    return opener.open(url, data, timeout)
  File "C:\ProgramData\Miniconda3\lib\urllib\request.py", line 510, in open
    req = Request(fullurl, data)
  File "C:\ProgramData\Miniconda3\lib\urllib\request.py", line 328, in __init__
    self.full_url = url
  File "C:\ProgramData\Miniconda3\lib\urllib\request.py", line 354, in full_url
    self._parse()
  File "C:\ProgramData\Miniconda3\lib\urllib\request.py", line 383, in _parse
    raise ValueError("unknown url type: %r" % self.full_url)
ValueError: unknown url type: 'media/ref_images/stitch/sarees.jpg'
 django.request 2020-04-26 00:17:09,534 ERROR    Internal Server Error: /product/csv-stitch
Traceback (most recent call last):
  File "C:\ProgramData\Miniconda3\lib\site-packages\django\core\handlers\exception.py", line 34, in inner
    response = get_response(request)
  File "C:\ProgramData\Miniconda3\lib\site-packages\django\core\handlers\base.py", line 115, in _get_response
    response = self.process_exception_by_middleware(e, request)
  File "C:\ProgramData\Miniconda3\lib\site-packages\django\core\handlers\base.py", line 113, in _get_response
    response = wrapped_callback(request, *callback_args, **callback_kwargs)
  File "C:\ProgramData\Miniconda3\lib\site-packages\django\views\decorators\csrf.py", line 54, in wrapped_view
    return view_func(*args, **kwargs)
  File "C:\ProgramData\Miniconda3\lib\site-packages\rest_framework\viewsets.py", line 114, in view
    return self.dispatch(request, *args, **kwargs)
  File "C:\ProgramData\Miniconda3\lib\site-packages\rest_framework\views.py", line 505, in dispatch
    response = self.handle_exception(exc)
  File "C:\ProgramData\Miniconda3\lib\site-packages\rest_framework\views.py", line 465, in handle_exception
    self.raise_uncaught_exception(exc)
  File "C:\ProgramData\Miniconda3\lib\site-packages\rest_framework\views.py", line 476, in raise_uncaught_exception
    raise exc
  File "C:\ProgramData\Miniconda3\lib\site-packages\rest_framework\views.py", line 502, in dispatch
    response = handler(request, *args, **kwargs)
  File "D:\MISC\GITHUB\knit_server//app\products\kviews\stitchview.py", line 106, in create
    img = os.path.join(settings.BASE_DIR, result)
  File "C:\ProgramData\Miniconda3\lib\urllib\request.py", line 247, in urlretrieve
    with contextlib.closing(urlopen(url, data)) as fp:
  File "C:\ProgramData\Miniconda3\lib\urllib\request.py", line 222, in urlopen
    return opener.open(url, data, timeout)
  File "C:\ProgramData\Miniconda3\lib\urllib\request.py", line 510, in open
    req = Request(fullurl, data)
  File "C:\ProgramData\Miniconda3\lib\urllib\request.py", line 328, in __init__
    self.full_url = url
  File "C:\ProgramData\Miniconda3\lib\urllib\request.py", line 354, in full_url
    self._parse()
  File "C:\ProgramData\Miniconda3\lib\urllib\request.py", line 383, in _parse
    raise ValueError("unknown url type: %r" % self.full_url)
ValueError: unknown url type: 'media/ref_images/stitch/sarees.jpg'
 django.request 2020-04-26 00:23:14,435 ERROR    Internal Server Error: /product/csv-stitch
Traceback (most recent call last):
  File "C:\ProgramData\Miniconda3\lib\site-packages\django\core\handlers\exception.py", line 34, in inner
    response = get_response(request)
  File "C:\ProgramData\Miniconda3\lib\site-packages\django\core\handlers\base.py", line 115, in _get_response
    response = self.process_exception_by_middleware(e, request)
  File "C:\ProgramData\Miniconda3\lib\site-packages\django\core\handlers\base.py", line 113, in _get_response
    response = wrapped_callback(request, *callback_args, **callback_kwargs)
  File "C:\ProgramData\Miniconda3\lib\site-packages\django\views\decorators\csrf.py", line 54, in wrapped_view
    return view_func(*args, **kwargs)
  File "C:\ProgramData\Miniconda3\lib\site-packages\rest_framework\viewsets.py", line 114, in view
    return self.dispatch(request, *args, **kwargs)
  File "C:\ProgramData\Miniconda3\lib\site-packages\rest_framework\views.py", line 505, in dispatch
    response = self.handle_exception(exc)
  File "C:\ProgramData\Miniconda3\lib\site-packages\rest_framework\views.py", line 465, in handle_exception
    self.raise_uncaught_exception(exc)
  File "C:\ProgramData\Miniconda3\lib\site-packages\rest_framework\views.py", line 476, in raise_uncaught_exception
    raise exc
  File "C:\ProgramData\Miniconda3\lib\site-packages\rest_framework\views.py", line 502, in dispatch
    response = handler(request, *args, **kwargs)
  File "D:\MISC\GITHUB\knit_server//app\products\kviews\stitchview.py", line 105, in create
    result = urllib.request.urlretrieve(row.get('image'))
  File "C:\ProgramData\Miniconda3\lib\urllib\request.py", line 247, in urlretrieve
    with contextlib.closing(urlopen(url, data)) as fp:
  File "C:\ProgramData\Miniconda3\lib\urllib\request.py", line 222, in urlopen
    return opener.open(url, data, timeout)
  File "C:\ProgramData\Miniconda3\lib\urllib\request.py", line 510, in open
    req = Request(fullurl, data)
  File "C:\ProgramData\Miniconda3\lib\urllib\request.py", line 328, in __init__
    self.full_url = url
  File "C:\ProgramData\Miniconda3\lib\urllib\request.py", line 354, in full_url
    self._parse()
  File "C:\ProgramData\Miniconda3\lib\urllib\request.py", line 383, in _parse
    raise ValueError("unknown url type: %r" % self.full_url)
ValueError: unknown url type: 'media/ref_images/stitch/sarees.jpg'
 django.request 2020-04-26 00:39:37,916 ERROR    Internal Server Error: /product/csv-stitch
Traceback (most recent call last):
  File "C:\ProgramData\Miniconda3\lib\site-packages\django\core\handlers\exception.py", line 34, in inner
    response = get_response(request)
  File "C:\ProgramData\Miniconda3\lib\site-packages\django\core\handlers\base.py", line 115, in _get_response
    response = self.process_exception_by_middleware(e, request)
  File "C:\ProgramData\Miniconda3\lib\site-packages\django\core\handlers\base.py", line 113, in _get_response
    response = wrapped_callback(request, *callback_args, **callback_kwargs)
  File "C:\ProgramData\Miniconda3\lib\site-packages\django\views\decorators\csrf.py", line 54, in wrapped_view
    return view_func(*args, **kwargs)
  File "C:\ProgramData\Miniconda3\lib\site-packages\rest_framework\viewsets.py", line 114, in view
    return self.dispatch(request, *args, **kwargs)
  File "C:\ProgramData\Miniconda3\lib\site-packages\rest_framework\views.py", line 505, in dispatch
    response = self.handle_exception(exc)
  File "C:\ProgramData\Miniconda3\lib\site-packages\rest_framework\views.py", line 465, in handle_exception
    self.raise_uncaught_exception(exc)
  File "C:\ProgramData\Miniconda3\lib\site-packages\rest_framework\views.py", line 476, in raise_uncaught_exception
    raise exc
  File "C:\ProgramData\Miniconda3\lib\site-packages\rest_framework\views.py", line 502, in dispatch
    response = handler(request, *args, **kwargs)
  File "D:\MISC\GITHUB\knit_server//app\products\kviews\stitchview.py", line 105, in create
    result = urllib.request.urlretrieve(row.get('image'))
  File "C:\ProgramData\Miniconda3\lib\urllib\request.py", line 247, in urlretrieve
    with contextlib.closing(urlopen(url, data)) as fp:
  File "C:\ProgramData\Miniconda3\lib\urllib\request.py", line 222, in urlopen
    return opener.open(url, data, timeout)
  File "C:\ProgramData\Miniconda3\lib\urllib\request.py", line 510, in open
    req = Request(fullurl, data)
  File "C:\ProgramData\Miniconda3\lib\urllib\request.py", line 328, in __init__
    self.full_url = url
  File "C:\ProgramData\Miniconda3\lib\urllib\request.py", line 354, in full_url
    self._parse()
  File "C:\ProgramData\Miniconda3\lib\urllib\request.py", line 383, in _parse
    raise ValueError("unknown url type: %r" % self.full_url)
ValueError: unknown url type: 'media/ref_images/stitch/sarees.jpg'
 django.request 2020-04-26 00:46:29,575 ERROR    Internal Server Error: /product/csv-stitch
Traceback (most recent call last):
  File "C:\ProgramData\Miniconda3\lib\site-packages\django\core\handlers\exception.py", line 34, in inner
    response = get_response(request)
  File "C:\ProgramData\Miniconda3\lib\site-packages\django\core\handlers\base.py", line 115, in _get_response
    response = self.process_exception_by_middleware(e, request)
  File "C:\ProgramData\Miniconda3\lib\site-packages\django\core\handlers\base.py", line 113, in _get_response
    response = wrapped_callback(request, *callback_args, **callback_kwargs)
  File "C:\ProgramData\Miniconda3\lib\site-packages\django\views\decorators\csrf.py", line 54, in wrapped_view
    return view_func(*args, **kwargs)
  File "C:\ProgramData\Miniconda3\lib\site-packages\rest_framework\viewsets.py", line 114, in view
    return self.dispatch(request, *args, **kwargs)
  File "C:\ProgramData\Miniconda3\lib\site-packages\rest_framework\views.py", line 505, in dispatch
    response = self.handle_exception(exc)
  File "C:\ProgramData\Miniconda3\lib\site-packages\rest_framework\views.py", line 465, in handle_exception
    self.raise_uncaught_exception(exc)
  File "C:\ProgramData\Miniconda3\lib\site-packages\rest_framework\views.py", line 476, in raise_uncaught_exception
    raise exc
  File "C:\ProgramData\Miniconda3\lib\site-packages\rest_framework\views.py", line 502, in dispatch
    response = handler(request, *args, **kwargs)
  File "D:\MISC\GITHUB\knit_server//app\products\kviews\stitchview.py", line 106, in create
    result = urllib.request.urlretrieve(row.get('image'))
  File "C:\ProgramData\Miniconda3\lib\urllib\request.py", line 247, in urlretrieve
    with contextlib.closing(urlopen(url, data)) as fp:
  File "C:\ProgramData\Miniconda3\lib\urllib\request.py", line 222, in urlopen
    return opener.open(url, data, timeout)
  File "C:\ProgramData\Miniconda3\lib\urllib\request.py", line 510, in open
    req = Request(fullurl, data)
  File "C:\ProgramData\Miniconda3\lib\urllib\request.py", line 328, in __init__
    self.full_url = url
  File "C:\ProgramData\Miniconda3\lib\urllib\request.py", line 354, in full_url
    self._parse()
  File "C:\ProgramData\Miniconda3\lib\urllib\request.py", line 383, in _parse
    raise ValueError("unknown url type: %r" % self.full_url)
ValueError: unknown url type: 'media/ref_images/stitch/sarees.jpg'
 django.request 2020-04-26 00:50:04,204 ERROR    Internal Server Error: /product/csv-stitch
Traceback (most recent call last):
  File "C:\ProgramData\Miniconda3\lib\site-packages\django\core\handlers\exception.py", line 34, in inner
    response = get_response(request)
  File "C:\ProgramData\Miniconda3\lib\site-packages\django\core\handlers\base.py", line 115, in _get_response
    response = self.process_exception_by_middleware(e, request)
  File "C:\ProgramData\Miniconda3\lib\site-packages\django\core\handlers\base.py", line 113, in _get_response
    response = wrapped_callback(request, *callback_args, **callback_kwargs)
  File "C:\ProgramData\Miniconda3\lib\site-packages\django\views\decorators\csrf.py", line 54, in wrapped_view
    return view_func(*args, **kwargs)
  File "C:\ProgramData\Miniconda3\lib\site-packages\rest_framework\viewsets.py", line 114, in view
    return self.dispatch(request, *args, **kwargs)
  File "C:\ProgramData\Miniconda3\lib\site-packages\rest_framework\views.py", line 505, in dispatch
    response = self.handle_exception(exc)
  File "C:\ProgramData\Miniconda3\lib\site-packages\rest_framework\views.py", line 465, in handle_exception
    self.raise_uncaught_exception(exc)
  File "C:\ProgramData\Miniconda3\lib\site-packages\rest_framework\views.py", line 476, in raise_uncaught_exception
    raise exc
  File "C:\ProgramData\Miniconda3\lib\site-packages\rest_framework\views.py", line 502, in dispatch
    response = handler(request, *args, **kwargs)
  File "D:\MISC\GITHUB\knit_server//app\products\kviews\stitchview.py", line 106, in create
    filename = urlparse(row['image']).path.split('/')[-1]
  File "C:\ProgramData\Miniconda3\lib\urllib\request.py", line 247, in urlretrieve
    with contextlib.closing(urlopen(url, data)) as fp:
  File "C:\ProgramData\Miniconda3\lib\urllib\request.py", line 222, in urlopen
    return opener.open(url, data, timeout)
  File "C:\ProgramData\Miniconda3\lib\urllib\request.py", line 510, in open
    req = Request(fullurl, data)
  File "C:\ProgramData\Miniconda3\lib\urllib\request.py", line 328, in __init__
    self.full_url = url
  File "C:\ProgramData\Miniconda3\lib\urllib\request.py", line 354, in full_url
    self._parse()
  File "C:\ProgramData\Miniconda3\lib\urllib\request.py", line 383, in _parse
    raise ValueError("unknown url type: %r" % self.full_url)
ValueError: unknown url type: 'media/ref_images/stitch/sarees.jpg'
 django.request 2020-04-26 00:52:52,003 WARNING  Not Found: /product/media/ref_images/stitch/sarees.jpg
 django.request 2020-04-26 00:52:56,346 ERROR    Internal Server Error: /product/csv-stitch
Traceback (most recent call last):
  File "C:\ProgramData\Miniconda3\lib\site-packages\django\core\handlers\exception.py", line 34, in inner
    response = get_response(request)
  File "C:\ProgramData\Miniconda3\lib\site-packages\django\core\handlers\base.py", line 115, in _get_response
    response = self.process_exception_by_middleware(e, request)
  File "C:\ProgramData\Miniconda3\lib\site-packages\django\core\handlers\base.py", line 113, in _get_response
    response = wrapped_callback(request, *callback_args, **callback_kwargs)
  File "C:\ProgramData\Miniconda3\lib\site-packages\django\views\decorators\csrf.py", line 54, in wrapped_view
    return view_func(*args, **kwargs)
  File "C:\ProgramData\Miniconda3\lib\site-packages\rest_framework\viewsets.py", line 114, in view
    return self.dispatch(request, *args, **kwargs)
  File "C:\ProgramData\Miniconda3\lib\site-packages\rest_framework\views.py", line 505, in dispatch
    response = self.handle_exception(exc)
  File "C:\ProgramData\Miniconda3\lib\site-packages\rest_framework\views.py", line 465, in handle_exception
    self.raise_uncaught_exception(exc)
  File "C:\ProgramData\Miniconda3\lib\site-packages\rest_framework\views.py", line 476, in raise_uncaught_exception
    raise exc
  File "C:\ProgramData\Miniconda3\lib\site-packages\rest_framework\views.py", line 502, in dispatch
    response = handler(request, *args, **kwargs)
  File "D:\MISC\GITHUB\knit_server//app\products\kviews\stitchview.py", line 106, in create
    filename = urlparse(row['image']).path.split('/')[-1]
  File "C:\ProgramData\Miniconda3\lib\urllib\request.py", line 247, in urlretrieve
    with contextlib.closing(urlopen(url, data)) as fp:
  File "C:\ProgramData\Miniconda3\lib\urllib\request.py", line 222, in urlopen
    return opener.open(url, data, timeout)
  File "C:\ProgramData\Miniconda3\lib\urllib\request.py", line 531, in open
    response = meth(req, response)
  File "C:\ProgramData\Miniconda3\lib\urllib\request.py", line 641, in http_response
    'http', request, response, code, msg, hdrs)
  File "C:\ProgramData\Miniconda3\lib\urllib\request.py", line 569, in error
    return self._call_chain(*args)
  File "C:\ProgramData\Miniconda3\lib\urllib\request.py", line 503, in _call_chain
    result = func(*args)
  File "C:\ProgramData\Miniconda3\lib\urllib\request.py", line 649, in http_error_default
    raise HTTPError(req.full_url, code, msg, hdrs, fp)
urllib.error.HTTPError: HTTP Error 404: Not Found
 django.request 2020-04-26 00:53:17,325 WARNING  Not Found: /product/media/ref_images/stitch/sarees.jpg
 django.request 2020-04-26 00:53:28,133 ERROR    Internal Server Error: /product/csv-stitch
Traceback (most recent call last):
  File "C:\ProgramData\Miniconda3\lib\site-packages\django\core\handlers\exception.py", line 34, in inner
    response = get_response(request)
  File "C:\ProgramData\Miniconda3\lib\site-packages\django\core\handlers\base.py", line 115, in _get_response
    response = self.process_exception_by_middleware(e, request)
  File "C:\ProgramData\Miniconda3\lib\site-packages\django\core\handlers\base.py", line 113, in _get_response
    response = wrapped_callback(request, *callback_args, **callback_kwargs)
  File "C:\ProgramData\Miniconda3\lib\site-packages\django\views\decorators\csrf.py", line 54, in wrapped_view
    return view_func(*args, **kwargs)
  File "C:\ProgramData\Miniconda3\lib\site-packages\rest_framework\viewsets.py", line 114, in view
    return self.dispatch(request, *args, **kwargs)
  File "C:\ProgramData\Miniconda3\lib\site-packages\rest_framework\views.py", line 505, in dispatch
    response = self.handle_exception(exc)
  File "C:\ProgramData\Miniconda3\lib\site-packages\rest_framework\views.py", line 465, in handle_exception
    self.raise_uncaught_exception(exc)
  File "C:\ProgramData\Miniconda3\lib\site-packages\rest_framework\views.py", line 476, in raise_uncaught_exception
    raise exc
  File "C:\ProgramData\Miniconda3\lib\site-packages\rest_framework\views.py", line 502, in dispatch
    response = handler(request, *args, **kwargs)
  File "D:\MISC\GITHUB\knit_server//app\products\kviews\stitchview.py", line 105, in create
    result = urllib.request.urlretrieve(img_path)
  File "C:\ProgramData\Miniconda3\lib\urllib\request.py", line 247, in urlretrieve
    with contextlib.closing(urlopen(url, data)) as fp:
  File "C:\ProgramData\Miniconda3\lib\urllib\request.py", line 222, in urlopen
    return opener.open(url, data, timeout)
  File "C:\ProgramData\Miniconda3\lib\urllib\request.py", line 531, in open
    response = meth(req, response)
  File "C:\ProgramData\Miniconda3\lib\urllib\request.py", line 641, in http_response
    'http', request, response, code, msg, hdrs)
  File "C:\ProgramData\Miniconda3\lib\urllib\request.py", line 569, in error
    return self._call_chain(*args)
  File "C:\ProgramData\Miniconda3\lib\urllib\request.py", line 503, in _call_chain
    result = func(*args)
  File "C:\ProgramData\Miniconda3\lib\urllib\request.py", line 649, in http_error_default
    raise HTTPError(req.full_url, code, msg, hdrs, fp)
urllib.error.HTTPError: HTTP Error 404: Not Found
 django.request 2020-04-26 01:02:10,037 WARNING  Not Found: /product/media/ref_images/stitch/sarees.jpg
 django.request 2020-04-26 01:08:13,882 ERROR    Internal Server Error: /product/csv-stitch
Traceback (most recent call last):
  File "C:\ProgramData\Miniconda3\lib\site-packages\django\core\handlers\exception.py", line 34, in inner
    response = get_response(request)
  File "C:\ProgramData\Miniconda3\lib\site-packages\django\core\handlers\base.py", line 115, in _get_response
    response = self.process_exception_by_middleware(e, request)
  File "C:\ProgramData\Miniconda3\lib\site-packages\django\core\handlers\base.py", line 113, in _get_response
    response = wrapped_callback(request, *callback_args, **callback_kwargs)
  File "C:\ProgramData\Miniconda3\lib\site-packages\django\views\decorators\csrf.py", line 54, in wrapped_view
    return view_func(*args, **kwargs)
  File "C:\ProgramData\Miniconda3\lib\site-packages\rest_framework\viewsets.py", line 114, in view
    return self.dispatch(request, *args, **kwargs)
  File "C:\ProgramData\Miniconda3\lib\site-packages\rest_framework\views.py", line 505, in dispatch
    response = self.handle_exception(exc)
  File "C:\ProgramData\Miniconda3\lib\site-packages\rest_framework\views.py", line 465, in handle_exception
    self.raise_uncaught_exception(exc)
  File "C:\ProgramData\Miniconda3\lib\site-packages\rest_framework\views.py", line 476, in raise_uncaught_exception
    raise exc
  File "C:\ProgramData\Miniconda3\lib\site-packages\rest_framework\views.py", line 502, in dispatch
    response = handler(request, *args, **kwargs)
  File "D:\MISC\GITHUB\knit_server//app\products\kviews\stitchview.py", line 108, in create
    stitch_data['images'] = File(open(result[0]))
FileNotFoundError: [Errno 2] No such file or directory: 'h'
 django.request 2020-04-26 01:09:53,055 ERROR    Internal Server Error: /product/csv-stitch
Traceback (most recent call last):
  File "C:\ProgramData\Miniconda3\lib\site-packages\django\core\handlers\exception.py", line 34, in inner
    response = get_response(request)
  File "C:\ProgramData\Miniconda3\lib\site-packages\django\core\handlers\base.py", line 115, in _get_response
    response = self.process_exception_by_middleware(e, request)
  File "C:\ProgramData\Miniconda3\lib\site-packages\django\core\handlers\base.py", line 113, in _get_response
    response = wrapped_callback(request, *callback_args, **callback_kwargs)
  File "C:\ProgramData\Miniconda3\lib\site-packages\django\views\decorators\csrf.py", line 54, in wrapped_view
    return view_func(*args, **kwargs)
  File "C:\ProgramData\Miniconda3\lib\site-packages\rest_framework\viewsets.py", line 114, in view
    return self.dispatch(request, *args, **kwargs)
  File "C:\ProgramData\Miniconda3\lib\site-packages\rest_framework\views.py", line 505, in dispatch
    response = self.handle_exception(exc)
  File "C:\ProgramData\Miniconda3\lib\site-packages\rest_framework\views.py", line 465, in handle_exception
    self.raise_uncaught_exception(exc)
  File "C:\ProgramData\Miniconda3\lib\site-packages\rest_framework\views.py", line 476, in raise_uncaught_exception
    raise exc
  File "C:\ProgramData\Miniconda3\lib\site-packages\rest_framework\views.py", line 502, in dispatch
    response = handler(request, *args, **kwargs)
  File "D:\MISC\GITHUB\knit_server//app\products\kviews\stitchview.py", line 108, in create
    stitch_data['images'] = File(open(result))
OSError: [Errno 22] Invalid argument: 'http://localhost:8000/media/ref_images/stitch/sarees.jpg'
 django.request 2020-04-26 01:37:39,956 ERROR    Internal Server Error: /product/csv-stitch
Traceback (most recent call last):
  File "C:\ProgramData\Miniconda3\lib\site-packages\django\core\handlers\exception.py", line 34, in inner
    response = get_response(request)
  File "C:\ProgramData\Miniconda3\lib\site-packages\django\core\handlers\base.py", line 115, in _get_response
    response = self.process_exception_by_middleware(e, request)
  File "C:\ProgramData\Miniconda3\lib\site-packages\django\core\handlers\base.py", line 113, in _get_response
    response = wrapped_callback(request, *callback_args, **callback_kwargs)
  File "C:\ProgramData\Miniconda3\lib\site-packages\django\views\decorators\csrf.py", line 54, in wrapped_view
    return view_func(*args, **kwargs)
  File "C:\ProgramData\Miniconda3\lib\site-packages\rest_framework\viewsets.py", line 114, in view
    return self.dispatch(request, *args, **kwargs)
  File "C:\ProgramData\Miniconda3\lib\site-packages\rest_framework\views.py", line 505, in dispatch
    response = self.handle_exception(exc)
  File "C:\ProgramData\Miniconda3\lib\site-packages\rest_framework\views.py", line 465, in handle_exception
    self.raise_uncaught_exception(exc)
  File "C:\ProgramData\Miniconda3\lib\site-packages\rest_framework\views.py", line 476, in raise_uncaught_exception
    raise exc
  File "C:\ProgramData\Miniconda3\lib\site-packages\rest_framework\views.py", line 502, in dispatch
    response = handler(request, *args, **kwargs)
  File "D:\MISC\GITHUB\knit_server//app\products\kviews\stitchview.py", line 108, in create
    stitch_data['images'] = File(open(row.get('image')))
FileNotFoundError: [Errno 2] No such file or directory: '/media/ref_images/stitch/sarees.jpg'
 django.request 2020-04-26 01:38:31,053 ERROR    Internal Server Error: /product/csv-stitch
Traceback (most recent call last):
  File "C:\ProgramData\Miniconda3\lib\site-packages\rest_framework\request.py", line 409, in __getattr__
    return getattr(self._request, attr)
AttributeError: 'WSGIRequest' object has no attribute 'get'

During handling of the above exception, another exception occurred:

Traceback (most recent call last):
  File "C:\ProgramData\Miniconda3\lib\site-packages\django\core\handlers\exception.py", line 34, in inner
    response = get_response(request)
  File "C:\ProgramData\Miniconda3\lib\site-packages\django\core\handlers\base.py", line 115, in _get_response
    response = self.process_exception_by_middleware(e, request)
  File "C:\ProgramData\Miniconda3\lib\site-packages\django\core\handlers\base.py", line 113, in _get_response
    response = wrapped_callback(request, *callback_args, **callback_kwargs)
  File "C:\ProgramData\Miniconda3\lib\site-packages\django\views\decorators\csrf.py", line 54, in wrapped_view
    return view_func(*args, **kwargs)
  File "C:\ProgramData\Miniconda3\lib\site-packages\rest_framework\viewsets.py", line 114, in view
    return self.dispatch(request, *args, **kwargs)
  File "C:\ProgramData\Miniconda3\lib\site-packages\rest_framework\views.py", line 505, in dispatch
    response = self.handle_exception(exc)
  File "C:\ProgramData\Miniconda3\lib\site-packages\rest_framework\views.py", line 465, in handle_exception
    self.raise_uncaught_exception(exc)
  File "C:\ProgramData\Miniconda3\lib\site-packages\rest_framework\views.py", line 476, in raise_uncaught_exception
    raise exc
  File "C:\ProgramData\Miniconda3\lib\site-packages\rest_framework\views.py", line 502, in dispatch
    response = handler(request, *args, **kwargs)
  File "D:\MISC\GITHUB\knit_server//app\products\kviews\stitchview.py", line 110, in create
    r = request.get(row.get('image'))
  File "C:\ProgramData\Miniconda3\lib\site-packages\rest_framework\request.py", line 411, in __getattr__
    return self.__getattribute__(attr)
AttributeError: 'Request' object has no attribute 'get'
 django.request 2020-04-26 01:42:34,805 ERROR    Internal Server Error: /product/csv-stitch
Traceback (most recent call last):
  File "C:\ProgramData\Miniconda3\lib\site-packages\django\core\handlers\exception.py", line 34, in inner
    response = get_response(request)
  File "C:\ProgramData\Miniconda3\lib\site-packages\django\core\handlers\base.py", line 115, in _get_response
    response = self.process_exception_by_middleware(e, request)
  File "C:\ProgramData\Miniconda3\lib\site-packages\django\core\handlers\base.py", line 113, in _get_response
    response = wrapped_callback(request, *callback_args, **callback_kwargs)
  File "C:\ProgramData\Miniconda3\lib\site-packages\django\views\decorators\csrf.py", line 54, in wrapped_view
    return view_func(*args, **kwargs)
  File "C:\ProgramData\Miniconda3\lib\site-packages\rest_framework\viewsets.py", line 114, in view
    return self.dispatch(request, *args, **kwargs)
  File "C:\ProgramData\Miniconda3\lib\site-packages\rest_framework\views.py", line 505, in dispatch
    response = self.handle_exception(exc)
  File "C:\ProgramData\Miniconda3\lib\site-packages\rest_framework\views.py", line 465, in handle_exception
    self.raise_uncaught_exception(exc)
  File "C:\ProgramData\Miniconda3\lib\site-packages\rest_framework\views.py", line 476, in raise_uncaught_exception
    raise exc
  File "C:\ProgramData\Miniconda3\lib\site-packages\rest_framework\views.py", line 502, in dispatch
    response = handler(request, *args, **kwargs)
  File "D:\MISC\GITHUB\knit_server//app\products\kviews\stitchview.py", line 110, in create
    model.thumbnail = File(f)
OSError: [Errno 22] Invalid argument: 'http://localhost:8000/media/ref_images/stitch/sarees.jpg'
 django.request 2020-04-26 01:43:39,625 ERROR    Internal Server Error: /product/csv-stitch
Traceback (most recent call last):
  File "C:\ProgramData\Miniconda3\lib\site-packages\django\core\handlers\exception.py", line 34, in inner
    response = get_response(request)
  File "C:\ProgramData\Miniconda3\lib\site-packages\django\core\handlers\base.py", line 115, in _get_response
    response = self.process_exception_by_middleware(e, request)
  File "C:\ProgramData\Miniconda3\lib\site-packages\django\core\handlers\base.py", line 113, in _get_response
    response = wrapped_callback(request, *callback_args, **callback_kwargs)
  File "C:\ProgramData\Miniconda3\lib\site-packages\django\views\decorators\csrf.py", line 54, in wrapped_view
    return view_func(*args, **kwargs)
  File "C:\ProgramData\Miniconda3\lib\site-packages\rest_framework\viewsets.py", line 114, in view
    return self.dispatch(request, *args, **kwargs)
  File "C:\ProgramData\Miniconda3\lib\site-packages\rest_framework\views.py", line 505, in dispatch
    response = self.handle_exception(exc)
  File "C:\ProgramData\Miniconda3\lib\site-packages\rest_framework\views.py", line 465, in handle_exception
    self.raise_uncaught_exception(exc)
  File "C:\ProgramData\Miniconda3\lib\site-packages\rest_framework\views.py", line 476, in raise_uncaught_exception
    raise exc
  File "C:\ProgramData\Miniconda3\lib\site-packages\rest_framework\views.py", line 502, in dispatch
    response = handler(request, *args, **kwargs)
  File "D:\MISC\GITHUB\knit_server//app\products\kviews\stitchview.py", line 110, in create
    model.thumbnail = File(f)
FileNotFoundError: [Errno 2] No such file or directory: '/media/ref_images/stitch/sarees.jpg'
 django.request 2020-04-26 01:46:04,341 ERROR    Internal Server Error: /product/csv-stitch
Traceback (most recent call last):
  File "C:\ProgramData\Miniconda3\lib\site-packages\django\core\handlers\exception.py", line 34, in inner
    response = get_response(request)
  File "C:\ProgramData\Miniconda3\lib\site-packages\django\core\handlers\base.py", line 115, in _get_response
    response = self.process_exception_by_middleware(e, request)
  File "C:\ProgramData\Miniconda3\lib\site-packages\django\core\handlers\base.py", line 113, in _get_response
    response = wrapped_callback(request, *callback_args, **callback_kwargs)
  File "C:\ProgramData\Miniconda3\lib\site-packages\django\views\decorators\csrf.py", line 54, in wrapped_view
    return view_func(*args, **kwargs)
  File "C:\ProgramData\Miniconda3\lib\site-packages\rest_framework\viewsets.py", line 114, in view
    return self.dispatch(request, *args, **kwargs)
  File "C:\ProgramData\Miniconda3\lib\site-packages\rest_framework\views.py", line 505, in dispatch
    response = self.handle_exception(exc)
  File "C:\ProgramData\Miniconda3\lib\site-packages\rest_framework\views.py", line 465, in handle_exception
    self.raise_uncaught_exception(exc)
  File "C:\ProgramData\Miniconda3\lib\site-packages\rest_framework\views.py", line 476, in raise_uncaught_exception
    raise exc
  File "C:\ProgramData\Miniconda3\lib\site-packages\rest_framework\views.py", line 502, in dispatch
    response = handler(request, *args, **kwargs)
  File "D:\MISC\GITHUB\knit_server//app\products\kviews\stitchview.py", line 104, in create
    result = urllib.request.urlretrieve(row.get('image'))
  File "C:\ProgramData\Miniconda3\lib\urllib\request.py", line 247, in urlretrieve
    with contextlib.closing(urlopen(url, data)) as fp:
  File "C:\ProgramData\Miniconda3\lib\urllib\request.py", line 222, in urlopen
    return opener.open(url, data, timeout)
  File "C:\ProgramData\Miniconda3\lib\urllib\request.py", line 510, in open
    req = Request(fullurl, data)
  File "C:\ProgramData\Miniconda3\lib\urllib\request.py", line 328, in __init__
    self.full_url = url
  File "C:\ProgramData\Miniconda3\lib\urllib\request.py", line 354, in full_url
    self._parse()
  File "C:\ProgramData\Miniconda3\lib\urllib\request.py", line 383, in _parse
    raise ValueError("unknown url type: %r" % self.full_url)
ValueError: unknown url type: '/media/ref_images/stitch/sarees.jpg'
 django.request 2020-04-26 01:47:29,244 ERROR    Internal Server Error: /product/csv-stitch
Traceback (most recent call last):
  File "C:\ProgramData\Miniconda3\lib\site-packages\django\core\handlers\exception.py", line 34, in inner
    response = get_response(request)
  File "C:\ProgramData\Miniconda3\lib\site-packages\django\core\handlers\base.py", line 115, in _get_response
    response = self.process_exception_by_middleware(e, request)
  File "C:\ProgramData\Miniconda3\lib\site-packages\django\core\handlers\base.py", line 113, in _get_response
    response = wrapped_callback(request, *callback_args, **callback_kwargs)
  File "C:\ProgramData\Miniconda3\lib\site-packages\django\views\decorators\csrf.py", line 54, in wrapped_view
    return view_func(*args, **kwargs)
  File "C:\ProgramData\Miniconda3\lib\site-packages\rest_framework\viewsets.py", line 114, in view
    return self.dispatch(request, *args, **kwargs)
  File "C:\ProgramData\Miniconda3\lib\site-packages\rest_framework\views.py", line 505, in dispatch
    response = self.handle_exception(exc)
  File "C:\ProgramData\Miniconda3\lib\site-packages\rest_framework\views.py", line 465, in handle_exception
    self.raise_uncaught_exception(exc)
  File "C:\ProgramData\Miniconda3\lib\site-packages\rest_framework\views.py", line 476, in raise_uncaught_exception
    raise exc
  File "C:\ProgramData\Miniconda3\lib\site-packages\rest_framework\views.py", line 502, in dispatch
    response = handler(request, *args, **kwargs)
  File "D:\MISC\GITHUB\knit_server//app\products\kviews\stitchview.py", line 107, in create
    stitch_data['images'] = File(open(result))
TypeError: expected str, bytes or os.PathLike object, not tuple
 django.request 2020-04-26 16:12:50,410 ERROR    Internal Server Error: /product/csv-stitch
Traceback (most recent call last):
  File "C:\ProgramData\Miniconda3\lib\site-packages\rest_framework\request.py", line 409, in __getattr__
    return getattr(self._request, attr)
AttributeError: 'WSGIRequest' object has no attribute 'get'

During handling of the above exception, another exception occurred:

Traceback (most recent call last):
  File "C:\ProgramData\Miniconda3\lib\site-packages\django\core\handlers\exception.py", line 34, in inner
    response = get_response(request)
  File "C:\ProgramData\Miniconda3\lib\site-packages\django\core\handlers\base.py", line 115, in _get_response
    response = self.process_exception_by_middleware(e, request)
  File "C:\ProgramData\Miniconda3\lib\site-packages\django\core\handlers\base.py", line 113, in _get_response
    response = wrapped_callback(request, *callback_args, **callback_kwargs)
  File "C:\ProgramData\Miniconda3\lib\site-packages\django\views\decorators\csrf.py", line 54, in wrapped_view
    return view_func(*args, **kwargs)
  File "C:\ProgramData\Miniconda3\lib\site-packages\rest_framework\viewsets.py", line 114, in view
    return self.dispatch(request, *args, **kwargs)
  File "C:\ProgramData\Miniconda3\lib\site-packages\rest_framework\views.py", line 505, in dispatch
    response = self.handle_exception(exc)
  File "C:\ProgramData\Miniconda3\lib\site-packages\rest_framework\views.py", line 465, in handle_exception
    self.raise_uncaught_exception(exc)
  File "C:\ProgramData\Miniconda3\lib\site-packages\rest_framework\views.py", line 476, in raise_uncaught_exception
    raise exc
  File "C:\ProgramData\Miniconda3\lib\site-packages\rest_framework\views.py", line 502, in dispatch
    response = handler(request, *args, **kwargs)
  File "D:\MISC\GITHUB\knit_server//app\products\kviews\stitchview.py", line 117, in create
    r = request.get(row.get("image"))
  File "C:\ProgramData\Miniconda3\lib\site-packages\rest_framework\request.py", line 411, in __getattr__
    return self.__getattribute__(attr)
AttributeError: 'Request' object has no attribute 'get'
 django.request 2020-04-26 16:16:59,557 ERROR    Internal Server Error: /product/csv-stitch
Traceback (most recent call last):
  File "C:\ProgramData\Miniconda3\lib\site-packages\django\core\handlers\exception.py", line 34, in inner
    response = get_response(request)
  File "C:\ProgramData\Miniconda3\lib\site-packages\django\core\handlers\base.py", line 115, in _get_response
    response = self.process_exception_by_middleware(e, request)
  File "C:\ProgramData\Miniconda3\lib\site-packages\django\core\handlers\base.py", line 113, in _get_response
    response = wrapped_callback(request, *callback_args, **callback_kwargs)
  File "C:\ProgramData\Miniconda3\lib\site-packages\django\views\decorators\csrf.py", line 54, in wrapped_view
    return view_func(*args, **kwargs)
  File "C:\ProgramData\Miniconda3\lib\site-packages\rest_framework\viewsets.py", line 114, in view
    return self.dispatch(request, *args, **kwargs)
  File "C:\ProgramData\Miniconda3\lib\site-packages\rest_framework\views.py", line 505, in dispatch
    response = self.handle_exception(exc)
  File "C:\ProgramData\Miniconda3\lib\site-packages\rest_framework\views.py", line 465, in handle_exception
    self.raise_uncaught_exception(exc)
  File "C:\ProgramData\Miniconda3\lib\site-packages\rest_framework\views.py", line 476, in raise_uncaught_exception
    raise exc
  File "C:\ProgramData\Miniconda3\lib\site-packages\rest_framework\views.py", line 502, in dispatch
    response = handler(request, *args, **kwargs)
  File "D:\MISC\GITHUB\knit_server//app\products\kviews\stitchview.py", line 118, in create
    image = r.content
AttributeError: 'str' object has no attribute 'content'
 django.request 2020-04-26 16:18:30,920 ERROR    Internal Server Error: /product/csv-stitch
Traceback (most recent call last):
  File "C:\ProgramData\Miniconda3\lib\site-packages\django\core\handlers\exception.py", line 34, in inner
    response = get_response(request)
  File "C:\ProgramData\Miniconda3\lib\site-packages\django\core\handlers\base.py", line 115, in _get_response
    response = self.process_exception_by_middleware(e, request)
  File "C:\ProgramData\Miniconda3\lib\site-packages\django\core\handlers\base.py", line 113, in _get_response
    response = wrapped_callback(request, *callback_args, **callback_kwargs)
  File "C:\ProgramData\Miniconda3\lib\site-packages\django\views\decorators\csrf.py", line 54, in wrapped_view
    return view_func(*args, **kwargs)
  File "C:\ProgramData\Miniconda3\lib\site-packages\rest_framework\viewsets.py", line 114, in view
    return self.dispatch(request, *args, **kwargs)
  File "C:\ProgramData\Miniconda3\lib\site-packages\rest_framework\views.py", line 505, in dispatch
    response = self.handle_exception(exc)
  File "C:\ProgramData\Miniconda3\lib\site-packages\rest_framework\views.py", line 465, in handle_exception
    self.raise_uncaught_exception(exc)
  File "C:\ProgramData\Miniconda3\lib\site-packages\rest_framework\views.py", line 476, in raise_uncaught_exception
    raise exc
  File "C:\ProgramData\Miniconda3\lib\site-packages\rest_framework\views.py", line 502, in dispatch
    response = handler(request, *args, **kwargs)
  File "D:\MISC\GITHUB\knit_server//app\products\kviews\stitchview.py", line 112, in create
    file = File(open(result[0], 'rb'))
  File "C:\ProgramData\Miniconda3\lib\urllib\request.py", line 247, in urlretrieve
    with contextlib.closing(urlopen(url, data)) as fp:
  File "C:\ProgramData\Miniconda3\lib\urllib\request.py", line 222, in urlopen
    return opener.open(url, data, timeout)
  File "C:\ProgramData\Miniconda3\lib\urllib\request.py", line 525, in open
    response = self._open(req, data)
  File "C:\ProgramData\Miniconda3\lib\urllib\request.py", line 548, in _open
    'unknown_open', req)
  File "C:\ProgramData\Miniconda3\lib\urllib\request.py", line 503, in _call_chain
    result = func(*args)
  File "C:\ProgramData\Miniconda3\lib\urllib\request.py", line 1389, in unknown_open
    raise URLError('unknown url type: %s' % type)
urllib.error.URLError: <urlopen error unknown url type: d>
 django.request 2020-04-26 16:20:07,434 ERROR    Internal Server Error: /product/csv-stitch
Traceback (most recent call last):
  File "C:\ProgramData\Miniconda3\lib\site-packages\django\core\handlers\exception.py", line 34, in inner
    response = get_response(request)
  File "C:\ProgramData\Miniconda3\lib\site-packages\django\core\handlers\base.py", line 115, in _get_response
    response = self.process_exception_by_middleware(e, request)
  File "C:\ProgramData\Miniconda3\lib\site-packages\django\core\handlers\base.py", line 113, in _get_response
    response = wrapped_callback(request, *callback_args, **callback_kwargs)
  File "C:\ProgramData\Miniconda3\lib\site-packages\django\views\decorators\csrf.py", line 54, in wrapped_view
    return view_func(*args, **kwargs)
  File "C:\ProgramData\Miniconda3\lib\site-packages\rest_framework\viewsets.py", line 114, in view
    return self.dispatch(request, *args, **kwargs)
  File "C:\ProgramData\Miniconda3\lib\site-packages\rest_framework\views.py", line 505, in dispatch
    response = self.handle_exception(exc)
  File "C:\ProgramData\Miniconda3\lib\site-packages\rest_framework\views.py", line 465, in handle_exception
    self.raise_uncaught_exception(exc)
  File "C:\ProgramData\Miniconda3\lib\site-packages\rest_framework\views.py", line 476, in raise_uncaught_exception
    raise exc
  File "C:\ProgramData\Miniconda3\lib\site-packages\rest_framework\views.py", line 502, in dispatch
    response = handler(request, *args, **kwargs)
  File "D:\MISC\GITHUB\knit_server//app\products\kviews\stitchview.py", line 112, in create
    file = File(result[0])
  File "C:\ProgramData\Miniconda3\lib\urllib\request.py", line 247, in urlretrieve
    with contextlib.closing(urlopen(url, data)) as fp:
  File "C:\ProgramData\Miniconda3\lib\urllib\request.py", line 222, in urlopen
    return opener.open(url, data, timeout)
  File "C:\ProgramData\Miniconda3\lib\urllib\request.py", line 525, in open
    response = self._open(req, data)
  File "C:\ProgramData\Miniconda3\lib\urllib\request.py", line 548, in _open
    'unknown_open', req)
  File "C:\ProgramData\Miniconda3\lib\urllib\request.py", line 503, in _call_chain
    result = func(*args)
  File "C:\ProgramData\Miniconda3\lib\urllib\request.py", line 1389, in unknown_open
    raise URLError('unknown url type: %s' % type)
urllib.error.URLError: <urlopen error unknown url type: d>
 django.request 2020-04-26 16:28:30,925 ERROR    Internal Server Error: /product/csv-stitch
Traceback (most recent call last):
  File "C:\ProgramData\Miniconda3\lib\site-packages\django\core\handlers\exception.py", line 34, in inner
    response = get_response(request)
  File "C:\ProgramData\Miniconda3\lib\site-packages\django\core\handlers\base.py", line 115, in _get_response
    response = self.process_exception_by_middleware(e, request)
  File "C:\ProgramData\Miniconda3\lib\site-packages\django\core\handlers\base.py", line 113, in _get_response
    response = wrapped_callback(request, *callback_args, **callback_kwargs)
  File "C:\ProgramData\Miniconda3\lib\site-packages\django\views\decorators\csrf.py", line 54, in wrapped_view
    return view_func(*args, **kwargs)
  File "C:\ProgramData\Miniconda3\lib\site-packages\rest_framework\viewsets.py", line 114, in view
    return self.dispatch(request, *args, **kwargs)
  File "C:\ProgramData\Miniconda3\lib\site-packages\rest_framework\views.py", line 505, in dispatch
    response = self.handle_exception(exc)
  File "C:\ProgramData\Miniconda3\lib\site-packages\rest_framework\views.py", line 465, in handle_exception
    self.raise_uncaught_exception(exc)
  File "C:\ProgramData\Miniconda3\lib\site-packages\rest_framework\views.py", line 476, in raise_uncaught_exception
    raise exc
  File "C:\ProgramData\Miniconda3\lib\site-packages\rest_framework\views.py", line 502, in dispatch
    response = handler(request, *args, **kwargs)
  File "D:\MISC\GITHUB\knit_server//app\products\kviews\stitchview.py", line 112, in create
    file = File(open(result[0], 'rb'))
  File "C:\ProgramData\Miniconda3\lib\urllib\request.py", line 247, in urlretrieve
    with contextlib.closing(urlopen(url, data)) as fp:
  File "C:\ProgramData\Miniconda3\lib\urllib\request.py", line 222, in urlopen
    return opener.open(url, data, timeout)
  File "C:\ProgramData\Miniconda3\lib\urllib\request.py", line 525, in open
    response = self._open(req, data)
  File "C:\ProgramData\Miniconda3\lib\urllib\request.py", line 548, in _open
    'unknown_open', req)
  File "C:\ProgramData\Miniconda3\lib\urllib\request.py", line 503, in _call_chain
    result = func(*args)
  File "C:\ProgramData\Miniconda3\lib\urllib\request.py", line 1389, in unknown_open
    raise URLError('unknown url type: %s' % type)
urllib.error.URLError: <urlopen error unknown url type: d>
 django.request 2020-04-26 16:30:33,271 ERROR    Internal Server Error: /product/csv-stitch
Traceback (most recent call last):
  File "C:\ProgramData\Miniconda3\lib\site-packages\django\core\handlers\exception.py", line 34, in inner
    response = get_response(request)
  File "C:\ProgramData\Miniconda3\lib\site-packages\django\core\handlers\base.py", line 115, in _get_response
    response = self.process_exception_by_middleware(e, request)
  File "C:\ProgramData\Miniconda3\lib\site-packages\django\core\handlers\base.py", line 113, in _get_response
    response = wrapped_callback(request, *callback_args, **callback_kwargs)
  File "C:\ProgramData\Miniconda3\lib\site-packages\django\views\decorators\csrf.py", line 54, in wrapped_view
    return view_func(*args, **kwargs)
  File "C:\ProgramData\Miniconda3\lib\site-packages\rest_framework\viewsets.py", line 114, in view
    return self.dispatch(request, *args, **kwargs)
  File "C:\ProgramData\Miniconda3\lib\site-packages\rest_framework\views.py", line 505, in dispatch
    response = self.handle_exception(exc)
  File "C:\ProgramData\Miniconda3\lib\site-packages\rest_framework\views.py", line 465, in handle_exception
    self.raise_uncaught_exception(exc)
  File "C:\ProgramData\Miniconda3\lib\site-packages\rest_framework\views.py", line 476, in raise_uncaught_exception
    raise exc
  File "C:\ProgramData\Miniconda3\lib\site-packages\rest_framework\views.py", line 502, in dispatch
    response = handler(request, *args, **kwargs)
  File "D:\MISC\GITHUB\knit_server//app\products\kviews\stitchview.py", line 112, in create
    file = File(open(result[0], 'rb'))
  File "C:\ProgramData\Miniconda3\lib\urllib\request.py", line 247, in urlretrieve
    with contextlib.closing(urlopen(url, data)) as fp:
  File "C:\ProgramData\Miniconda3\lib\urllib\request.py", line 222, in urlopen
    return opener.open(url, data, timeout)
  File "C:\ProgramData\Miniconda3\lib\urllib\request.py", line 525, in open
    response = self._open(req, data)
  File "C:\ProgramData\Miniconda3\lib\urllib\request.py", line 548, in _open
    'unknown_open', req)
  File "C:\ProgramData\Miniconda3\lib\urllib\request.py", line 503, in _call_chain
    result = func(*args)
  File "C:\ProgramData\Miniconda3\lib\urllib\request.py", line 1389, in unknown_open
    raise URLError('unknown url type: %s' % type)
urllib.error.URLError: <urlopen error unknown url type: d>
 django.request 2020-04-26 16:46:00,059 WARNING  Not Found: /favicon.ico
 django.request 2020-04-26 17:00:14,528 ERROR    Internal Server Error: /product/csv-stitch
Traceback (most recent call last):
  File "C:\ProgramData\Miniconda3\lib\site-packages\django\core\handlers\exception.py", line 34, in inner
    response = get_response(request)
  File "C:\ProgramData\Miniconda3\lib\site-packages\django\core\handlers\base.py", line 115, in _get_response
    response = self.process_exception_by_middleware(e, request)
  File "C:\ProgramData\Miniconda3\lib\site-packages\django\core\handlers\base.py", line 113, in _get_response
    response = wrapped_callback(request, *callback_args, **callback_kwargs)
  File "C:\ProgramData\Miniconda3\lib\site-packages\django\views\decorators\csrf.py", line 54, in wrapped_view
    return view_func(*args, **kwargs)
  File "C:\ProgramData\Miniconda3\lib\site-packages\rest_framework\viewsets.py", line 114, in view
    return self.dispatch(request, *args, **kwargs)
  File "C:\ProgramData\Miniconda3\lib\site-packages\rest_framework\views.py", line 505, in dispatch
    response = self.handle_exception(exc)
  File "C:\ProgramData\Miniconda3\lib\site-packages\rest_framework\views.py", line 465, in handle_exception
    self.raise_uncaught_exception(exc)
  File "C:\ProgramData\Miniconda3\lib\site-packages\rest_framework\views.py", line 476, in raise_uncaught_exception
    raise exc
  File "C:\ProgramData\Miniconda3\lib\site-packages\rest_framework\views.py", line 502, in dispatch
    response = handler(request, *args, **kwargs)
  File "D:\MISC\GITHUB\knit_server//app\products\kviews\stitchview.py", line 116, in create
    image = InMemoryUploadedFile(f, 'image', 'abcc.jpeg', 'image/jpeg', 82, 'utf-8')
NameError: name 'InMemoryUploadedFile' is not defined
 django.request 2020-04-26 17:47:54,620 ERROR    Internal Server Error: /product/csv-stitch
Traceback (most recent call last):
  File "C:\ProgramData\Miniconda3\lib\site-packages\django\core\handlers\exception.py", line 34, in inner
    response = get_response(request)
  File "C:\ProgramData\Miniconda3\lib\site-packages\django\core\handlers\base.py", line 115, in _get_response
    response = self.process_exception_by_middleware(e, request)
  File "C:\ProgramData\Miniconda3\lib\site-packages\django\core\handlers\base.py", line 113, in _get_response
    response = wrapped_callback(request, *callback_args, **callback_kwargs)
  File "C:\ProgramData\Miniconda3\lib\site-packages\django\views\decorators\csrf.py", line 54, in wrapped_view
    return view_func(*args, **kwargs)
  File "C:\ProgramData\Miniconda3\lib\site-packages\rest_framework\viewsets.py", line 114, in view
    return self.dispatch(request, *args, **kwargs)
  File "C:\ProgramData\Miniconda3\lib\site-packages\rest_framework\views.py", line 505, in dispatch
    response = self.handle_exception(exc)
  File "C:\ProgramData\Miniconda3\lib\site-packages\rest_framework\views.py", line 465, in handle_exception
    self.raise_uncaught_exception(exc)
  File "C:\ProgramData\Miniconda3\lib\site-packages\rest_framework\views.py", line 476, in raise_uncaught_exception
    raise exc
  File "C:\ProgramData\Miniconda3\lib\site-packages\rest_framework\views.py", line 502, in dispatch
    response = handler(request, *args, **kwargs)
  File "D:\MISC\GITHUB\knit_server//app\products\kviews\stitchview.py", line 117, in create
    stitch_data['images'] = MultiValueDict()
NameError: name 'MultiValueDict' is not defined
 django.request 2020-04-26 18:25:53,818 WARNING  Not Found: //media/images/stitch_73/lehenga.png
 django.request 2020-04-26 18:28:31,328 ERROR    Internal Server Error: /product/csv-stitch
Traceback (most recent call last):
  File "C:\ProgramData\Miniconda3\lib\site-packages\django\core\handlers\exception.py", line 34, in inner
    response = get_response(request)
  File "C:\ProgramData\Miniconda3\lib\site-packages\django\core\handlers\base.py", line 115, in _get_response
    response = self.process_exception_by_middleware(e, request)
  File "C:\ProgramData\Miniconda3\lib\site-packages\django\core\handlers\base.py", line 113, in _get_response
    response = wrapped_callback(request, *callback_args, **callback_kwargs)
  File "C:\ProgramData\Miniconda3\lib\site-packages\django\views\decorators\csrf.py", line 54, in wrapped_view
    return view_func(*args, **kwargs)
  File "C:\ProgramData\Miniconda3\lib\site-packages\rest_framework\viewsets.py", line 114, in view
    return self.dispatch(request, *args, **kwargs)
  File "C:\ProgramData\Miniconda3\lib\site-packages\rest_framework\views.py", line 505, in dispatch
    response = self.handle_exception(exc)
  File "C:\ProgramData\Miniconda3\lib\site-packages\rest_framework\views.py", line 465, in handle_exception
    self.raise_uncaught_exception(exc)
  File "C:\ProgramData\Miniconda3\lib\site-packages\rest_framework\views.py", line 476, in raise_uncaught_exception
    raise exc
  File "C:\ProgramData\Miniconda3\lib\site-packages\rest_framework\views.py", line 502, in dispatch
    response = handler(request, *args, **kwargs)
  File "D:\MISC\GITHUB\knit_server//app\products\kviews\stitchview.py", line 111, in create
    result = urllib.request.urlretrieve(row.get("image"))
  File "C:\ProgramData\Miniconda3\lib\urllib\request.py", line 247, in urlretrieve
    with contextlib.closing(urlopen(url, data)) as fp:
  File "C:\ProgramData\Miniconda3\lib\urllib\request.py", line 222, in urlopen
    return opener.open(url, data, timeout)
  File "C:\ProgramData\Miniconda3\lib\urllib\request.py", line 525, in open
    response = self._open(req, data)
  File "C:\ProgramData\Miniconda3\lib\urllib\request.py", line 548, in _open
    'unknown_open', req)
  File "C:\ProgramData\Miniconda3\lib\urllib\request.py", line 503, in _call_chain
    result = func(*args)
  File "C:\ProgramData\Miniconda3\lib\urllib\request.py", line 1389, in unknown_open
    raise URLError('unknown url type: %s' % type)
urllib.error.URLError: <urlopen error unknown url type: d>
 django.request 2020-04-26 18:29:03,786 ERROR    Internal Server Error: /product/csv-stitch
Traceback (most recent call last):
  File "C:\ProgramData\Miniconda3\lib\site-packages\django\core\handlers\exception.py", line 34, in inner
    response = get_response(request)
  File "C:\ProgramData\Miniconda3\lib\site-packages\django\core\handlers\base.py", line 115, in _get_response
    response = self.process_exception_by_middleware(e, request)
  File "C:\ProgramData\Miniconda3\lib\site-packages\django\core\handlers\base.py", line 113, in _get_response
    response = wrapped_callback(request, *callback_args, **callback_kwargs)
  File "C:\ProgramData\Miniconda3\lib\site-packages\django\views\decorators\csrf.py", line 54, in wrapped_view
    return view_func(*args, **kwargs)
  File "C:\ProgramData\Miniconda3\lib\site-packages\rest_framework\viewsets.py", line 114, in view
    return self.dispatch(request, *args, **kwargs)
  File "C:\ProgramData\Miniconda3\lib\site-packages\rest_framework\views.py", line 505, in dispatch
    response = self.handle_exception(exc)
  File "C:\ProgramData\Miniconda3\lib\site-packages\rest_framework\views.py", line 465, in handle_exception
    self.raise_uncaught_exception(exc)
  File "C:\ProgramData\Miniconda3\lib\site-packages\rest_framework\views.py", line 476, in raise_uncaught_exception
    raise exc
  File "C:\ProgramData\Miniconda3\lib\site-packages\rest_framework\views.py", line 502, in dispatch
    response = handler(request, *args, **kwargs)
  File "D:\MISC\GITHUB\knit_server//app\products\kviews\stitchview.py", line 111, in create
    result = urllib.request.urlretrieve(row.get("image"))
  File "C:\ProgramData\Miniconda3\lib\urllib\request.py", line 247, in urlretrieve
    with contextlib.closing(urlopen(url, data)) as fp:
  File "C:\ProgramData\Miniconda3\lib\urllib\request.py", line 222, in urlopen
    return opener.open(url, data, timeout)
  File "C:\ProgramData\Miniconda3\lib\urllib\request.py", line 525, in open
    response = self._open(req, data)
  File "C:\ProgramData\Miniconda3\lib\urllib\request.py", line 548, in _open
    'unknown_open', req)
  File "C:\ProgramData\Miniconda3\lib\urllib\request.py", line 503, in _call_chain
    result = func(*args)
  File "C:\ProgramData\Miniconda3\lib\urllib\request.py", line 1389, in unknown_open
    raise URLError('unknown url type: %s' % type)
urllib.error.URLError: <urlopen error unknown url type: d>
 django.request 2020-04-26 18:29:21,293 ERROR    Internal Server Error: /product/csv-stitch
Traceback (most recent call last):
  File "C:\ProgramData\Miniconda3\lib\site-packages\django\core\handlers\exception.py", line 34, in inner
    response = get_response(request)
  File "C:\ProgramData\Miniconda3\lib\site-packages\django\core\handlers\base.py", line 115, in _get_response
    response = self.process_exception_by_middleware(e, request)
  File "C:\ProgramData\Miniconda3\lib\site-packages\django\core\handlers\base.py", line 113, in _get_response
    response = wrapped_callback(request, *callback_args, **callback_kwargs)
  File "C:\ProgramData\Miniconda3\lib\site-packages\django\views\decorators\csrf.py", line 54, in wrapped_view
    return view_func(*args, **kwargs)
  File "C:\ProgramData\Miniconda3\lib\site-packages\rest_framework\viewsets.py", line 114, in view
    return self.dispatch(request, *args, **kwargs)
  File "C:\ProgramData\Miniconda3\lib\site-packages\rest_framework\views.py", line 505, in dispatch
    response = self.handle_exception(exc)
  File "C:\ProgramData\Miniconda3\lib\site-packages\rest_framework\views.py", line 465, in handle_exception
    self.raise_uncaught_exception(exc)
  File "C:\ProgramData\Miniconda3\lib\site-packages\rest_framework\views.py", line 476, in raise_uncaught_exception
    raise exc
  File "C:\ProgramData\Miniconda3\lib\site-packages\rest_framework\views.py", line 502, in dispatch
    response = handler(request, *args, **kwargs)
  File "D:\MISC\GITHUB\knit_server//app\products\kviews\stitchview.py", line 111, in create
    result = urllib.request.urlretrieve(row.get("image"))
  File "C:\ProgramData\Miniconda3\lib\urllib\request.py", line 247, in urlretrieve
    with contextlib.closing(urlopen(url, data)) as fp:
  File "C:\ProgramData\Miniconda3\lib\urllib\request.py", line 222, in urlopen
    return opener.open(url, data, timeout)
  File "C:\ProgramData\Miniconda3\lib\urllib\request.py", line 525, in open
    response = self._open(req, data)
  File "C:\ProgramData\Miniconda3\lib\urllib\request.py", line 548, in _open
    'unknown_open', req)
  File "C:\ProgramData\Miniconda3\lib\urllib\request.py", line 503, in _call_chain
    result = func(*args)
  File "C:\ProgramData\Miniconda3\lib\urllib\request.py", line 1389, in unknown_open
    raise URLError('unknown url type: %s' % type)
urllib.error.URLError: <urlopen error unknown url type: d>
 django.request 2020-04-26 18:30:36,231 ERROR    Internal Server Error: /product/csv-stitch
Traceback (most recent call last):
  File "C:\ProgramData\Miniconda3\lib\site-packages\django\core\handlers\exception.py", line 34, in inner
    response = get_response(request)
  File "C:\ProgramData\Miniconda3\lib\site-packages\django\core\handlers\base.py", line 115, in _get_response
    response = self.process_exception_by_middleware(e, request)
  File "C:\ProgramData\Miniconda3\lib\site-packages\django\core\handlers\base.py", line 113, in _get_response
    response = wrapped_callback(request, *callback_args, **callback_kwargs)
  File "C:\ProgramData\Miniconda3\lib\site-packages\django\views\decorators\csrf.py", line 54, in wrapped_view
    return view_func(*args, **kwargs)
  File "C:\ProgramData\Miniconda3\lib\site-packages\rest_framework\viewsets.py", line 114, in view
    return self.dispatch(request, *args, **kwargs)
  File "C:\ProgramData\Miniconda3\lib\site-packages\rest_framework\views.py", line 505, in dispatch
    response = self.handle_exception(exc)
  File "C:\ProgramData\Miniconda3\lib\site-packages\rest_framework\views.py", line 465, in handle_exception
    self.raise_uncaught_exception(exc)
  File "C:\ProgramData\Miniconda3\lib\site-packages\rest_framework\views.py", line 476, in raise_uncaught_exception
    raise exc
  File "C:\ProgramData\Miniconda3\lib\site-packages\rest_framework\views.py", line 502, in dispatch
    response = handler(request, *args, **kwargs)
  File "D:\MISC\GITHUB\knit_server//app\products\kviews\stitchview.py", line 111, in create
    p = urllib.request.urlretrieve(row.get("image"))
  File "C:\ProgramData\Miniconda3\lib\urllib\request.py", line 247, in urlretrieve
    with contextlib.closing(urlopen(url, data)) as fp:
  File "C:\ProgramData\Miniconda3\lib\urllib\request.py", line 222, in urlopen
    return opener.open(url, data, timeout)
  File "C:\ProgramData\Miniconda3\lib\urllib\request.py", line 525, in open
    response = self._open(req, data)
  File "C:\ProgramData\Miniconda3\lib\urllib\request.py", line 548, in _open
    'unknown_open', req)
  File "C:\ProgramData\Miniconda3\lib\urllib\request.py", line 503, in _call_chain
    result = func(*args)
  File "C:\ProgramData\Miniconda3\lib\urllib\request.py", line 1389, in unknown_open
    raise URLError('unknown url type: %s' % type)
urllib.error.URLError: <urlopen error unknown url type: d>
 django.request 2020-04-26 20:18:01,096 ERROR    Internal Server Error: /product/csv-stitch-types
Traceback (most recent call last):
  File "C:\ProgramData\Miniconda3\lib\site-packages\django\core\handlers\exception.py", line 34, in inner
    response = get_response(request)
  File "C:\ProgramData\Miniconda3\lib\site-packages\django\core\handlers\base.py", line 115, in _get_response
    response = self.process_exception_by_middleware(e, request)
  File "C:\ProgramData\Miniconda3\lib\site-packages\django\core\handlers\base.py", line 113, in _get_response
    response = wrapped_callback(request, *callback_args, **callback_kwargs)
  File "C:\ProgramData\Miniconda3\lib\site-packages\django\views\decorators\csrf.py", line 54, in wrapped_view
    return view_func(*args, **kwargs)
  File "C:\ProgramData\Miniconda3\lib\site-packages\rest_framework\viewsets.py", line 114, in view
    return self.dispatch(request, *args, **kwargs)
  File "C:\ProgramData\Miniconda3\lib\site-packages\rest_framework\views.py", line 505, in dispatch
    response = self.handle_exception(exc)
  File "C:\ProgramData\Miniconda3\lib\site-packages\rest_framework\views.py", line 465, in handle_exception
    self.raise_uncaught_exception(exc)
  File "C:\ProgramData\Miniconda3\lib\site-packages\rest_framework\views.py", line 476, in raise_uncaught_exception
    raise exc
  File "C:\ProgramData\Miniconda3\lib\site-packages\rest_framework\views.py", line 502, in dispatch
    response = handler(request, *args, **kwargs)
  File "D:\MISC\GITHUB\knit_server//app\products\kviews\csv_ref_stitch_view.py", line 77, in create
    decoded_file = request.FILES[csv_file].read().decode('utf-8').splitlines()
UnicodeDecodeError: 'utf-8' codec can't decode byte 0xa0 in position 293: invalid start byte
 django.request 2020-04-26 20:21:06,636 ERROR    Internal Server Error: /product/csv-stitch-types
Traceback (most recent call last):
  File "C:\ProgramData\Miniconda3\lib\site-packages\django\core\handlers\exception.py", line 34, in inner
    response = get_response(request)
  File "C:\ProgramData\Miniconda3\lib\site-packages\django\core\handlers\base.py", line 115, in _get_response
    response = self.process_exception_by_middleware(e, request)
  File "C:\ProgramData\Miniconda3\lib\site-packages\django\core\handlers\base.py", line 113, in _get_response
    response = wrapped_callback(request, *callback_args, **callback_kwargs)
  File "C:\ProgramData\Miniconda3\lib\site-packages\django\views\decorators\csrf.py", line 54, in wrapped_view
    return view_func(*args, **kwargs)
  File "C:\ProgramData\Miniconda3\lib\site-packages\rest_framework\viewsets.py", line 114, in view
    return self.dispatch(request, *args, **kwargs)
  File "C:\ProgramData\Miniconda3\lib\site-packages\rest_framework\views.py", line 505, in dispatch
    response = self.handle_exception(exc)
  File "C:\ProgramData\Miniconda3\lib\site-packages\rest_framework\views.py", line 465, in handle_exception
    self.raise_uncaught_exception(exc)
  File "C:\ProgramData\Miniconda3\lib\site-packages\rest_framework\views.py", line 476, in raise_uncaught_exception
    raise exc
  File "C:\ProgramData\Miniconda3\lib\site-packages\rest_framework\views.py", line 502, in dispatch
    response = handler(request, *args, **kwargs)
  File "D:\MISC\GITHUB\knit_server//app\products\kviews\csv_ref_stitch_view.py", line 77, in create
    decoded_file = request.FILES[csv_file].read().decode('utf-8').splitlines()
UnicodeDecodeError: 'utf-8' codec can't decode byte 0xa0 in position 293: invalid start byte
 django.request 2020-04-26 20:24:21,719 ERROR    Internal Server Error: /product/csv-stitch-types
Traceback (most recent call last):
  File "C:\ProgramData\Miniconda3\lib\site-packages\django\core\handlers\exception.py", line 34, in inner
    response = get_response(request)
  File "C:\ProgramData\Miniconda3\lib\site-packages\django\core\handlers\base.py", line 115, in _get_response
    response = self.process_exception_by_middleware(e, request)
  File "C:\ProgramData\Miniconda3\lib\site-packages\django\core\handlers\base.py", line 113, in _get_response
    response = wrapped_callback(request, *callback_args, **callback_kwargs)
  File "C:\ProgramData\Miniconda3\lib\site-packages\django\views\decorators\csrf.py", line 54, in wrapped_view
    return view_func(*args, **kwargs)
  File "C:\ProgramData\Miniconda3\lib\site-packages\rest_framework\viewsets.py", line 114, in view
    return self.dispatch(request, *args, **kwargs)
  File "C:\ProgramData\Miniconda3\lib\site-packages\rest_framework\views.py", line 505, in dispatch
    response = self.handle_exception(exc)
  File "C:\ProgramData\Miniconda3\lib\site-packages\rest_framework\views.py", line 465, in handle_exception
    self.raise_uncaught_exception(exc)
  File "C:\ProgramData\Miniconda3\lib\site-packages\rest_framework\views.py", line 476, in raise_uncaught_exception
    raise exc
  File "C:\ProgramData\Miniconda3\lib\site-packages\rest_framework\views.py", line 502, in dispatch
    response = handler(request, *args, **kwargs)
  File "D:\MISC\GITHUB\knit_server//app\products\kviews\csv_ref_stitch_view.py", line 77, in create
    decoded_file = request.FILES[csv_file].read().decode('utf-8').splitlines()
UnicodeDecodeError: 'utf-8' codec can't decode byte 0xa0 in position 293: invalid start byte
 django.request 2020-04-26 20:24:56,814 ERROR    Internal Server Error: /product/csv-stitch-types
Traceback (most recent call last):
  File "C:\ProgramData\Miniconda3\lib\site-packages\django\core\handlers\exception.py", line 34, in inner
    response = get_response(request)
  File "C:\ProgramData\Miniconda3\lib\site-packages\django\core\handlers\base.py", line 115, in _get_response
    response = self.process_exception_by_middleware(e, request)
  File "C:\ProgramData\Miniconda3\lib\site-packages\django\core\handlers\base.py", line 113, in _get_response
    response = wrapped_callback(request, *callback_args, **callback_kwargs)
  File "C:\ProgramData\Miniconda3\lib\site-packages\django\views\decorators\csrf.py", line 54, in wrapped_view
    return view_func(*args, **kwargs)
  File "C:\ProgramData\Miniconda3\lib\site-packages\rest_framework\viewsets.py", line 114, in view
    return self.dispatch(request, *args, **kwargs)
  File "C:\ProgramData\Miniconda3\lib\site-packages\rest_framework\views.py", line 505, in dispatch
    response = self.handle_exception(exc)
  File "C:\ProgramData\Miniconda3\lib\site-packages\rest_framework\views.py", line 465, in handle_exception
    self.raise_uncaught_exception(exc)
  File "C:\ProgramData\Miniconda3\lib\site-packages\rest_framework\views.py", line 476, in raise_uncaught_exception
    raise exc
  File "C:\ProgramData\Miniconda3\lib\site-packages\rest_framework\views.py", line 502, in dispatch
    response = handler(request, *args, **kwargs)
  File "D:\MISC\GITHUB\knit_server//app\products\kviews\csv_ref_stitch_view.py", line 77, in create
    decoded_file = request.FILES[csv_file].read().decode('utf-8').splitlines()
UnicodeDecodeError: 'utf-8' codec can't decode byte 0xa0 in position 293: invalid start byte
 django.request 2020-04-26 20:35:37,098 ERROR    Internal Server Error: /product/csv-stitch-types
Traceback (most recent call last):
  File "C:\ProgramData\Miniconda3\lib\site-packages\django\core\handlers\exception.py", line 34, in inner
    response = get_response(request)
  File "C:\ProgramData\Miniconda3\lib\site-packages\django\core\handlers\base.py", line 115, in _get_response
    response = self.process_exception_by_middleware(e, request)
  File "C:\ProgramData\Miniconda3\lib\site-packages\django\core\handlers\base.py", line 113, in _get_response
    response = wrapped_callback(request, *callback_args, **callback_kwargs)
  File "C:\ProgramData\Miniconda3\lib\site-packages\django\views\decorators\csrf.py", line 54, in wrapped_view
    return view_func(*args, **kwargs)
  File "C:\ProgramData\Miniconda3\lib\site-packages\rest_framework\viewsets.py", line 114, in view
    return self.dispatch(request, *args, **kwargs)
  File "C:\ProgramData\Miniconda3\lib\site-packages\rest_framework\views.py", line 505, in dispatch
    response = self.handle_exception(exc)
  File "C:\ProgramData\Miniconda3\lib\site-packages\rest_framework\views.py", line 465, in handle_exception
    self.raise_uncaught_exception(exc)
  File "C:\ProgramData\Miniconda3\lib\site-packages\rest_framework\views.py", line 476, in raise_uncaught_exception
    raise exc
  File "C:\ProgramData\Miniconda3\lib\site-packages\rest_framework\views.py", line 502, in dispatch
    response = handler(request, *args, **kwargs)
  File "D:\MISC\GITHUB\knit_server//app\products\kviews\csv_ref_stitch_view.py", line 76, in create
    with open(request.FILES[csv_file].name) as f:
FileNotFoundError: [Errno 2] No such file or directory: 'ref_stitch_type.csv'
 django.request 2020-04-26 20:36:16,134 ERROR    Internal Server Error: /product/csv-stitch-types
Traceback (most recent call last):
  File "C:\ProgramData\Miniconda3\lib\site-packages\django\core\handlers\exception.py", line 34, in inner
    response = get_response(request)
  File "C:\ProgramData\Miniconda3\lib\site-packages\django\core\handlers\base.py", line 115, in _get_response
    response = self.process_exception_by_middleware(e, request)
  File "C:\ProgramData\Miniconda3\lib\site-packages\django\core\handlers\base.py", line 113, in _get_response
    response = wrapped_callback(request, *callback_args, **callback_kwargs)
  File "C:\ProgramData\Miniconda3\lib\site-packages\django\views\decorators\csrf.py", line 54, in wrapped_view
    return view_func(*args, **kwargs)
  File "C:\ProgramData\Miniconda3\lib\site-packages\rest_framework\viewsets.py", line 114, in view
    return self.dispatch(request, *args, **kwargs)
  File "C:\ProgramData\Miniconda3\lib\site-packages\rest_framework\views.py", line 505, in dispatch
    response = self.handle_exception(exc)
  File "C:\ProgramData\Miniconda3\lib\site-packages\rest_framework\views.py", line 465, in handle_exception
    self.raise_uncaught_exception(exc)
  File "C:\ProgramData\Miniconda3\lib\site-packages\rest_framework\views.py", line 476, in raise_uncaught_exception
    raise exc
  File "C:\ProgramData\Miniconda3\lib\site-packages\rest_framework\views.py", line 502, in dispatch
    response = handler(request, *args, **kwargs)
  File "D:\MISC\GITHUB\knit_server//app\products\kviews\csv_ref_stitch_view.py", line 76, in create
    with open(request.FILES[csv_file]) as f:
TypeError: expected str, bytes or os.PathLike object, not InMemoryUploadedFile
 django.request 2020-04-26 20:36:45,314 ERROR    Internal Server Error: /product/csv-stitch-types
Traceback (most recent call last):
  File "C:\ProgramData\Miniconda3\lib\site-packages\django\core\handlers\exception.py", line 34, in inner
    response = get_response(request)
  File "C:\ProgramData\Miniconda3\lib\site-packages\django\core\handlers\base.py", line 115, in _get_response
    response = self.process_exception_by_middleware(e, request)
  File "C:\ProgramData\Miniconda3\lib\site-packages\django\core\handlers\base.py", line 113, in _get_response
    response = wrapped_callback(request, *callback_args, **callback_kwargs)
  File "C:\ProgramData\Miniconda3\lib\site-packages\django\views\decorators\csrf.py", line 54, in wrapped_view
    return view_func(*args, **kwargs)
  File "C:\ProgramData\Miniconda3\lib\site-packages\rest_framework\viewsets.py", line 114, in view
    return self.dispatch(request, *args, **kwargs)
  File "C:\ProgramData\Miniconda3\lib\site-packages\rest_framework\views.py", line 505, in dispatch
    response = self.handle_exception(exc)
  File "C:\ProgramData\Miniconda3\lib\site-packages\rest_framework\views.py", line 465, in handle_exception
    self.raise_uncaught_exception(exc)
  File "C:\ProgramData\Miniconda3\lib\site-packages\rest_framework\views.py", line 476, in raise_uncaught_exception
    raise exc
  File "C:\ProgramData\Miniconda3\lib\site-packages\rest_framework\views.py", line 502, in dispatch
    response = handler(request, *args, **kwargs)
  File "D:\MISC\GITHUB\knit_server//app\products\kviews\csv_ref_stitch_view.py", line 76, in create
    with open(request.FILES[csv_file].name) as f:
FileNotFoundError: [Errno 2] No such file or directory: 'ref_stitch_type.csv'
 django.request 2020-04-26 20:38:11,092 ERROR    Internal Server Error: /product/csv-stitch-types
Traceback (most recent call last):
  File "C:\ProgramData\Miniconda3\lib\site-packages\django\core\handlers\exception.py", line 34, in inner
    response = get_response(request)
  File "C:\ProgramData\Miniconda3\lib\site-packages\django\core\handlers\base.py", line 115, in _get_response
    response = self.process_exception_by_middleware(e, request)
  File "C:\ProgramData\Miniconda3\lib\site-packages\django\core\handlers\base.py", line 113, in _get_response
    response = wrapped_callback(request, *callback_args, **callback_kwargs)
  File "C:\ProgramData\Miniconda3\lib\site-packages\django\views\decorators\csrf.py", line 54, in wrapped_view
    return view_func(*args, **kwargs)
  File "C:\ProgramData\Miniconda3\lib\site-packages\rest_framework\viewsets.py", line 114, in view
    return self.dispatch(request, *args, **kwargs)
  File "C:\ProgramData\Miniconda3\lib\site-packages\rest_framework\views.py", line 505, in dispatch
    response = self.handle_exception(exc)
  File "C:\ProgramData\Miniconda3\lib\site-packages\rest_framework\views.py", line 465, in handle_exception
    self.raise_uncaught_exception(exc)
  File "C:\ProgramData\Miniconda3\lib\site-packages\rest_framework\views.py", line 476, in raise_uncaught_exception
    raise exc
  File "C:\ProgramData\Miniconda3\lib\site-packages\rest_framework\views.py", line 502, in dispatch
    response = handler(request, *args, **kwargs)
  File "D:\MISC\GITHUB\knit_server//app\products\kviews\csv_ref_stitch_view.py", line 76, in create
    with open(request.FILES[csv_file].name) as f:
FileNotFoundError: [Errno 2] No such file or directory: 'ref_stitch_type.csv'
 django.request 2020-04-27 11:04:21,347 ERROR    Internal Server Error: /product/csv-stitch
Traceback (most recent call last):
  File "C:\ProgramData\Miniconda3\lib\site-packages\django\core\handlers\exception.py", line 34, in inner
    response = get_response(request)
  File "C:\ProgramData\Miniconda3\lib\site-packages\django\core\handlers\base.py", line 115, in _get_response
    response = self.process_exception_by_middleware(e, request)
  File "C:\ProgramData\Miniconda3\lib\site-packages\django\core\handlers\base.py", line 113, in _get_response
    response = wrapped_callback(request, *callback_args, **callback_kwargs)
  File "C:\ProgramData\Miniconda3\lib\site-packages\django\views\decorators\csrf.py", line 54, in wrapped_view
    return view_func(*args, **kwargs)
  File "C:\ProgramData\Miniconda3\lib\site-packages\rest_framework\viewsets.py", line 114, in view
    return self.dispatch(request, *args, **kwargs)
  File "C:\ProgramData\Miniconda3\lib\site-packages\rest_framework\views.py", line 505, in dispatch
    response = self.handle_exception(exc)
  File "C:\ProgramData\Miniconda3\lib\site-packages\rest_framework\views.py", line 465, in handle_exception
    self.raise_uncaught_exception(exc)
  File "C:\ProgramData\Miniconda3\lib\site-packages\rest_framework\views.py", line 476, in raise_uncaught_exception
    raise exc
  File "C:\ProgramData\Miniconda3\lib\site-packages\rest_framework\views.py", line 502, in dispatch
    response = handler(request, *args, **kwargs)
  File "D:\MISC\GITHUB\knit_server//app\products\kviews\csv_ref_stitch_view.py", line 57, in create
    return Response(results, status=status.HTTP_201_CREATED)
UnboundLocalError: local variable 'results' referenced before assignment
 django.request 2020-04-27 11:13:55,961 WARNING  Not Found: /favicon.ico
 django.request 2020-04-27 11:17:20,879 ERROR    Internal Server Error: /product/csv-stitch-types
Traceback (most recent call last):
  File "C:\ProgramData\Miniconda3\lib\site-packages\django\core\handlers\exception.py", line 34, in inner
    response = get_response(request)
  File "C:\ProgramData\Miniconda3\lib\site-packages\django\core\handlers\base.py", line 115, in _get_response
    response = self.process_exception_by_middleware(e, request)
  File "C:\ProgramData\Miniconda3\lib\site-packages\django\core\handlers\base.py", line 113, in _get_response
    response = wrapped_callback(request, *callback_args, **callback_kwargs)
  File "C:\ProgramData\Miniconda3\lib\site-packages\django\views\decorators\csrf.py", line 54, in wrapped_view
    return view_func(*args, **kwargs)
  File "C:\ProgramData\Miniconda3\lib\site-packages\rest_framework\viewsets.py", line 114, in view
    return self.dispatch(request, *args, **kwargs)
  File "C:\ProgramData\Miniconda3\lib\site-packages\rest_framework\views.py", line 505, in dispatch
    response = self.handle_exception(exc)
  File "C:\ProgramData\Miniconda3\lib\site-packages\rest_framework\views.py", line 465, in handle_exception
    self.raise_uncaught_exception(exc)
  File "C:\ProgramData\Miniconda3\lib\site-packages\rest_framework\views.py", line 476, in raise_uncaught_exception
    raise exc
  File "C:\ProgramData\Miniconda3\lib\site-packages\rest_framework\views.py", line 502, in dispatch
    response = handler(request, *args, **kwargs)
  File "D:\MISC\GITHUB\knit_server//app\products\kviews\csv_ref_stitch_view.py", line 86, in create
    if stitch_obj:
UnboundLocalError: local variable 'stitch_obj' referenced before assignment
 django.request 2020-04-27 11:32:10,174 ERROR    Internal Server Error: /product/csv-stitch-types
Traceback (most recent call last):
  File "C:\ProgramData\Miniconda3\lib\site-packages\django\core\handlers\exception.py", line 34, in inner
    response = get_response(request)
  File "C:\ProgramData\Miniconda3\lib\site-packages\django\core\handlers\base.py", line 115, in _get_response
    response = self.process_exception_by_middleware(e, request)
  File "C:\ProgramData\Miniconda3\lib\site-packages\django\core\handlers\base.py", line 113, in _get_response
    response = wrapped_callback(request, *callback_args, **callback_kwargs)
  File "C:\ProgramData\Miniconda3\lib\site-packages\django\views\decorators\csrf.py", line 54, in wrapped_view
    return view_func(*args, **kwargs)
  File "C:\ProgramData\Miniconda3\lib\site-packages\rest_framework\viewsets.py", line 114, in view
    return self.dispatch(request, *args, **kwargs)
  File "C:\ProgramData\Miniconda3\lib\site-packages\rest_framework\views.py", line 505, in dispatch
    response = self.handle_exception(exc)
  File "C:\ProgramData\Miniconda3\lib\site-packages\rest_framework\views.py", line 465, in handle_exception
    self.raise_uncaught_exception(exc)
  File "C:\ProgramData\Miniconda3\lib\site-packages\rest_framework\views.py", line 476, in raise_uncaught_exception
    raise exc
  File "C:\ProgramData\Miniconda3\lib\site-packages\rest_framework\views.py", line 502, in dispatch
    response = handler(request, *args, **kwargs)
  File "D:\MISC\GITHUB\knit_server//app\products\kviews\csv_ref_stitch_view.py", line 86, in create
    if stitch_obj:
UnboundLocalError: local variable 'stitch_obj' referenced before assignment
 django.request 2020-04-27 11:32:16,650 ERROR    Internal Server Error: /product/csv-stitch-types
Traceback (most recent call last):
  File "C:\ProgramData\Miniconda3\lib\site-packages\django\core\handlers\exception.py", line 34, in inner
    response = get_response(request)
  File "C:\ProgramData\Miniconda3\lib\site-packages\django\core\handlers\base.py", line 115, in _get_response
    response = self.process_exception_by_middleware(e, request)
  File "C:\ProgramData\Miniconda3\lib\site-packages\django\core\handlers\base.py", line 113, in _get_response
    response = wrapped_callback(request, *callback_args, **callback_kwargs)
  File "C:\ProgramData\Miniconda3\lib\site-packages\django\views\decorators\csrf.py", line 54, in wrapped_view
    return view_func(*args, **kwargs)
  File "C:\ProgramData\Miniconda3\lib\site-packages\rest_framework\viewsets.py", line 114, in view
    return self.dispatch(request, *args, **kwargs)
  File "C:\ProgramData\Miniconda3\lib\site-packages\rest_framework\views.py", line 505, in dispatch
    response = self.handle_exception(exc)
  File "C:\ProgramData\Miniconda3\lib\site-packages\rest_framework\views.py", line 465, in handle_exception
    self.raise_uncaught_exception(exc)
  File "C:\ProgramData\Miniconda3\lib\site-packages\rest_framework\views.py", line 476, in raise_uncaught_exception
    raise exc
  File "C:\ProgramData\Miniconda3\lib\site-packages\rest_framework\views.py", line 502, in dispatch
    response = handler(request, *args, **kwargs)
  File "D:\MISC\GITHUB\knit_server//app\products\kviews\csv_ref_stitch_view.py", line 86, in create
    if stitch_obj:
UnboundLocalError: local variable 'stitch_obj' referenced before assignment
 django.request 2020-04-27 11:32:46,187 WARNING  Bad Request: /product/csv-stitch-types
 django.request 2020-04-27 11:33:57,522 WARNING  Bad Request: /product/csv-stitch-types
 django.request 2020-04-27 11:34:22,725 WARNING  Bad Request: /product/csv-stitch-types
 django.request 2020-04-27 11:34:54,385 WARNING  Bad Request: /product/csv-stitch-types
 django.request 2020-04-27 11:36:50,057 WARNING  Bad Request: /product/csv-stitch-types
 django.request 2020-04-27 11:37:17,478 WARNING  Bad Request: /product/csv-stitch-types
 django.request 2020-04-27 11:37:38,197 WARNING  Bad Request: /product/csv-stitch-types
 django.request 2020-04-27 11:37:59,128 WARNING  Bad Request: /product/csv-stitch-types
 django.request 2020-04-27 11:38:50,217 WARNING  Bad Request: /product/csv-stitch-types
 django.request 2020-04-27 11:39:30,695 WARNING  Bad Request: /product/csv-stitch-types
 django.request 2020-04-27 11:40:21,730 ERROR    Internal Server Error: /product/csv-stitch-types
Traceback (most recent call last):
  File "C:\ProgramData\Miniconda3\lib\site-packages\django\core\handlers\exception.py", line 34, in inner
    response = get_response(request)
  File "C:\ProgramData\Miniconda3\lib\site-packages\django\core\handlers\base.py", line 115, in _get_response
    response = self.process_exception_by_middleware(e, request)
  File "C:\ProgramData\Miniconda3\lib\site-packages\django\core\handlers\base.py", line 113, in _get_response
    response = wrapped_callback(request, *callback_args, **callback_kwargs)
  File "C:\ProgramData\Miniconda3\lib\site-packages\django\views\decorators\csrf.py", line 54, in wrapped_view
    return view_func(*args, **kwargs)
  File "C:\ProgramData\Miniconda3\lib\site-packages\rest_framework\viewsets.py", line 114, in view
    return self.dispatch(request, *args, **kwargs)
  File "C:\ProgramData\Miniconda3\lib\site-packages\rest_framework\views.py", line 505, in dispatch
    response = self.handle_exception(exc)
  File "C:\ProgramData\Miniconda3\lib\site-packages\rest_framework\views.py", line 465, in handle_exception
    self.raise_uncaught_exception(exc)
  File "C:\ProgramData\Miniconda3\lib\site-packages\rest_framework\views.py", line 476, in raise_uncaught_exception
    raise exc
  File "C:\ProgramData\Miniconda3\lib\site-packages\rest_framework\views.py", line 502, in dispatch
    response = handler(request, *args, **kwargs)
  File "D:\MISC\GITHUB\knit_server//app\products\kviews\csv_ref_stitch_view.py", line 86, in create
    stitch_obj = Stitch.objects.filter(code__icontains=row.get('sitch-code'))
  File "C:\ProgramData\Miniconda3\lib\site-packages\django\db\models\manager.py", line 82, in manager_method
    return getattr(self.get_queryset(), name)(*args, **kwargs)
  File "C:\ProgramData\Miniconda3\lib\site-packages\django\db\models\query.py", line 904, in filter
    return self._filter_or_exclude(False, *args, **kwargs)
  File "C:\ProgramData\Miniconda3\lib\site-packages\django\db\models\query.py", line 923, in _filter_or_exclude
    clone.query.add_q(Q(*args, **kwargs))
  File "C:\ProgramData\Miniconda3\lib\site-packages\django\db\models\sql\query.py", line 1340, in add_q
    clause, _ = self._add_q(q_object, self.used_aliases)
  File "C:\ProgramData\Miniconda3\lib\site-packages\django\db\models\sql\query.py", line 1371, in _add_q
    check_filterable=check_filterable,
  File "C:\ProgramData\Miniconda3\lib\site-packages\django\db\models\sql\query.py", line 1301, in build_filter
    condition = self.build_lookup(lookups, col, value)
  File "C:\ProgramData\Miniconda3\lib\site-packages\django\db\models\sql\query.py", line 1160, in build_lookup
    raise ValueError("Cannot use None as a query value")
ValueError: Cannot use None as a query value
 django.request 2020-04-27 11:41:34,934 ERROR    Internal Server Error: /product/csv-stitch-types
Traceback (most recent call last):
  File "C:\ProgramData\Miniconda3\lib\site-packages\django\core\handlers\exception.py", line 34, in inner
    response = get_response(request)
  File "C:\ProgramData\Miniconda3\lib\site-packages\django\core\handlers\base.py", line 115, in _get_response
    response = self.process_exception_by_middleware(e, request)
  File "C:\ProgramData\Miniconda3\lib\site-packages\django\core\handlers\base.py", line 113, in _get_response
    response = wrapped_callback(request, *callback_args, **callback_kwargs)
  File "C:\ProgramData\Miniconda3\lib\site-packages\django\views\decorators\csrf.py", line 54, in wrapped_view
    return view_func(*args, **kwargs)
  File "C:\ProgramData\Miniconda3\lib\site-packages\rest_framework\viewsets.py", line 114, in view
    return self.dispatch(request, *args, **kwargs)
  File "C:\ProgramData\Miniconda3\lib\site-packages\rest_framework\views.py", line 505, in dispatch
    response = self.handle_exception(exc)
  File "C:\ProgramData\Miniconda3\lib\site-packages\rest_framework\views.py", line 465, in handle_exception
    self.raise_uncaught_exception(exc)
  File "C:\ProgramData\Miniconda3\lib\site-packages\rest_framework\views.py", line 476, in raise_uncaught_exception
    raise exc
  File "C:\ProgramData\Miniconda3\lib\site-packages\rest_framework\views.py", line 502, in dispatch
    response = handler(request, *args, **kwargs)
  File "D:\MISC\GITHUB\knit_server//app\products\kviews\csv_ref_stitch_view.py", line 90, in create
    stitch_data['stitch'] = stitch_obj.id
AttributeError: 'QuerySet' object has no attribute 'id'
 django.request 2020-04-27 11:47:19,155 ERROR    Internal Server Error: /product/csv-stitch-types
Traceback (most recent call last):
  File "C:\ProgramData\Miniconda3\lib\site-packages\django\core\handlers\exception.py", line 34, in inner
    response = get_response(request)
  File "C:\ProgramData\Miniconda3\lib\site-packages\django\core\handlers\base.py", line 115, in _get_response
    response = self.process_exception_by_middleware(e, request)
  File "C:\ProgramData\Miniconda3\lib\site-packages\django\core\handlers\base.py", line 113, in _get_response
    response = wrapped_callback(request, *callback_args, **callback_kwargs)
  File "C:\ProgramData\Miniconda3\lib\site-packages\django\views\decorators\csrf.py", line 54, in wrapped_view
    return view_func(*args, **kwargs)
  File "C:\ProgramData\Miniconda3\lib\site-packages\rest_framework\viewsets.py", line 114, in view
    return self.dispatch(request, *args, **kwargs)
  File "C:\ProgramData\Miniconda3\lib\site-packages\rest_framework\views.py", line 505, in dispatch
    response = self.handle_exception(exc)
  File "C:\ProgramData\Miniconda3\lib\site-packages\rest_framework\views.py", line 465, in handle_exception
    self.raise_uncaught_exception(exc)
  File "C:\ProgramData\Miniconda3\lib\site-packages\rest_framework\views.py", line 476, in raise_uncaught_exception
    raise exc
  File "C:\ProgramData\Miniconda3\lib\site-packages\rest_framework\views.py", line 502, in dispatch
    response = handler(request, *args, **kwargs)
  File "D:\MISC\GITHUB\knit_server//app\products\kviews\csv_ref_stitch_view.py", line 75, in create
    decoded_file = request.FILES[csv_file].read().decode('utf-8').splitlines()
UnicodeDecodeError: 'utf-8' codec can't decode byte 0xa0 in position 293: invalid start byte
 django.request 2020-04-27 11:48:48,801 ERROR    Internal Server Error: /product/csv-stitch-types
Traceback (most recent call last):
  File "C:\ProgramData\Miniconda3\lib\site-packages\django\core\handlers\exception.py", line 34, in inner
    response = get_response(request)
  File "C:\ProgramData\Miniconda3\lib\site-packages\django\core\handlers\base.py", line 115, in _get_response
    response = self.process_exception_by_middleware(e, request)
  File "C:\ProgramData\Miniconda3\lib\site-packages\django\core\handlers\base.py", line 113, in _get_response
    response = wrapped_callback(request, *callback_args, **callback_kwargs)
  File "C:\ProgramData\Miniconda3\lib\site-packages\django\views\decorators\csrf.py", line 54, in wrapped_view
    return view_func(*args, **kwargs)
  File "C:\ProgramData\Miniconda3\lib\site-packages\rest_framework\viewsets.py", line 114, in view
    return self.dispatch(request, *args, **kwargs)
  File "C:\ProgramData\Miniconda3\lib\site-packages\rest_framework\views.py", line 505, in dispatch
    response = self.handle_exception(exc)
  File "C:\ProgramData\Miniconda3\lib\site-packages\rest_framework\views.py", line 465, in handle_exception
    self.raise_uncaught_exception(exc)
  File "C:\ProgramData\Miniconda3\lib\site-packages\rest_framework\views.py", line 476, in raise_uncaught_exception
    raise exc
  File "C:\ProgramData\Miniconda3\lib\site-packages\rest_framework\views.py", line 502, in dispatch
    response = handler(request, *args, **kwargs)
  File "D:\MISC\GITHUB\knit_server//app\products\kviews\csv_ref_stitch_view.py", line 75, in create
    decoded_file = request.FILES[csv_file].read().decode('utf-8').splitlines()
UnicodeDecodeError: 'utf-8' codec can't decode byte 0xa0 in position 293: invalid start byte
 django.request 2020-04-27 11:50:25,994 WARNING  Bad Request: /product/csv-stitch-types
 django.request 2020-04-27 11:51:12,365 WARNING  Bad Request: /product/csv-stitch-types
 django.request 2020-04-27 11:51:26,172 WARNING  Bad Request: /product/csv-stitch-types
 django.request 2020-04-27 11:51:59,055 ERROR    Internal Server Error: /product/csv-stitch-types
Traceback (most recent call last):
  File "C:\ProgramData\Miniconda3\lib\site-packages\django\core\handlers\exception.py", line 34, in inner
    response = get_response(request)
  File "C:\ProgramData\Miniconda3\lib\site-packages\django\core\handlers\base.py", line 115, in _get_response
    response = self.process_exception_by_middleware(e, request)
  File "C:\ProgramData\Miniconda3\lib\site-packages\django\core\handlers\base.py", line 113, in _get_response
    response = wrapped_callback(request, *callback_args, **callback_kwargs)
  File "C:\ProgramData\Miniconda3\lib\site-packages\django\views\decorators\csrf.py", line 54, in wrapped_view
    return view_func(*args, **kwargs)
  File "C:\ProgramData\Miniconda3\lib\site-packages\rest_framework\viewsets.py", line 114, in view
    return self.dispatch(request, *args, **kwargs)
  File "C:\ProgramData\Miniconda3\lib\site-packages\rest_framework\views.py", line 505, in dispatch
    response = self.handle_exception(exc)
  File "C:\ProgramData\Miniconda3\lib\site-packages\rest_framework\views.py", line 465, in handle_exception
    self.raise_uncaught_exception(exc)
  File "C:\ProgramData\Miniconda3\lib\site-packages\rest_framework\views.py", line 476, in raise_uncaught_exception
    raise exc
  File "C:\ProgramData\Miniconda3\lib\site-packages\rest_framework\views.py", line 502, in dispatch
    response = handler(request, *args, **kwargs)
  File "D:\MISC\GITHUB\knit_server//app\products\kviews\csv_ref_stitch_view.py", line 75, in create
    decoded_file = request.FILES[csv_file].read().encoding('latin1').splitlines()
AttributeError: 'bytes' object has no attribute 'encoding'
 django.request 2020-04-27 11:52:33,797 ERROR    Internal Server Error: /product/csv-stitch-types
Traceback (most recent call last):
  File "C:\ProgramData\Miniconda3\lib\site-packages\django\core\handlers\exception.py", line 34, in inner
    response = get_response(request)
  File "C:\ProgramData\Miniconda3\lib\site-packages\django\core\handlers\base.py", line 115, in _get_response
    response = self.process_exception_by_middleware(e, request)
  File "C:\ProgramData\Miniconda3\lib\site-packages\django\core\handlers\base.py", line 113, in _get_response
    response = wrapped_callback(request, *callback_args, **callback_kwargs)
  File "C:\ProgramData\Miniconda3\lib\site-packages\django\views\decorators\csrf.py", line 54, in wrapped_view
    return view_func(*args, **kwargs)
  File "C:\ProgramData\Miniconda3\lib\site-packages\rest_framework\viewsets.py", line 114, in view
    return self.dispatch(request, *args, **kwargs)
  File "C:\ProgramData\Miniconda3\lib\site-packages\rest_framework\views.py", line 505, in dispatch
    response = self.handle_exception(exc)
  File "C:\ProgramData\Miniconda3\lib\site-packages\rest_framework\views.py", line 465, in handle_exception
    self.raise_uncaught_exception(exc)
  File "C:\ProgramData\Miniconda3\lib\site-packages\rest_framework\views.py", line 476, in raise_uncaught_exception
    raise exc
  File "C:\ProgramData\Miniconda3\lib\site-packages\rest_framework\views.py", line 502, in dispatch
    response = handler(request, *args, **kwargs)
  File "D:\MISC\GITHUB\knit_server//app\products\kviews\csv_ref_stitch_view.py", line 75, in create
    decoded_file = request.FILES[csv_file].read().encode('utf-8').splitlines()
AttributeError: 'bytes' object has no attribute 'encode'
 django.request 2020-04-27 11:53:03,154 ERROR    Internal Server Error: /product/csv-stitch-types
Traceback (most recent call last):
  File "C:\ProgramData\Miniconda3\lib\site-packages\django\core\handlers\exception.py", line 34, in inner
    response = get_response(request)
  File "C:\ProgramData\Miniconda3\lib\site-packages\django\core\handlers\base.py", line 115, in _get_response
    response = self.process_exception_by_middleware(e, request)
  File "C:\ProgramData\Miniconda3\lib\site-packages\django\core\handlers\base.py", line 113, in _get_response
    response = wrapped_callback(request, *callback_args, **callback_kwargs)
  File "C:\ProgramData\Miniconda3\lib\site-packages\django\views\decorators\csrf.py", line 54, in wrapped_view
    return view_func(*args, **kwargs)
  File "C:\ProgramData\Miniconda3\lib\site-packages\rest_framework\viewsets.py", line 114, in view
    return self.dispatch(request, *args, **kwargs)
  File "C:\ProgramData\Miniconda3\lib\site-packages\rest_framework\views.py", line 505, in dispatch
    response = self.handle_exception(exc)
  File "C:\ProgramData\Miniconda3\lib\site-packages\rest_framework\views.py", line 465, in handle_exception
    self.raise_uncaught_exception(exc)
  File "C:\ProgramData\Miniconda3\lib\site-packages\rest_framework\views.py", line 476, in raise_uncaught_exception
    raise exc
  File "C:\ProgramData\Miniconda3\lib\site-packages\rest_framework\views.py", line 502, in dispatch
    response = handler(request, *args, **kwargs)
  File "D:\MISC\GITHUB\knit_server//app\products\kviews\csv_ref_stitch_view.py", line 75, in create
    decoded_file = request.FILES[csv_file].read().encode('utf-8').decode('utf-8').splitlines()
AttributeError: 'bytes' object has no attribute 'encode'
 django.request 2020-04-27 11:55:54,683 ERROR    Internal Server Error: /product/csv-stitch-types
Traceback (most recent call last):
  File "C:\ProgramData\Miniconda3\lib\site-packages\django\core\handlers\exception.py", line 34, in inner
    response = get_response(request)
  File "C:\ProgramData\Miniconda3\lib\site-packages\django\core\handlers\base.py", line 115, in _get_response
    response = self.process_exception_by_middleware(e, request)
  File "C:\ProgramData\Miniconda3\lib\site-packages\django\core\handlers\base.py", line 113, in _get_response
    response = wrapped_callback(request, *callback_args, **callback_kwargs)
  File "C:\ProgramData\Miniconda3\lib\site-packages\django\views\decorators\csrf.py", line 54, in wrapped_view
    return view_func(*args, **kwargs)
  File "C:\ProgramData\Miniconda3\lib\site-packages\rest_framework\viewsets.py", line 114, in view
    return self.dispatch(request, *args, **kwargs)
  File "C:\ProgramData\Miniconda3\lib\site-packages\rest_framework\views.py", line 505, in dispatch
    response = self.handle_exception(exc)
  File "C:\ProgramData\Miniconda3\lib\site-packages\rest_framework\views.py", line 465, in handle_exception
    self.raise_uncaught_exception(exc)
  File "C:\ProgramData\Miniconda3\lib\site-packages\rest_framework\views.py", line 476, in raise_uncaught_exception
    raise exc
  File "C:\ProgramData\Miniconda3\lib\site-packages\rest_framework\views.py", line 502, in dispatch
    response = handler(request, *args, **kwargs)
  File "D:\MISC\GITHUB\knit_server//app\products\kviews\csv_ref_stitch_view.py", line 74, in create
    with open(request.FILES[csv_file].name, 'rb') as f:
FileNotFoundError: [Errno 2] No such file or directory: 'ref_stitch_types.csv'
 django.request 2020-04-27 11:56:41,424 ERROR    Internal Server Error: /product/csv-stitch-types
Traceback (most recent call last):
  File "C:\ProgramData\Miniconda3\lib\site-packages\django\core\handlers\exception.py", line 34, in inner
    response = get_response(request)
  File "C:\ProgramData\Miniconda3\lib\site-packages\django\core\handlers\base.py", line 115, in _get_response
    response = self.process_exception_by_middleware(e, request)
  File "C:\ProgramData\Miniconda3\lib\site-packages\django\core\handlers\base.py", line 113, in _get_response
    response = wrapped_callback(request, *callback_args, **callback_kwargs)
  File "C:\ProgramData\Miniconda3\lib\site-packages\django\views\decorators\csrf.py", line 54, in wrapped_view
    return view_func(*args, **kwargs)
  File "C:\ProgramData\Miniconda3\lib\site-packages\rest_framework\viewsets.py", line 114, in view
    return self.dispatch(request, *args, **kwargs)
  File "C:\ProgramData\Miniconda3\lib\site-packages\rest_framework\views.py", line 505, in dispatch
    response = self.handle_exception(exc)
  File "C:\ProgramData\Miniconda3\lib\site-packages\rest_framework\views.py", line 465, in handle_exception
    self.raise_uncaught_exception(exc)
  File "C:\ProgramData\Miniconda3\lib\site-packages\rest_framework\views.py", line 476, in raise_uncaught_exception
    raise exc
  File "C:\ProgramData\Miniconda3\lib\site-packages\rest_framework\views.py", line 502, in dispatch
    response = handler(request, *args, **kwargs)
  File "D:\MISC\GITHUB\knit_server//app\products\kviews\csv_ref_stitch_view.py", line 74, in create
    with open(request.FILES[csv_file].name, 'rb') as f:
FileNotFoundError: [Errno 2] No such file or directory: 'ref_stitch_types.csv'
 django.request 2020-04-27 11:57:55,770 WARNING  Bad Request: /product/csv-stitch-types
 django.request 2020-04-27 12:01:25,284 WARNING  Bad Request: /product/csv-stitch-types
 django.request 2020-04-27 12:03:14,344 WARNING  Bad Request: /product/csv-stitch-types
 django.request 2020-04-27 12:03:41,537 ERROR    Internal Server Error: /product/csv-stitch-types
Traceback (most recent call last):
  File "C:\ProgramData\Miniconda3\lib\site-packages\django\core\handlers\exception.py", line 34, in inner
    response = get_response(request)
  File "C:\ProgramData\Miniconda3\lib\site-packages\django\core\handlers\base.py", line 115, in _get_response
    response = self.process_exception_by_middleware(e, request)
  File "C:\ProgramData\Miniconda3\lib\site-packages\django\core\handlers\base.py", line 113, in _get_response
    response = wrapped_callback(request, *callback_args, **callback_kwargs)
  File "C:\ProgramData\Miniconda3\lib\site-packages\django\views\decorators\csrf.py", line 54, in wrapped_view
    return view_func(*args, **kwargs)
  File "C:\ProgramData\Miniconda3\lib\site-packages\rest_framework\viewsets.py", line 114, in view
    return self.dispatch(request, *args, **kwargs)
  File "C:\ProgramData\Miniconda3\lib\site-packages\rest_framework\views.py", line 505, in dispatch
    response = self.handle_exception(exc)
  File "C:\ProgramData\Miniconda3\lib\site-packages\rest_framework\views.py", line 465, in handle_exception
    self.raise_uncaught_exception(exc)
  File "C:\ProgramData\Miniconda3\lib\site-packages\rest_framework\views.py", line 476, in raise_uncaught_exception
    raise exc
  File "C:\ProgramData\Miniconda3\lib\site-packages\rest_framework\views.py", line 502, in dispatch
    response = handler(request, *args, **kwargs)
  File "D:\MISC\GITHUB\knit_server//app\products\kviews\csv_ref_stitch_view.py", line 93, in create
    stitch_data['description'] = unicodedata.normalize(row.get('description')).encode('ascii')
TypeError: normalize() takes exactly 2 arguments (1 given)
 django.request 2020-04-27 12:05:53,026 WARNING  Bad Request: /product/csv-stitch-types
 django.request 2020-04-27 12:10:27,940 WARNING  Bad Request: /product/csv-stitch-types
 django.request 2020-04-27 12:11:45,653 WARNING  Bad Request: /product/csv-stitch-types
 django.request 2020-04-27 12:13:29,776 WARNING  Bad Request: /product/csv-stitch-types
 django.request 2020-04-27 12:14:21,301 WARNING  Bad Request: /product/csv-stitch-types
 django.request 2020-04-27 12:16:26,227 WARNING  Bad Request: /product/csv-stitch-types
 django.request 2020-04-27 12:17:02,157 WARNING  Bad Request: /product/csv-stitch-types
 django.request 2020-04-27 12:22:44,742 ERROR    Internal Server Error: /product/csv-stitch-types
Traceback (most recent call last):
  File "C:\ProgramData\Miniconda3\lib\site-packages\django\core\handlers\exception.py", line 34, in inner
    response = get_response(request)
  File "C:\ProgramData\Miniconda3\lib\site-packages\django\core\handlers\base.py", line 115, in _get_response
    response = self.process_exception_by_middleware(e, request)
  File "C:\ProgramData\Miniconda3\lib\site-packages\django\core\handlers\base.py", line 113, in _get_response
    response = wrapped_callback(request, *callback_args, **callback_kwargs)
  File "C:\ProgramData\Miniconda3\lib\site-packages\django\views\decorators\csrf.py", line 54, in wrapped_view
    return view_func(*args, **kwargs)
  File "C:\ProgramData\Miniconda3\lib\site-packages\rest_framework\viewsets.py", line 114, in view
    return self.dispatch(request, *args, **kwargs)
  File "C:\ProgramData\Miniconda3\lib\site-packages\rest_framework\views.py", line 505, in dispatch
    response = self.handle_exception(exc)
  File "C:\ProgramData\Miniconda3\lib\site-packages\rest_framework\views.py", line 465, in handle_exception
    self.raise_uncaught_exception(exc)
  File "C:\ProgramData\Miniconda3\lib\site-packages\rest_framework\views.py", line 476, in raise_uncaught_exception
    raise exc
  File "C:\ProgramData\Miniconda3\lib\site-packages\rest_framework\views.py", line 502, in dispatch
    response = handler(request, *args, **kwargs)
  File "D:\MISC\GITHUB\knit_server//app\products\kviews\csv_ref_stitch_view.py", line 94, in create
    stitch_data['description'] = desc.encode("utf-8").decode("utf-8")
AttributeError: 'bytes' object has no attribute 'encode'
 django.request 2020-04-27 12:23:36,087 WARNING  Bad Request: /product/csv-stitch-types
 django.request 2020-04-27 12:24:41,668 WARNING  Bad Request: /product/csv-stitch-types
 django.request 2020-04-27 12:25:52,700 WARNING  Bad Request: /product/csv-stitch-types
 django.request 2020-04-27 13:38:57,479 ERROR    Internal Server Error: /product/csv-stitch
Traceback (most recent call last):
  File "C:\ProgramData\Miniconda3\lib\site-packages\django\core\handlers\exception.py", line 34, in inner
    response = get_response(request)
  File "C:\ProgramData\Miniconda3\lib\site-packages\django\core\handlers\base.py", line 115, in _get_response
    response = self.process_exception_by_middleware(e, request)
  File "C:\ProgramData\Miniconda3\lib\site-packages\django\core\handlers\base.py", line 113, in _get_response
    response = wrapped_callback(request, *callback_args, **callback_kwargs)
  File "C:\ProgramData\Miniconda3\lib\site-packages\django\views\decorators\csrf.py", line 54, in wrapped_view
    return view_func(*args, **kwargs)
  File "C:\ProgramData\Miniconda3\lib\site-packages\rest_framework\viewsets.py", line 114, in view
    return self.dispatch(request, *args, **kwargs)
  File "C:\ProgramData\Miniconda3\lib\site-packages\rest_framework\views.py", line 505, in dispatch
    response = self.handle_exception(exc)
  File "C:\ProgramData\Miniconda3\lib\site-packages\rest_framework\views.py", line 465, in handle_exception
    self.raise_uncaught_exception(exc)
  File "C:\ProgramData\Miniconda3\lib\site-packages\rest_framework\views.py", line 476, in raise_uncaught_exception
    raise exc
  File "C:\ProgramData\Miniconda3\lib\site-packages\rest_framework\views.py", line 502, in dispatch
    response = handler(request, *args, **kwargs)
  File "D:\MISC\GITHUB\knit_server//app\products\kviews\csv_ref_stitch_view.py", line 49, in create
    logger.info(stitch_serializer.is_valid())
  File "C:\ProgramData\Miniconda3\lib\site-packages\rest_framework\serializers.py", line 234, in is_valid
    self._validated_data = self.run_validation(self.initial_data)
  File "C:\ProgramData\Miniconda3\lib\site-packages\rest_framework\serializers.py", line 436, in run_validation
    value = self.validate(value)
  File "D:\MISC\GITHUB\knit_server//app\products\kserializers\stitchserializer.py", line 26, in validate
    hasType = Stitch.objects.filter(type=value)
NameError: name 'value' is not defined
 django.request 2020-04-27 13:39:27,230 WARNING  Bad Request: /product/csv-stitch
