Internal Server Error: /rest-auth/login/
Traceback (most recent call last):
  File "C:\ProgramData\Miniconda3\lib\site-packages\django\core\handlers\exception.py", line 34, in inner
    response = get_response(request)
  File "C:\ProgramData\Miniconda3\lib\site-packages\django\core\handlers\base.py", line 115, in _get_response
    response = self.process_exception_by_middleware(e, request)
  File "C:\ProgramData\Miniconda3\lib\site-packages\django\core\handlers\base.py", line 113, in _get_response
    response = wrapped_callback(request, *callback_args, **callback_kwargs)
  File "C:\ProgramData\Miniconda3\lib\site-packages\django\views\decorators\csrf.py", line 54, in wrapped_view
    return view_func(*args, **kwargs)
  File "C:\ProgramData\Miniconda3\lib\site-packages\django\views\generic\base.py", line 71, in view
    return self.dispatch(request, *args, **kwargs)
  File "C:\ProgramData\Miniconda3\lib\site-packages\django\utils\decorators.py", line 43, in _wrapper
    return bound_method(*args, **kwargs)
  File "C:\ProgramData\Miniconda3\lib\site-packages\django\views\decorators\debug.py", line 76, in sensitive_post_parameters_wrapper
    return view(request, *args, **kwargs)
  File "C:\ProgramData\Miniconda3\lib\site-packages\rest_auth\views.py", line 49, in dispatch
    return super(LoginView, self).dispatch(*args, **kwargs)
  File "C:\ProgramData\Miniconda3\lib\site-packages\rest_framework\views.py", line 505, in dispatch
    response = self.handle_exception(exc)
  File "C:\ProgramData\Miniconda3\lib\site-packages\rest_framework\views.py", line 465, in handle_exception
    self.raise_uncaught_exception(exc)
  File "C:\ProgramData\Miniconda3\lib\site-packages\rest_framework\views.py", line 476, in raise_uncaught_exception
    raise exc
  File "C:\ProgramData\Miniconda3\lib\site-packages\rest_framework\views.py", line 502, in dispatch
    response = handler(request, *args, **kwargs)
  File "C:\ProgramData\Miniconda3\lib\site-packages\rest_auth\views.py", line 103, in post
    self.serializer.is_valid(raise_exception=True)
  File "C:\ProgramData\Miniconda3\lib\site-packages\rest_framework\serializers.py", line 234, in is_valid
    self._validated_data = self.run_validation(self.initial_data)
  File "C:\ProgramData\Miniconda3\lib\site-packages\rest_framework\serializers.py", line 436, in run_validation
    value = self.validate(value)
  File "D:\MISC\GITHUB\knit_server//app\users\kserializers\login_serializer.py", line 93, in validate
    user = self._validate_phone(phone, password)
  File "D:\MISC\GITHUB\knit_server//app\users\kserializers\login_serializer.py", line 41, in _validate_phone
    user = self.authenticate(phone=phone, password=password)
  File "D:\MISC\GITHUB\knit_server//app\users\kserializers\login_serializer.py", line 35, in authenticate
    return authenticate(self.context['request'], **kwargs)
  File "C:\ProgramData\Miniconda3\lib\site-packages\django\contrib\auth\__init__.py", line 72, in authenticate
    user = backend.authenticate(request, **credentials)
  File "D:\MISC\GITHUB\knit_server//app\users\backends.py", line 41, in authenticate
    user = get_user_model().objects.get((Q(email=email) | Q(phone=phone) | Q(username=username)) )
  File "C:\ProgramData\Miniconda3\lib\site-packages\django\db\models\manager.py", line 82, in manager_method
    return getattr(self.get_queryset(), name)(*args, **kwargs)
  File "C:\ProgramData\Miniconda3\lib\site-packages\django\db\models\query.py", line 422, in get
    num if not limit or num < limit else 'more than %s' % (limit - 1),
users.models.User.MultipleObjectsReturned: get() returned more than one User -- it returned more than 20!
Internal Server Error: /rest-auth/login/
Traceback (most recent call last):
  File "C:\ProgramData\Miniconda3\lib\site-packages\django\core\handlers\exception.py", line 34, in inner
    response = get_response(request)
  File "C:\ProgramData\Miniconda3\lib\site-packages\django\core\handlers\base.py", line 115, in _get_response
    response = self.process_exception_by_middleware(e, request)
  File "C:\ProgramData\Miniconda3\lib\site-packages\django\core\handlers\base.py", line 113, in _get_response
    response = wrapped_callback(request, *callback_args, **callback_kwargs)
  File "C:\ProgramData\Miniconda3\lib\site-packages\django\views\decorators\csrf.py", line 54, in wrapped_view
    return view_func(*args, **kwargs)
  File "C:\ProgramData\Miniconda3\lib\site-packages\django\views\generic\base.py", line 71, in view
    return self.dispatch(request, *args, **kwargs)
  File "C:\ProgramData\Miniconda3\lib\site-packages\django\utils\decorators.py", line 43, in _wrapper
    return bound_method(*args, **kwargs)
  File "C:\ProgramData\Miniconda3\lib\site-packages\django\views\decorators\debug.py", line 76, in sensitive_post_parameters_wrapper
    return view(request, *args, **kwargs)
  File "C:\ProgramData\Miniconda3\lib\site-packages\rest_auth\views.py", line 49, in dispatch
    return super(LoginView, self).dispatch(*args, **kwargs)
  File "C:\ProgramData\Miniconda3\lib\site-packages\rest_framework\views.py", line 505, in dispatch
    response = self.handle_exception(exc)
  File "C:\ProgramData\Miniconda3\lib\site-packages\rest_framework\views.py", line 465, in handle_exception
    self.raise_uncaught_exception(exc)
  File "C:\ProgramData\Miniconda3\lib\site-packages\rest_framework\views.py", line 476, in raise_uncaught_exception
    raise exc
  File "C:\ProgramData\Miniconda3\lib\site-packages\rest_framework\views.py", line 502, in dispatch
    response = handler(request, *args, **kwargs)
  File "C:\ProgramData\Miniconda3\lib\site-packages\rest_auth\views.py", line 103, in post
    self.serializer.is_valid(raise_exception=True)
  File "C:\ProgramData\Miniconda3\lib\site-packages\rest_framework\serializers.py", line 234, in is_valid
    self._validated_data = self.run_validation(self.initial_data)
  File "C:\ProgramData\Miniconda3\lib\site-packages\rest_framework\serializers.py", line 436, in run_validation
    value = self.validate(value)
  File "D:\MISC\GITHUB\knit_server//app\users\kserializers\login_serializer.py", line 93, in validate
    user = self._validate_phone(phone, password)
  File "D:\MISC\GITHUB\knit_server//app\users\kserializers\login_serializer.py", line 41, in _validate_phone
    user = self.authenticate(phone=phone, password=password)
  File "D:\MISC\GITHUB\knit_server//app\users\kserializers\login_serializer.py", line 35, in authenticate
    return authenticate(self.context['request'], **kwargs)
  File "C:\ProgramData\Miniconda3\lib\site-packages\django\contrib\auth\__init__.py", line 72, in authenticate
    user = backend.authenticate(request, **credentials)
  File "D:\MISC\GITHUB\knit_server//app\users\backends.py", line 41, in authenticate
    user = get_user_model().objects.get((Q(email=email) | Q(phone=phone) | Q(username=username)) )
  File "C:\ProgramData\Miniconda3\lib\site-packages\django\db\models\manager.py", line 82, in manager_method
    return getattr(self.get_queryset(), name)(*args, **kwargs)
  File "C:\ProgramData\Miniconda3\lib\site-packages\django\db\models\query.py", line 422, in get
    num if not limit or num < limit else 'more than %s' % (limit - 1),
users.models.User.MultipleObjectsReturned: get() returned more than one User -- it returned more than 20!
Not Found: /user/user-typs
Bad Request: /user/address
Internal Server Error: /user/users
Traceback (most recent call last):
  File "C:\ProgramData\Miniconda3\lib\site-packages\django\core\handlers\exception.py", line 34, in inner
    response = get_response(request)
  File "C:\ProgramData\Miniconda3\lib\site-packages\django\core\handlers\base.py", line 115, in _get_response
    response = self.process_exception_by_middleware(e, request)
  File "C:\ProgramData\Miniconda3\lib\site-packages\django\core\handlers\base.py", line 113, in _get_response
    response = wrapped_callback(request, *callback_args, **callback_kwargs)
  File "C:\ProgramData\Miniconda3\lib\site-packages\django\views\decorators\csrf.py", line 54, in wrapped_view
    return view_func(*args, **kwargs)
  File "C:\ProgramData\Miniconda3\lib\site-packages\rest_framework\viewsets.py", line 114, in view
    return self.dispatch(request, *args, **kwargs)
  File "C:\ProgramData\Miniconda3\lib\site-packages\rest_framework\views.py", line 505, in dispatch
    response = self.handle_exception(exc)
  File "C:\ProgramData\Miniconda3\lib\site-packages\rest_framework\views.py", line 465, in handle_exception
    self.raise_uncaught_exception(exc)
  File "C:\ProgramData\Miniconda3\lib\site-packages\rest_framework\views.py", line 476, in raise_uncaught_exception
    raise exc
  File "C:\ProgramData\Miniconda3\lib\site-packages\rest_framework\views.py", line 502, in dispatch
    response = handler(request, *args, **kwargs)
  File "D:\MISC\GITHUB\knit_server//app\users\kviews\user_view.py", line 42, in create
    if user_serializer.is_valid():
  File "C:\ProgramData\Miniconda3\lib\site-packages\rest_framework\serializers.py", line 234, in is_valid
    self._validated_data = self.run_validation(self.initial_data)
  File "C:\ProgramData\Miniconda3\lib\site-packages\rest_framework\serializers.py", line 436, in run_validation
    value = self.validate(value)
  File "D:\MISC\GITHUB\knit_server//app\users\kserializers\user_serializer.py", line 123, in validate
    data['username'] = data.get('username', None)
  File "C:\ProgramData\Miniconda3\lib\site-packages\django\http\request.py", line 467, in __setitem__
    self._assert_mutable()
  File "C:\ProgramData\Miniconda3\lib\site-packages\django\http\request.py", line 464, in _assert_mutable
    raise AttributeError("This QueryDict instance is immutable")
AttributeError: This QueryDict instance is immutable
Bad Request: /user/users
Internal Server Error: /user/users
Traceback (most recent call last):
  File "C:\ProgramData\Miniconda3\lib\site-packages\django\core\handlers\exception.py", line 34, in inner
    response = get_response(request)
  File "C:\ProgramData\Miniconda3\lib\site-packages\django\core\handlers\base.py", line 145, in _get_response
    response = self.process_exception_by_middleware(e, request)
  File "C:\ProgramData\Miniconda3\lib\site-packages\django\core\handlers\base.py", line 143, in _get_response
    response = response.render()
  File "C:\ProgramData\Miniconda3\lib\site-packages\django\template\response.py", line 105, in render
    self.content = self.rendered_content
  File "C:\ProgramData\Miniconda3\lib\site-packages\rest_framework\response.py", line 70, in rendered_content
    ret = renderer.render(self.data, accepted_media_type, context)
  File "C:\ProgramData\Miniconda3\lib\site-packages\rest_framework\renderers.py", line 724, in render
    context = self.get_context(data, accepted_media_type, renderer_context)
  File "C:\ProgramData\Miniconda3\lib\site-packages\rest_framework\renderers.py", line 655, in get_context
    raw_data_post_form = self.get_raw_data_form(data, view, 'POST', request)
  File "C:\ProgramData\Miniconda3\lib\site-packages\rest_framework\renderers.py", line 563, in get_raw_data_form
    data = serializer.data.copy()
  File "C:\ProgramData\Miniconda3\lib\site-packages\rest_framework\serializers.py", line 562, in data
    ret = super().data
  File "C:\ProgramData\Miniconda3\lib\site-packages\rest_framework\serializers.py", line 264, in data
    self._data = self.get_initial()
  File "C:\ProgramData\Miniconda3\lib\site-packages\rest_framework\serializers.py", line 412, in get_initial
    for field in self.fields.values()
  File "C:\ProgramData\Miniconda3\lib\site-packages\django\utils\functional.py", line 48, in __get__
    res = instance.__dict__[self.name] = self.func(instance)
  File "C:\ProgramData\Miniconda3\lib\site-packages\rest_framework\serializers.py", line 363, in fields
    for key, value in self.get_fields().items():
  File "C:\ProgramData\Miniconda3\lib\site-packages\rest_framework\serializers.py", line 1038, in get_fields
    field_names = self.get_field_names(declared_fields, info)
  File "C:\ProgramData\Miniconda3\lib\site-packages\rest_framework\serializers.py", line 1139, in get_field_names
    serializer_class=self.__class__.__name__
AssertionError: The field 'password' was declared on serializer UserSerializer, but has not been included in the 'fields' option.
Internal Server Error: /user/users
Traceback (most recent call last):
  File "C:\ProgramData\Miniconda3\lib\site-packages\django\db\backends\utils.py", line 86, in _execute
    return self.cursor.execute(sql, params)
  File "C:\ProgramData\Miniconda3\lib\site-packages\django\db\backends\mysql\base.py", line 74, in execute
    return self.cursor.execute(query, args)
  File "C:\ProgramData\Miniconda3\lib\site-packages\MySQLdb\cursors.py", line 209, in execute
    res = self._query(query)
  File "C:\ProgramData\Miniconda3\lib\site-packages\MySQLdb\cursors.py", line 315, in _query
    db.query(q)
  File "C:\ProgramData\Miniconda3\lib\site-packages\MySQLdb\connections.py", line 239, in query
    _mysql.connection.query(self, query)
MySQLdb._exceptions.IntegrityError: (1062, "Duplicate entry '' for key 'phone'")

The above exception was the direct cause of the following exception:

Traceback (most recent call last):
  File "C:\ProgramData\Miniconda3\lib\site-packages\django\core\handlers\exception.py", line 34, in inner
    response = get_response(request)
  File "C:\ProgramData\Miniconda3\lib\site-packages\django\core\handlers\base.py", line 115, in _get_response
    response = self.process_exception_by_middleware(e, request)
  File "C:\ProgramData\Miniconda3\lib\site-packages\django\core\handlers\base.py", line 113, in _get_response
    response = wrapped_callback(request, *callback_args, **callback_kwargs)
  File "C:\ProgramData\Miniconda3\lib\site-packages\django\views\decorators\csrf.py", line 54, in wrapped_view
    return view_func(*args, **kwargs)
  File "C:\ProgramData\Miniconda3\lib\site-packages\rest_framework\viewsets.py", line 114, in view
    return self.dispatch(request, *args, **kwargs)
  File "C:\ProgramData\Miniconda3\lib\site-packages\rest_framework\views.py", line 505, in dispatch
    response = self.handle_exception(exc)
  File "C:\ProgramData\Miniconda3\lib\site-packages\rest_framework\views.py", line 465, in handle_exception
    self.raise_uncaught_exception(exc)
  File "C:\ProgramData\Miniconda3\lib\site-packages\rest_framework\views.py", line 476, in raise_uncaught_exception
    raise exc
  File "C:\ProgramData\Miniconda3\lib\site-packages\rest_framework\views.py", line 502, in dispatch
    response = handler(request, *args, **kwargs)
  File "D:\MISC\GITHUB\knit_server//app\users\kviews\user_view.py", line 44, in create
    user_serializer.save()
  File "C:\ProgramData\Miniconda3\lib\site-packages\rest_framework\serializers.py", line 212, in save
    self.instance = self.create(validated_data)
  File "D:\MISC\GITHUB\knit_server//app\users\kserializers\user_serializer.py", line 35, in create
    user = User.objects.create_user(**validated_data)
  File "D:\MISC\GITHUB\knit_server//app\users\models.py", line 33, in create_user
    user.save(using=self._db)
  File "C:\ProgramData\Miniconda3\lib\site-packages\django\contrib\auth\base_user.py", line 66, in save
    super().save(*args, **kwargs)
  File "C:\ProgramData\Miniconda3\lib\site-packages\django\db\models\base.py", line 746, in save
    force_update=force_update, update_fields=update_fields)
  File "C:\ProgramData\Miniconda3\lib\site-packages\django\db\models\base.py", line 784, in save_base
    force_update, using, update_fields,
  File "C:\ProgramData\Miniconda3\lib\site-packages\django\db\models\base.py", line 886, in _save_table
    results = self._do_insert(cls._base_manager, using, fields, returning_fields, raw)
  File "C:\ProgramData\Miniconda3\lib\site-packages\django\db\models\base.py", line 925, in _do_insert
    using=using, raw=raw,
  File "C:\ProgramData\Miniconda3\lib\site-packages\django\db\models\manager.py", line 82, in manager_method
    return getattr(self.get_queryset(), name)(*args, **kwargs)
  File "C:\ProgramData\Miniconda3\lib\site-packages\django\db\models\query.py", line 1204, in _insert
    return query.get_compiler(using=using).execute_sql(returning_fields)
  File "C:\ProgramData\Miniconda3\lib\site-packages\django\db\models\sql\compiler.py", line 1377, in execute_sql
    cursor.execute(sql, params)
  File "C:\ProgramData\Miniconda3\lib\site-packages\django\db\backends\utils.py", line 100, in execute
    return super().execute(sql, params)
  File "C:\ProgramData\Miniconda3\lib\site-packages\django\db\backends\utils.py", line 68, in execute
    return self._execute_with_wrappers(sql, params, many=False, executor=self._execute)
  File "C:\ProgramData\Miniconda3\lib\site-packages\django\db\backends\utils.py", line 77, in _execute_with_wrappers
    return executor(sql, params, many, context)
  File "C:\ProgramData\Miniconda3\lib\site-packages\django\db\backends\utils.py", line 86, in _execute
    return self.cursor.execute(sql, params)
  File "C:\ProgramData\Miniconda3\lib\site-packages\django\db\utils.py", line 90, in __exit__
    raise dj_exc_value.with_traceback(traceback) from exc_value
  File "C:\ProgramData\Miniconda3\lib\site-packages\django\db\backends\utils.py", line 86, in _execute
    return self.cursor.execute(sql, params)
  File "C:\ProgramData\Miniconda3\lib\site-packages\django\db\backends\mysql\base.py", line 74, in execute
    return self.cursor.execute(query, args)
  File "C:\ProgramData\Miniconda3\lib\site-packages\MySQLdb\cursors.py", line 209, in execute
    res = self._query(query)
  File "C:\ProgramData\Miniconda3\lib\site-packages\MySQLdb\cursors.py", line 315, in _query
    db.query(q)
  File "C:\ProgramData\Miniconda3\lib\site-packages\MySQLdb\connections.py", line 239, in query
    _mysql.connection.query(self, query)
django.db.utils.IntegrityError: (1062, "Duplicate entry '' for key 'phone'")
Internal Server Error: /user/users
Traceback (most recent call last):
  File "C:\ProgramData\Miniconda3\lib\site-packages\django\db\backends\utils.py", line 86, in _execute
    return self.cursor.execute(sql, params)
  File "C:\ProgramData\Miniconda3\lib\site-packages\django\db\backends\mysql\base.py", line 74, in execute
    return self.cursor.execute(query, args)
  File "C:\ProgramData\Miniconda3\lib\site-packages\MySQLdb\cursors.py", line 209, in execute
    res = self._query(query)
  File "C:\ProgramData\Miniconda3\lib\site-packages\MySQLdb\cursors.py", line 315, in _query
    db.query(q)
  File "C:\ProgramData\Miniconda3\lib\site-packages\MySQLdb\connections.py", line 239, in query
    _mysql.connection.query(self, query)
MySQLdb._exceptions.IntegrityError: (1062, "Duplicate entry '' for key 'phone'")

The above exception was the direct cause of the following exception:

Traceback (most recent call last):
  File "C:\ProgramData\Miniconda3\lib\site-packages\django\core\handlers\exception.py", line 34, in inner
    response = get_response(request)
  File "C:\ProgramData\Miniconda3\lib\site-packages\django\core\handlers\base.py", line 115, in _get_response
    response = self.process_exception_by_middleware(e, request)
  File "C:\ProgramData\Miniconda3\lib\site-packages\django\core\handlers\base.py", line 113, in _get_response
    response = wrapped_callback(request, *callback_args, **callback_kwargs)
  File "C:\ProgramData\Miniconda3\lib\site-packages\django\views\decorators\csrf.py", line 54, in wrapped_view
    return view_func(*args, **kwargs)
  File "C:\ProgramData\Miniconda3\lib\site-packages\rest_framework\viewsets.py", line 114, in view
    return self.dispatch(request, *args, **kwargs)
  File "C:\ProgramData\Miniconda3\lib\site-packages\rest_framework\views.py", line 505, in dispatch
    response = self.handle_exception(exc)
  File "C:\ProgramData\Miniconda3\lib\site-packages\rest_framework\views.py", line 465, in handle_exception
    self.raise_uncaught_exception(exc)
  File "C:\ProgramData\Miniconda3\lib\site-packages\rest_framework\views.py", line 476, in raise_uncaught_exception
    raise exc
  File "C:\ProgramData\Miniconda3\lib\site-packages\rest_framework\views.py", line 502, in dispatch
    response = handler(request, *args, **kwargs)
  File "D:\MISC\GITHUB\knit_server//app\users\kviews\user_view.py", line 44, in create
    user_serializer.save()
  File "C:\ProgramData\Miniconda3\lib\site-packages\rest_framework\serializers.py", line 212, in save
    self.instance = self.create(validated_data)
  File "D:\MISC\GITHUB\knit_server//app\users\kserializers\user_serializer.py", line 35, in create
    user = User.objects.create_user(**validated_data)
  File "D:\MISC\GITHUB\knit_server//app\users\models.py", line 33, in create_user
    user.save(using=self._db)
  File "C:\ProgramData\Miniconda3\lib\site-packages\django\contrib\auth\base_user.py", line 66, in save
    super().save(*args, **kwargs)
  File "C:\ProgramData\Miniconda3\lib\site-packages\django\db\models\base.py", line 746, in save
    force_update=force_update, update_fields=update_fields)
  File "C:\ProgramData\Miniconda3\lib\site-packages\django\db\models\base.py", line 784, in save_base
    force_update, using, update_fields,
  File "C:\ProgramData\Miniconda3\lib\site-packages\django\db\models\base.py", line 886, in _save_table
    results = self._do_insert(cls._base_manager, using, fields, returning_fields, raw)
  File "C:\ProgramData\Miniconda3\lib\site-packages\django\db\models\base.py", line 925, in _do_insert
    using=using, raw=raw,
  File "C:\ProgramData\Miniconda3\lib\site-packages\django\db\models\manager.py", line 82, in manager_method
    return getattr(self.get_queryset(), name)(*args, **kwargs)
  File "C:\ProgramData\Miniconda3\lib\site-packages\django\db\models\query.py", line 1204, in _insert
    return query.get_compiler(using=using).execute_sql(returning_fields)
  File "C:\ProgramData\Miniconda3\lib\site-packages\django\db\models\sql\compiler.py", line 1377, in execute_sql
    cursor.execute(sql, params)
  File "C:\ProgramData\Miniconda3\lib\site-packages\django\db\backends\utils.py", line 100, in execute
    return super().execute(sql, params)
  File "C:\ProgramData\Miniconda3\lib\site-packages\django\db\backends\utils.py", line 68, in execute
    return self._execute_with_wrappers(sql, params, many=False, executor=self._execute)
  File "C:\ProgramData\Miniconda3\lib\site-packages\django\db\backends\utils.py", line 77, in _execute_with_wrappers
    return executor(sql, params, many, context)
  File "C:\ProgramData\Miniconda3\lib\site-packages\django\db\backends\utils.py", line 86, in _execute
    return self.cursor.execute(sql, params)
  File "C:\ProgramData\Miniconda3\lib\site-packages\django\db\utils.py", line 90, in __exit__
    raise dj_exc_value.with_traceback(traceback) from exc_value
  File "C:\ProgramData\Miniconda3\lib\site-packages\django\db\backends\utils.py", line 86, in _execute
    return self.cursor.execute(sql, params)
  File "C:\ProgramData\Miniconda3\lib\site-packages\django\db\backends\mysql\base.py", line 74, in execute
    return self.cursor.execute(query, args)
  File "C:\ProgramData\Miniconda3\lib\site-packages\MySQLdb\cursors.py", line 209, in execute
    res = self._query(query)
  File "C:\ProgramData\Miniconda3\lib\site-packages\MySQLdb\cursors.py", line 315, in _query
    db.query(q)
  File "C:\ProgramData\Miniconda3\lib\site-packages\MySQLdb\connections.py", line 239, in query
    _mysql.connection.query(self, query)
django.db.utils.IntegrityError: (1062, "Duplicate entry '' for key 'phone'")
Internal Server Error: /user/users
Traceback (most recent call last):
  File "C:\ProgramData\Miniconda3\lib\site-packages\django\db\backends\utils.py", line 86, in _execute
    return self.cursor.execute(sql, params)
  File "C:\ProgramData\Miniconda3\lib\site-packages\django\db\backends\mysql\base.py", line 74, in execute
    return self.cursor.execute(query, args)
  File "C:\ProgramData\Miniconda3\lib\site-packages\MySQLdb\cursors.py", line 209, in execute
    res = self._query(query)
  File "C:\ProgramData\Miniconda3\lib\site-packages\MySQLdb\cursors.py", line 315, in _query
    db.query(q)
  File "C:\ProgramData\Miniconda3\lib\site-packages\MySQLdb\connections.py", line 239, in query
    _mysql.connection.query(self, query)
MySQLdb._exceptions.IntegrityError: (1062, "Duplicate entry '' for key 'phone'")

The above exception was the direct cause of the following exception:

Traceback (most recent call last):
  File "C:\ProgramData\Miniconda3\lib\site-packages\django\core\handlers\exception.py", line 34, in inner
    response = get_response(request)
  File "C:\ProgramData\Miniconda3\lib\site-packages\django\core\handlers\base.py", line 115, in _get_response
    response = self.process_exception_by_middleware(e, request)
  File "C:\ProgramData\Miniconda3\lib\site-packages\django\core\handlers\base.py", line 113, in _get_response
    response = wrapped_callback(request, *callback_args, **callback_kwargs)
  File "C:\ProgramData\Miniconda3\lib\site-packages\django\views\decorators\csrf.py", line 54, in wrapped_view
    return view_func(*args, **kwargs)
  File "C:\ProgramData\Miniconda3\lib\site-packages\rest_framework\viewsets.py", line 114, in view
    return self.dispatch(request, *args, **kwargs)
  File "C:\ProgramData\Miniconda3\lib\site-packages\rest_framework\views.py", line 505, in dispatch
    response = self.handle_exception(exc)
  File "C:\ProgramData\Miniconda3\lib\site-packages\rest_framework\views.py", line 465, in handle_exception
    self.raise_uncaught_exception(exc)
  File "C:\ProgramData\Miniconda3\lib\site-packages\rest_framework\views.py", line 476, in raise_uncaught_exception
    raise exc
  File "C:\ProgramData\Miniconda3\lib\site-packages\rest_framework\views.py", line 502, in dispatch
    response = handler(request, *args, **kwargs)
  File "D:\MISC\GITHUB\knit_server//app\users\kviews\user_view.py", line 44, in create
    user_serializer.save()
  File "C:\ProgramData\Miniconda3\lib\site-packages\rest_framework\serializers.py", line 212, in save
    self.instance = self.create(validated_data)
  File "D:\MISC\GITHUB\knit_server//app\users\kserializers\user_serializer.py", line 35, in create
    user = User.objects.create_user(**validated_data)
  File "D:\MISC\GITHUB\knit_server//app\users\models.py", line 33, in create_user
    user.save(using=self._db)
  File "C:\ProgramData\Miniconda3\lib\site-packages\django\contrib\auth\base_user.py", line 66, in save
    super().save(*args, **kwargs)
  File "C:\ProgramData\Miniconda3\lib\site-packages\django\db\models\base.py", line 746, in save
    force_update=force_update, update_fields=update_fields)
  File "C:\ProgramData\Miniconda3\lib\site-packages\django\db\models\base.py", line 784, in save_base
    force_update, using, update_fields,
  File "C:\ProgramData\Miniconda3\lib\site-packages\django\db\models\base.py", line 886, in _save_table
    results = self._do_insert(cls._base_manager, using, fields, returning_fields, raw)
  File "C:\ProgramData\Miniconda3\lib\site-packages\django\db\models\base.py", line 925, in _do_insert
    using=using, raw=raw,
  File "C:\ProgramData\Miniconda3\lib\site-packages\django\db\models\manager.py", line 82, in manager_method
    return getattr(self.get_queryset(), name)(*args, **kwargs)
  File "C:\ProgramData\Miniconda3\lib\site-packages\django\db\models\query.py", line 1204, in _insert
    return query.get_compiler(using=using).execute_sql(returning_fields)
  File "C:\ProgramData\Miniconda3\lib\site-packages\django\db\models\sql\compiler.py", line 1377, in execute_sql
    cursor.execute(sql, params)
  File "C:\ProgramData\Miniconda3\lib\site-packages\django\db\backends\utils.py", line 100, in execute
    return super().execute(sql, params)
  File "C:\ProgramData\Miniconda3\lib\site-packages\django\db\backends\utils.py", line 68, in execute
    return self._execute_with_wrappers(sql, params, many=False, executor=self._execute)
  File "C:\ProgramData\Miniconda3\lib\site-packages\django\db\backends\utils.py", line 77, in _execute_with_wrappers
    return executor(sql, params, many, context)
  File "C:\ProgramData\Miniconda3\lib\site-packages\django\db\backends\utils.py", line 86, in _execute
    return self.cursor.execute(sql, params)
  File "C:\ProgramData\Miniconda3\lib\site-packages\django\db\utils.py", line 90, in __exit__
    raise dj_exc_value.with_traceback(traceback) from exc_value
  File "C:\ProgramData\Miniconda3\lib\site-packages\django\db\backends\utils.py", line 86, in _execute
    return self.cursor.execute(sql, params)
  File "C:\ProgramData\Miniconda3\lib\site-packages\django\db\backends\mysql\base.py", line 74, in execute
    return self.cursor.execute(query, args)
  File "C:\ProgramData\Miniconda3\lib\site-packages\MySQLdb\cursors.py", line 209, in execute
    res = self._query(query)
  File "C:\ProgramData\Miniconda3\lib\site-packages\MySQLdb\cursors.py", line 315, in _query
    db.query(q)
  File "C:\ProgramData\Miniconda3\lib\site-packages\MySQLdb\connections.py", line 239, in query
    _mysql.connection.query(self, query)
django.db.utils.IntegrityError: (1062, "Duplicate entry '' for key 'phone'")
Internal Server Error: /user/users
Traceback (most recent call last):
  File "C:\ProgramData\Miniconda3\lib\site-packages\django\db\backends\utils.py", line 86, in _execute
    return self.cursor.execute(sql, params)
  File "C:\ProgramData\Miniconda3\lib\site-packages\django\db\backends\mysql\base.py", line 74, in execute
    return self.cursor.execute(query, args)
  File "C:\ProgramData\Miniconda3\lib\site-packages\MySQLdb\cursors.py", line 209, in execute
    res = self._query(query)
  File "C:\ProgramData\Miniconda3\lib\site-packages\MySQLdb\cursors.py", line 315, in _query
    db.query(q)
  File "C:\ProgramData\Miniconda3\lib\site-packages\MySQLdb\connections.py", line 239, in query
    _mysql.connection.query(self, query)
MySQLdb._exceptions.IntegrityError: (1062, "Duplicate entry '' for key 'phone'")

The above exception was the direct cause of the following exception:

Traceback (most recent call last):
  File "C:\ProgramData\Miniconda3\lib\site-packages\django\core\handlers\exception.py", line 34, in inner
    response = get_response(request)
  File "C:\ProgramData\Miniconda3\lib\site-packages\django\core\handlers\base.py", line 115, in _get_response
    response = self.process_exception_by_middleware(e, request)
  File "C:\ProgramData\Miniconda3\lib\site-packages\django\core\handlers\base.py", line 113, in _get_response
    response = wrapped_callback(request, *callback_args, **callback_kwargs)
  File "C:\ProgramData\Miniconda3\lib\site-packages\django\views\decorators\csrf.py", line 54, in wrapped_view
    return view_func(*args, **kwargs)
  File "C:\ProgramData\Miniconda3\lib\site-packages\rest_framework\viewsets.py", line 114, in view
    return self.dispatch(request, *args, **kwargs)
  File "C:\ProgramData\Miniconda3\lib\site-packages\rest_framework\views.py", line 505, in dispatch
    response = self.handle_exception(exc)
  File "C:\ProgramData\Miniconda3\lib\site-packages\rest_framework\views.py", line 465, in handle_exception
    self.raise_uncaught_exception(exc)
  File "C:\ProgramData\Miniconda3\lib\site-packages\rest_framework\views.py", line 476, in raise_uncaught_exception
    raise exc
  File "C:\ProgramData\Miniconda3\lib\site-packages\rest_framework\views.py", line 502, in dispatch
    response = handler(request, *args, **kwargs)
  File "D:\MISC\GITHUB\knit_server//app\users\kviews\user_view.py", line 44, in create
    user_serializer.save()
  File "C:\ProgramData\Miniconda3\lib\site-packages\rest_framework\serializers.py", line 212, in save
    self.instance = self.create(validated_data)
  File "D:\MISC\GITHUB\knit_server//app\users\kserializers\user_serializer.py", line 35, in create
    user = User.objects.create_user(**validated_data)
  File "D:\MISC\GITHUB\knit_server//app\users\models.py", line 33, in create_user
    user.save(using=self._db)
  File "C:\ProgramData\Miniconda3\lib\site-packages\django\contrib\auth\base_user.py", line 66, in save
    super().save(*args, **kwargs)
  File "C:\ProgramData\Miniconda3\lib\site-packages\django\db\models\base.py", line 746, in save
    force_update=force_update, update_fields=update_fields)
  File "C:\ProgramData\Miniconda3\lib\site-packages\django\db\models\base.py", line 784, in save_base
    force_update, using, update_fields,
  File "C:\ProgramData\Miniconda3\lib\site-packages\django\db\models\base.py", line 886, in _save_table
    results = self._do_insert(cls._base_manager, using, fields, returning_fields, raw)
  File "C:\ProgramData\Miniconda3\lib\site-packages\django\db\models\base.py", line 925, in _do_insert
    using=using, raw=raw,
  File "C:\ProgramData\Miniconda3\lib\site-packages\django\db\models\manager.py", line 82, in manager_method
    return getattr(self.get_queryset(), name)(*args, **kwargs)
  File "C:\ProgramData\Miniconda3\lib\site-packages\django\db\models\query.py", line 1204, in _insert
    return query.get_compiler(using=using).execute_sql(returning_fields)
  File "C:\ProgramData\Miniconda3\lib\site-packages\django\db\models\sql\compiler.py", line 1377, in execute_sql
    cursor.execute(sql, params)
  File "C:\ProgramData\Miniconda3\lib\site-packages\django\db\backends\utils.py", line 100, in execute
    return super().execute(sql, params)
  File "C:\ProgramData\Miniconda3\lib\site-packages\django\db\backends\utils.py", line 68, in execute
    return self._execute_with_wrappers(sql, params, many=False, executor=self._execute)
  File "C:\ProgramData\Miniconda3\lib\site-packages\django\db\backends\utils.py", line 77, in _execute_with_wrappers
    return executor(sql, params, many, context)
  File "C:\ProgramData\Miniconda3\lib\site-packages\django\db\backends\utils.py", line 86, in _execute
    return self.cursor.execute(sql, params)
  File "C:\ProgramData\Miniconda3\lib\site-packages\django\db\utils.py", line 90, in __exit__
    raise dj_exc_value.with_traceback(traceback) from exc_value
  File "C:\ProgramData\Miniconda3\lib\site-packages\django\db\backends\utils.py", line 86, in _execute
    return self.cursor.execute(sql, params)
  File "C:\ProgramData\Miniconda3\lib\site-packages\django\db\backends\mysql\base.py", line 74, in execute
    return self.cursor.execute(query, args)
  File "C:\ProgramData\Miniconda3\lib\site-packages\MySQLdb\cursors.py", line 209, in execute
    res = self._query(query)
  File "C:\ProgramData\Miniconda3\lib\site-packages\MySQLdb\cursors.py", line 315, in _query
    db.query(q)
  File "C:\ProgramData\Miniconda3\lib\site-packages\MySQLdb\connections.py", line 239, in query
    _mysql.connection.query(self, query)
django.db.utils.IntegrityError: (1062, "Duplicate entry '' for key 'phone'")
Internal Server Error: /user/users
Traceback (most recent call last):
  File "C:\ProgramData\Miniconda3\lib\site-packages\django\db\backends\utils.py", line 86, in _execute
    return self.cursor.execute(sql, params)
  File "C:\ProgramData\Miniconda3\lib\site-packages\django\db\backends\mysql\base.py", line 74, in execute
    return self.cursor.execute(query, args)
  File "C:\ProgramData\Miniconda3\lib\site-packages\MySQLdb\cursors.py", line 209, in execute
    res = self._query(query)
  File "C:\ProgramData\Miniconda3\lib\site-packages\MySQLdb\cursors.py", line 315, in _query
    db.query(q)
  File "C:\ProgramData\Miniconda3\lib\site-packages\MySQLdb\connections.py", line 239, in query
    _mysql.connection.query(self, query)
MySQLdb._exceptions.IntegrityError: (1062, "Duplicate entry '' for key 'phone'")

The above exception was the direct cause of the following exception:

Traceback (most recent call last):
  File "C:\ProgramData\Miniconda3\lib\site-packages\django\core\handlers\exception.py", line 34, in inner
    response = get_response(request)
  File "C:\ProgramData\Miniconda3\lib\site-packages\django\core\handlers\base.py", line 115, in _get_response
    response = self.process_exception_by_middleware(e, request)
  File "C:\ProgramData\Miniconda3\lib\site-packages\django\core\handlers\base.py", line 113, in _get_response
    response = wrapped_callback(request, *callback_args, **callback_kwargs)
  File "C:\ProgramData\Miniconda3\lib\site-packages\django\views\decorators\csrf.py", line 54, in wrapped_view
    return view_func(*args, **kwargs)
  File "C:\ProgramData\Miniconda3\lib\site-packages\rest_framework\viewsets.py", line 114, in view
    return self.dispatch(request, *args, **kwargs)
  File "C:\ProgramData\Miniconda3\lib\site-packages\rest_framework\views.py", line 505, in dispatch
    response = self.handle_exception(exc)
  File "C:\ProgramData\Miniconda3\lib\site-packages\rest_framework\views.py", line 465, in handle_exception
    self.raise_uncaught_exception(exc)
  File "C:\ProgramData\Miniconda3\lib\site-packages\rest_framework\views.py", line 476, in raise_uncaught_exception
    raise exc
  File "C:\ProgramData\Miniconda3\lib\site-packages\rest_framework\views.py", line 502, in dispatch
    response = handler(request, *args, **kwargs)
  File "D:\MISC\GITHUB\knit_server//app\users\kviews\user_view.py", line 44, in create
    user_serializer.save()
  File "C:\ProgramData\Miniconda3\lib\site-packages\rest_framework\serializers.py", line 212, in save
    self.instance = self.create(validated_data)
  File "D:\MISC\GITHUB\knit_server//app\users\kserializers\user_serializer.py", line 35, in create
    user = User.objects.create_user(**validated_data)
  File "D:\MISC\GITHUB\knit_server//app\users\models.py", line 33, in create_user
    user.save(using=self._db)
  File "C:\ProgramData\Miniconda3\lib\site-packages\django\contrib\auth\base_user.py", line 66, in save
    super().save(*args, **kwargs)
  File "C:\ProgramData\Miniconda3\lib\site-packages\django\db\models\base.py", line 746, in save
    force_update=force_update, update_fields=update_fields)
  File "C:\ProgramData\Miniconda3\lib\site-packages\django\db\models\base.py", line 784, in save_base
    force_update, using, update_fields,
  File "C:\ProgramData\Miniconda3\lib\site-packages\django\db\models\base.py", line 886, in _save_table
    results = self._do_insert(cls._base_manager, using, fields, returning_fields, raw)
  File "C:\ProgramData\Miniconda3\lib\site-packages\django\db\models\base.py", line 925, in _do_insert
    using=using, raw=raw,
  File "C:\ProgramData\Miniconda3\lib\site-packages\django\db\models\manager.py", line 82, in manager_method
    return getattr(self.get_queryset(), name)(*args, **kwargs)
  File "C:\ProgramData\Miniconda3\lib\site-packages\django\db\models\query.py", line 1204, in _insert
    return query.get_compiler(using=using).execute_sql(returning_fields)
  File "C:\ProgramData\Miniconda3\lib\site-packages\django\db\models\sql\compiler.py", line 1377, in execute_sql
    cursor.execute(sql, params)
  File "C:\ProgramData\Miniconda3\lib\site-packages\django\db\backends\utils.py", line 100, in execute
    return super().execute(sql, params)
  File "C:\ProgramData\Miniconda3\lib\site-packages\django\db\backends\utils.py", line 68, in execute
    return self._execute_with_wrappers(sql, params, many=False, executor=self._execute)
  File "C:\ProgramData\Miniconda3\lib\site-packages\django\db\backends\utils.py", line 77, in _execute_with_wrappers
    return executor(sql, params, many, context)
  File "C:\ProgramData\Miniconda3\lib\site-packages\django\db\backends\utils.py", line 86, in _execute
    return self.cursor.execute(sql, params)
  File "C:\ProgramData\Miniconda3\lib\site-packages\django\db\utils.py", line 90, in __exit__
    raise dj_exc_value.with_traceback(traceback) from exc_value
  File "C:\ProgramData\Miniconda3\lib\site-packages\django\db\backends\utils.py", line 86, in _execute
    return self.cursor.execute(sql, params)
  File "C:\ProgramData\Miniconda3\lib\site-packages\django\db\backends\mysql\base.py", line 74, in execute
    return self.cursor.execute(query, args)
  File "C:\ProgramData\Miniconda3\lib\site-packages\MySQLdb\cursors.py", line 209, in execute
    res = self._query(query)
  File "C:\ProgramData\Miniconda3\lib\site-packages\MySQLdb\cursors.py", line 315, in _query
    db.query(q)
  File "C:\ProgramData\Miniconda3\lib\site-packages\MySQLdb\connections.py", line 239, in query
    _mysql.connection.query(self, query)
django.db.utils.IntegrityError: (1062, "Duplicate entry '' for key 'phone'")
Bad Request: /user/users
Internal Server Error: /user/users
Traceback (most recent call last):
  File "C:\ProgramData\Miniconda3\lib\site-packages\django\db\backends\utils.py", line 86, in _execute
    return self.cursor.execute(sql, params)
  File "C:\ProgramData\Miniconda3\lib\site-packages\django\db\backends\mysql\base.py", line 74, in execute
    return self.cursor.execute(query, args)
  File "C:\ProgramData\Miniconda3\lib\site-packages\MySQLdb\cursors.py", line 209, in execute
    res = self._query(query)
  File "C:\ProgramData\Miniconda3\lib\site-packages\MySQLdb\cursors.py", line 315, in _query
    db.query(q)
  File "C:\ProgramData\Miniconda3\lib\site-packages\MySQLdb\connections.py", line 239, in query
    _mysql.connection.query(self, query)
MySQLdb._exceptions.IntegrityError: (1062, "Duplicate entry '' for key 'phone'")

The above exception was the direct cause of the following exception:

Traceback (most recent call last):
  File "C:\ProgramData\Miniconda3\lib\site-packages\django\core\handlers\exception.py", line 34, in inner
    response = get_response(request)
  File "C:\ProgramData\Miniconda3\lib\site-packages\django\core\handlers\base.py", line 115, in _get_response
    response = self.process_exception_by_middleware(e, request)
  File "C:\ProgramData\Miniconda3\lib\site-packages\django\core\handlers\base.py", line 113, in _get_response
    response = wrapped_callback(request, *callback_args, **callback_kwargs)
  File "C:\ProgramData\Miniconda3\lib\site-packages\django\views\decorators\csrf.py", line 54, in wrapped_view
    return view_func(*args, **kwargs)
  File "C:\ProgramData\Miniconda3\lib\site-packages\rest_framework\viewsets.py", line 114, in view
    return self.dispatch(request, *args, **kwargs)
  File "C:\ProgramData\Miniconda3\lib\site-packages\rest_framework\views.py", line 505, in dispatch
    response = self.handle_exception(exc)
  File "C:\ProgramData\Miniconda3\lib\site-packages\rest_framework\views.py", line 465, in handle_exception
    self.raise_uncaught_exception(exc)
  File "C:\ProgramData\Miniconda3\lib\site-packages\rest_framework\views.py", line 476, in raise_uncaught_exception
    raise exc
  File "C:\ProgramData\Miniconda3\lib\site-packages\rest_framework\views.py", line 502, in dispatch
    response = handler(request, *args, **kwargs)
  File "D:\MISC\GITHUB\knit_server//app\users\kviews\user_view.py", line 44, in create
    user_serializer.save()
  File "C:\ProgramData\Miniconda3\lib\site-packages\rest_framework\serializers.py", line 212, in save
    self.instance = self.create(validated_data)
  File "D:\MISC\GITHUB\knit_server//app\users\kserializers\user_serializer.py", line 35, in create
    user = User.objects.create_user(**validated_data)
  File "D:\MISC\GITHUB\knit_server//app\users\models.py", line 33, in create_user
    user.save(using=self._db)
  File "C:\ProgramData\Miniconda3\lib\site-packages\django\contrib\auth\base_user.py", line 66, in save
    super().save(*args, **kwargs)
  File "C:\ProgramData\Miniconda3\lib\site-packages\django\db\models\base.py", line 746, in save
    force_update=force_update, update_fields=update_fields)
  File "C:\ProgramData\Miniconda3\lib\site-packages\django\db\models\base.py", line 784, in save_base
    force_update, using, update_fields,
  File "C:\ProgramData\Miniconda3\lib\site-packages\django\db\models\base.py", line 886, in _save_table
    results = self._do_insert(cls._base_manager, using, fields, returning_fields, raw)
  File "C:\ProgramData\Miniconda3\lib\site-packages\django\db\models\base.py", line 925, in _do_insert
    using=using, raw=raw,
  File "C:\ProgramData\Miniconda3\lib\site-packages\django\db\models\manager.py", line 82, in manager_method
    return getattr(self.get_queryset(), name)(*args, **kwargs)
  File "C:\ProgramData\Miniconda3\lib\site-packages\django\db\models\query.py", line 1204, in _insert
    return query.get_compiler(using=using).execute_sql(returning_fields)
  File "C:\ProgramData\Miniconda3\lib\site-packages\django\db\models\sql\compiler.py", line 1377, in execute_sql
    cursor.execute(sql, params)
  File "C:\ProgramData\Miniconda3\lib\site-packages\django\db\backends\utils.py", line 100, in execute
    return super().execute(sql, params)
  File "C:\ProgramData\Miniconda3\lib\site-packages\django\db\backends\utils.py", line 68, in execute
    return self._execute_with_wrappers(sql, params, many=False, executor=self._execute)
  File "C:\ProgramData\Miniconda3\lib\site-packages\django\db\backends\utils.py", line 77, in _execute_with_wrappers
    return executor(sql, params, many, context)
  File "C:\ProgramData\Miniconda3\lib\site-packages\django\db\backends\utils.py", line 86, in _execute
    return self.cursor.execute(sql, params)
  File "C:\ProgramData\Miniconda3\lib\site-packages\django\db\utils.py", line 90, in __exit__
    raise dj_exc_value.with_traceback(traceback) from exc_value
  File "C:\ProgramData\Miniconda3\lib\site-packages\django\db\backends\utils.py", line 86, in _execute
    return self.cursor.execute(sql, params)
  File "C:\ProgramData\Miniconda3\lib\site-packages\django\db\backends\mysql\base.py", line 74, in execute
    return self.cursor.execute(query, args)
  File "C:\ProgramData\Miniconda3\lib\site-packages\MySQLdb\cursors.py", line 209, in execute
    res = self._query(query)
  File "C:\ProgramData\Miniconda3\lib\site-packages\MySQLdb\cursors.py", line 315, in _query
    db.query(q)
  File "C:\ProgramData\Miniconda3\lib\site-packages\MySQLdb\connections.py", line 239, in query
    _mysql.connection.query(self, query)
django.db.utils.IntegrityError: (1062, "Duplicate entry '' for key 'phone'")
Internal Server Error: /user/users
Traceback (most recent call last):
  File "C:\ProgramData\Miniconda3\lib\site-packages\django\db\backends\utils.py", line 86, in _execute
    return self.cursor.execute(sql, params)
  File "C:\ProgramData\Miniconda3\lib\site-packages\django\db\backends\mysql\base.py", line 74, in execute
    return self.cursor.execute(query, args)
  File "C:\ProgramData\Miniconda3\lib\site-packages\MySQLdb\cursors.py", line 209, in execute
    res = self._query(query)
  File "C:\ProgramData\Miniconda3\lib\site-packages\MySQLdb\cursors.py", line 315, in _query
    db.query(q)
  File "C:\ProgramData\Miniconda3\lib\site-packages\MySQLdb\connections.py", line 239, in query
    _mysql.connection.query(self, query)
MySQLdb._exceptions.IntegrityError: (1062, "Duplicate entry '' for key 'phone'")

The above exception was the direct cause of the following exception:

Traceback (most recent call last):
  File "C:\ProgramData\Miniconda3\lib\site-packages\django\core\handlers\exception.py", line 34, in inner
    response = get_response(request)
  File "C:\ProgramData\Miniconda3\lib\site-packages\django\core\handlers\base.py", line 115, in _get_response
    response = self.process_exception_by_middleware(e, request)
  File "C:\ProgramData\Miniconda3\lib\site-packages\django\core\handlers\base.py", line 113, in _get_response
    response = wrapped_callback(request, *callback_args, **callback_kwargs)
  File "C:\ProgramData\Miniconda3\lib\site-packages\django\views\decorators\csrf.py", line 54, in wrapped_view
    return view_func(*args, **kwargs)
  File "C:\ProgramData\Miniconda3\lib\site-packages\rest_framework\viewsets.py", line 114, in view
    return self.dispatch(request, *args, **kwargs)
  File "C:\ProgramData\Miniconda3\lib\site-packages\rest_framework\views.py", line 505, in dispatch
    response = self.handle_exception(exc)
  File "C:\ProgramData\Miniconda3\lib\site-packages\rest_framework\views.py", line 465, in handle_exception
    self.raise_uncaught_exception(exc)
  File "C:\ProgramData\Miniconda3\lib\site-packages\rest_framework\views.py", line 476, in raise_uncaught_exception
    raise exc
  File "C:\ProgramData\Miniconda3\lib\site-packages\rest_framework\views.py", line 502, in dispatch
    response = handler(request, *args, **kwargs)
  File "D:\MISC\GITHUB\knit_server//app\users\kviews\user_view.py", line 44, in create
    user_serializer.save()
  File "C:\ProgramData\Miniconda3\lib\site-packages\rest_framework\serializers.py", line 212, in save
    self.instance = self.create(validated_data)
  File "D:\MISC\GITHUB\knit_server//app\users\kserializers\user_serializer.py", line 35, in create
    user = User.objects.create_user(**validated_data)
  File "D:\MISC\GITHUB\knit_server//app\users\models.py", line 33, in create_user
    user.save(using=self._db)
  File "C:\ProgramData\Miniconda3\lib\site-packages\django\contrib\auth\base_user.py", line 66, in save
    super().save(*args, **kwargs)
  File "C:\ProgramData\Miniconda3\lib\site-packages\django\db\models\base.py", line 746, in save
    force_update=force_update, update_fields=update_fields)
  File "C:\ProgramData\Miniconda3\lib\site-packages\django\db\models\base.py", line 784, in save_base
    force_update, using, update_fields,
  File "C:\ProgramData\Miniconda3\lib\site-packages\django\db\models\base.py", line 886, in _save_table
    results = self._do_insert(cls._base_manager, using, fields, returning_fields, raw)
  File "C:\ProgramData\Miniconda3\lib\site-packages\django\db\models\base.py", line 925, in _do_insert
    using=using, raw=raw,
  File "C:\ProgramData\Miniconda3\lib\site-packages\django\db\models\manager.py", line 82, in manager_method
    return getattr(self.get_queryset(), name)(*args, **kwargs)
  File "C:\ProgramData\Miniconda3\lib\site-packages\django\db\models\query.py", line 1204, in _insert
    return query.get_compiler(using=using).execute_sql(returning_fields)
  File "C:\ProgramData\Miniconda3\lib\site-packages\django\db\models\sql\compiler.py", line 1377, in execute_sql
    cursor.execute(sql, params)
  File "C:\ProgramData\Miniconda3\lib\site-packages\django\db\backends\utils.py", line 100, in execute
    return super().execute(sql, params)
  File "C:\ProgramData\Miniconda3\lib\site-packages\django\db\backends\utils.py", line 68, in execute
    return self._execute_with_wrappers(sql, params, many=False, executor=self._execute)
  File "C:\ProgramData\Miniconda3\lib\site-packages\django\db\backends\utils.py", line 77, in _execute_with_wrappers
    return executor(sql, params, many, context)
  File "C:\ProgramData\Miniconda3\lib\site-packages\django\db\backends\utils.py", line 86, in _execute
    return self.cursor.execute(sql, params)
  File "C:\ProgramData\Miniconda3\lib\site-packages\django\db\utils.py", line 90, in __exit__
    raise dj_exc_value.with_traceback(traceback) from exc_value
  File "C:\ProgramData\Miniconda3\lib\site-packages\django\db\backends\utils.py", line 86, in _execute
    return self.cursor.execute(sql, params)
  File "C:\ProgramData\Miniconda3\lib\site-packages\django\db\backends\mysql\base.py", line 74, in execute
    return self.cursor.execute(query, args)
  File "C:\ProgramData\Miniconda3\lib\site-packages\MySQLdb\cursors.py", line 209, in execute
    res = self._query(query)
  File "C:\ProgramData\Miniconda3\lib\site-packages\MySQLdb\cursors.py", line 315, in _query
    db.query(q)
  File "C:\ProgramData\Miniconda3\lib\site-packages\MySQLdb\connections.py", line 239, in query
    _mysql.connection.query(self, query)
django.db.utils.IntegrityError: (1062, "Duplicate entry '' for key 'phone'")
Internal Server Error: /user/users
Traceback (most recent call last):
  File "C:\ProgramData\Miniconda3\lib\site-packages\django\core\handlers\exception.py", line 34, in inner
    response = get_response(request)
  File "C:\ProgramData\Miniconda3\lib\site-packages\django\core\handlers\base.py", line 115, in _get_response
    response = self.process_exception_by_middleware(e, request)
  File "C:\ProgramData\Miniconda3\lib\site-packages\django\core\handlers\base.py", line 113, in _get_response
    response = wrapped_callback(request, *callback_args, **callback_kwargs)
  File "C:\ProgramData\Miniconda3\lib\site-packages\django\views\decorators\csrf.py", line 54, in wrapped_view
    return view_func(*args, **kwargs)
  File "C:\ProgramData\Miniconda3\lib\site-packages\rest_framework\viewsets.py", line 114, in view
    return self.dispatch(request, *args, **kwargs)
  File "C:\ProgramData\Miniconda3\lib\site-packages\rest_framework\views.py", line 505, in dispatch
    response = self.handle_exception(exc)
  File "C:\ProgramData\Miniconda3\lib\site-packages\rest_framework\views.py", line 465, in handle_exception
    self.raise_uncaught_exception(exc)
  File "C:\ProgramData\Miniconda3\lib\site-packages\rest_framework\views.py", line 476, in raise_uncaught_exception
    raise exc
  File "C:\ProgramData\Miniconda3\lib\site-packages\rest_framework\views.py", line 502, in dispatch
    response = handler(request, *args, **kwargs)
  File "D:\MISC\GITHUB\knit_server//app\users\kviews\user_view.py", line 43, in create
    if user_serializer.is_valid():
  File "C:\ProgramData\Miniconda3\lib\site-packages\rest_framework\serializers.py", line 234, in is_valid
    self._validated_data = self.run_validation(self.initial_data)
  File "C:\ProgramData\Miniconda3\lib\site-packages\rest_framework\serializers.py", line 436, in run_validation
    value = self.validate(value)
  File "D:\MISC\GITHUB\knit_server//app\users\kserializers\user_serializer.py", line 127, in validate
    data['username'] = data.get('username', null)
NameError: name 'null' is not defined
Internal Server Error: /user/users
Traceback (most recent call last):
  File "C:\ProgramData\Miniconda3\lib\site-packages\django\core\handlers\exception.py", line 34, in inner
    response = get_response(request)
  File "C:\ProgramData\Miniconda3\lib\site-packages\django\core\handlers\base.py", line 115, in _get_response
    response = self.process_exception_by_middleware(e, request)
  File "C:\ProgramData\Miniconda3\lib\site-packages\django\core\handlers\base.py", line 113, in _get_response
    response = wrapped_callback(request, *callback_args, **callback_kwargs)
  File "C:\ProgramData\Miniconda3\lib\site-packages\django\views\decorators\csrf.py", line 54, in wrapped_view
    return view_func(*args, **kwargs)
  File "C:\ProgramData\Miniconda3\lib\site-packages\rest_framework\viewsets.py", line 114, in view
    return self.dispatch(request, *args, **kwargs)
  File "C:\ProgramData\Miniconda3\lib\site-packages\rest_framework\views.py", line 505, in dispatch
    response = self.handle_exception(exc)
  File "C:\ProgramData\Miniconda3\lib\site-packages\rest_framework\views.py", line 465, in handle_exception
    self.raise_uncaught_exception(exc)
  File "C:\ProgramData\Miniconda3\lib\site-packages\rest_framework\views.py", line 476, in raise_uncaught_exception
    raise exc
  File "C:\ProgramData\Miniconda3\lib\site-packages\rest_framework\views.py", line 502, in dispatch
    response = handler(request, *args, **kwargs)
  File "C:\ProgramData\Miniconda3\lib\site-packages\rest_framework\mixins.py", line 43, in list
    return self.get_paginated_response(serializer.data)
  File "C:\ProgramData\Miniconda3\lib\site-packages\rest_framework\serializers.py", line 760, in data
    ret = super().data
  File "C:\ProgramData\Miniconda3\lib\site-packages\rest_framework\serializers.py", line 260, in data
    self._data = self.to_representation(self.instance)
  File "C:\ProgramData\Miniconda3\lib\site-packages\rest_framework\serializers.py", line 678, in to_representation
    self.child.to_representation(item) for item in iterable
  File "C:\ProgramData\Miniconda3\lib\site-packages\rest_framework\serializers.py", line 678, in <listcomp>
    self.child.to_representation(item) for item in iterable
  File "D:\MISC\GITHUB\knit_server//app\users\kserializers\user_serializer.py", line 142, in to_representation
    representation = super().to_representation(instance)
  File "C:\ProgramData\Miniconda3\lib\site-packages\rest_framework\serializers.py", line 514, in to_representation
    for field in fields:
  File "C:\ProgramData\Miniconda3\lib\site-packages\rest_framework\serializers.py", line 375, in _readable_fields
    for field in self.fields.values():
  File "C:\ProgramData\Miniconda3\lib\site-packages\django\utils\functional.py", line 48, in __get__
    res = instance.__dict__[self.name] = self.func(instance)
  File "C:\ProgramData\Miniconda3\lib\site-packages\rest_framework\serializers.py", line 363, in fields
    for key, value in self.get_fields().items():
  File "C:\ProgramData\Miniconda3\lib\site-packages\rest_framework\serializers.py", line 1038, in get_fields
    field_names = self.get_field_names(declared_fields, info)
  File "C:\ProgramData\Miniconda3\lib\site-packages\rest_framework\serializers.py", line 1139, in get_field_names
    serializer_class=self.__class__.__name__
AssertionError: The field 'profile' was declared on serializer UserSerializer, but has not been included in the 'fields' option.
Bad Request: /rest-auth/login/
Not Found: /user/users.2
Not Found: /user/users/158
