 django.request 2020-05-01 19:26:21,536 WARNING  Not Found: /
 django.request 2020-05-01 19:26:21,647 WARNING  Not Found: /favicon.ico
 django.request 2020-05-02 19:34:26,592 WARNING  Not Found: /favicon.ico
 django.request 2020-05-02 19:37:38,075 WARNING  Unauthorized: /user/user-types/1
 django.request 2020-05-02 19:37:55,379 WARNING  Unauthorized: /user/user-types/2
 django.request 2020-05-02 19:38:11,545 WARNING  Unauthorized: /user/user-types/2
 django.request 2020-05-02 19:39:14,871 WARNING  Unauthorized: /user/user-types
 django.request 2020-05-02 19:50:18,755 WARNING  Method Not Allowed: /user/user-types/8
 django.request 2020-05-02 19:54:10,553 WARNING  Method Not Allowed: /user/user-types
 django.request 2020-05-02 19:54:42,798 WARNING  Not Found: /user/colors
 django.request 2020-05-02 19:54:45,779 WARNING  Not Found: /user/color
 django.request 2020-05-02 19:54:50,473 WARNING  Not Found: /product/color
 django.request 2020-05-02 19:58:01,861 WARNING  Method Not Allowed: /product/colors/14
 django.request 2020-05-02 19:58:42,611 WARNING  Not Found: /product/size
 django.request 2020-05-03 11:41:59,755 WARNING  Not Found: /user/vndors
 django.request 2020-05-03 11:41:59,888 WARNING  Not Found: /favicon.ico
 django.request 2020-05-04 22:57:36,066 WARNING  Not Found: /favicon.ico
 django.request 2020-05-04 23:24:48,223 ERROR    Internal Server Error: /product/maggam-catalogs
Traceback (most recent call last):
  File "C:\ProgramData\Miniconda3\lib\site-packages\django\core\handlers\exception.py", line 34, in inner
    response = get_response(request)
  File "C:\ProgramData\Miniconda3\lib\site-packages\django\core\handlers\base.py", line 115, in _get_response
    response = self.process_exception_by_middleware(e, request)
  File "C:\ProgramData\Miniconda3\lib\site-packages\django\core\handlers\base.py", line 113, in _get_response
    response = wrapped_callback(request, *callback_args, **callback_kwargs)
  File "C:\ProgramData\Miniconda3\lib\site-packages\django\views\decorators\csrf.py", line 54, in wrapped_view
    return view_func(*args, **kwargs)
  File "C:\ProgramData\Miniconda3\lib\site-packages\rest_framework\viewsets.py", line 114, in view
    return self.dispatch(request, *args, **kwargs)
  File "C:\ProgramData\Miniconda3\lib\site-packages\rest_framework\views.py", line 505, in dispatch
    response = self.handle_exception(exc)
  File "C:\ProgramData\Miniconda3\lib\site-packages\rest_framework\views.py", line 465, in handle_exception
    self.raise_uncaught_exception(exc)
  File "C:\ProgramData\Miniconda3\lib\site-packages\rest_framework\views.py", line 476, in raise_uncaught_exception
    raise exc
  File "C:\ProgramData\Miniconda3\lib\site-packages\rest_framework\views.py", line 502, in dispatch
    response = handler(request, *args, **kwargs)
  File "D:\MISC\GITHUB\knit_server//app\products\kviews\maggam_catalog_view.py", line 38, in create
    relations['category'] = request.data.pop("category")
  File "C:\ProgramData\Miniconda3\lib\site-packages\django\http\request.py", line 506, in pop
    self._assert_mutable()
  File "C:\ProgramData\Miniconda3\lib\site-packages\django\http\request.py", line 464, in _assert_mutable
    raise AttributeError("This QueryDict instance is immutable")
AttributeError: This QueryDict instance is immutable
 django.request 2020-05-04 23:26:10,417 ERROR    Internal Server Error: /product/maggam-catalogs
Traceback (most recent call last):
  File "C:\ProgramData\Miniconda3\lib\site-packages\django\core\handlers\exception.py", line 34, in inner
    response = get_response(request)
  File "C:\ProgramData\Miniconda3\lib\site-packages\django\core\handlers\base.py", line 115, in _get_response
    response = self.process_exception_by_middleware(e, request)
  File "C:\ProgramData\Miniconda3\lib\site-packages\django\core\handlers\base.py", line 113, in _get_response
    response = wrapped_callback(request, *callback_args, **callback_kwargs)
  File "C:\ProgramData\Miniconda3\lib\site-packages\django\views\decorators\csrf.py", line 54, in wrapped_view
    return view_func(*args, **kwargs)
  File "C:\ProgramData\Miniconda3\lib\site-packages\rest_framework\viewsets.py", line 114, in view
    return self.dispatch(request, *args, **kwargs)
  File "C:\ProgramData\Miniconda3\lib\site-packages\rest_framework\views.py", line 505, in dispatch
    response = self.handle_exception(exc)
  File "C:\ProgramData\Miniconda3\lib\site-packages\rest_framework\views.py", line 465, in handle_exception
    self.raise_uncaught_exception(exc)
  File "C:\ProgramData\Miniconda3\lib\site-packages\rest_framework\views.py", line 476, in raise_uncaught_exception
    raise exc
  File "C:\ProgramData\Miniconda3\lib\site-packages\rest_framework\views.py", line 502, in dispatch
    response = handler(request, *args, **kwargs)
  File "D:\MISC\GITHUB\knit_server//app\products\kviews\maggam_catalog_view.py", line 40, in create
    relations['category'] = request.data.pop("category")
  File "C:\ProgramData\Miniconda3\lib\site-packages\django\http\request.py", line 506, in pop
    self._assert_mutable()
  File "C:\ProgramData\Miniconda3\lib\site-packages\django\http\request.py", line 464, in _assert_mutable
    raise AttributeError("This QueryDict instance is immutable")
AttributeError: This QueryDict instance is immutable
 django.request 2020-05-04 23:26:53,670 WARNING  Bad Request: /product/maggam-catalogs
 django.request 2020-05-04 23:32:45,506 WARNING  Bad Request: /product/maggam-catalogs
 django.request 2020-05-04 23:38:24,452 WARNING  Bad Request: /product/maggam-catalogs
 django.request 2020-05-04 23:40:28,371 WARNING  Bad Request: /product/maggam-catalogs
 django.request 2020-05-04 23:45:32,186 ERROR    Internal Server Error: /product/maggam-catalogs
Traceback (most recent call last):
  File "C:\ProgramData\Miniconda3\lib\site-packages\django\db\models\query.py", line 559, in get_or_create
    return self.get(**kwargs), False
  File "C:\ProgramData\Miniconda3\lib\site-packages\django\db\models\query.py", line 417, in get
    self.model._meta.object_name
products.kmodels.maggam_catalog_model.MaggamCatalog.DoesNotExist: MaggamCatalog matching query does not exist.

During handling of the above exception, another exception occurred:

Traceback (most recent call last):
  File "C:\ProgramData\Miniconda3\lib\site-packages\django\core\handlers\exception.py", line 34, in inner
    response = get_response(request)
  File "C:\ProgramData\Miniconda3\lib\site-packages\django\core\handlers\base.py", line 115, in _get_response
    response = self.process_exception_by_middleware(e, request)
  File "C:\ProgramData\Miniconda3\lib\site-packages\django\core\handlers\base.py", line 113, in _get_response
    response = wrapped_callback(request, *callback_args, **callback_kwargs)
  File "C:\ProgramData\Miniconda3\lib\site-packages\django\views\decorators\csrf.py", line 54, in wrapped_view
    return view_func(*args, **kwargs)
  File "C:\ProgramData\Miniconda3\lib\site-packages\rest_framework\viewsets.py", line 114, in view
    return self.dispatch(request, *args, **kwargs)
  File "C:\ProgramData\Miniconda3\lib\site-packages\rest_framework\views.py", line 505, in dispatch
    response = self.handle_exception(exc)
  File "C:\ProgramData\Miniconda3\lib\site-packages\rest_framework\views.py", line 465, in handle_exception
    self.raise_uncaught_exception(exc)
  File "C:\ProgramData\Miniconda3\lib\site-packages\rest_framework\views.py", line 476, in raise_uncaught_exception
    raise exc
  File "C:\ProgramData\Miniconda3\lib\site-packages\rest_framework\views.py", line 502, in dispatch
    response = handler(request, *args, **kwargs)
  File "D:\MISC\GITHUB\knit_server//app\products\kviews\maggam_catalog_view.py", line 46, in create
    if maggam_catalog_serializer.is_valid():
  File "C:\ProgramData\Miniconda3\lib\site-packages\rest_framework\serializers.py", line 212, in save
    self.instance = self.create(validated_data)
  File "D:\MISC\GITHUB\knit_server//app\products\kserializers\maggam_catalog_serializer.py", line 51, in create
    maggam_catalog, created = MaggamCatalog.objects.get_or_create(**validated_data)
  File "C:\ProgramData\Miniconda3\lib\site-packages\django\db\models\manager.py", line 82, in manager_method
    return getattr(self.get_queryset(), name)(*args, **kwargs)
  File "C:\ProgramData\Miniconda3\lib\site-packages\django\db\models\query.py", line 562, in get_or_create
    return self._create_object_from_params(kwargs, params)
  File "C:\ProgramData\Miniconda3\lib\site-packages\django\db\models\query.py", line 596, in _create_object_from_params
    obj = self.create(**params)
  File "C:\ProgramData\Miniconda3\lib\site-packages\django\db\models\query.py", line 433, in create
    obj.save(force_insert=True, using=self.db)
  File "D:\MISC\GITHUB\knit_server//app\products\kmodels\maggam_catalog_model.py", line 27, in save
    super(MaggamCatalog).save(*args, **kwargs)
AttributeError: 'super' object has no attribute 'save'
 django.request 2020-05-04 23:47:25,021 ERROR    Internal Server Error: /product/maggam-catalogs
Traceback (most recent call last):
  File "C:\ProgramData\Miniconda3\lib\site-packages\django\core\handlers\exception.py", line 34, in inner
    response = get_response(request)
  File "C:\ProgramData\Miniconda3\lib\site-packages\django\core\handlers\base.py", line 115, in _get_response
    response = self.process_exception_by_middleware(e, request)
  File "C:\ProgramData\Miniconda3\lib\site-packages\django\core\handlers\base.py", line 113, in _get_response
    response = wrapped_callback(request, *callback_args, **callback_kwargs)
  File "C:\ProgramData\Miniconda3\lib\site-packages\django\views\decorators\csrf.py", line 54, in wrapped_view
    return view_func(*args, **kwargs)
  File "C:\ProgramData\Miniconda3\lib\site-packages\rest_framework\viewsets.py", line 114, in view
    return self.dispatch(request, *args, **kwargs)
  File "C:\ProgramData\Miniconda3\lib\site-packages\rest_framework\views.py", line 505, in dispatch
    response = self.handle_exception(exc)
  File "C:\ProgramData\Miniconda3\lib\site-packages\rest_framework\views.py", line 465, in handle_exception
    self.raise_uncaught_exception(exc)
  File "C:\ProgramData\Miniconda3\lib\site-packages\rest_framework\views.py", line 476, in raise_uncaught_exception
    raise exc
  File "C:\ProgramData\Miniconda3\lib\site-packages\rest_framework\views.py", line 502, in dispatch
    response = handler(request, *args, **kwargs)
  File "D:\MISC\GITHUB\knit_server//app\products\kviews\maggam_catalog_view.py", line 46, in create
    if maggam_catalog_serializer.is_valid():
  File "C:\ProgramData\Miniconda3\lib\site-packages\rest_framework\serializers.py", line 212, in save
    self.instance = self.create(validated_data)
  File "D:\MISC\GITHUB\knit_server//app\products\kserializers\maggam_catalog_serializer.py", line 59, in create
    if category_str:
NameError: name 'category_str' is not defined
 django.request 2020-05-04 23:49:06,268 ERROR    Internal Server Error: /product/maggam-catalogs
Traceback (most recent call last):
  File "C:\ProgramData\Miniconda3\lib\site-packages\django\core\handlers\exception.py", line 34, in inner
    response = get_response(request)
  File "C:\ProgramData\Miniconda3\lib\site-packages\django\core\handlers\base.py", line 115, in _get_response
    response = self.process_exception_by_middleware(e, request)
  File "C:\ProgramData\Miniconda3\lib\site-packages\django\core\handlers\base.py", line 113, in _get_response
    response = wrapped_callback(request, *callback_args, **callback_kwargs)
  File "C:\ProgramData\Miniconda3\lib\site-packages\django\views\decorators\csrf.py", line 54, in wrapped_view
    return view_func(*args, **kwargs)
  File "C:\ProgramData\Miniconda3\lib\site-packages\rest_framework\viewsets.py", line 114, in view
    return self.dispatch(request, *args, **kwargs)
  File "C:\ProgramData\Miniconda3\lib\site-packages\rest_framework\views.py", line 505, in dispatch
    response = self.handle_exception(exc)
  File "C:\ProgramData\Miniconda3\lib\site-packages\rest_framework\views.py", line 465, in handle_exception
    self.raise_uncaught_exception(exc)
  File "C:\ProgramData\Miniconda3\lib\site-packages\rest_framework\views.py", line 476, in raise_uncaught_exception
    raise exc
  File "C:\ProgramData\Miniconda3\lib\site-packages\rest_framework\views.py", line 502, in dispatch
    response = handler(request, *args, **kwargs)
  File "D:\MISC\GITHUB\knit_server//app\products\kviews\maggam_catalog_view.py", line 46, in create
    if maggam_catalog_serializer.is_valid():
  File "C:\ProgramData\Miniconda3\lib\site-packages\rest_framework\serializers.py", line 212, in save
    self.instance = self.create(validated_data)
  File "D:\MISC\GITHUB\knit_server//app\products\kserializers\maggam_catalog_serializer.py", line 66, in create
    maggam_catalog.category.set(catalog)
  File "C:\ProgramData\Miniconda3\lib\site-packages\django\db\models\fields\related_descriptors.py", line 1008, in set
    self.add(*new_objs, through_defaults=through_defaults)
  File "C:\ProgramData\Miniconda3\lib\site-packages\django\db\models\fields\related_descriptors.py", line 946, in add
    through_defaults=through_defaults,
  File "C:\ProgramData\Miniconda3\lib\site-packages\django\db\models\fields\related_descriptors.py", line 1119, in _add_items
    target_ids = self._get_target_ids(target_field_name, objs)
  File "C:\ProgramData\Miniconda3\lib\site-packages\django\db\models\fields\related_descriptors.py", line 1063, in _get_target_ids
    (self.model._meta.object_name, obj)
TypeError: 'Category' instance expected, got <MaggamCatalog: Buttons>
 django.request 2020-05-04 23:54:09,861 WARNING  Bad Request: /product/maggam-catalogs
 django.request 2020-05-04 23:57:52,975 WARNING  Not Found: /product/csv-ref-tables
 django.request 2020-05-05 18:48:21,195 WARNING  Not Found: /user/vendor
 django.request 2020-05-05 18:48:21,300 WARNING  Not Found: /favicon.ico
 django.request 2020-05-05 18:48:24,460 WARNING  Not Found: /user/vendors/
 django.request 2020-05-05 18:48:27,561 ERROR    Internal Server Error: /user/vendors
Traceback (most recent call last):
  File "C:\ProgramData\Miniconda3\lib\site-packages\django\core\handlers\exception.py", line 34, in inner
    response = get_response(request)
  File "C:\ProgramData\Miniconda3\lib\site-packages\django\core\handlers\base.py", line 115, in _get_response
    response = self.process_exception_by_middleware(e, request)
  File "C:\ProgramData\Miniconda3\lib\site-packages\django\core\handlers\base.py", line 113, in _get_response
    response = wrapped_callback(request, *callback_args, **callback_kwargs)
  File "C:\ProgramData\Miniconda3\lib\site-packages\django\views\decorators\csrf.py", line 54, in wrapped_view
    return view_func(*args, **kwargs)
  File "C:\ProgramData\Miniconda3\lib\site-packages\rest_framework\viewsets.py", line 114, in view
    return self.dispatch(request, *args, **kwargs)
  File "C:\ProgramData\Miniconda3\lib\site-packages\rest_framework\views.py", line 505, in dispatch
    response = self.handle_exception(exc)
  File "C:\ProgramData\Miniconda3\lib\site-packages\rest_framework\views.py", line 465, in handle_exception
    self.raise_uncaught_exception(exc)
  File "C:\ProgramData\Miniconda3\lib\site-packages\rest_framework\views.py", line 476, in raise_uncaught_exception
    raise exc
  File "C:\ProgramData\Miniconda3\lib\site-packages\rest_framework\views.py", line 502, in dispatch
    response = handler(request, *args, **kwargs)
  File "C:\ProgramData\Miniconda3\lib\site-packages\rest_framework\mixins.py", line 38, in list
    queryset = self.filter_queryset(self.get_queryset())
  File "D:\MISC\GITHUB\knit_server//app\users\kviews\vendor_view.py", line 45, in get_queryset
    profile = Profile.objects.filter(is_active=True)
NameError: name 'Profile' is not defined
 django.request 2020-05-05 18:50:40,360 WARNING  Not Found: /users/vendors
 django.request 2020-05-05 18:50:44,243 ERROR    Internal Server Error: /user/vendors
Traceback (most recent call last):
  File "C:\ProgramData\Miniconda3\lib\site-packages\django\core\handlers\exception.py", line 34, in inner
    response = get_response(request)
  File "C:\ProgramData\Miniconda3\lib\site-packages\django\core\handlers\base.py", line 115, in _get_response
    response = self.process_exception_by_middleware(e, request)
  File "C:\ProgramData\Miniconda3\lib\site-packages\django\core\handlers\base.py", line 113, in _get_response
    response = wrapped_callback(request, *callback_args, **callback_kwargs)
  File "C:\ProgramData\Miniconda3\lib\site-packages\django\views\decorators\csrf.py", line 54, in wrapped_view
    return view_func(*args, **kwargs)
  File "C:\ProgramData\Miniconda3\lib\site-packages\rest_framework\viewsets.py", line 114, in view
    return self.dispatch(request, *args, **kwargs)
  File "C:\ProgramData\Miniconda3\lib\site-packages\rest_framework\views.py", line 505, in dispatch
    response = self.handle_exception(exc)
  File "C:\ProgramData\Miniconda3\lib\site-packages\rest_framework\views.py", line 465, in handle_exception
    self.raise_uncaught_exception(exc)
  File "C:\ProgramData\Miniconda3\lib\site-packages\rest_framework\views.py", line 476, in raise_uncaught_exception
    raise exc
  File "C:\ProgramData\Miniconda3\lib\site-packages\rest_framework\views.py", line 502, in dispatch
    response = handler(request, *args, **kwargs)
  File "C:\ProgramData\Miniconda3\lib\site-packages\rest_framework\mixins.py", line 38, in list
    queryset = self.filter_queryset(self.get_queryset())
  File "D:\MISC\GITHUB\knit_server//app\users\kviews\vendor_view.py", line 45, in get_queryset
    profile = Profile.objects.filter(is_active=True)
NameError: name 'Profile' is not defined
 django.request 2020-05-05 18:52:54,319 WARNING  Not Found: /user/vendors/
 django.request 2020-05-05 18:52:54,447 WARNING  Not Found: /favicon.ico
 django.request 2020-05-05 18:52:57,765 WARNING  Not Found: /user/vendor
 django.request 2020-05-05 18:53:05,024 ERROR    Internal Server Error: /user/vendors
Traceback (most recent call last):
  File "C:\ProgramData\Miniconda3\lib\site-packages\django\core\handlers\exception.py", line 34, in inner
    response = get_response(request)
  File "C:\ProgramData\Miniconda3\lib\site-packages\django\core\handlers\base.py", line 115, in _get_response
    response = self.process_exception_by_middleware(e, request)
  File "C:\ProgramData\Miniconda3\lib\site-packages\django\core\handlers\base.py", line 113, in _get_response
    response = wrapped_callback(request, *callback_args, **callback_kwargs)
  File "C:\ProgramData\Miniconda3\lib\site-packages\django\views\decorators\csrf.py", line 54, in wrapped_view
    return view_func(*args, **kwargs)
  File "C:\ProgramData\Miniconda3\lib\site-packages\rest_framework\viewsets.py", line 114, in view
    return self.dispatch(request, *args, **kwargs)
  File "C:\ProgramData\Miniconda3\lib\site-packages\rest_framework\views.py", line 505, in dispatch
    response = self.handle_exception(exc)
  File "C:\ProgramData\Miniconda3\lib\site-packages\rest_framework\views.py", line 465, in handle_exception
    self.raise_uncaught_exception(exc)
  File "C:\ProgramData\Miniconda3\lib\site-packages\rest_framework\views.py", line 476, in raise_uncaught_exception
    raise exc
  File "C:\ProgramData\Miniconda3\lib\site-packages\rest_framework\views.py", line 502, in dispatch
    response = handler(request, *args, **kwargs)
  File "C:\ProgramData\Miniconda3\lib\site-packages\rest_framework\mixins.py", line 38, in list
    queryset = self.filter_queryset(self.get_queryset())
  File "D:\MISC\GITHUB\knit_server//app\users\kviews\vendor_view.py", line 45, in get_queryset
    profile = Vendor.objects.filter(is_active=True)
  File "C:\ProgramData\Miniconda3\lib\site-packages\django\db\models\manager.py", line 82, in manager_method
    return getattr(self.get_queryset(), name)(*args, **kwargs)
  File "C:\ProgramData\Miniconda3\lib\site-packages\django\db\models\query.py", line 904, in filter
    return self._filter_or_exclude(False, *args, **kwargs)
  File "C:\ProgramData\Miniconda3\lib\site-packages\django\db\models\query.py", line 923, in _filter_or_exclude
    clone.query.add_q(Q(*args, **kwargs))
  File "C:\ProgramData\Miniconda3\lib\site-packages\django\db\models\sql\query.py", line 1340, in add_q
    clause, _ = self._add_q(q_object, self.used_aliases)
  File "C:\ProgramData\Miniconda3\lib\site-packages\django\db\models\sql\query.py", line 1371, in _add_q
    check_filterable=check_filterable,
  File "C:\ProgramData\Miniconda3\lib\site-packages\django\db\models\sql\query.py", line 1240, in build_filter
    lookups, parts, reffed_expression = self.solve_lookup_type(arg)
  File "C:\ProgramData\Miniconda3\lib\site-packages\django\db\models\sql\query.py", line 1077, in solve_lookup_type
    _, field, _, lookup_parts = self.names_to_path(lookup_splitted, self.get_meta())
  File "C:\ProgramData\Miniconda3\lib\site-packages\django\db\models\sql\query.py", line 1473, in names_to_path
    "Choices are: %s" % (name, ", ".join(available)))
django.core.exceptions.FieldError: Cannot resolve keyword 'is_active' into field. Choices are: alternateDays, closeTime, closed, description, doorService, emergency, id, images, isWeekends, masters, name, openTime, user, user_id
 django.request 2020-05-05 19:01:44,904 ERROR    Internal Server Error: /product/maggam-catalogs
Traceback (most recent call last):
  File "C:\ProgramData\Miniconda3\lib\site-packages\django\core\handlers\exception.py", line 34, in inner
    response = get_response(request)
  File "C:\ProgramData\Miniconda3\lib\site-packages\django\core\handlers\base.py", line 115, in _get_response
    response = self.process_exception_by_middleware(e, request)
  File "C:\ProgramData\Miniconda3\lib\site-packages\django\core\handlers\base.py", line 113, in _get_response
    response = wrapped_callback(request, *callback_args, **callback_kwargs)
  File "C:\ProgramData\Miniconda3\lib\site-packages\django\views\decorators\csrf.py", line 54, in wrapped_view
    return view_func(*args, **kwargs)
  File "C:\ProgramData\Miniconda3\lib\site-packages\rest_framework\viewsets.py", line 114, in view
    return self.dispatch(request, *args, **kwargs)
  File "C:\ProgramData\Miniconda3\lib\site-packages\rest_framework\views.py", line 505, in dispatch
    response = self.handle_exception(exc)
  File "C:\ProgramData\Miniconda3\lib\site-packages\rest_framework\views.py", line 465, in handle_exception
    self.raise_uncaught_exception(exc)
  File "C:\ProgramData\Miniconda3\lib\site-packages\rest_framework\views.py", line 476, in raise_uncaught_exception
    raise exc
  File "C:\ProgramData\Miniconda3\lib\site-packages\rest_framework\views.py", line 502, in dispatch
    response = handler(request, *args, **kwargs)
  File "D:\MISC\GITHUB\knit_server//app\products\kviews\maggam_catalog_view.py", line 47, in create
    maggam_catalog_serializer.save()
  File "C:\ProgramData\Miniconda3\lib\site-packages\rest_framework\serializers.py", line 212, in save
    self.instance = self.create(validated_data)
  File "D:\MISC\GITHUB\knit_server//app\products\kserializers\maggam_catalog_serializer.py", line 60, in create
    c_image= image_data[image]
UnboundLocalError: local variable 'image_data' referenced before assignment
 django.request 2020-05-05 19:02:31,327 WARNING  Bad Request: /product/maggam-catalogs
 django.request 2020-05-05 19:02:45,721 ERROR    Internal Server Error: /product/maggam-catalogs
Traceback (most recent call last):
  File "C:\ProgramData\Miniconda3\lib\site-packages\django\core\handlers\exception.py", line 34, in inner
    response = get_response(request)
  File "C:\ProgramData\Miniconda3\lib\site-packages\django\core\handlers\base.py", line 115, in _get_response
    response = self.process_exception_by_middleware(e, request)
  File "C:\ProgramData\Miniconda3\lib\site-packages\django\core\handlers\base.py", line 113, in _get_response
    response = wrapped_callback(request, *callback_args, **callback_kwargs)
  File "C:\ProgramData\Miniconda3\lib\site-packages\django\views\decorators\csrf.py", line 54, in wrapped_view
    return view_func(*args, **kwargs)
  File "C:\ProgramData\Miniconda3\lib\site-packages\rest_framework\viewsets.py", line 114, in view
    return self.dispatch(request, *args, **kwargs)
  File "C:\ProgramData\Miniconda3\lib\site-packages\rest_framework\views.py", line 505, in dispatch
    response = self.handle_exception(exc)
  File "C:\ProgramData\Miniconda3\lib\site-packages\rest_framework\views.py", line 465, in handle_exception
    self.raise_uncaught_exception(exc)
  File "C:\ProgramData\Miniconda3\lib\site-packages\rest_framework\views.py", line 476, in raise_uncaught_exception
    raise exc
  File "C:\ProgramData\Miniconda3\lib\site-packages\rest_framework\views.py", line 502, in dispatch
    response = handler(request, *args, **kwargs)
  File "D:\MISC\GITHUB\knit_server//app\products\kviews\maggam_catalog_view.py", line 47, in create
    maggam_catalog_serializer.save()
  File "C:\ProgramData\Miniconda3\lib\site-packages\rest_framework\serializers.py", line 212, in save
    self.instance = self.create(validated_data)
  File "D:\MISC\GITHUB\knit_server//app\products\kserializers\maggam_catalog_serializer.py", line 60, in create
    c_image= image_data[image]
NameError: name 'image_data' is not defined
 django.request 2020-05-05 19:41:17,244 WARNING  Not Found: /product/csv-ref-tables
 django.request 2020-05-05 20:04:45,305 ERROR    Internal Server Error: /product/maggam-catalogs/1
Traceback (most recent call last):
  File "C:\ProgramData\Miniconda3\lib\site-packages\django\core\handlers\exception.py", line 34, in inner
    response = get_response(request)
  File "C:\ProgramData\Miniconda3\lib\site-packages\django\core\handlers\base.py", line 115, in _get_response
    response = self.process_exception_by_middleware(e, request)
  File "C:\ProgramData\Miniconda3\lib\site-packages\django\core\handlers\base.py", line 113, in _get_response
    response = wrapped_callback(request, *callback_args, **callback_kwargs)
  File "C:\ProgramData\Miniconda3\lib\site-packages\django\views\decorators\csrf.py", line 54, in wrapped_view
    return view_func(*args, **kwargs)
  File "C:\ProgramData\Miniconda3\lib\site-packages\rest_framework\viewsets.py", line 114, in view
    return self.dispatch(request, *args, **kwargs)
  File "C:\ProgramData\Miniconda3\lib\site-packages\rest_framework\views.py", line 505, in dispatch
    response = self.handle_exception(exc)
  File "C:\ProgramData\Miniconda3\lib\site-packages\rest_framework\views.py", line 465, in handle_exception
    self.raise_uncaught_exception(exc)
  File "C:\ProgramData\Miniconda3\lib\site-packages\rest_framework\views.py", line 476, in raise_uncaught_exception
    raise exc
  File "C:\ProgramData\Miniconda3\lib\site-packages\rest_framework\views.py", line 502, in dispatch
    response = handler(request, *args, **kwargs)
  File "C:\ProgramData\Miniconda3\lib\site-packages\rest_framework\mixins.py", line 56, in retrieve
    return Response(serializer.data)
  File "C:\ProgramData\Miniconda3\lib\site-packages\rest_framework\serializers.py", line 562, in data
    ret = super().data
  File "C:\ProgramData\Miniconda3\lib\site-packages\rest_framework\serializers.py", line 260, in data
    self._data = self.to_representation(self.instance)
  File "C:\ProgramData\Miniconda3\lib\site-packages\rest_framework\serializers.py", line 514, in to_representation
    for field in fields:
  File "C:\ProgramData\Miniconda3\lib\site-packages\rest_framework\serializers.py", line 375, in _readable_fields
    for field in self.fields.values():
  File "C:\ProgramData\Miniconda3\lib\site-packages\django\utils\functional.py", line 48, in __get__
    res = instance.__dict__[self.name] = self.func(instance)
  File "C:\ProgramData\Miniconda3\lib\site-packages\rest_framework\serializers.py", line 363, in fields
    for key, value in self.get_fields().items():
  File "C:\ProgramData\Miniconda3\lib\site-packages\rest_framework\serializers.py", line 1038, in get_fields
    field_names = self.get_field_names(declared_fields, info)
  File "C:\ProgramData\Miniconda3\lib\site-packages\rest_framework\serializers.py", line 1139, in get_field_names
    serializer_class=self.__class__.__name__
AssertionError: The field 'category' was declared on serializer MaggamCatalogSerializer, but has not been included in the 'fields' option.
 django.request 2020-05-05 20:09:33,046 WARNING  Method Not Allowed: /product/maggam-catalogs/1
 django.request 2020-05-05 20:14:18,979 WARNING  Not Found: /product/product
 django.request 2020-05-05 20:14:36,243 WARNING  Bad Request: /product/products
 django.request 2020-05-05 20:16:36,458 ERROR    Internal Server Error: /product/products
Traceback (most recent call last):
  File "C:\ProgramData\Miniconda3\lib\site-packages\django\core\handlers\exception.py", line 34, in inner
    response = get_response(request)
  File "C:\ProgramData\Miniconda3\lib\site-packages\django\core\handlers\base.py", line 115, in _get_response
    response = self.process_exception_by_middleware(e, request)
  File "C:\ProgramData\Miniconda3\lib\site-packages\django\core\handlers\base.py", line 113, in _get_response
    response = wrapped_callback(request, *callback_args, **callback_kwargs)
  File "C:\ProgramData\Miniconda3\lib\site-packages\django\views\decorators\csrf.py", line 54, in wrapped_view
    return view_func(*args, **kwargs)
  File "C:\ProgramData\Miniconda3\lib\site-packages\rest_framework\viewsets.py", line 114, in view
    return self.dispatch(request, *args, **kwargs)
  File "C:\ProgramData\Miniconda3\lib\site-packages\rest_framework\views.py", line 505, in dispatch
    response = self.handle_exception(exc)
  File "C:\ProgramData\Miniconda3\lib\site-packages\rest_framework\views.py", line 465, in handle_exception
    self.raise_uncaught_exception(exc)
  File "C:\ProgramData\Miniconda3\lib\site-packages\rest_framework\views.py", line 476, in raise_uncaught_exception
    raise exc
  File "C:\ProgramData\Miniconda3\lib\site-packages\rest_framework\views.py", line 502, in dispatch
    response = handler(request, *args, **kwargs)
  File "C:\ProgramData\Miniconda3\lib\site-packages\rest_framework\mixins.py", line 43, in list
    return self.get_paginated_response(serializer.data)
  File "C:\ProgramData\Miniconda3\lib\site-packages\rest_framework\serializers.py", line 760, in data
    ret = super().data
  File "C:\ProgramData\Miniconda3\lib\site-packages\rest_framework\serializers.py", line 260, in data
    self._data = self.to_representation(self.instance)
  File "C:\ProgramData\Miniconda3\lib\site-packages\rest_framework\serializers.py", line 678, in to_representation
    self.child.to_representation(item) for item in iterable
  File "C:\ProgramData\Miniconda3\lib\site-packages\rest_framework\serializers.py", line 678, in <listcomp>
    self.child.to_representation(item) for item in iterable
  File "C:\ProgramData\Miniconda3\lib\site-packages\rest_framework\serializers.py", line 529, in to_representation
    ret[field.field_name] = field.to_representation(attribute)
  File "C:\ProgramData\Miniconda3\lib\site-packages\rest_framework\fields.py", line 1905, in to_representation
    return method(value)
  File "D:\MISC\GITHUB\knit_server//app\products\kserializers\product_serializer.py", line 46, in get_sub_category
    serializer = SubCategorySerializer(obj.sub_category, many=True)
AttributeError: 'Product' object has no attribute 'sub_category'
 django.request 2020-05-05 20:34:50,673 ERROR    Internal Server Error: /product/products/2
Traceback (most recent call last):
  File "C:\ProgramData\Miniconda3\lib\site-packages\django\core\handlers\exception.py", line 34, in inner
    response = get_response(request)
  File "C:\ProgramData\Miniconda3\lib\site-packages\django\core\handlers\base.py", line 115, in _get_response
    response = self.process_exception_by_middleware(e, request)
  File "C:\ProgramData\Miniconda3\lib\site-packages\django\core\handlers\base.py", line 113, in _get_response
    response = wrapped_callback(request, *callback_args, **callback_kwargs)
  File "C:\ProgramData\Miniconda3\lib\site-packages\django\views\decorators\csrf.py", line 54, in wrapped_view
    return view_func(*args, **kwargs)
  File "C:\ProgramData\Miniconda3\lib\site-packages\rest_framework\viewsets.py", line 114, in view
    return self.dispatch(request, *args, **kwargs)
  File "C:\ProgramData\Miniconda3\lib\site-packages\rest_framework\views.py", line 505, in dispatch
    response = self.handle_exception(exc)
  File "C:\ProgramData\Miniconda3\lib\site-packages\rest_framework\views.py", line 465, in handle_exception
    self.raise_uncaught_exception(exc)
  File "C:\ProgramData\Miniconda3\lib\site-packages\rest_framework\views.py", line 476, in raise_uncaught_exception
    raise exc
  File "C:\ProgramData\Miniconda3\lib\site-packages\rest_framework\views.py", line 502, in dispatch
    response = handler(request, *args, **kwargs)
  File "D:\MISC\GITHUB\knit_server//app\products\kviews\productview.py", line 62, in update
    self.perform_update(serializer)
  File "C:\ProgramData\Miniconda3\lib\site-packages\rest_framework\mixins.py", line 78, in perform_update
    serializer.save()
  File "C:\ProgramData\Miniconda3\lib\site-packages\rest_framework\serializers.py", line 207, in save
    self.instance = self.update(self.instance, validated_data)
  File "D:\MISC\GITHUB\knit_server//app\products\kserializers\product_serializer.py", line 118, in update
    self.setProductRelations(instance, product_relations)
  File "D:\MISC\GITHUB\knit_server//app\products\kserializers\product_serializer.py", line 170, in setProductRelations
    product.colors.set(sub_category)
  File "C:\ProgramData\Miniconda3\lib\site-packages\django\db\models\fields\related_descriptors.py", line 1008, in set
    self.add(*new_objs, through_defaults=through_defaults)
  File "C:\ProgramData\Miniconda3\lib\site-packages\django\db\models\fields\related_descriptors.py", line 946, in add
    through_defaults=through_defaults,
  File "C:\ProgramData\Miniconda3\lib\site-packages\django\db\models\fields\related_descriptors.py", line 1119, in _add_items
    target_ids = self._get_target_ids(target_field_name, objs)
  File "C:\ProgramData\Miniconda3\lib\site-packages\django\db\models\fields\related_descriptors.py", line 1063, in _get_target_ids
    (self.model._meta.object_name, obj)
TypeError: 'ColorModel' instance expected, got <SubCategory: NET_BLOUSE>
 django.request 2020-05-05 20:50:43,060 WARNING  Bad Request: /product/products
 django.request 2020-05-05 20:51:07,037 WARNING  Bad Request: /product/products
 django.request 2020-05-05 20:51:41,454 WARNING  Bad Request: /product/products
 django.request 2020-05-05 20:52:00,765 WARNING  Bad Request: /product/products
 django.request 2020-05-05 20:52:07,163 WARNING  Bad Request: /product/products
 django.request 2020-05-05 20:52:28,930 WARNING  Bad Request: /product/products
 django.request 2020-05-05 20:52:55,527 WARNING  Bad Request: /product/products
 django.request 2020-05-05 21:40:53,272 WARNING  Bad Request: /product/products
 django.request 2020-05-05 21:42:21,957 ERROR    Internal Server Error: /product/products
Traceback (most recent call last):
  File "C:\ProgramData\Miniconda3\lib\site-packages\django\core\handlers\exception.py", line 34, in inner
    response = get_response(request)
  File "C:\ProgramData\Miniconda3\lib\site-packages\django\core\handlers\base.py", line 115, in _get_response
    response = self.process_exception_by_middleware(e, request)
  File "C:\ProgramData\Miniconda3\lib\site-packages\django\core\handlers\base.py", line 113, in _get_response
    response = wrapped_callback(request, *callback_args, **callback_kwargs)
  File "C:\ProgramData\Miniconda3\lib\site-packages\django\views\decorators\csrf.py", line 54, in wrapped_view
    return view_func(*args, **kwargs)
  File "C:\ProgramData\Miniconda3\lib\site-packages\rest_framework\viewsets.py", line 114, in view
    return self.dispatch(request, *args, **kwargs)
  File "C:\ProgramData\Miniconda3\lib\site-packages\rest_framework\views.py", line 505, in dispatch
    response = self.handle_exception(exc)
  File "C:\ProgramData\Miniconda3\lib\site-packages\rest_framework\views.py", line 465, in handle_exception
    self.raise_uncaught_exception(exc)
  File "C:\ProgramData\Miniconda3\lib\site-packages\rest_framework\views.py", line 476, in raise_uncaught_exception
    raise exc
  File "C:\ProgramData\Miniconda3\lib\site-packages\rest_framework\views.py", line 502, in dispatch
    response = handler(request, *args, **kwargs)
  File "D:\MISC\GITHUB\knit_server//app\products\kviews\productview.py", line 46, in create
    product.additional_data['images'] = request.FILES
AttributeError: 'dict' object has no attribute 'additional_data'
 django.request 2020-05-05 21:48:24,721 ERROR    Internal Server Error: /product/products
Traceback (most recent call last):
  File "C:\ProgramData\Miniconda3\lib\site-packages\django\core\handlers\exception.py", line 34, in inner
    response = get_response(request)
  File "C:\ProgramData\Miniconda3\lib\site-packages\django\core\handlers\base.py", line 115, in _get_response
    response = self.process_exception_by_middleware(e, request)
  File "C:\ProgramData\Miniconda3\lib\site-packages\django\core\handlers\base.py", line 113, in _get_response
    response = wrapped_callback(request, *callback_args, **callback_kwargs)
  File "C:\ProgramData\Miniconda3\lib\site-packages\django\views\decorators\csrf.py", line 54, in wrapped_view
    return view_func(*args, **kwargs)
  File "C:\ProgramData\Miniconda3\lib\site-packages\rest_framework\viewsets.py", line 114, in view
    return self.dispatch(request, *args, **kwargs)
  File "C:\ProgramData\Miniconda3\lib\site-packages\rest_framework\views.py", line 505, in dispatch
    response = self.handle_exception(exc)
  File "C:\ProgramData\Miniconda3\lib\site-packages\rest_framework\views.py", line 465, in handle_exception
    self.raise_uncaught_exception(exc)
  File "C:\ProgramData\Miniconda3\lib\site-packages\rest_framework\views.py", line 476, in raise_uncaught_exception
    raise exc
  File "C:\ProgramData\Miniconda3\lib\site-packages\rest_framework\views.py", line 502, in dispatch
    response = handler(request, *args, **kwargs)
  File "D:\MISC\GITHUB\knit_server//app\products\kviews\productview.py", line 52, in create
    product_serializer.save()
  File "C:\ProgramData\Miniconda3\lib\site-packages\rest_framework\serializers.py", line 212, in save
    self.instance = self.create(validated_data)
  File "D:\MISC\GITHUB\knit_server//app\products\kserializers\product_serializer.py", line 102, in create
    self.setProductRelations(product, product_relations)
  File "D:\MISC\GITHUB\knit_server//app\products\kserializers\product_serializer.py", line 133, in setProductRelations
    product.colors.set(col)
  File "C:\ProgramData\Miniconda3\lib\site-packages\django\db\models\fields\related_descriptors.py", line 1008, in set
    self.add(*new_objs, through_defaults=through_defaults)
  File "C:\ProgramData\Miniconda3\lib\site-packages\django\db\models\fields\related_descriptors.py", line 946, in add
    through_defaults=through_defaults,
  File "C:\ProgramData\Miniconda3\lib\site-packages\django\db\models\fields\related_descriptors.py", line 1119, in _add_items
    target_ids = self._get_target_ids(target_field_name, objs)
  File "C:\ProgramData\Miniconda3\lib\site-packages\django\db\models\fields\related_descriptors.py", line 1063, in _get_target_ids
    (self.model._meta.object_name, obj)
TypeError: 'ColorModel' instance expected, got <Category: BLOUSE>
 django.request 2020-05-05 21:52:13,514 ERROR    Internal Server Error: /product/products
Traceback (most recent call last):
  File "C:\ProgramData\Miniconda3\lib\site-packages\django\core\handlers\exception.py", line 34, in inner
    response = get_response(request)
  File "C:\ProgramData\Miniconda3\lib\site-packages\django\core\handlers\base.py", line 115, in _get_response
    response = self.process_exception_by_middleware(e, request)
  File "C:\ProgramData\Miniconda3\lib\site-packages\django\core\handlers\base.py", line 113, in _get_response
    response = wrapped_callback(request, *callback_args, **callback_kwargs)
  File "C:\ProgramData\Miniconda3\lib\site-packages\django\views\decorators\csrf.py", line 54, in wrapped_view
    return view_func(*args, **kwargs)
  File "C:\ProgramData\Miniconda3\lib\site-packages\rest_framework\viewsets.py", line 114, in view
    return self.dispatch(request, *args, **kwargs)
  File "C:\ProgramData\Miniconda3\lib\site-packages\rest_framework\views.py", line 505, in dispatch
    response = self.handle_exception(exc)
  File "C:\ProgramData\Miniconda3\lib\site-packages\rest_framework\views.py", line 465, in handle_exception
    self.raise_uncaught_exception(exc)
  File "C:\ProgramData\Miniconda3\lib\site-packages\rest_framework\views.py", line 476, in raise_uncaught_exception
    raise exc
  File "C:\ProgramData\Miniconda3\lib\site-packages\rest_framework\views.py", line 502, in dispatch
    response = handler(request, *args, **kwargs)
  File "D:\MISC\GITHUB\knit_server//app\products\kviews\productview.py", line 52, in create
    product_serializer.save()
  File "C:\ProgramData\Miniconda3\lib\site-packages\rest_framework\serializers.py", line 212, in save
    self.instance = self.create(validated_data)
  File "D:\MISC\GITHUB\knit_server//app\products\kserializers\product_serializer.py", line 103, in create
    self.setProductRelations(product, product_relations)
  File "D:\MISC\GITHUB\knit_server//app\products\kserializers\product_serializer.py", line 170, in setProductRelations
    c_image= image_data[image]
NameError: name 'image_data' is not defined
 django.request 2020-05-05 21:52:57,325 ERROR    Internal Server Error: /product/products
Traceback (most recent call last):
  File "C:\ProgramData\Miniconda3\lib\site-packages\django\core\handlers\exception.py", line 34, in inner
    response = get_response(request)
  File "C:\ProgramData\Miniconda3\lib\site-packages\django\core\handlers\base.py", line 115, in _get_response
    response = self.process_exception_by_middleware(e, request)
  File "C:\ProgramData\Miniconda3\lib\site-packages\django\core\handlers\base.py", line 113, in _get_response
    response = wrapped_callback(request, *callback_args, **callback_kwargs)
  File "C:\ProgramData\Miniconda3\lib\site-packages\django\views\decorators\csrf.py", line 54, in wrapped_view
    return view_func(*args, **kwargs)
  File "C:\ProgramData\Miniconda3\lib\site-packages\rest_framework\viewsets.py", line 114, in view
    return self.dispatch(request, *args, **kwargs)
  File "C:\ProgramData\Miniconda3\lib\site-packages\rest_framework\views.py", line 505, in dispatch
    response = self.handle_exception(exc)
  File "C:\ProgramData\Miniconda3\lib\site-packages\rest_framework\views.py", line 465, in handle_exception
    self.raise_uncaught_exception(exc)
  File "C:\ProgramData\Miniconda3\lib\site-packages\rest_framework\views.py", line 476, in raise_uncaught_exception
    raise exc
  File "C:\ProgramData\Miniconda3\lib\site-packages\rest_framework\views.py", line 502, in dispatch
    response = handler(request, *args, **kwargs)
  File "D:\MISC\GITHUB\knit_server//app\products\kviews\productview.py", line 52, in create
    product_serializer.save()
  File "C:\ProgramData\Miniconda3\lib\site-packages\rest_framework\serializers.py", line 212, in save
    self.instance = self.create(validated_data)
  File "D:\MISC\GITHUB\knit_server//app\products\kserializers\product_serializer.py", line 103, in create
    self.setProductRelations(product, product_relations)
  File "D:\MISC\GITHUB\knit_server//app\products\kserializers\product_serializer.py", line 183, in setProductRelations
    instance.category.set(catalog)
NameError: name 'instance' is not defined
 django.request 2020-05-05 22:18:06,337 WARNING  Bad Request: /product/fashion-catalogs
 django.request 2020-05-05 22:23:50,643 WARNING  Not Found: /product/fashion-catalog
 django.request 2020-05-05 22:25:13,783 WARNING  Bad Request: /product/fashion-catalogs
 django.request 2020-05-05 22:26:57,353 WARNING  Not Found: //media/images/fashion_catalogs/fashion_2/3_broad_flared_lehenga.png
 django.request 2020-05-05 22:28:35,613 WARNING  Method Not Allowed: /product/fashion-catalogs/2
 django.request 2020-05-05 22:35:41,653 WARNING  Bad Request: /product/fashion-catalogs/1
 django.request 2020-05-05 22:38:52,238 WARNING  Bad Request: /product/fashion-catalogs/1
 django.request 2020-05-05 22:39:19,038 WARNING  Bad Request: /product/fashion-catalogs/1
 django.request 2020-05-06 20:38:36,101 ERROR    Internal Server Error: /user/vendors
Traceback (most recent call last):
  File "C:\ProgramData\Miniconda3\lib\site-packages\django\core\handlers\exception.py", line 34, in inner
    response = get_response(request)
  File "C:\ProgramData\Miniconda3\lib\site-packages\django\core\handlers\base.py", line 115, in _get_response
    response = self.process_exception_by_middleware(e, request)
  File "C:\ProgramData\Miniconda3\lib\site-packages\django\core\handlers\base.py", line 113, in _get_response
    response = wrapped_callback(request, *callback_args, **callback_kwargs)
  File "C:\ProgramData\Miniconda3\lib\site-packages\django\views\decorators\csrf.py", line 54, in wrapped_view
    return view_func(*args, **kwargs)
  File "C:\ProgramData\Miniconda3\lib\site-packages\rest_framework\viewsets.py", line 114, in view
    return self.dispatch(request, *args, **kwargs)
  File "C:\ProgramData\Miniconda3\lib\site-packages\rest_framework\views.py", line 505, in dispatch
    response = self.handle_exception(exc)
  File "C:\ProgramData\Miniconda3\lib\site-packages\rest_framework\views.py", line 465, in handle_exception
    self.raise_uncaught_exception(exc)
  File "C:\ProgramData\Miniconda3\lib\site-packages\rest_framework\views.py", line 476, in raise_uncaught_exception
    raise exc
  File "C:\ProgramData\Miniconda3\lib\site-packages\rest_framework\views.py", line 502, in dispatch
    response = handler(request, *args, **kwargs)
  File "C:\ProgramData\Miniconda3\lib\site-packages\rest_framework\mixins.py", line 38, in list
    queryset = self.filter_queryset(self.get_queryset())
  File "C:\ProgramData\Miniconda3\lib\site-packages\rest_framework\generics.py", line 150, in filter_queryset
    queryset = backend().filter_queryset(self.request, queryset, self)
  File "C:\ProgramData\Miniconda3\lib\site-packages\url_filter\integrations\drf.py", line 143, in filter_queryset
    filter_class = self.get_filter_class(view, queryset)
  File "C:\ProgramData\Miniconda3\lib\site-packages\url_filter\integrations\drf.py", line 94, in get_filter_class
    model = filter_class_default.filter_backend_class(queryset).get_model()
  File "C:\ProgramData\Miniconda3\lib\site-packages\url_filter\backends\django.py", line 60, in get_model
    return self.queryset.model
AttributeError: 'ListSerializer' object has no attribute 'model'
 django.request 2020-05-06 20:38:36,358 WARNING  Not Found: /favicon.ico
 django.request 2020-05-06 20:42:40,984 ERROR    Internal Server Error: /user/vendors
Traceback (most recent call last):
  File "C:\ProgramData\Miniconda3\lib\site-packages\django\db\backends\utils.py", line 86, in _execute
    return self.cursor.execute(sql, params)
  File "C:\ProgramData\Miniconda3\lib\site-packages\django\db\backends\mysql\base.py", line 74, in execute
    return self.cursor.execute(query, args)
  File "C:\ProgramData\Miniconda3\lib\site-packages\MySQLdb\cursors.py", line 209, in execute
    res = self._query(query)
  File "C:\ProgramData\Miniconda3\lib\site-packages\MySQLdb\cursors.py", line 315, in _query
    db.query(q)
  File "C:\ProgramData\Miniconda3\lib\site-packages\MySQLdb\connections.py", line 239, in query
    _mysql.connection.query(self, query)
MySQLdb._exceptions.OperationalError: (1054, "Unknown column 'latitude' in 'field list'")

The above exception was the direct cause of the following exception:

Traceback (most recent call last):
  File "C:\ProgramData\Miniconda3\lib\site-packages\django\core\handlers\exception.py", line 34, in inner
    response = get_response(request)
  File "C:\ProgramData\Miniconda3\lib\site-packages\django\core\handlers\base.py", line 115, in _get_response
    response = self.process_exception_by_middleware(e, request)
  File "C:\ProgramData\Miniconda3\lib\site-packages\django\core\handlers\base.py", line 113, in _get_response
    response = wrapped_callback(request, *callback_args, **callback_kwargs)
  File "C:\ProgramData\Miniconda3\lib\site-packages\django\views\decorators\csrf.py", line 54, in wrapped_view
    return view_func(*args, **kwargs)
  File "C:\ProgramData\Miniconda3\lib\site-packages\rest_framework\viewsets.py", line 114, in view
    return self.dispatch(request, *args, **kwargs)
  File "C:\ProgramData\Miniconda3\lib\site-packages\rest_framework\views.py", line 505, in dispatch
    response = self.handle_exception(exc)
  File "C:\ProgramData\Miniconda3\lib\site-packages\rest_framework\views.py", line 465, in handle_exception
    self.raise_uncaught_exception(exc)
  File "C:\ProgramData\Miniconda3\lib\site-packages\rest_framework\views.py", line 476, in raise_uncaught_exception
    raise exc
  File "C:\ProgramData\Miniconda3\lib\site-packages\rest_framework\views.py", line 502, in dispatch
    response = handler(request, *args, **kwargs)
  File "C:\ProgramData\Miniconda3\lib\site-packages\rest_framework\mixins.py", line 40, in list
    page = self.paginate_queryset(queryset)
  File "C:\ProgramData\Miniconda3\lib\site-packages\rest_framework\generics.py", line 171, in paginate_queryset
    return self.paginator.paginate_queryset(queryset, self.request, view=self)
  File "C:\ProgramData\Miniconda3\lib\site-packages\rest_framework\pagination.py", line 206, in paginate_queryset
    self.page = paginator.page(page_number)
  File "C:\ProgramData\Miniconda3\lib\site-packages\django\core\paginator.py", line 70, in page
    number = self.validate_number(number)
  File "C:\ProgramData\Miniconda3\lib\site-packages\django\core\paginator.py", line 48, in validate_number
    if number > self.num_pages:
  File "C:\ProgramData\Miniconda3\lib\site-packages\django\utils\functional.py", line 48, in __get__
    res = instance.__dict__[self.name] = self.func(instance)
  File "C:\ProgramData\Miniconda3\lib\site-packages\django\core\paginator.py", line 97, in num_pages
    if self.count == 0 and not self.allow_empty_first_page:
  File "C:\ProgramData\Miniconda3\lib\site-packages\django\utils\functional.py", line 48, in __get__
    res = instance.__dict__[self.name] = self.func(instance)
  File "C:\ProgramData\Miniconda3\lib\site-packages\django\core\paginator.py", line 92, in count
    return len(self.object_list)
  File "C:\ProgramData\Miniconda3\lib\site-packages\django\db\models\query.py", line 1413, in __len__
    self._fetch_all()
  File "C:\ProgramData\Miniconda3\lib\site-packages\django\db\models\query.py", line 1408, in _fetch_all
    self._result_cache = list(self.iterator())
  File "C:\ProgramData\Miniconda3\lib\site-packages\django\db\models\query.py", line 1431, in iterator
    query = iter(self.query)
  File "C:\ProgramData\Miniconda3\lib\site-packages\django\db\models\sql\query.py", line 109, in __iter__
    self._execute_query()
  File "C:\ProgramData\Miniconda3\lib\site-packages\django\db\models\sql\query.py", line 143, in _execute_query
    self.cursor.execute(self.sql, params)
  File "C:\ProgramData\Miniconda3\lib\site-packages\django\db\backends\utils.py", line 100, in execute
    return super().execute(sql, params)
  File "C:\ProgramData\Miniconda3\lib\site-packages\django\db\backends\utils.py", line 68, in execute
    return self._execute_with_wrappers(sql, params, many=False, executor=self._execute)
  File "C:\ProgramData\Miniconda3\lib\site-packages\django\db\backends\utils.py", line 77, in _execute_with_wrappers
    return executor(sql, params, many, context)
  File "C:\ProgramData\Miniconda3\lib\site-packages\django\db\backends\utils.py", line 86, in _execute
    return self.cursor.execute(sql, params)
  File "C:\ProgramData\Miniconda3\lib\site-packages\django\db\utils.py", line 90, in __exit__
    raise dj_exc_value.with_traceback(traceback) from exc_value
  File "C:\ProgramData\Miniconda3\lib\site-packages\django\db\backends\utils.py", line 86, in _execute
    return self.cursor.execute(sql, params)
  File "C:\ProgramData\Miniconda3\lib\site-packages\django\db\backends\mysql\base.py", line 74, in execute
    return self.cursor.execute(query, args)
  File "C:\ProgramData\Miniconda3\lib\site-packages\MySQLdb\cursors.py", line 209, in execute
    res = self._query(query)
  File "C:\ProgramData\Miniconda3\lib\site-packages\MySQLdb\cursors.py", line 315, in _query
    db.query(q)
  File "C:\ProgramData\Miniconda3\lib\site-packages\MySQLdb\connections.py", line 239, in query
    _mysql.connection.query(self, query)
django.db.utils.OperationalError: (1054, "Unknown column 'latitude' in 'field list'")
 django.request 2020-05-06 20:49:47,368 ERROR    Internal Server Error: /user/address
Traceback (most recent call last):
  File "C:\ProgramData\Miniconda3\lib\site-packages\django\core\handlers\exception.py", line 34, in inner
    response = get_response(request)
  File "C:\ProgramData\Miniconda3\lib\site-packages\django\core\handlers\base.py", line 115, in _get_response
    response = self.process_exception_by_middleware(e, request)
  File "C:\ProgramData\Miniconda3\lib\site-packages\django\core\handlers\base.py", line 113, in _get_response
    response = wrapped_callback(request, *callback_args, **callback_kwargs)
  File "C:\ProgramData\Miniconda3\lib\site-packages\django\views\decorators\csrf.py", line 54, in wrapped_view
    return view_func(*args, **kwargs)
  File "C:\ProgramData\Miniconda3\lib\site-packages\rest_framework\viewsets.py", line 114, in view
    return self.dispatch(request, *args, **kwargs)
  File "C:\ProgramData\Miniconda3\lib\site-packages\rest_framework\views.py", line 505, in dispatch
    response = self.handle_exception(exc)
  File "C:\ProgramData\Miniconda3\lib\site-packages\rest_framework\views.py", line 465, in handle_exception
    self.raise_uncaught_exception(exc)
  File "C:\ProgramData\Miniconda3\lib\site-packages\rest_framework\views.py", line 476, in raise_uncaught_exception
    raise exc
  File "C:\ProgramData\Miniconda3\lib\site-packages\rest_framework\views.py", line 502, in dispatch
    response = handler(request, *args, **kwargs)
  File "C:\ProgramData\Miniconda3\lib\site-packages\rest_framework\mixins.py", line 38, in list
    queryset = self.filter_queryset(self.get_queryset())
  File "D:\MISC\GITHUB\knit_server//app\users\kviews\address_view.py", line 55, in get_queryset
    queryset = Vendor.objects.raw(query)
NameError: name 'Vendor' is not defined
 django.request 2020-05-06 20:50:05,260 ERROR    Internal Server Error: /user/address
Traceback (most recent call last):
  File "C:\ProgramData\Miniconda3\lib\site-packages\django\core\handlers\exception.py", line 34, in inner
    response = get_response(request)
  File "C:\ProgramData\Miniconda3\lib\site-packages\django\core\handlers\base.py", line 115, in _get_response
    response = self.process_exception_by_middleware(e, request)
  File "C:\ProgramData\Miniconda3\lib\site-packages\django\core\handlers\base.py", line 113, in _get_response
    response = wrapped_callback(request, *callback_args, **callback_kwargs)
  File "C:\ProgramData\Miniconda3\lib\site-packages\django\views\decorators\csrf.py", line 54, in wrapped_view
    return view_func(*args, **kwargs)
  File "C:\ProgramData\Miniconda3\lib\site-packages\rest_framework\viewsets.py", line 114, in view
    return self.dispatch(request, *args, **kwargs)
  File "C:\ProgramData\Miniconda3\lib\site-packages\rest_framework\views.py", line 505, in dispatch
    response = self.handle_exception(exc)
  File "C:\ProgramData\Miniconda3\lib\site-packages\rest_framework\views.py", line 465, in handle_exception
    self.raise_uncaught_exception(exc)
  File "C:\ProgramData\Miniconda3\lib\site-packages\rest_framework\views.py", line 476, in raise_uncaught_exception
    raise exc
  File "C:\ProgramData\Miniconda3\lib\site-packages\rest_framework\views.py", line 502, in dispatch
    response = handler(request, *args, **kwargs)
  File "C:\ProgramData\Miniconda3\lib\site-packages\rest_framework\mixins.py", line 43, in list
    return self.get_paginated_response(serializer.data)
  File "C:\ProgramData\Miniconda3\lib\site-packages\rest_framework\serializers.py", line 760, in data
    ret = super().data
  File "C:\ProgramData\Miniconda3\lib\site-packages\rest_framework\serializers.py", line 260, in data
    self._data = self.to_representation(self.instance)
  File "C:\ProgramData\Miniconda3\lib\site-packages\rest_framework\serializers.py", line 678, in to_representation
    self.child.to_representation(item) for item in iterable
  File "C:\ProgramData\Miniconda3\lib\site-packages\rest_framework\serializers.py", line 678, in <listcomp>
    self.child.to_representation(item) for item in iterable
  File "C:\ProgramData\Miniconda3\lib\site-packages\rest_framework\serializers.py", line 516, in to_representation
    attribute = field.get_attribute(instance)
  File "C:\ProgramData\Miniconda3\lib\site-packages\rest_framework\fields.py", line 454, in get_attribute
    return get_attribute(instance, self.source_attrs)
  File "C:\ProgramData\Miniconda3\lib\site-packages\rest_framework\fields.py", line 99, in get_attribute
    instance = instance()
  File "D:\MISC\GITHUB\knit_server//app\users\kmodels\address_model.py", line 25, in get_full_address
    address_line += self.house_name if self.house_name else ""
  File "C:\ProgramData\Miniconda3\lib\site-packages\django\db\models\query_utils.py", line 139, in __get__
    instance.refresh_from_db(fields=[field_name])
  File "C:\ProgramData\Miniconda3\lib\site-packages\django\db\models\base.py", line 627, in refresh_from_db
    db_instance = db_instance_qs.get()
  File "C:\ProgramData\Miniconda3\lib\site-packages\django\db\models\query.py", line 417, in get
    self.model._meta.object_name
users.kmodels.address_model.Address.DoesNotExist: Address matching query does not exist.
 django.request 2020-05-06 20:50:16,811 ERROR    Internal Server Error: /user/address
Traceback (most recent call last):
  File "C:\ProgramData\Miniconda3\lib\site-packages\django\core\handlers\exception.py", line 34, in inner
    response = get_response(request)
  File "C:\ProgramData\Miniconda3\lib\site-packages\django\core\handlers\base.py", line 115, in _get_response
    response = self.process_exception_by_middleware(e, request)
  File "C:\ProgramData\Miniconda3\lib\site-packages\django\core\handlers\base.py", line 113, in _get_response
    response = wrapped_callback(request, *callback_args, **callback_kwargs)
  File "C:\ProgramData\Miniconda3\lib\site-packages\django\views\decorators\csrf.py", line 54, in wrapped_view
    return view_func(*args, **kwargs)
  File "C:\ProgramData\Miniconda3\lib\site-packages\rest_framework\viewsets.py", line 114, in view
    return self.dispatch(request, *args, **kwargs)
  File "C:\ProgramData\Miniconda3\lib\site-packages\rest_framework\views.py", line 505, in dispatch
    response = self.handle_exception(exc)
  File "C:\ProgramData\Miniconda3\lib\site-packages\rest_framework\views.py", line 465, in handle_exception
    self.raise_uncaught_exception(exc)
  File "C:\ProgramData\Miniconda3\lib\site-packages\rest_framework\views.py", line 476, in raise_uncaught_exception
    raise exc
  File "C:\ProgramData\Miniconda3\lib\site-packages\rest_framework\views.py", line 502, in dispatch
    response = handler(request, *args, **kwargs)
  File "C:\ProgramData\Miniconda3\lib\site-packages\rest_framework\mixins.py", line 43, in list
    return self.get_paginated_response(serializer.data)
  File "C:\ProgramData\Miniconda3\lib\site-packages\rest_framework\serializers.py", line 760, in data
    ret = super().data
  File "C:\ProgramData\Miniconda3\lib\site-packages\rest_framework\serializers.py", line 260, in data
    self._data = self.to_representation(self.instance)
  File "C:\ProgramData\Miniconda3\lib\site-packages\rest_framework\serializers.py", line 678, in to_representation
    self.child.to_representation(item) for item in iterable
  File "C:\ProgramData\Miniconda3\lib\site-packages\rest_framework\serializers.py", line 678, in <listcomp>
    self.child.to_representation(item) for item in iterable
  File "C:\ProgramData\Miniconda3\lib\site-packages\rest_framework\serializers.py", line 516, in to_representation
    attribute = field.get_attribute(instance)
  File "C:\ProgramData\Miniconda3\lib\site-packages\rest_framework\fields.py", line 454, in get_attribute
    return get_attribute(instance, self.source_attrs)
  File "C:\ProgramData\Miniconda3\lib\site-packages\rest_framework\fields.py", line 99, in get_attribute
    instance = instance()
  File "D:\MISC\GITHUB\knit_server//app\users\kmodels\address_model.py", line 25, in get_full_address
    address_line += self.house_name if self.house_name else ""
  File "C:\ProgramData\Miniconda3\lib\site-packages\django\db\models\query_utils.py", line 139, in __get__
    instance.refresh_from_db(fields=[field_name])
  File "C:\ProgramData\Miniconda3\lib\site-packages\django\db\models\base.py", line 627, in refresh_from_db
    db_instance = db_instance_qs.get()
  File "C:\ProgramData\Miniconda3\lib\site-packages\django\db\models\query.py", line 417, in get
    self.model._meta.object_name
users.kmodels.address_model.Address.DoesNotExist: Address matching query does not exist.
 django.request 2020-05-06 20:51:03,124 ERROR    Internal Server Error: /user/address
Traceback (most recent call last):
  File "C:\ProgramData\Miniconda3\lib\site-packages\django\core\handlers\exception.py", line 34, in inner
    response = get_response(request)
  File "C:\ProgramData\Miniconda3\lib\site-packages\django\core\handlers\base.py", line 115, in _get_response
    response = self.process_exception_by_middleware(e, request)
  File "C:\ProgramData\Miniconda3\lib\site-packages\django\core\handlers\base.py", line 113, in _get_response
    response = wrapped_callback(request, *callback_args, **callback_kwargs)
  File "C:\ProgramData\Miniconda3\lib\site-packages\django\views\decorators\csrf.py", line 54, in wrapped_view
    return view_func(*args, **kwargs)
  File "C:\ProgramData\Miniconda3\lib\site-packages\rest_framework\viewsets.py", line 114, in view
    return self.dispatch(request, *args, **kwargs)
  File "C:\ProgramData\Miniconda3\lib\site-packages\rest_framework\views.py", line 505, in dispatch
    response = self.handle_exception(exc)
  File "C:\ProgramData\Miniconda3\lib\site-packages\rest_framework\views.py", line 465, in handle_exception
    self.raise_uncaught_exception(exc)
  File "C:\ProgramData\Miniconda3\lib\site-packages\rest_framework\views.py", line 476, in raise_uncaught_exception
    raise exc
  File "C:\ProgramData\Miniconda3\lib\site-packages\rest_framework\views.py", line 502, in dispatch
    response = handler(request, *args, **kwargs)
  File "C:\ProgramData\Miniconda3\lib\site-packages\rest_framework\mixins.py", line 43, in list
    return self.get_paginated_response(serializer.data)
  File "C:\ProgramData\Miniconda3\lib\site-packages\rest_framework\serializers.py", line 760, in data
    ret = super().data
  File "C:\ProgramData\Miniconda3\lib\site-packages\rest_framework\serializers.py", line 260, in data
    self._data = self.to_representation(self.instance)
  File "C:\ProgramData\Miniconda3\lib\site-packages\rest_framework\serializers.py", line 678, in to_representation
    self.child.to_representation(item) for item in iterable
  File "C:\ProgramData\Miniconda3\lib\site-packages\rest_framework\serializers.py", line 678, in <listcomp>
    self.child.to_representation(item) for item in iterable
  File "C:\ProgramData\Miniconda3\lib\site-packages\rest_framework\serializers.py", line 516, in to_representation
    attribute = field.get_attribute(instance)
  File "C:\ProgramData\Miniconda3\lib\site-packages\rest_framework\fields.py", line 454, in get_attribute
    return get_attribute(instance, self.source_attrs)
  File "C:\ProgramData\Miniconda3\lib\site-packages\rest_framework\fields.py", line 99, in get_attribute
    instance = instance()
  File "D:\MISC\GITHUB\knit_server//app\users\kmodels\address_model.py", line 25, in get_full_address
    address_line += self.house_name if self.house_name else ""
  File "C:\ProgramData\Miniconda3\lib\site-packages\django\db\models\query_utils.py", line 139, in __get__
    instance.refresh_from_db(fields=[field_name])
  File "C:\ProgramData\Miniconda3\lib\site-packages\django\db\models\base.py", line 627, in refresh_from_db
    db_instance = db_instance_qs.get()
  File "C:\ProgramData\Miniconda3\lib\site-packages\django\db\models\query.py", line 417, in get
    self.model._meta.object_name
users.kmodels.address_model.Address.DoesNotExist: Address matching query does not exist.
 django.request 2020-05-06 20:51:50,525 ERROR    Internal Server Error: /user/address
Traceback (most recent call last):
  File "C:\ProgramData\Miniconda3\lib\site-packages\django\core\handlers\exception.py", line 34, in inner
    response = get_response(request)
  File "C:\ProgramData\Miniconda3\lib\site-packages\django\core\handlers\base.py", line 115, in _get_response
    response = self.process_exception_by_middleware(e, request)
  File "C:\ProgramData\Miniconda3\lib\site-packages\django\core\handlers\base.py", line 113, in _get_response
    response = wrapped_callback(request, *callback_args, **callback_kwargs)
  File "C:\ProgramData\Miniconda3\lib\site-packages\django\views\decorators\csrf.py", line 54, in wrapped_view
    return view_func(*args, **kwargs)
  File "C:\ProgramData\Miniconda3\lib\site-packages\rest_framework\viewsets.py", line 114, in view
    return self.dispatch(request, *args, **kwargs)
  File "C:\ProgramData\Miniconda3\lib\site-packages\rest_framework\views.py", line 505, in dispatch
    response = self.handle_exception(exc)
  File "C:\ProgramData\Miniconda3\lib\site-packages\rest_framework\views.py", line 465, in handle_exception
    self.raise_uncaught_exception(exc)
  File "C:\ProgramData\Miniconda3\lib\site-packages\rest_framework\views.py", line 476, in raise_uncaught_exception
    raise exc
  File "C:\ProgramData\Miniconda3\lib\site-packages\rest_framework\views.py", line 502, in dispatch
    response = handler(request, *args, **kwargs)
  File "C:\ProgramData\Miniconda3\lib\site-packages\rest_framework\mixins.py", line 43, in list
    return self.get_paginated_response(serializer.data)
  File "C:\ProgramData\Miniconda3\lib\site-packages\rest_framework\serializers.py", line 760, in data
    ret = super().data
  File "C:\ProgramData\Miniconda3\lib\site-packages\rest_framework\serializers.py", line 260, in data
    self._data = self.to_representation(self.instance)
  File "C:\ProgramData\Miniconda3\lib\site-packages\rest_framework\serializers.py", line 678, in to_representation
    self.child.to_representation(item) for item in iterable
  File "C:\ProgramData\Miniconda3\lib\site-packages\rest_framework\serializers.py", line 678, in <listcomp>
    self.child.to_representation(item) for item in iterable
  File "C:\ProgramData\Miniconda3\lib\site-packages\rest_framework\serializers.py", line 516, in to_representation
    attribute = field.get_attribute(instance)
  File "C:\ProgramData\Miniconda3\lib\site-packages\rest_framework\fields.py", line 454, in get_attribute
    return get_attribute(instance, self.source_attrs)
  File "C:\ProgramData\Miniconda3\lib\site-packages\rest_framework\fields.py", line 99, in get_attribute
    instance = instance()
  File "D:\MISC\GITHUB\knit_server//app\users\kmodels\address_model.py", line 25, in get_full_address
    address_line += self.house_name if self.house_name else ""
  File "C:\ProgramData\Miniconda3\lib\site-packages\django\db\models\query_utils.py", line 139, in __get__
    instance.refresh_from_db(fields=[field_name])
  File "C:\ProgramData\Miniconda3\lib\site-packages\django\db\models\base.py", line 627, in refresh_from_db
    db_instance = db_instance_qs.get()
  File "C:\ProgramData\Miniconda3\lib\site-packages\django\db\models\query.py", line 417, in get
    self.model._meta.object_name
users.kmodels.address_model.Address.DoesNotExist: Address matching query does not exist.
 django.request 2020-05-06 20:54:22,790 ERROR    Internal Server Error: /user/address
Traceback (most recent call last):
  File "C:\ProgramData\Miniconda3\lib\site-packages\django\db\backends\utils.py", line 86, in _execute
    return self.cursor.execute(sql, params)
  File "C:\ProgramData\Miniconda3\lib\site-packages\django\db\backends\mysql\base.py", line 74, in execute
    return self.cursor.execute(query, args)
  File "C:\ProgramData\Miniconda3\lib\site-packages\MySQLdb\cursors.py", line 209, in execute
    res = self._query(query)
  File "C:\ProgramData\Miniconda3\lib\site-packages\MySQLdb\cursors.py", line 315, in _query
    db.query(q)
  File "C:\ProgramData\Miniconda3\lib\site-packages\MySQLdb\connections.py", line 239, in query
    _mysql.connection.query(self, query)
MySQLdb._exceptions.ProgrammingError: (1064, "You have an error in your SQL syntax; check the manual that corresponds to your MySQL server version for the right syntax to use near '* FROM knit_user_profile HAVING\n                distance < 0.001000 ORDER BY dis' at line 4")

The above exception was the direct cause of the following exception:

Traceback (most recent call last):
  File "C:\ProgramData\Miniconda3\lib\site-packages\django\core\handlers\exception.py", line 34, in inner
    response = get_response(request)
  File "C:\ProgramData\Miniconda3\lib\site-packages\django\core\handlers\base.py", line 115, in _get_response
    response = self.process_exception_by_middleware(e, request)
  File "C:\ProgramData\Miniconda3\lib\site-packages\django\core\handlers\base.py", line 113, in _get_response
    response = wrapped_callback(request, *callback_args, **callback_kwargs)
  File "C:\ProgramData\Miniconda3\lib\site-packages\django\views\decorators\csrf.py", line 54, in wrapped_view
    return view_func(*args, **kwargs)
  File "C:\ProgramData\Miniconda3\lib\site-packages\rest_framework\viewsets.py", line 114, in view
    return self.dispatch(request, *args, **kwargs)
  File "C:\ProgramData\Miniconda3\lib\site-packages\rest_framework\views.py", line 505, in dispatch
    response = self.handle_exception(exc)
  File "C:\ProgramData\Miniconda3\lib\site-packages\rest_framework\views.py", line 465, in handle_exception
    self.raise_uncaught_exception(exc)
  File "C:\ProgramData\Miniconda3\lib\site-packages\rest_framework\views.py", line 476, in raise_uncaught_exception
    raise exc
  File "C:\ProgramData\Miniconda3\lib\site-packages\rest_framework\views.py", line 502, in dispatch
    response = handler(request, *args, **kwargs)
  File "C:\ProgramData\Miniconda3\lib\site-packages\rest_framework\mixins.py", line 40, in list
    page = self.paginate_queryset(queryset)
  File "C:\ProgramData\Miniconda3\lib\site-packages\rest_framework\generics.py", line 171, in paginate_queryset
    return self.paginator.paginate_queryset(queryset, self.request, view=self)
  File "C:\ProgramData\Miniconda3\lib\site-packages\rest_framework\pagination.py", line 206, in paginate_queryset
    self.page = paginator.page(page_number)
  File "C:\ProgramData\Miniconda3\lib\site-packages\django\core\paginator.py", line 70, in page
    number = self.validate_number(number)
  File "C:\ProgramData\Miniconda3\lib\site-packages\django\core\paginator.py", line 48, in validate_number
    if number > self.num_pages:
  File "C:\ProgramData\Miniconda3\lib\site-packages\django\utils\functional.py", line 48, in __get__
    res = instance.__dict__[self.name] = self.func(instance)
  File "C:\ProgramData\Miniconda3\lib\site-packages\django\core\paginator.py", line 97, in num_pages
    if self.count == 0 and not self.allow_empty_first_page:
  File "C:\ProgramData\Miniconda3\lib\site-packages\django\utils\functional.py", line 48, in __get__
    res = instance.__dict__[self.name] = self.func(instance)
  File "C:\ProgramData\Miniconda3\lib\site-packages\django\core\paginator.py", line 92, in count
    return len(self.object_list)
  File "C:\ProgramData\Miniconda3\lib\site-packages\django\db\models\query.py", line 1413, in __len__
    self._fetch_all()
  File "C:\ProgramData\Miniconda3\lib\site-packages\django\db\models\query.py", line 1408, in _fetch_all
    self._result_cache = list(self.iterator())
  File "C:\ProgramData\Miniconda3\lib\site-packages\django\db\models\query.py", line 1431, in iterator
    query = iter(self.query)
  File "C:\ProgramData\Miniconda3\lib\site-packages\django\db\models\sql\query.py", line 109, in __iter__
    self._execute_query()
  File "C:\ProgramData\Miniconda3\lib\site-packages\django\db\models\sql\query.py", line 143, in _execute_query
    self.cursor.execute(self.sql, params)
  File "C:\ProgramData\Miniconda3\lib\site-packages\django\db\backends\utils.py", line 100, in execute
    return super().execute(sql, params)
  File "C:\ProgramData\Miniconda3\lib\site-packages\django\db\backends\utils.py", line 68, in execute
    return self._execute_with_wrappers(sql, params, many=False, executor=self._execute)
  File "C:\ProgramData\Miniconda3\lib\site-packages\django\db\backends\utils.py", line 77, in _execute_with_wrappers
    return executor(sql, params, many, context)
  File "C:\ProgramData\Miniconda3\lib\site-packages\django\db\backends\utils.py", line 86, in _execute
    return self.cursor.execute(sql, params)
  File "C:\ProgramData\Miniconda3\lib\site-packages\django\db\utils.py", line 90, in __exit__
    raise dj_exc_value.with_traceback(traceback) from exc_value
  File "C:\ProgramData\Miniconda3\lib\site-packages\django\db\backends\utils.py", line 86, in _execute
    return self.cursor.execute(sql, params)
  File "C:\ProgramData\Miniconda3\lib\site-packages\django\db\backends\mysql\base.py", line 74, in execute
    return self.cursor.execute(query, args)
  File "C:\ProgramData\Miniconda3\lib\site-packages\MySQLdb\cursors.py", line 209, in execute
    res = self._query(query)
  File "C:\ProgramData\Miniconda3\lib\site-packages\MySQLdb\cursors.py", line 315, in _query
    db.query(q)
  File "C:\ProgramData\Miniconda3\lib\site-packages\MySQLdb\connections.py", line 239, in query
    _mysql.connection.query(self, query)
django.db.utils.ProgrammingError: (1064, "You have an error in your SQL syntax; check the manual that corresponds to your MySQL server version for the right syntax to use near '* FROM knit_user_profile HAVING\n                distance < 0.001000 ORDER BY dis' at line 4")
 django.request 2020-05-06 21:00:14,377 ERROR    Internal Server Error: /user/address
Traceback (most recent call last):
  File "C:\ProgramData\Miniconda3\lib\site-packages\django\core\handlers\exception.py", line 34, in inner
    response = get_response(request)
  File "C:\ProgramData\Miniconda3\lib\site-packages\django\core\handlers\base.py", line 115, in _get_response
    response = self.process_exception_by_middleware(e, request)
  File "C:\ProgramData\Miniconda3\lib\site-packages\django\core\handlers\base.py", line 113, in _get_response
    response = wrapped_callback(request, *callback_args, **callback_kwargs)
  File "C:\ProgramData\Miniconda3\lib\site-packages\django\views\decorators\csrf.py", line 54, in wrapped_view
    return view_func(*args, **kwargs)
  File "C:\ProgramData\Miniconda3\lib\site-packages\rest_framework\viewsets.py", line 114, in view
    return self.dispatch(request, *args, **kwargs)
  File "C:\ProgramData\Miniconda3\lib\site-packages\rest_framework\views.py", line 505, in dispatch
    response = self.handle_exception(exc)
  File "C:\ProgramData\Miniconda3\lib\site-packages\rest_framework\views.py", line 465, in handle_exception
    self.raise_uncaught_exception(exc)
  File "C:\ProgramData\Miniconda3\lib\site-packages\rest_framework\views.py", line 476, in raise_uncaught_exception
    raise exc
  File "C:\ProgramData\Miniconda3\lib\site-packages\rest_framework\views.py", line 502, in dispatch
    response = handler(request, *args, **kwargs)
  File "C:\ProgramData\Miniconda3\lib\site-packages\rest_framework\mixins.py", line 43, in list
    return self.get_paginated_response(serializer.data)
  File "C:\ProgramData\Miniconda3\lib\site-packages\rest_framework\serializers.py", line 760, in data
    ret = super().data
  File "C:\ProgramData\Miniconda3\lib\site-packages\rest_framework\serializers.py", line 260, in data
    self._data = self.to_representation(self.instance)
  File "C:\ProgramData\Miniconda3\lib\site-packages\rest_framework\serializers.py", line 678, in to_representation
    self.child.to_representation(item) for item in iterable
  File "C:\ProgramData\Miniconda3\lib\site-packages\rest_framework\serializers.py", line 678, in <listcomp>
    self.child.to_representation(item) for item in iterable
  File "C:\ProgramData\Miniconda3\lib\site-packages\rest_framework\serializers.py", line 516, in to_representation
    attribute = field.get_attribute(instance)
  File "C:\ProgramData\Miniconda3\lib\site-packages\rest_framework\fields.py", line 454, in get_attribute
    return get_attribute(instance, self.source_attrs)
  File "C:\ProgramData\Miniconda3\lib\site-packages\rest_framework\fields.py", line 99, in get_attribute
    instance = instance()
  File "D:\MISC\GITHUB\knit_server//app\users\kmodels\address_model.py", line 25, in get_full_address
    address_line += self.house_name if self.house_name else ""
  File "C:\ProgramData\Miniconda3\lib\site-packages\django\db\models\query_utils.py", line 139, in __get__
    instance.refresh_from_db(fields=[field_name])
  File "C:\ProgramData\Miniconda3\lib\site-packages\django\db\models\base.py", line 627, in refresh_from_db
    db_instance = db_instance_qs.get()
  File "C:\ProgramData\Miniconda3\lib\site-packages\django\db\models\query.py", line 417, in get
    self.model._meta.object_name
users.kmodels.address_model.Address.DoesNotExist: Address matching query does not exist.
 django.request 2020-05-06 21:12:01,752 WARNING  Not Found: /user/address
 django.request 2020-05-06 21:32:27,911 ERROR    Internal Server Error: /user/address
Traceback (most recent call last):
  File "C:\ProgramData\Miniconda3\lib\site-packages\django\core\handlers\exception.py", line 34, in inner
    response = get_response(request)
  File "C:\ProgramData\Miniconda3\lib\site-packages\django\core\handlers\base.py", line 115, in _get_response
    response = self.process_exception_by_middleware(e, request)
  File "C:\ProgramData\Miniconda3\lib\site-packages\django\core\handlers\base.py", line 113, in _get_response
    response = wrapped_callback(request, *callback_args, **callback_kwargs)
  File "C:\ProgramData\Miniconda3\lib\site-packages\django\views\decorators\csrf.py", line 54, in wrapped_view
    return view_func(*args, **kwargs)
  File "C:\ProgramData\Miniconda3\lib\site-packages\rest_framework\viewsets.py", line 114, in view
    return self.dispatch(request, *args, **kwargs)
  File "C:\ProgramData\Miniconda3\lib\site-packages\rest_framework\views.py", line 505, in dispatch
    response = self.handle_exception(exc)
  File "C:\ProgramData\Miniconda3\lib\site-packages\rest_framework\views.py", line 465, in handle_exception
    self.raise_uncaught_exception(exc)
  File "C:\ProgramData\Miniconda3\lib\site-packages\rest_framework\views.py", line 476, in raise_uncaught_exception
    raise exc
  File "C:\ProgramData\Miniconda3\lib\site-packages\rest_framework\views.py", line 502, in dispatch
    response = handler(request, *args, **kwargs)
  File "C:\ProgramData\Miniconda3\lib\site-packages\rest_framework\mixins.py", line 38, in list
    queryset = self.filter_queryset(self.get_queryset())
  File "D:\MISC\GITHUB\knit_server//app\users\kviews\address_view.py", line 64, in get_queryset
    limit
TypeError: not all arguments converted during string formatting
 django.request 2020-05-06 22:49:26,877 ERROR    Internal Server Error: /user/address
Traceback (most recent call last):
  File "C:\ProgramData\Miniconda3\lib\site-packages\django\db\backends\utils.py", line 86, in _execute
    return self.cursor.execute(sql, params)
  File "C:\ProgramData\Miniconda3\lib\site-packages\django\db\backends\mysql\base.py", line 74, in execute
    return self.cursor.execute(query, args)
  File "C:\ProgramData\Miniconda3\lib\site-packages\MySQLdb\cursors.py", line 209, in execute
    res = self._query(query)
  File "C:\ProgramData\Miniconda3\lib\site-packages\MySQLdb\cursors.py", line 315, in _query
    db.query(q)
  File "C:\ProgramData\Miniconda3\lib\site-packages\MySQLdb\connections.py", line 239, in query
    _mysql.connection.query(self, query)
MySQLdb._exceptions.ProgrammingError: (1064, "You have an error in your SQL syntax; check the manual that corresponds to your MySQL server version for the right syntax to use near ':lat ) ) *\n                                cos( radians( `latitude` ) ) *\n      ' at line 6")

The above exception was the direct cause of the following exception:

Traceback (most recent call last):
  File "C:\ProgramData\Miniconda3\lib\site-packages\django\core\handlers\exception.py", line 34, in inner
    response = get_response(request)
  File "C:\ProgramData\Miniconda3\lib\site-packages\django\core\handlers\base.py", line 115, in _get_response
    response = self.process_exception_by_middleware(e, request)
  File "C:\ProgramData\Miniconda3\lib\site-packages\django\core\handlers\base.py", line 113, in _get_response
    response = wrapped_callback(request, *callback_args, **callback_kwargs)
  File "C:\ProgramData\Miniconda3\lib\site-packages\django\views\decorators\csrf.py", line 54, in wrapped_view
    return view_func(*args, **kwargs)
  File "C:\ProgramData\Miniconda3\lib\site-packages\rest_framework\viewsets.py", line 114, in view
    return self.dispatch(request, *args, **kwargs)
  File "C:\ProgramData\Miniconda3\lib\site-packages\rest_framework\views.py", line 505, in dispatch
    response = self.handle_exception(exc)
  File "C:\ProgramData\Miniconda3\lib\site-packages\rest_framework\views.py", line 465, in handle_exception
    self.raise_uncaught_exception(exc)
  File "C:\ProgramData\Miniconda3\lib\site-packages\rest_framework\views.py", line 476, in raise_uncaught_exception
    raise exc
  File "C:\ProgramData\Miniconda3\lib\site-packages\rest_framework\views.py", line 502, in dispatch
    response = handler(request, *args, **kwargs)
  File "C:\ProgramData\Miniconda3\lib\site-packages\rest_framework\mixins.py", line 40, in list
    page = self.paginate_queryset(queryset)
  File "C:\ProgramData\Miniconda3\lib\site-packages\rest_framework\generics.py", line 171, in paginate_queryset
    return self.paginator.paginate_queryset(queryset, self.request, view=self)
  File "C:\ProgramData\Miniconda3\lib\site-packages\rest_framework\pagination.py", line 206, in paginate_queryset
    self.page = paginator.page(page_number)
  File "C:\ProgramData\Miniconda3\lib\site-packages\django\core\paginator.py", line 70, in page
    number = self.validate_number(number)
  File "C:\ProgramData\Miniconda3\lib\site-packages\django\core\paginator.py", line 48, in validate_number
    if number > self.num_pages:
  File "C:\ProgramData\Miniconda3\lib\site-packages\django\utils\functional.py", line 48, in __get__
    res = instance.__dict__[self.name] = self.func(instance)
  File "C:\ProgramData\Miniconda3\lib\site-packages\django\core\paginator.py", line 97, in num_pages
    if self.count == 0 and not self.allow_empty_first_page:
  File "C:\ProgramData\Miniconda3\lib\site-packages\django\utils\functional.py", line 48, in __get__
    res = instance.__dict__[self.name] = self.func(instance)
  File "C:\ProgramData\Miniconda3\lib\site-packages\django\core\paginator.py", line 92, in count
    return len(self.object_list)
  File "C:\ProgramData\Miniconda3\lib\site-packages\django\db\models\query.py", line 1413, in __len__
    self._fetch_all()
  File "C:\ProgramData\Miniconda3\lib\site-packages\django\db\models\query.py", line 1408, in _fetch_all
    self._result_cache = list(self.iterator())
  File "C:\ProgramData\Miniconda3\lib\site-packages\django\db\models\query.py", line 1431, in iterator
    query = iter(self.query)
  File "C:\ProgramData\Miniconda3\lib\site-packages\django\db\models\sql\query.py", line 109, in __iter__
    self._execute_query()
  File "C:\ProgramData\Miniconda3\lib\site-packages\django\db\models\sql\query.py", line 143, in _execute_query
    self.cursor.execute(self.sql, params)
  File "C:\ProgramData\Miniconda3\lib\site-packages\django\db\backends\utils.py", line 100, in execute
    return super().execute(sql, params)
  File "C:\ProgramData\Miniconda3\lib\site-packages\django\db\backends\utils.py", line 68, in execute
    return self._execute_with_wrappers(sql, params, many=False, executor=self._execute)
  File "C:\ProgramData\Miniconda3\lib\site-packages\django\db\backends\utils.py", line 77, in _execute_with_wrappers
    return executor(sql, params, many, context)
  File "C:\ProgramData\Miniconda3\lib\site-packages\django\db\backends\utils.py", line 86, in _execute
    return self.cursor.execute(sql, params)
  File "C:\ProgramData\Miniconda3\lib\site-packages\django\db\utils.py", line 90, in __exit__
    raise dj_exc_value.with_traceback(traceback) from exc_value
  File "C:\ProgramData\Miniconda3\lib\site-packages\django\db\backends\utils.py", line 86, in _execute
    return self.cursor.execute(sql, params)
  File "C:\ProgramData\Miniconda3\lib\site-packages\django\db\backends\mysql\base.py", line 74, in execute
    return self.cursor.execute(query, args)
  File "C:\ProgramData\Miniconda3\lib\site-packages\MySQLdb\cursors.py", line 209, in execute
    res = self._query(query)
  File "C:\ProgramData\Miniconda3\lib\site-packages\MySQLdb\cursors.py", line 315, in _query
    db.query(q)
  File "C:\ProgramData\Miniconda3\lib\site-packages\MySQLdb\connections.py", line 239, in query
    _mysql.connection.query(self, query)
django.db.utils.ProgrammingError: (1064, "You have an error in your SQL syntax; check the manual that corresponds to your MySQL server version for the right syntax to use near ':lat ) ) *\n                                cos( radians( `latitude` ) ) *\n      ' at line 6")
 django.request 2020-05-06 22:54:44,508 ERROR    Internal Server Error: /user/address
Traceback (most recent call last):
  File "C:\ProgramData\Miniconda3\lib\site-packages\django\core\handlers\exception.py", line 34, in inner
    response = get_response(request)
  File "C:\ProgramData\Miniconda3\lib\site-packages\django\core\handlers\base.py", line 115, in _get_response
    response = self.process_exception_by_middleware(e, request)
  File "C:\ProgramData\Miniconda3\lib\site-packages\django\core\handlers\base.py", line 113, in _get_response
    response = wrapped_callback(request, *callback_args, **callback_kwargs)
  File "C:\ProgramData\Miniconda3\lib\site-packages\django\views\decorators\csrf.py", line 54, in wrapped_view
    return view_func(*args, **kwargs)
  File "C:\ProgramData\Miniconda3\lib\site-packages\rest_framework\viewsets.py", line 114, in view
    return self.dispatch(request, *args, **kwargs)
  File "C:\ProgramData\Miniconda3\lib\site-packages\rest_framework\views.py", line 505, in dispatch
    response = self.handle_exception(exc)
  File "C:\ProgramData\Miniconda3\lib\site-packages\rest_framework\views.py", line 465, in handle_exception
    self.raise_uncaught_exception(exc)
  File "C:\ProgramData\Miniconda3\lib\site-packages\rest_framework\views.py", line 476, in raise_uncaught_exception
    raise exc
  File "C:\ProgramData\Miniconda3\lib\site-packages\rest_framework\views.py", line 502, in dispatch
    response = handler(request, *args, **kwargs)
  File "C:\ProgramData\Miniconda3\lib\site-packages\rest_framework\mixins.py", line 40, in list
    page = self.paginate_queryset(queryset)
  File "C:\ProgramData\Miniconda3\lib\site-packages\rest_framework\generics.py", line 171, in paginate_queryset
    return self.paginator.paginate_queryset(queryset, self.request, view=self)
  File "C:\ProgramData\Miniconda3\lib\site-packages\rest_framework\pagination.py", line 206, in paginate_queryset
    self.page = paginator.page(page_number)
  File "C:\ProgramData\Miniconda3\lib\site-packages\django\core\paginator.py", line 70, in page
    number = self.validate_number(number)
  File "C:\ProgramData\Miniconda3\lib\site-packages\django\core\paginator.py", line 48, in validate_number
    if number > self.num_pages:
  File "C:\ProgramData\Miniconda3\lib\site-packages\django\utils\functional.py", line 48, in __get__
    res = instance.__dict__[self.name] = self.func(instance)
  File "C:\ProgramData\Miniconda3\lib\site-packages\django\core\paginator.py", line 97, in num_pages
    if self.count == 0 and not self.allow_empty_first_page:
  File "C:\ProgramData\Miniconda3\lib\site-packages\django\utils\functional.py", line 48, in __get__
    res = instance.__dict__[self.name] = self.func(instance)
  File "C:\ProgramData\Miniconda3\lib\site-packages\django\core\paginator.py", line 92, in count
    return len(self.object_list)
  File "C:\ProgramData\Miniconda3\lib\site-packages\django\db\models\query.py", line 1413, in __len__
    self._fetch_all()
  File "C:\ProgramData\Miniconda3\lib\site-packages\django\db\models\query.py", line 1408, in _fetch_all
    self._result_cache = list(self.iterator())
  File "C:\ProgramData\Miniconda3\lib\site-packages\django\db\models\query.py", line 1436, in iterator
    raise InvalidQuery('Raw query must include the primary key')
django.db.models.query_utils.InvalidQuery: Raw query must include the primary key
 django.request 2020-05-06 22:58:06,323 ERROR    Internal Server Error: /user/address
Traceback (most recent call last):
  File "C:\ProgramData\Miniconda3\lib\site-packages\django\core\handlers\exception.py", line 34, in inner
    response = get_response(request)
  File "C:\ProgramData\Miniconda3\lib\site-packages\django\core\handlers\base.py", line 115, in _get_response
    response = self.process_exception_by_middleware(e, request)
  File "C:\ProgramData\Miniconda3\lib\site-packages\django\core\handlers\base.py", line 113, in _get_response
    response = wrapped_callback(request, *callback_args, **callback_kwargs)
  File "C:\ProgramData\Miniconda3\lib\site-packages\django\views\decorators\csrf.py", line 54, in wrapped_view
    return view_func(*args, **kwargs)
  File "C:\ProgramData\Miniconda3\lib\site-packages\rest_framework\viewsets.py", line 114, in view
    return self.dispatch(request, *args, **kwargs)
  File "C:\ProgramData\Miniconda3\lib\site-packages\rest_framework\views.py", line 505, in dispatch
    response = self.handle_exception(exc)
  File "C:\ProgramData\Miniconda3\lib\site-packages\rest_framework\views.py", line 465, in handle_exception
    self.raise_uncaught_exception(exc)
  File "C:\ProgramData\Miniconda3\lib\site-packages\rest_framework\views.py", line 476, in raise_uncaught_exception
    raise exc
  File "C:\ProgramData\Miniconda3\lib\site-packages\rest_framework\views.py", line 502, in dispatch
    response = handler(request, *args, **kwargs)
  File "C:\ProgramData\Miniconda3\lib\site-packages\rest_framework\mixins.py", line 40, in list
    page = self.paginate_queryset(queryset)
  File "C:\ProgramData\Miniconda3\lib\site-packages\rest_framework\generics.py", line 171, in paginate_queryset
    return self.paginator.paginate_queryset(queryset, self.request, view=self)
  File "C:\ProgramData\Miniconda3\lib\site-packages\rest_framework\pagination.py", line 206, in paginate_queryset
    self.page = paginator.page(page_number)
  File "C:\ProgramData\Miniconda3\lib\site-packages\django\core\paginator.py", line 70, in page
    number = self.validate_number(number)
  File "C:\ProgramData\Miniconda3\lib\site-packages\django\core\paginator.py", line 48, in validate_number
    if number > self.num_pages:
  File "C:\ProgramData\Miniconda3\lib\site-packages\django\utils\functional.py", line 48, in __get__
    res = instance.__dict__[self.name] = self.func(instance)
  File "C:\ProgramData\Miniconda3\lib\site-packages\django\core\paginator.py", line 97, in num_pages
    if self.count == 0 and not self.allow_empty_first_page:
  File "C:\ProgramData\Miniconda3\lib\site-packages\django\utils\functional.py", line 48, in __get__
    res = instance.__dict__[self.name] = self.func(instance)
  File "C:\ProgramData\Miniconda3\lib\site-packages\django\core\paginator.py", line 92, in count
    return len(self.object_list)
  File "C:\ProgramData\Miniconda3\lib\site-packages\django\db\models\query.py", line 1413, in __len__
    self._fetch_all()
  File "C:\ProgramData\Miniconda3\lib\site-packages\django\db\models\query.py", line 1408, in _fetch_all
    self._result_cache = list(self.iterator())
  File "C:\ProgramData\Miniconda3\lib\site-packages\django\db\models\query.py", line 1436, in iterator
    raise InvalidQuery('Raw query must include the primary key')
django.db.models.query_utils.InvalidQuery: Raw query must include the primary key
 django.request 2020-05-06 23:02:36,837 ERROR    Internal Server Error: /user/address
Traceback (most recent call last):
  File "C:\ProgramData\Miniconda3\lib\site-packages\django\db\backends\utils.py", line 86, in _execute
    return self.cursor.execute(sql, params)
  File "C:\ProgramData\Miniconda3\lib\site-packages\django\db\backends\mysql\base.py", line 74, in execute
    return self.cursor.execute(query, args)
  File "C:\ProgramData\Miniconda3\lib\site-packages\MySQLdb\cursors.py", line 209, in execute
    res = self._query(query)
  File "C:\ProgramData\Miniconda3\lib\site-packages\MySQLdb\cursors.py", line 315, in _query
    db.query(q)
  File "C:\ProgramData\Miniconda3\lib\site-packages\MySQLdb\connections.py", line 239, in query
    _mysql.connection.query(self, query)
MySQLdb._exceptions.ProgrammingError: (1146, "Table 'knit_db.carpark' doesn't exist")

The above exception was the direct cause of the following exception:

Traceback (most recent call last):
  File "C:\ProgramData\Miniconda3\lib\site-packages\django\core\handlers\exception.py", line 34, in inner
    response = get_response(request)
  File "C:\ProgramData\Miniconda3\lib\site-packages\django\core\handlers\base.py", line 115, in _get_response
    response = self.process_exception_by_middleware(e, request)
  File "C:\ProgramData\Miniconda3\lib\site-packages\django\core\handlers\base.py", line 113, in _get_response
    response = wrapped_callback(request, *callback_args, **callback_kwargs)
  File "C:\ProgramData\Miniconda3\lib\site-packages\django\views\decorators\csrf.py", line 54, in wrapped_view
    return view_func(*args, **kwargs)
  File "C:\ProgramData\Miniconda3\lib\site-packages\rest_framework\viewsets.py", line 114, in view
    return self.dispatch(request, *args, **kwargs)
  File "C:\ProgramData\Miniconda3\lib\site-packages\rest_framework\views.py", line 505, in dispatch
    response = self.handle_exception(exc)
  File "C:\ProgramData\Miniconda3\lib\site-packages\rest_framework\views.py", line 465, in handle_exception
    self.raise_uncaught_exception(exc)
  File "C:\ProgramData\Miniconda3\lib\site-packages\rest_framework\views.py", line 476, in raise_uncaught_exception
    raise exc
  File "C:\ProgramData\Miniconda3\lib\site-packages\rest_framework\views.py", line 502, in dispatch
    response = handler(request, *args, **kwargs)
  File "C:\ProgramData\Miniconda3\lib\site-packages\rest_framework\mixins.py", line 40, in list
    page = self.paginate_queryset(queryset)
  File "C:\ProgramData\Miniconda3\lib\site-packages\rest_framework\generics.py", line 171, in paginate_queryset
    return self.paginator.paginate_queryset(queryset, self.request, view=self)
  File "C:\ProgramData\Miniconda3\lib\site-packages\rest_framework\pagination.py", line 206, in paginate_queryset
    self.page = paginator.page(page_number)
  File "C:\ProgramData\Miniconda3\lib\site-packages\django\core\paginator.py", line 70, in page
    number = self.validate_number(number)
  File "C:\ProgramData\Miniconda3\lib\site-packages\django\core\paginator.py", line 48, in validate_number
    if number > self.num_pages:
  File "C:\ProgramData\Miniconda3\lib\site-packages\django\utils\functional.py", line 48, in __get__
    res = instance.__dict__[self.name] = self.func(instance)
  File "C:\ProgramData\Miniconda3\lib\site-packages\django\core\paginator.py", line 97, in num_pages
    if self.count == 0 and not self.allow_empty_first_page:
  File "C:\ProgramData\Miniconda3\lib\site-packages\django\utils\functional.py", line 48, in __get__
    res = instance.__dict__[self.name] = self.func(instance)
  File "C:\ProgramData\Miniconda3\lib\site-packages\django\core\paginator.py", line 92, in count
    return len(self.object_list)
  File "C:\ProgramData\Miniconda3\lib\site-packages\django\db\models\query.py", line 1413, in __len__
    self._fetch_all()
  File "C:\ProgramData\Miniconda3\lib\site-packages\django\db\models\query.py", line 1408, in _fetch_all
    self._result_cache = list(self.iterator())
  File "C:\ProgramData\Miniconda3\lib\site-packages\django\db\models\query.py", line 1431, in iterator
    query = iter(self.query)
  File "C:\ProgramData\Miniconda3\lib\site-packages\django\db\models\sql\query.py", line 109, in __iter__
    self._execute_query()
  File "C:\ProgramData\Miniconda3\lib\site-packages\django\db\models\sql\query.py", line 143, in _execute_query
    self.cursor.execute(self.sql, params)
  File "C:\ProgramData\Miniconda3\lib\site-packages\django\db\backends\utils.py", line 100, in execute
    return super().execute(sql, params)
  File "C:\ProgramData\Miniconda3\lib\site-packages\django\db\backends\utils.py", line 68, in execute
    return self._execute_with_wrappers(sql, params, many=False, executor=self._execute)
  File "C:\ProgramData\Miniconda3\lib\site-packages\django\db\backends\utils.py", line 77, in _execute_with_wrappers
    return executor(sql, params, many, context)
  File "C:\ProgramData\Miniconda3\lib\site-packages\django\db\backends\utils.py", line 86, in _execute
    return self.cursor.execute(sql, params)
  File "C:\ProgramData\Miniconda3\lib\site-packages\django\db\utils.py", line 90, in __exit__
    raise dj_exc_value.with_traceback(traceback) from exc_value
  File "C:\ProgramData\Miniconda3\lib\site-packages\django\db\backends\utils.py", line 86, in _execute
    return self.cursor.execute(sql, params)
  File "C:\ProgramData\Miniconda3\lib\site-packages\django\db\backends\mysql\base.py", line 74, in execute
    return self.cursor.execute(query, args)
  File "C:\ProgramData\Miniconda3\lib\site-packages\MySQLdb\cursors.py", line 209, in execute
    res = self._query(query)
  File "C:\ProgramData\Miniconda3\lib\site-packages\MySQLdb\cursors.py", line 315, in _query
    db.query(q)
  File "C:\ProgramData\Miniconda3\lib\site-packages\MySQLdb\connections.py", line 239, in query
    _mysql.connection.query(self, query)
django.db.utils.ProgrammingError: (1146, "Table 'knit_db.carpark' doesn't exist")
 django.request 2020-05-06 23:02:50,022 ERROR    Internal Server Error: /user/address
Traceback (most recent call last):
  File "C:\ProgramData\Miniconda3\lib\site-packages\django\db\backends\utils.py", line 86, in _execute
    return self.cursor.execute(sql, params)
  File "C:\ProgramData\Miniconda3\lib\site-packages\django\db\backends\mysql\base.py", line 74, in execute
    return self.cursor.execute(query, args)
  File "C:\ProgramData\Miniconda3\lib\site-packages\MySQLdb\cursors.py", line 209, in execute
    res = self._query(query)
  File "C:\ProgramData\Miniconda3\lib\site-packages\MySQLdb\cursors.py", line 315, in _query
    db.query(q)
  File "C:\ProgramData\Miniconda3\lib\site-packages\MySQLdb\connections.py", line 239, in query
    _mysql.connection.query(self, query)
MySQLdb._exceptions.OperationalError: (1054, "Unknown column 'lat' in 'field list'")

The above exception was the direct cause of the following exception:

Traceback (most recent call last):
  File "C:\ProgramData\Miniconda3\lib\site-packages\django\core\handlers\exception.py", line 34, in inner
    response = get_response(request)
  File "C:\ProgramData\Miniconda3\lib\site-packages\django\core\handlers\base.py", line 115, in _get_response
    response = self.process_exception_by_middleware(e, request)
  File "C:\ProgramData\Miniconda3\lib\site-packages\django\core\handlers\base.py", line 113, in _get_response
    response = wrapped_callback(request, *callback_args, **callback_kwargs)
  File "C:\ProgramData\Miniconda3\lib\site-packages\django\views\decorators\csrf.py", line 54, in wrapped_view
    return view_func(*args, **kwargs)
  File "C:\ProgramData\Miniconda3\lib\site-packages\rest_framework\viewsets.py", line 114, in view
    return self.dispatch(request, *args, **kwargs)
  File "C:\ProgramData\Miniconda3\lib\site-packages\rest_framework\views.py", line 505, in dispatch
    response = self.handle_exception(exc)
  File "C:\ProgramData\Miniconda3\lib\site-packages\rest_framework\views.py", line 465, in handle_exception
    self.raise_uncaught_exception(exc)
  File "C:\ProgramData\Miniconda3\lib\site-packages\rest_framework\views.py", line 476, in raise_uncaught_exception
    raise exc
  File "C:\ProgramData\Miniconda3\lib\site-packages\rest_framework\views.py", line 502, in dispatch
    response = handler(request, *args, **kwargs)
  File "C:\ProgramData\Miniconda3\lib\site-packages\rest_framework\mixins.py", line 40, in list
    page = self.paginate_queryset(queryset)
  File "C:\ProgramData\Miniconda3\lib\site-packages\rest_framework\generics.py", line 171, in paginate_queryset
    return self.paginator.paginate_queryset(queryset, self.request, view=self)
  File "C:\ProgramData\Miniconda3\lib\site-packages\rest_framework\pagination.py", line 206, in paginate_queryset
    self.page = paginator.page(page_number)
  File "C:\ProgramData\Miniconda3\lib\site-packages\django\core\paginator.py", line 70, in page
    number = self.validate_number(number)
  File "C:\ProgramData\Miniconda3\lib\site-packages\django\core\paginator.py", line 48, in validate_number
    if number > self.num_pages:
  File "C:\ProgramData\Miniconda3\lib\site-packages\django\utils\functional.py", line 48, in __get__
    res = instance.__dict__[self.name] = self.func(instance)
  File "C:\ProgramData\Miniconda3\lib\site-packages\django\core\paginator.py", line 97, in num_pages
    if self.count == 0 and not self.allow_empty_first_page:
  File "C:\ProgramData\Miniconda3\lib\site-packages\django\utils\functional.py", line 48, in __get__
    res = instance.__dict__[self.name] = self.func(instance)
  File "C:\ProgramData\Miniconda3\lib\site-packages\django\core\paginator.py", line 92, in count
    return len(self.object_list)
  File "C:\ProgramData\Miniconda3\lib\site-packages\django\db\models\query.py", line 1413, in __len__
    self._fetch_all()
  File "C:\ProgramData\Miniconda3\lib\site-packages\django\db\models\query.py", line 1408, in _fetch_all
    self._result_cache = list(self.iterator())
  File "C:\ProgramData\Miniconda3\lib\site-packages\django\db\models\query.py", line 1431, in iterator
    query = iter(self.query)
  File "C:\ProgramData\Miniconda3\lib\site-packages\django\db\models\sql\query.py", line 109, in __iter__
    self._execute_query()
  File "C:\ProgramData\Miniconda3\lib\site-packages\django\db\models\sql\query.py", line 143, in _execute_query
    self.cursor.execute(self.sql, params)
  File "C:\ProgramData\Miniconda3\lib\site-packages\django\db\backends\utils.py", line 100, in execute
    return super().execute(sql, params)
  File "C:\ProgramData\Miniconda3\lib\site-packages\django\db\backends\utils.py", line 68, in execute
    return self._execute_with_wrappers(sql, params, many=False, executor=self._execute)
  File "C:\ProgramData\Miniconda3\lib\site-packages\django\db\backends\utils.py", line 77, in _execute_with_wrappers
    return executor(sql, params, many, context)
  File "C:\ProgramData\Miniconda3\lib\site-packages\django\db\backends\utils.py", line 86, in _execute
    return self.cursor.execute(sql, params)
  File "C:\ProgramData\Miniconda3\lib\site-packages\django\db\utils.py", line 90, in __exit__
    raise dj_exc_value.with_traceback(traceback) from exc_value
  File "C:\ProgramData\Miniconda3\lib\site-packages\django\db\backends\utils.py", line 86, in _execute
    return self.cursor.execute(sql, params)
  File "C:\ProgramData\Miniconda3\lib\site-packages\django\db\backends\mysql\base.py", line 74, in execute
    return self.cursor.execute(query, args)
  File "C:\ProgramData\Miniconda3\lib\site-packages\MySQLdb\cursors.py", line 209, in execute
    res = self._query(query)
  File "C:\ProgramData\Miniconda3\lib\site-packages\MySQLdb\cursors.py", line 315, in _query
    db.query(q)
  File "C:\ProgramData\Miniconda3\lib\site-packages\MySQLdb\connections.py", line 239, in query
    _mysql.connection.query(self, query)
django.db.utils.OperationalError: (1054, "Unknown column 'lat' in 'field list'")
 django.request 2020-05-06 23:03:34,789 ERROR    Internal Server Error: /user/address
Traceback (most recent call last):
  File "C:\ProgramData\Miniconda3\lib\site-packages\django\db\backends\utils.py", line 86, in _execute
    return self.cursor.execute(sql, params)
  File "C:\ProgramData\Miniconda3\lib\site-packages\django\db\backends\mysql\base.py", line 74, in execute
    return self.cursor.execute(query, args)
  File "C:\ProgramData\Miniconda3\lib\site-packages\MySQLdb\cursors.py", line 209, in execute
    res = self._query(query)
  File "C:\ProgramData\Miniconda3\lib\site-packages\MySQLdb\cursors.py", line 315, in _query
    db.query(q)
  File "C:\ProgramData\Miniconda3\lib\site-packages\MySQLdb\connections.py", line 239, in query
    _mysql.connection.query(self, query)
MySQLdb._exceptions.OperationalError: (1054, "Unknown column 'lat' in 'field list'")

The above exception was the direct cause of the following exception:

Traceback (most recent call last):
  File "C:\ProgramData\Miniconda3\lib\site-packages\django\core\handlers\exception.py", line 34, in inner
    response = get_response(request)
  File "C:\ProgramData\Miniconda3\lib\site-packages\django\core\handlers\base.py", line 115, in _get_response
    response = self.process_exception_by_middleware(e, request)
  File "C:\ProgramData\Miniconda3\lib\site-packages\django\core\handlers\base.py", line 113, in _get_response
    response = wrapped_callback(request, *callback_args, **callback_kwargs)
  File "C:\ProgramData\Miniconda3\lib\site-packages\django\views\decorators\csrf.py", line 54, in wrapped_view
    return view_func(*args, **kwargs)
  File "C:\ProgramData\Miniconda3\lib\site-packages\rest_framework\viewsets.py", line 114, in view
    return self.dispatch(request, *args, **kwargs)
  File "C:\ProgramData\Miniconda3\lib\site-packages\rest_framework\views.py", line 505, in dispatch
    response = self.handle_exception(exc)
  File "C:\ProgramData\Miniconda3\lib\site-packages\rest_framework\views.py", line 465, in handle_exception
    self.raise_uncaught_exception(exc)
  File "C:\ProgramData\Miniconda3\lib\site-packages\rest_framework\views.py", line 476, in raise_uncaught_exception
    raise exc
  File "C:\ProgramData\Miniconda3\lib\site-packages\rest_framework\views.py", line 502, in dispatch
    response = handler(request, *args, **kwargs)
  File "C:\ProgramData\Miniconda3\lib\site-packages\rest_framework\mixins.py", line 40, in list
    page = self.paginate_queryset(queryset)
  File "C:\ProgramData\Miniconda3\lib\site-packages\rest_framework\generics.py", line 171, in paginate_queryset
    return self.paginator.paginate_queryset(queryset, self.request, view=self)
  File "C:\ProgramData\Miniconda3\lib\site-packages\rest_framework\pagination.py", line 206, in paginate_queryset
    self.page = paginator.page(page_number)
  File "C:\ProgramData\Miniconda3\lib\site-packages\django\core\paginator.py", line 70, in page
    number = self.validate_number(number)
  File "C:\ProgramData\Miniconda3\lib\site-packages\django\core\paginator.py", line 48, in validate_number
    if number > self.num_pages:
  File "C:\ProgramData\Miniconda3\lib\site-packages\django\utils\functional.py", line 48, in __get__
    res = instance.__dict__[self.name] = self.func(instance)
  File "C:\ProgramData\Miniconda3\lib\site-packages\django\core\paginator.py", line 97, in num_pages
    if self.count == 0 and not self.allow_empty_first_page:
  File "C:\ProgramData\Miniconda3\lib\site-packages\django\utils\functional.py", line 48, in __get__
    res = instance.__dict__[self.name] = self.func(instance)
  File "C:\ProgramData\Miniconda3\lib\site-packages\django\core\paginator.py", line 92, in count
    return len(self.object_list)
  File "C:\ProgramData\Miniconda3\lib\site-packages\django\db\models\query.py", line 1413, in __len__
    self._fetch_all()
  File "C:\ProgramData\Miniconda3\lib\site-packages\django\db\models\query.py", line 1408, in _fetch_all
    self._result_cache = list(self.iterator())
  File "C:\ProgramData\Miniconda3\lib\site-packages\django\db\models\query.py", line 1431, in iterator
    query = iter(self.query)
  File "C:\ProgramData\Miniconda3\lib\site-packages\django\db\models\sql\query.py", line 109, in __iter__
    self._execute_query()
  File "C:\ProgramData\Miniconda3\lib\site-packages\django\db\models\sql\query.py", line 143, in _execute_query
    self.cursor.execute(self.sql, params)
  File "C:\ProgramData\Miniconda3\lib\site-packages\django\db\backends\utils.py", line 100, in execute
    return super().execute(sql, params)
  File "C:\ProgramData\Miniconda3\lib\site-packages\django\db\backends\utils.py", line 68, in execute
    return self._execute_with_wrappers(sql, params, many=False, executor=self._execute)
  File "C:\ProgramData\Miniconda3\lib\site-packages\django\db\backends\utils.py", line 77, in _execute_with_wrappers
    return executor(sql, params, many, context)
  File "C:\ProgramData\Miniconda3\lib\site-packages\django\db\backends\utils.py", line 86, in _execute
    return self.cursor.execute(sql, params)
  File "C:\ProgramData\Miniconda3\lib\site-packages\django\db\utils.py", line 90, in __exit__
    raise dj_exc_value.with_traceback(traceback) from exc_value
  File "C:\ProgramData\Miniconda3\lib\site-packages\django\db\backends\utils.py", line 86, in _execute
    return self.cursor.execute(sql, params)
  File "C:\ProgramData\Miniconda3\lib\site-packages\django\db\backends\mysql\base.py", line 74, in execute
    return self.cursor.execute(query, args)
  File "C:\ProgramData\Miniconda3\lib\site-packages\MySQLdb\cursors.py", line 209, in execute
    res = self._query(query)
  File "C:\ProgramData\Miniconda3\lib\site-packages\MySQLdb\cursors.py", line 315, in _query
    db.query(q)
  File "C:\ProgramData\Miniconda3\lib\site-packages\MySQLdb\connections.py", line 239, in query
    _mysql.connection.query(self, query)
django.db.utils.OperationalError: (1054, "Unknown column 'lat' in 'field list'")
 django.request 2020-05-06 23:03:53,092 ERROR    Internal Server Error: /user/address
Traceback (most recent call last):
  File "C:\ProgramData\Miniconda3\lib\site-packages\django\db\backends\utils.py", line 86, in _execute
    return self.cursor.execute(sql, params)
  File "C:\ProgramData\Miniconda3\lib\site-packages\django\db\backends\mysql\base.py", line 74, in execute
    return self.cursor.execute(query, args)
  File "C:\ProgramData\Miniconda3\lib\site-packages\MySQLdb\cursors.py", line 209, in execute
    res = self._query(query)
  File "C:\ProgramData\Miniconda3\lib\site-packages\MySQLdb\cursors.py", line 315, in _query
    db.query(q)
  File "C:\ProgramData\Miniconda3\lib\site-packages\MySQLdb\connections.py", line 239, in query
    _mysql.connection.query(self, query)
MySQLdb._exceptions.OperationalError: (1054, "Unknown column 'distance' in 'where clause'")

The above exception was the direct cause of the following exception:

Traceback (most recent call last):
  File "C:\ProgramData\Miniconda3\lib\site-packages\django\core\handlers\exception.py", line 34, in inner
    response = get_response(request)
  File "C:\ProgramData\Miniconda3\lib\site-packages\django\core\handlers\base.py", line 115, in _get_response
    response = self.process_exception_by_middleware(e, request)
  File "C:\ProgramData\Miniconda3\lib\site-packages\django\core\handlers\base.py", line 113, in _get_response
    response = wrapped_callback(request, *callback_args, **callback_kwargs)
  File "C:\ProgramData\Miniconda3\lib\site-packages\django\views\decorators\csrf.py", line 54, in wrapped_view
    return view_func(*args, **kwargs)
  File "C:\ProgramData\Miniconda3\lib\site-packages\rest_framework\viewsets.py", line 114, in view
    return self.dispatch(request, *args, **kwargs)
  File "C:\ProgramData\Miniconda3\lib\site-packages\rest_framework\views.py", line 505, in dispatch
    response = self.handle_exception(exc)
  File "C:\ProgramData\Miniconda3\lib\site-packages\rest_framework\views.py", line 465, in handle_exception
    self.raise_uncaught_exception(exc)
  File "C:\ProgramData\Miniconda3\lib\site-packages\rest_framework\views.py", line 476, in raise_uncaught_exception
    raise exc
  File "C:\ProgramData\Miniconda3\lib\site-packages\rest_framework\views.py", line 502, in dispatch
    response = handler(request, *args, **kwargs)
  File "C:\ProgramData\Miniconda3\lib\site-packages\rest_framework\mixins.py", line 40, in list
    page = self.paginate_queryset(queryset)
  File "C:\ProgramData\Miniconda3\lib\site-packages\rest_framework\generics.py", line 171, in paginate_queryset
    return self.paginator.paginate_queryset(queryset, self.request, view=self)
  File "C:\ProgramData\Miniconda3\lib\site-packages\rest_framework\pagination.py", line 206, in paginate_queryset
    self.page = paginator.page(page_number)
  File "C:\ProgramData\Miniconda3\lib\site-packages\django\core\paginator.py", line 70, in page
    number = self.validate_number(number)
  File "C:\ProgramData\Miniconda3\lib\site-packages\django\core\paginator.py", line 48, in validate_number
    if number > self.num_pages:
  File "C:\ProgramData\Miniconda3\lib\site-packages\django\utils\functional.py", line 48, in __get__
    res = instance.__dict__[self.name] = self.func(instance)
  File "C:\ProgramData\Miniconda3\lib\site-packages\django\core\paginator.py", line 97, in num_pages
    if self.count == 0 and not self.allow_empty_first_page:
  File "C:\ProgramData\Miniconda3\lib\site-packages\django\utils\functional.py", line 48, in __get__
    res = instance.__dict__[self.name] = self.func(instance)
  File "C:\ProgramData\Miniconda3\lib\site-packages\django\core\paginator.py", line 92, in count
    return len(self.object_list)
  File "C:\ProgramData\Miniconda3\lib\site-packages\django\db\models\query.py", line 1413, in __len__
    self._fetch_all()
  File "C:\ProgramData\Miniconda3\lib\site-packages\django\db\models\query.py", line 1408, in _fetch_all
    self._result_cache = list(self.iterator())
  File "C:\ProgramData\Miniconda3\lib\site-packages\django\db\models\query.py", line 1431, in iterator
    query = iter(self.query)
  File "C:\ProgramData\Miniconda3\lib\site-packages\django\db\models\sql\query.py", line 109, in __iter__
    self._execute_query()
  File "C:\ProgramData\Miniconda3\lib\site-packages\django\db\models\sql\query.py", line 143, in _execute_query
    self.cursor.execute(self.sql, params)
  File "C:\ProgramData\Miniconda3\lib\site-packages\django\db\backends\utils.py", line 100, in execute
    return super().execute(sql, params)
  File "C:\ProgramData\Miniconda3\lib\site-packages\django\db\backends\utils.py", line 68, in execute
    return self._execute_with_wrappers(sql, params, many=False, executor=self._execute)
  File "C:\ProgramData\Miniconda3\lib\site-packages\django\db\backends\utils.py", line 77, in _execute_with_wrappers
    return executor(sql, params, many, context)
  File "C:\ProgramData\Miniconda3\lib\site-packages\django\db\backends\utils.py", line 86, in _execute
    return self.cursor.execute(sql, params)
  File "C:\ProgramData\Miniconda3\lib\site-packages\django\db\utils.py", line 90, in __exit__
    raise dj_exc_value.with_traceback(traceback) from exc_value
  File "C:\ProgramData\Miniconda3\lib\site-packages\django\db\backends\utils.py", line 86, in _execute
    return self.cursor.execute(sql, params)
  File "C:\ProgramData\Miniconda3\lib\site-packages\django\db\backends\mysql\base.py", line 74, in execute
    return self.cursor.execute(query, args)
  File "C:\ProgramData\Miniconda3\lib\site-packages\MySQLdb\cursors.py", line 209, in execute
    res = self._query(query)
  File "C:\ProgramData\Miniconda3\lib\site-packages\MySQLdb\cursors.py", line 315, in _query
    db.query(q)
  File "C:\ProgramData\Miniconda3\lib\site-packages\MySQLdb\connections.py", line 239, in query
    _mysql.connection.query(self, query)
django.db.utils.OperationalError: (1054, "Unknown column 'distance' in 'where clause'")
 django.request 2020-05-06 23:05:10,849 ERROR    Internal Server Error: /user/address
Traceback (most recent call last):
  File "C:\ProgramData\Miniconda3\lib\site-packages\django\db\backends\utils.py", line 86, in _execute
    return self.cursor.execute(sql, params)
  File "C:\ProgramData\Miniconda3\lib\site-packages\django\db\backends\mysql\base.py", line 74, in execute
    return self.cursor.execute(query, args)
  File "C:\ProgramData\Miniconda3\lib\site-packages\MySQLdb\cursors.py", line 209, in execute
    res = self._query(query)
  File "C:\ProgramData\Miniconda3\lib\site-packages\MySQLdb\cursors.py", line 315, in _query
    db.query(q)
  File "C:\ProgramData\Miniconda3\lib\site-packages\MySQLdb\connections.py", line 239, in query
    _mysql.connection.query(self, query)
MySQLdb._exceptions.OperationalError: (1054, "Unknown column 'distance' in 'where clause'")

The above exception was the direct cause of the following exception:

Traceback (most recent call last):
  File "C:\ProgramData\Miniconda3\lib\site-packages\django\core\handlers\exception.py", line 34, in inner
    response = get_response(request)
  File "C:\ProgramData\Miniconda3\lib\site-packages\django\core\handlers\base.py", line 115, in _get_response
    response = self.process_exception_by_middleware(e, request)
  File "C:\ProgramData\Miniconda3\lib\site-packages\django\core\handlers\base.py", line 113, in _get_response
    response = wrapped_callback(request, *callback_args, **callback_kwargs)
  File "C:\ProgramData\Miniconda3\lib\site-packages\django\views\decorators\csrf.py", line 54, in wrapped_view
    return view_func(*args, **kwargs)
  File "C:\ProgramData\Miniconda3\lib\site-packages\rest_framework\viewsets.py", line 114, in view
    return self.dispatch(request, *args, **kwargs)
  File "C:\ProgramData\Miniconda3\lib\site-packages\rest_framework\views.py", line 505, in dispatch
    response = self.handle_exception(exc)
  File "C:\ProgramData\Miniconda3\lib\site-packages\rest_framework\views.py", line 465, in handle_exception
    self.raise_uncaught_exception(exc)
  File "C:\ProgramData\Miniconda3\lib\site-packages\rest_framework\views.py", line 476, in raise_uncaught_exception
    raise exc
  File "C:\ProgramData\Miniconda3\lib\site-packages\rest_framework\views.py", line 502, in dispatch
    response = handler(request, *args, **kwargs)
  File "C:\ProgramData\Miniconda3\lib\site-packages\rest_framework\mixins.py", line 40, in list
    page = self.paginate_queryset(queryset)
  File "C:\ProgramData\Miniconda3\lib\site-packages\rest_framework\generics.py", line 171, in paginate_queryset
    return self.paginator.paginate_queryset(queryset, self.request, view=self)
  File "C:\ProgramData\Miniconda3\lib\site-packages\rest_framework\pagination.py", line 206, in paginate_queryset
    self.page = paginator.page(page_number)
  File "C:\ProgramData\Miniconda3\lib\site-packages\django\core\paginator.py", line 70, in page
    number = self.validate_number(number)
  File "C:\ProgramData\Miniconda3\lib\site-packages\django\core\paginator.py", line 48, in validate_number
    if number > self.num_pages:
  File "C:\ProgramData\Miniconda3\lib\site-packages\django\utils\functional.py", line 48, in __get__
    res = instance.__dict__[self.name] = self.func(instance)
  File "C:\ProgramData\Miniconda3\lib\site-packages\django\core\paginator.py", line 97, in num_pages
    if self.count == 0 and not self.allow_empty_first_page:
  File "C:\ProgramData\Miniconda3\lib\site-packages\django\utils\functional.py", line 48, in __get__
    res = instance.__dict__[self.name] = self.func(instance)
  File "C:\ProgramData\Miniconda3\lib\site-packages\django\core\paginator.py", line 92, in count
    return len(self.object_list)
  File "C:\ProgramData\Miniconda3\lib\site-packages\django\db\models\query.py", line 1413, in __len__
    self._fetch_all()
  File "C:\ProgramData\Miniconda3\lib\site-packages\django\db\models\query.py", line 1408, in _fetch_all
    self._result_cache = list(self.iterator())
  File "C:\ProgramData\Miniconda3\lib\site-packages\django\db\models\query.py", line 1431, in iterator
    query = iter(self.query)
  File "C:\ProgramData\Miniconda3\lib\site-packages\django\db\models\sql\query.py", line 109, in __iter__
    self._execute_query()
  File "C:\ProgramData\Miniconda3\lib\site-packages\django\db\models\sql\query.py", line 143, in _execute_query
    self.cursor.execute(self.sql, params)
  File "C:\ProgramData\Miniconda3\lib\site-packages\django\db\backends\utils.py", line 100, in execute
    return super().execute(sql, params)
  File "C:\ProgramData\Miniconda3\lib\site-packages\django\db\backends\utils.py", line 68, in execute
    return self._execute_with_wrappers(sql, params, many=False, executor=self._execute)
  File "C:\ProgramData\Miniconda3\lib\site-packages\django\db\backends\utils.py", line 77, in _execute_with_wrappers
    return executor(sql, params, many, context)
  File "C:\ProgramData\Miniconda3\lib\site-packages\django\db\backends\utils.py", line 86, in _execute
    return self.cursor.execute(sql, params)
  File "C:\ProgramData\Miniconda3\lib\site-packages\django\db\utils.py", line 90, in __exit__
    raise dj_exc_value.with_traceback(traceback) from exc_value
  File "C:\ProgramData\Miniconda3\lib\site-packages\django\db\backends\utils.py", line 86, in _execute
    return self.cursor.execute(sql, params)
  File "C:\ProgramData\Miniconda3\lib\site-packages\django\db\backends\mysql\base.py", line 74, in execute
    return self.cursor.execute(query, args)
  File "C:\ProgramData\Miniconda3\lib\site-packages\MySQLdb\cursors.py", line 209, in execute
    res = self._query(query)
  File "C:\ProgramData\Miniconda3\lib\site-packages\MySQLdb\cursors.py", line 315, in _query
    db.query(q)
  File "C:\ProgramData\Miniconda3\lib\site-packages\MySQLdb\connections.py", line 239, in query
    _mysql.connection.query(self, query)
django.db.utils.OperationalError: (1054, "Unknown column 'distance' in 'where clause'")
 django.request 2020-05-06 23:06:26,289 ERROR    Internal Server Error: /user/address
Traceback (most recent call last):
  File "C:\ProgramData\Miniconda3\lib\site-packages\django\db\backends\utils.py", line 86, in _execute
    return self.cursor.execute(sql, params)
  File "C:\ProgramData\Miniconda3\lib\site-packages\django\db\backends\mysql\base.py", line 74, in execute
    return self.cursor.execute(query, args)
  File "C:\ProgramData\Miniconda3\lib\site-packages\MySQLdb\cursors.py", line 209, in execute
    res = self._query(query)
  File "C:\ProgramData\Miniconda3\lib\site-packages\MySQLdb\cursors.py", line 315, in _query
    db.query(q)
  File "C:\ProgramData\Miniconda3\lib\site-packages\MySQLdb\connections.py", line 239, in query
    _mysql.connection.query(self, query)
MySQLdb._exceptions.OperationalError: (1054, "Unknown column 'distance' in 'where clause'")

The above exception was the direct cause of the following exception:

Traceback (most recent call last):
  File "C:\ProgramData\Miniconda3\lib\site-packages\django\core\handlers\exception.py", line 34, in inner
    response = get_response(request)
  File "C:\ProgramData\Miniconda3\lib\site-packages\django\core\handlers\base.py", line 115, in _get_response
    response = self.process_exception_by_middleware(e, request)
  File "C:\ProgramData\Miniconda3\lib\site-packages\django\core\handlers\base.py", line 113, in _get_response
    response = wrapped_callback(request, *callback_args, **callback_kwargs)
  File "C:\ProgramData\Miniconda3\lib\site-packages\django\views\decorators\csrf.py", line 54, in wrapped_view
    return view_func(*args, **kwargs)
  File "C:\ProgramData\Miniconda3\lib\site-packages\rest_framework\viewsets.py", line 114, in view
    return self.dispatch(request, *args, **kwargs)
  File "C:\ProgramData\Miniconda3\lib\site-packages\rest_framework\views.py", line 505, in dispatch
    response = self.handle_exception(exc)
  File "C:\ProgramData\Miniconda3\lib\site-packages\rest_framework\views.py", line 465, in handle_exception
    self.raise_uncaught_exception(exc)
  File "C:\ProgramData\Miniconda3\lib\site-packages\rest_framework\views.py", line 476, in raise_uncaught_exception
    raise exc
  File "C:\ProgramData\Miniconda3\lib\site-packages\rest_framework\views.py", line 502, in dispatch
    response = handler(request, *args, **kwargs)
  File "C:\ProgramData\Miniconda3\lib\site-packages\rest_framework\mixins.py", line 40, in list
    page = self.paginate_queryset(queryset)
  File "C:\ProgramData\Miniconda3\lib\site-packages\rest_framework\generics.py", line 171, in paginate_queryset
    return self.paginator.paginate_queryset(queryset, self.request, view=self)
  File "C:\ProgramData\Miniconda3\lib\site-packages\rest_framework\pagination.py", line 206, in paginate_queryset
    self.page = paginator.page(page_number)
  File "C:\ProgramData\Miniconda3\lib\site-packages\django\core\paginator.py", line 70, in page
    number = self.validate_number(number)
  File "C:\ProgramData\Miniconda3\lib\site-packages\django\core\paginator.py", line 48, in validate_number
    if number > self.num_pages:
  File "C:\ProgramData\Miniconda3\lib\site-packages\django\utils\functional.py", line 48, in __get__
    res = instance.__dict__[self.name] = self.func(instance)
  File "C:\ProgramData\Miniconda3\lib\site-packages\django\core\paginator.py", line 97, in num_pages
    if self.count == 0 and not self.allow_empty_first_page:
  File "C:\ProgramData\Miniconda3\lib\site-packages\django\utils\functional.py", line 48, in __get__
    res = instance.__dict__[self.name] = self.func(instance)
  File "C:\ProgramData\Miniconda3\lib\site-packages\django\core\paginator.py", line 92, in count
    return len(self.object_list)
  File "C:\ProgramData\Miniconda3\lib\site-packages\django\db\models\query.py", line 1413, in __len__
    self._fetch_all()
  File "C:\ProgramData\Miniconda3\lib\site-packages\django\db\models\query.py", line 1408, in _fetch_all
    self._result_cache = list(self.iterator())
  File "C:\ProgramData\Miniconda3\lib\site-packages\django\db\models\query.py", line 1431, in iterator
    query = iter(self.query)
  File "C:\ProgramData\Miniconda3\lib\site-packages\django\db\models\sql\query.py", line 109, in __iter__
    self._execute_query()
  File "C:\ProgramData\Miniconda3\lib\site-packages\django\db\models\sql\query.py", line 143, in _execute_query
    self.cursor.execute(self.sql, params)
  File "C:\ProgramData\Miniconda3\lib\site-packages\django\db\backends\utils.py", line 100, in execute
    return super().execute(sql, params)
  File "C:\ProgramData\Miniconda3\lib\site-packages\django\db\backends\utils.py", line 68, in execute
    return self._execute_with_wrappers(sql, params, many=False, executor=self._execute)
  File "C:\ProgramData\Miniconda3\lib\site-packages\django\db\backends\utils.py", line 77, in _execute_with_wrappers
    return executor(sql, params, many, context)
  File "C:\ProgramData\Miniconda3\lib\site-packages\django\db\backends\utils.py", line 86, in _execute
    return self.cursor.execute(sql, params)
  File "C:\ProgramData\Miniconda3\lib\site-packages\django\db\utils.py", line 90, in __exit__
    raise dj_exc_value.with_traceback(traceback) from exc_value
  File "C:\ProgramData\Miniconda3\lib\site-packages\django\db\backends\utils.py", line 86, in _execute
    return self.cursor.execute(sql, params)
  File "C:\ProgramData\Miniconda3\lib\site-packages\django\db\backends\mysql\base.py", line 74, in execute
    return self.cursor.execute(query, args)
  File "C:\ProgramData\Miniconda3\lib\site-packages\MySQLdb\cursors.py", line 209, in execute
    res = self._query(query)
  File "C:\ProgramData\Miniconda3\lib\site-packages\MySQLdb\cursors.py", line 315, in _query
    db.query(q)
  File "C:\ProgramData\Miniconda3\lib\site-packages\MySQLdb\connections.py", line 239, in query
    _mysql.connection.query(self, query)
django.db.utils.OperationalError: (1054, "Unknown column 'distance' in 'where clause'")
 django.request 2020-05-06 23:07:18,070 ERROR    Internal Server Error: /user/address
Traceback (most recent call last):
  File "C:\ProgramData\Miniconda3\lib\site-packages\django\db\backends\utils.py", line 86, in _execute
    return self.cursor.execute(sql, params)
  File "C:\ProgramData\Miniconda3\lib\site-packages\django\db\backends\mysql\base.py", line 74, in execute
    return self.cursor.execute(query, args)
  File "C:\ProgramData\Miniconda3\lib\site-packages\MySQLdb\cursors.py", line 209, in execute
    res = self._query(query)
  File "C:\ProgramData\Miniconda3\lib\site-packages\MySQLdb\cursors.py", line 315, in _query
    db.query(q)
  File "C:\ProgramData\Miniconda3\lib\site-packages\MySQLdb\connections.py", line 239, in query
    _mysql.connection.query(self, query)
MySQLdb._exceptions.OperationalError: (1054, "Unknown column 'distance' in 'where clause'")

The above exception was the direct cause of the following exception:

Traceback (most recent call last):
  File "C:\ProgramData\Miniconda3\lib\site-packages\django\core\handlers\exception.py", line 34, in inner
    response = get_response(request)
  File "C:\ProgramData\Miniconda3\lib\site-packages\django\core\handlers\base.py", line 115, in _get_response
    response = self.process_exception_by_middleware(e, request)
  File "C:\ProgramData\Miniconda3\lib\site-packages\django\core\handlers\base.py", line 113, in _get_response
    response = wrapped_callback(request, *callback_args, **callback_kwargs)
  File "C:\ProgramData\Miniconda3\lib\site-packages\django\views\decorators\csrf.py", line 54, in wrapped_view
    return view_func(*args, **kwargs)
  File "C:\ProgramData\Miniconda3\lib\site-packages\rest_framework\viewsets.py", line 114, in view
    return self.dispatch(request, *args, **kwargs)
  File "C:\ProgramData\Miniconda3\lib\site-packages\rest_framework\views.py", line 505, in dispatch
    response = self.handle_exception(exc)
  File "C:\ProgramData\Miniconda3\lib\site-packages\rest_framework\views.py", line 465, in handle_exception
    self.raise_uncaught_exception(exc)
  File "C:\ProgramData\Miniconda3\lib\site-packages\rest_framework\views.py", line 476, in raise_uncaught_exception
    raise exc
  File "C:\ProgramData\Miniconda3\lib\site-packages\rest_framework\views.py", line 502, in dispatch
    response = handler(request, *args, **kwargs)
  File "C:\ProgramData\Miniconda3\lib\site-packages\rest_framework\mixins.py", line 40, in list
    page = self.paginate_queryset(queryset)
  File "C:\ProgramData\Miniconda3\lib\site-packages\rest_framework\generics.py", line 171, in paginate_queryset
    return self.paginator.paginate_queryset(queryset, self.request, view=self)
  File "C:\ProgramData\Miniconda3\lib\site-packages\rest_framework\pagination.py", line 206, in paginate_queryset
    self.page = paginator.page(page_number)
  File "C:\ProgramData\Miniconda3\lib\site-packages\django\core\paginator.py", line 70, in page
    number = self.validate_number(number)
  File "C:\ProgramData\Miniconda3\lib\site-packages\django\core\paginator.py", line 48, in validate_number
    if number > self.num_pages:
  File "C:\ProgramData\Miniconda3\lib\site-packages\django\utils\functional.py", line 48, in __get__
    res = instance.__dict__[self.name] = self.func(instance)
  File "C:\ProgramData\Miniconda3\lib\site-packages\django\core\paginator.py", line 97, in num_pages
    if self.count == 0 and not self.allow_empty_first_page:
  File "C:\ProgramData\Miniconda3\lib\site-packages\django\utils\functional.py", line 48, in __get__
    res = instance.__dict__[self.name] = self.func(instance)
  File "C:\ProgramData\Miniconda3\lib\site-packages\django\core\paginator.py", line 92, in count
    return len(self.object_list)
  File "C:\ProgramData\Miniconda3\lib\site-packages\django\db\models\query.py", line 1413, in __len__
    self._fetch_all()
  File "C:\ProgramData\Miniconda3\lib\site-packages\django\db\models\query.py", line 1408, in _fetch_all
    self._result_cache = list(self.iterator())
  File "C:\ProgramData\Miniconda3\lib\site-packages\django\db\models\query.py", line 1431, in iterator
    query = iter(self.query)
  File "C:\ProgramData\Miniconda3\lib\site-packages\django\db\models\sql\query.py", line 109, in __iter__
    self._execute_query()
  File "C:\ProgramData\Miniconda3\lib\site-packages\django\db\models\sql\query.py", line 143, in _execute_query
    self.cursor.execute(self.sql, params)
  File "C:\ProgramData\Miniconda3\lib\site-packages\django\db\backends\utils.py", line 100, in execute
    return super().execute(sql, params)
  File "C:\ProgramData\Miniconda3\lib\site-packages\django\db\backends\utils.py", line 68, in execute
    return self._execute_with_wrappers(sql, params, many=False, executor=self._execute)
  File "C:\ProgramData\Miniconda3\lib\site-packages\django\db\backends\utils.py", line 77, in _execute_with_wrappers
    return executor(sql, params, many, context)
  File "C:\ProgramData\Miniconda3\lib\site-packages\django\db\backends\utils.py", line 86, in _execute
    return self.cursor.execute(sql, params)
  File "C:\ProgramData\Miniconda3\lib\site-packages\django\db\utils.py", line 90, in __exit__
    raise dj_exc_value.with_traceback(traceback) from exc_value
  File "C:\ProgramData\Miniconda3\lib\site-packages\django\db\backends\utils.py", line 86, in _execute
    return self.cursor.execute(sql, params)
  File "C:\ProgramData\Miniconda3\lib\site-packages\django\db\backends\mysql\base.py", line 74, in execute
    return self.cursor.execute(query, args)
  File "C:\ProgramData\Miniconda3\lib\site-packages\MySQLdb\cursors.py", line 209, in execute
    res = self._query(query)
  File "C:\ProgramData\Miniconda3\lib\site-packages\MySQLdb\cursors.py", line 315, in _query
    db.query(q)
  File "C:\ProgramData\Miniconda3\lib\site-packages\MySQLdb\connections.py", line 239, in query
    _mysql.connection.query(self, query)
django.db.utils.OperationalError: (1054, "Unknown column 'distance' in 'where clause'")
 django.request 2020-05-06 23:14:49,907 ERROR    Internal Server Error: /user/address
Traceback (most recent call last):
  File "C:\ProgramData\Miniconda3\lib\site-packages\django\db\backends\utils.py", line 86, in _execute
    return self.cursor.execute(sql, params)
  File "C:\ProgramData\Miniconda3\lib\site-packages\django\db\backends\mysql\base.py", line 74, in execute
    return self.cursor.execute(query, args)
  File "C:\ProgramData\Miniconda3\lib\site-packages\MySQLdb\cursors.py", line 209, in execute
    res = self._query(query)
  File "C:\ProgramData\Miniconda3\lib\site-packages\MySQLdb\cursors.py", line 315, in _query
    db.query(q)
  File "C:\ProgramData\Miniconda3\lib\site-packages\MySQLdb\connections.py", line 239, in query
    _mysql.connection.query(self, query)
MySQLdb._exceptions.OperationalError: (1054, "Unknown column '$latitude' in 'field list'")

The above exception was the direct cause of the following exception:

Traceback (most recent call last):
  File "C:\ProgramData\Miniconda3\lib\site-packages\django\core\handlers\exception.py", line 34, in inner
    response = get_response(request)
  File "C:\ProgramData\Miniconda3\lib\site-packages\django\core\handlers\base.py", line 115, in _get_response
    response = self.process_exception_by_middleware(e, request)
  File "C:\ProgramData\Miniconda3\lib\site-packages\django\core\handlers\base.py", line 113, in _get_response
    response = wrapped_callback(request, *callback_args, **callback_kwargs)
  File "C:\ProgramData\Miniconda3\lib\site-packages\django\views\decorators\csrf.py", line 54, in wrapped_view
    return view_func(*args, **kwargs)
  File "C:\ProgramData\Miniconda3\lib\site-packages\rest_framework\viewsets.py", line 114, in view
    return self.dispatch(request, *args, **kwargs)
  File "C:\ProgramData\Miniconda3\lib\site-packages\rest_framework\views.py", line 505, in dispatch
    response = self.handle_exception(exc)
  File "C:\ProgramData\Miniconda3\lib\site-packages\rest_framework\views.py", line 465, in handle_exception
    self.raise_uncaught_exception(exc)
  File "C:\ProgramData\Miniconda3\lib\site-packages\rest_framework\views.py", line 476, in raise_uncaught_exception
    raise exc
  File "C:\ProgramData\Miniconda3\lib\site-packages\rest_framework\views.py", line 502, in dispatch
    response = handler(request, *args, **kwargs)
  File "C:\ProgramData\Miniconda3\lib\site-packages\rest_framework\mixins.py", line 40, in list
    page = self.paginate_queryset(queryset)
  File "C:\ProgramData\Miniconda3\lib\site-packages\rest_framework\generics.py", line 171, in paginate_queryset
    return self.paginator.paginate_queryset(queryset, self.request, view=self)
  File "C:\ProgramData\Miniconda3\lib\site-packages\rest_framework\pagination.py", line 206, in paginate_queryset
    self.page = paginator.page(page_number)
  File "C:\ProgramData\Miniconda3\lib\site-packages\django\core\paginator.py", line 70, in page
    number = self.validate_number(number)
  File "C:\ProgramData\Miniconda3\lib\site-packages\django\core\paginator.py", line 48, in validate_number
    if number > self.num_pages:
  File "C:\ProgramData\Miniconda3\lib\site-packages\django\utils\functional.py", line 48, in __get__
    res = instance.__dict__[self.name] = self.func(instance)
  File "C:\ProgramData\Miniconda3\lib\site-packages\django\core\paginator.py", line 97, in num_pages
    if self.count == 0 and not self.allow_empty_first_page:
  File "C:\ProgramData\Miniconda3\lib\site-packages\django\utils\functional.py", line 48, in __get__
    res = instance.__dict__[self.name] = self.func(instance)
  File "C:\ProgramData\Miniconda3\lib\site-packages\django\core\paginator.py", line 92, in count
    return len(self.object_list)
  File "C:\ProgramData\Miniconda3\lib\site-packages\django\db\models\query.py", line 1413, in __len__
    self._fetch_all()
  File "C:\ProgramData\Miniconda3\lib\site-packages\django\db\models\query.py", line 1408, in _fetch_all
    self._result_cache = list(self.iterator())
  File "C:\ProgramData\Miniconda3\lib\site-packages\django\db\models\query.py", line 1431, in iterator
    query = iter(self.query)
  File "C:\ProgramData\Miniconda3\lib\site-packages\django\db\models\sql\query.py", line 109, in __iter__
    self._execute_query()
  File "C:\ProgramData\Miniconda3\lib\site-packages\django\db\models\sql\query.py", line 143, in _execute_query
    self.cursor.execute(self.sql, params)
  File "C:\ProgramData\Miniconda3\lib\site-packages\django\db\backends\utils.py", line 100, in execute
    return super().execute(sql, params)
  File "C:\ProgramData\Miniconda3\lib\site-packages\django\db\backends\utils.py", line 68, in execute
    return self._execute_with_wrappers(sql, params, many=False, executor=self._execute)
  File "C:\ProgramData\Miniconda3\lib\site-packages\django\db\backends\utils.py", line 77, in _execute_with_wrappers
    return executor(sql, params, many, context)
  File "C:\ProgramData\Miniconda3\lib\site-packages\django\db\backends\utils.py", line 86, in _execute
    return self.cursor.execute(sql, params)
  File "C:\ProgramData\Miniconda3\lib\site-packages\django\db\utils.py", line 90, in __exit__
    raise dj_exc_value.with_traceback(traceback) from exc_value
  File "C:\ProgramData\Miniconda3\lib\site-packages\django\db\backends\utils.py", line 86, in _execute
    return self.cursor.execute(sql, params)
  File "C:\ProgramData\Miniconda3\lib\site-packages\django\db\backends\mysql\base.py", line 74, in execute
    return self.cursor.execute(query, args)
  File "C:\ProgramData\Miniconda3\lib\site-packages\MySQLdb\cursors.py", line 209, in execute
    res = self._query(query)
  File "C:\ProgramData\Miniconda3\lib\site-packages\MySQLdb\cursors.py", line 315, in _query
    db.query(q)
  File "C:\ProgramData\Miniconda3\lib\site-packages\MySQLdb\connections.py", line 239, in query
    _mysql.connection.query(self, query)
django.db.utils.OperationalError: (1054, "Unknown column '$latitude' in 'field list'")
